Workbook

Sheet July 2024
A1: Datum | B1: Název | C1: Jména Instor | D1: Začátek směny Instor | E1: Konec směny Instor | F1: Pauza Instor | G1: Počet hodin Instor | H1: Jména Kurýr | I1: Začátek směny Kurýr | J1: Konec směny Kurýr | K1: Pauza Kurýr | L1: Počet hodin Kurýr | M1: Počet rozvozů Kurýr | N1: TRUE | O1: Vyplatit PHM | P1: Wolt drive | Q1: Otevíral | R1: Zavíral | S1: Online Platby - Wolt | T1: Online Platby - Bolt | U1: Online Platby - Dáme Jídlo | V1: Vlastní API | W1: Online Platby - Wolt cash | X1: Online Platby - DJ Cash | Y1: Terminál | Z1: Stravenky | AA1: Hotovost | AB1: Tržba | AC1: Pokladna - VÝSLEDEK | AD1: COL | AE1: Benzín | AF1: Auta | AG1: Suroviny | AH1: Ostatní | AI1: PHM - soukromé | AJ1: Zrušené obj. ks | AK1: Zrušené obj. $ | AL1: Počet zpožděných objednávek z webu +5 min | AM1: Průměrný make Time | AN1: Počet vydajových dokladů
A2: 45499 | B2: Pátek | C2: Veselý Ondřej | D2: 10:00 | E2: 22:00 | G2: 12:00
A3: 45499 | B3: Pátek | C3: Michal Nedbal | D3: 17:00 | E3: 1:00 | G3: 08:00
A4: 45499 | B4: Pátek | C4: Suchánek Daniel | D4: 10:00 | E4: 23:00 | G4: 13:00
A5: 45499 | B5: Pátek | C5: Šebesta Tomáš | D5: 10:00 | E5: 23:00 | G5: 13:00
A6: 45499 | B6: Pátek | C6: Hanakova Ayuna | D6: 10:00 | E6: 17:00 | G6: 07:00
A7: 45499 | B7: Pátek | H7: Kučera Karel | I7: 17:00 | J7: 1:00 | L7: 08:00 | M7: 10 | N7: TRUE | O7: 400
A8: 45499 | B8: Pátek | H8: Černohorský Otakar | I8: 00:30 | J8: 00:00 | L8: 23:30 | M8: 1
A9: 45499 | B9: Pátek | S9: 10 | T9: 20 | U9: 30 | V9: 4 | W9: 5 | X9: 6 | Y9: 7 | Z9: 8 | AA9: 9 | AB9: 50000 | AC9: -37157 | AD9: 0.49276157 | AE9: 11 | AF9: 111 | AG9: 1111 | AH9: 11111 | AI9: 400 | AL9: 5 | AM9: 11 min 45 s | AN9: 1
A10: 45499 | B10: Pátek | AC10: 0 | AD10: Zadej tržbu | AI10: 0 | AN10: 1
A11: 45496 | B11: Úterý | C11: Kučera Karel | D11: 10:00 | E11: 17:00 | G11: 07:00 | AJ11: 1 | AK11: 5 | AM11: 11 min 45 s
A12: 45496 | B12: Úterý | C12: Veselý Ondřej | D12: 10:00 | E12: 20:00 | G12: 10:00 | AJ12: 1 | AK12: 2
A13: 45496 | B13: Úterý | C13: Michal Nedbal | D13: 17:00 | E13: 1:00 | G13: 08:00 | AJ13: 1 | AK13: 1 | AM13: 11 min 45 s | AN13: 2
A14: 45496 | B14: Úterý | H14: Černohorský Otakar | I14: 11:00 | J14: 17:00 | L14: 06:00
A15: 45496 | B15: Úterý | H15: Novák Jakub | I15: 17:00 | J15: 1:00 | L15: 08:00
A16: 45496 | B16: Úterý | S16: 9060 | T16: 3651 | U16: 14729 | V16: 10695 | W16: 374 | X16: 368 | AB16: 41872 | AC16: -2995 | AD16: 0.23834367 | AI16: 0 | AN16: 0
A17: 45501 | B17: Neděle | C17: Veselý Ondřej | D17: 17:00 | E17: 0:00 | G17: 07:00
A18: 45501 | B18: Neděle | C18: Michal Nedbal | D18: 17:00 | E18: 0:00 | G18: 07:00
A19: 45501 | B19: Neděle | H19: Kučera Karel | I19: 11:00 | J19: 17:00 | L19: 06:00
A20: 45501 | B20: Neděle | H20: Novák Jakub | I20: 17:00 | J20: 0:00 | L20: 07:00
A21: 45501 | B21: Neděle | AC21: 0 | AD21: Zadej tržbu | AI21: 0
A22: 45502 | B22: Pondělí | C22: Hanakova Ayuna | D22: 17:00 | E22: 0:00 | G22: 07:00
A23: 45502 | B23: Pondělí | C23: Černohorský Otakar | D23: 17:00 | E23: 0:00 | G23: 07:00
A24: 45502 | B24: Pondělí | H24: Kučera Karel | I24: 11:00 | J24: 18:00 | L24: 07:00
A25: 45502 | B25: Pondělí | H25: Jakub Zimmer | I25: 18:00 | J25: 0:00 | L25: 06:00
A26: 45502 | B26: Pondělí | AC26: 0 | AD26: Zadej tržbu | AI26: 0
A27: 45503 | B27: Úterý | C27: Kučera Karel | D27: 11:00 | E27: 17:00 | G27: 06:00
A28: 45503 | B28: Úterý | C28: Trachtová Martina | D28: 10:00 | E28: 17:00 | G28: 07:00
A29: 45503 | B29: Úterý | C29: Veselý Ondřej | D29: 17:00 | E29: 0:00 | G29: 07:00
A30: 45503 | B30: Úterý | H30: Novák Jakub | I30: 17:00 | J30: 0:00 | L30: 07:00
A31: 45503 | B31: Úterý | AC31: 0 | AD31: Zadej tržbu | AI31: 0
A32: 45504 | B32: Středa | C32: Hanakova Ayuna | D32: 17:00 | E32: 0:00 | G32: 07:00
A33: 45504 | B33: Středa | H33: Novák Jakub | I33: 11:00 | J33: 18:00 | L33: 07:00
A34: 45504 | B34: Středa | H34: Jakub Zimmer | L34: 0:00 | M34: 4
A35: 45504 | B35: Středa | P35: 3 | S35: 9414 | T35: 3907 | U35: 9081 | V35: 4024 | W35: 1310 | X35: 2052 | AB35: 38044 | AC35: -8256 | AD35: 0.25491082 | AI35: 0 | AN35: 0

Sheet DatabaseRestia
A1: Datum | B1: Platforma | C1: Stav | D1: Cena | E1: Sleva | F1: Kurýr | G1: Doručení | H1: Platba | I1: Vytvořeno | J1: Připraveno v | K1: Dokončeno v | L1: Přenos do dispecinku | M1: Zpoždění | N1: Přiřazení WoltDrivu | O1: Make Time
A2: 45527 | B2: wolt | C2: ready_pickup | D2: 377 | E2: 0 | F2: Wolt Kurýr | G2: external-delivery | H2: online | I2: 2024-08-24T02:26:06.216+02:00 | J2: 2024-08-24T02:36:57.269+02:00 | K2: 2024-08-24T02:36:57.269+02:00 | M2: -4 | O2: 10.850883
A3: 45527 | B3: damejidlo | C3: ready_pickup | D3: 271 | E3: 50 | G3: external-delivery | H3: cash | I3: 2024-08-24T01:49:47.019+02:00 | J3: 2024-08-24T01:55:39.344+02:00 | K3: 2024-08-24T01:55:39.344+02:00 | M3: -2 | O3: 5.8720833
A4: 45527 | B4: damejidlo | C4: ready_pickup | D4: 273 | E4: 0 | G4: external-delivery | H4: cash | I4: 2024-08-24T01:46:19.469+02:00 | J4: 2024-08-24T01:54:00.246+02:00 | K4: 2024-08-24T01:54:00.246+02:00 | M4: 0 | O4: 7.6796167
A5: 45527 | B5: damejidlo | C5: ready_pickup | D5: 498 | E5: 0 | G5: external-delivery | H5: online | I5: 2024-08-24T01:31:47.044+02:00 | J5: 2024-08-24T01:41:46.273+02:00 | K5: 2024-08-24T01:41:46.273+02:00 | M5: 1 | O5: 9.98715
A6: 45527 | B6: bolt | C6: ready_pickup | D6: 329 | E6: 0 | F6: Kuldeep | G6: external-delivery | H6: online | I6: 2024-08-24T01:31:17.833+02:00 | J6: 2024-08-24T01:46:54.181+02:00 | K6: 2024-08-24T01:46:54.181+02:00 | M6: 0 | O6: 15.6058
A7: 45527 | B7: wolt | C7: delivered | D7: 289 | E7: 0 | F7: Wolt Kurýr | G7: external-delivery | H7: online | I7: 2024-08-24T01:20:07.722+02:00 | J7: 2024-08-24T01:27:23.215+02:00 | K7: 2024-08-24T01:27:23.215+02:00 | M7: -7 | O7: 7.2582167
A8: 45527 | B8: manual | C8: delivered | D8: 80 | E8: 0 | G8: pickup | H8: cash | I8: 2024-08-24T01:13:35.417+02:00 | J8: 2024-08-24T01:14:02.397+02:00 | K8: 2024-08-24T01:14:02.397+02:00 | M8: -4 | O8: 0.44966667
A9: 45527 | B9: wolt | C9: delivered | D9: 399 | E9: 0 | F9: Wolt Kurýr | G9: external-delivery | H9: online | I9: 2024-08-24T01:11:04.401+02:00 | J9: 2024-08-24T01:26:36.285+02:00 | K9: 2024-08-24T01:26:36.285+02:00 | M9: 0 | O9: 15.5314
A10: 45527 | B10: generic | C10: delivered | D10: 245 | E10: 61 | G10: pickup | H10: cash | I10: 2024-08-24T00:59:03.033+02:00 | J10: 2024-08-24T01:11:21.995+02:00 | K10: 2024-08-24T01:11:21.995+02:00 | M10: -6 | O10: 12.316033
A11: 45527 | B11: bolt | C11: ready_pickup | D11: 321 | E11: 0 | F11: Shirshak | G11: external-delivery | H11: online | I11: 2024-08-24T00:55:11.648+02:00 | J11: 2024-08-24T01:04:47.133+02:00 | K11: 2024-08-24T01:04:47.133+02:00 | M11: -5 | O11: 9.5914167
A12: 45527 | B12: bolt | C12: ready_pickup | D12: 723 | E12: 0 | F12: Volodymyr | G12: external-delivery | H12: online | I12: 2024-08-24T00:40:52.520+02:00 | J12: 2024-08-24T01:03:21.084+02:00 | K12: 2024-08-24T01:03:21.084+02:00 | M12: 2 | O12: 22.476067
A13: 45527 | B13: manual | C13: ready_pickup | D13: 49 | E13: 0 | G13: pickup | H13: cash | I13: 2024-08-24T00:30:50.156+02:00 | J13: 2024-08-24T00:32:40.988+02:00 | K13: 2024-08-24T00:32:40.988+02:00 | M13: -3 | O13: 1.8472
A14: 45527 | B14: damejidlo | C14: ready_pickup | D14: 264 | E14: 100 | G14: external-delivery | H14: online | I14: 2024-08-24T00:30:45.992+02:00 | J14: 2024-08-24T00:49:17.672+02:00 | K14: 2024-08-24T00:49:17.672+02:00 | M14: 9 | O14: 18.528
A15: 45527 | B15: bolt | C15: ready_pickup | D15: 394 | E15: 0 | F15: Shirshak | G15: external-delivery | H15: online | I15: 2024-08-24T00:25:55.526+02:00 | J15: 2024-08-24T00:47:58.140+02:00 | K15: 2024-08-24T00:47:58.140+02:00 | M15: 7 | O15: 22.043567
A16: 45527 | B16: bolt | C16: ready_pickup | D16: 289 | E16: 0 | F16: Zilolahon | G16: external-delivery | H16: online | I16: 2024-08-24T00:25:37.925+02:00 | J16: 2024-08-24T00:45:36.099+02:00 | K16: 2024-08-24T00:45:36.099+02:00 | M16: 4 | O16: 19.969567
A17: 45527 | B17: damejidlo | C17: ready_pickup | D17: 373 | E17: 150 | G17: external-delivery | H17: online | I17: 2024-08-24T00:21:46.024+02:00 | J17: 2024-08-24T00:36:40.313+02:00 | K17: 2024-08-24T00:36:40.313+02:00 | M17: 5 | O17: 14.904817
A18: 45527 | B18: manual | C18: ready_pickup | D18: 309 | E18: 0 | G18: pickup | H18: cash | I18: 2024-08-24T00:21:04.648+02:00 | J18: 2024-08-24T00:54:35.008+02:00 | K18: 2024-08-24T00:54:35.008+02:00 | M18: 28 | O18: 33.506
A19: 45527 | B19: damejidlo | C19: ready_pickup | D19: 508 | E19: 150 | G19: external-delivery | H19: online | I19: 2024-08-24T00:20:45.503+02:00 | J19: 2024-08-24T00:33:39.369+02:00 | K19: 2024-08-24T00:33:39.369+02:00 | M19: 1 | O19: 12.897767
A20: 45527 | B20: manual | C20: ready_pickup | D20: 249 | E20: 0 | G20: pickup | H20: cash | I20: 2024-08-24T00:20:21.251+02:00 | J20: 2024-08-24T00:52:46.081+02:00 | K20: 2024-08-24T00:52:46.081+02:00 | M20: 27 | O20: 32.413833
A21: 45527 | B21: manual | C21: ready_pickup | D21: 249 | E21: 0 | G21: pickup | H21: cash | I21: 2024-08-24T00:19:47.525+02:00 | J21: 2024-08-24T00:49:49.999+02:00 | K21: 2024-08-24T00:49:49.999+02:00 | M21: 25 | O21: 30.041233
A22: 45527 | B22: manual | C22: ready_pickup | D22: 249 | E22: 0 | G22: pickup | H22: cash | I22: 2024-08-24T00:19:23.248+02:00 | J22: 2024-08-24T00:45:55.976+02:00 | K22: 2024-08-24T00:45:55.976+02:00 | M22: 21 | O22: 26.545467
A23: 45527 | B23: manual | C23: ready_pickup | D23: 498 | E23: 0 | G23: pickup | H23: cash | I23: 2024-08-24T00:18:27.940+02:00 | J23: 2024-08-24T00:40:30.013+02:00 | K23: 2024-08-24T00:40:30.013+02:00 | M23: 17 | O23: 22.03455
A24: 45527 | B24: damejidlo | C24: ready_pickup | D24: 758 | E24: 0 | G24: external-delivery | H24: cash | I24: 2024-08-24T00:17:46.098+02:00 | J24: 2024-08-24T00:29:20.267+02:00 | K24: 2024-08-24T00:29:20.267+02:00 | M24: 0 | O24: 11.569483
A25: 45527 | B25: damejidlo | C25: ready_pickup | D25: 313 | E25: 100 | G25: external-delivery | H25: cash | I25: 2024-08-24T00:15:45.602+02:00 | J25: 2024-08-24T00:25:16.444+02:00 | K25: 2024-08-24T00:25:16.444+02:00 | M25: 1 | O25: 9.5140333
A26: 45527 | B26: wolt | C26: delivered | D26: 378 | E26: 0 | F26: Wolt Kurýr | G26: external-delivery | H26: online | I26: 2024-08-24T00:14:37.658+02:00 | J26: 2024-08-24T00:23:58.169+02:00 | K26: 2024-08-24T00:23:58.169+02:00 | M26: -5 | O26: 9.34185
A27: 45527 | B27: manual | C27: ready_pickup | D27: 239 | E27: 239 | G27: pickup | H27: cash | I27: 2024-08-24T00:07:03.036+02:00 | J27: 2024-08-24T00:13:59.002+02:00 | K27: 2024-08-24T00:13:59.002+02:00 | M27: 1 | O27: 6.9327667
A28: 45527 | B28: wolt | C28: delivered | D28: 618 | E28: 0 | F28: Wolt Kurýr | G28: external-delivery | H28: online | I28: 2024-08-23T23:46:55.346+02:00 | J28: 2024-08-24T00:06:01.208+02:00 | K28: 2024-08-24T00:06:01.208+02:00 | M28: 0 | O28: 19.0977
A29: 45527 | B29: damejidlo | C29: delivered | D29: 313 | E29: 0 | G29: external-delivery | H29: cash | I29: 2024-08-23T23:43:45.093+02:00 | J29: 2024-08-24T00:01:46.355+02:00 | K29: 2024-08-24T00:01:46.355+02:00 | M29: 9 | O29: 18.021033
A30: 45527 | B30: damejidlo | C30: delivered | D30: 658 | E30: 0 | G30: external-delivery | H30: online | I30: 2024-08-23T23:41:44.727+02:00 | J30: 2024-08-23T23:57:45.386+02:00 | K30: 2024-08-23T23:57:45.386+02:00 | M30: 6 | O30: 16.010983
A31: 45527 | B31: damejidlo | C31: delivered | D31: 434 | E31: 0 | G31: external-delivery | H31: cash | I31: 2024-08-23T23:41:44.678+02:00 | J31: 2024-08-23T23:49:40.491+02:00 | K31: 2024-08-23T23:49:40.491+02:00 | M31: -1 | O31: 7.9302167
A32: 45527 | B32: damejidlo | C32: delivered | D32: 433 | E32: 0 | G32: external-delivery | H32: online | I32: 2024-08-23T23:39:45.699+02:00 | J32: 2024-08-23T23:48:05.551+02:00 | K32: 2024-08-23T23:48:05.551+02:00 | M32: 0 | O32: 8.3308667
A33: 45527 | B33: wolt | C33: delivered | D33: 264 | E33: 0 | F33: Wolt Kurýr | G33: external-delivery | H33: online | I33: 2024-08-23T23:23:48.037+02:00 | J33: 2024-08-23T23:31:31.287+02:00 | K33: 2024-08-23T23:31:31.287+02:00 | M33: -7 | O33: 7.7208333
A34: 45527 | B34: manual | C34: delivered | D34: 39 | E34: 0 | G34: pickup | H34: cash | I34: 2024-08-23T23:17:51.235+02:00 | J34: 2024-08-23T23:19:44.998+02:00 | K34: 2024-08-23T23:19:44.998+02:00 | M34: -3 | O34: 1.89605
A35: 45527 | B35: manual | C35: delivered | D35: 39 | E35: 0 | G35: pickup | H35: cash | I35: 2024-08-23T23:13:47.229+02:00 | J35: 2024-08-23T23:15:42.031+02:00 | K35: 2024-08-23T23:15:42.031+02:00 | M35: -3 | O35: 1.9133667
A36: 45527 | B36: damejidlo | C36: ready_pickup | D36: 585 | E36: 0 | G36: external-delivery | H36: online | I36: 2024-08-23T23:11:43.987+02:00 | J36: 2024-08-23T23:20:02.508+02:00 | K36: 2024-08-23T23:20:02.508+02:00 | M36: -2 | O36: 8.3086833
A37: 45527 | B37: generic | C37: delivered | D37: 250 | E37: 0 | F37: Čech Dominik | G37: delivery | H37: online | I37: 2024-08-23T23:04:02.973+02:00 | J37: 2024-08-23T23:22:10.029+02:00 | K37: 2024-08-23T23:29:41.605+02:00 | L37: 2024-08-23T23:04:03.599+02:00 | M37: -1 | N37: 0.010433333 | O37: 18.1176
A38: 45527 | B38: damejidlo | C38: ready_pickup | D38: 474 | E38: 0 | G38: external-delivery | H38: cash | I38: 2024-08-23T22:56:45.092+02:00 | J38: 2024-08-23T23:17:32.262+02:00 | K38: 2024-08-23T23:17:32.262+02:00 | M38: 11 | O38: 20.786167
A39: 45527 | B39: damejidlo | C39: ready_pickup | D39: 394 | E39: 0 | G39: external-delivery | H39: online | I39: 2024-08-23T22:55:07.053+02:00 | J39: 2024-08-23T23:12:34.408+02:00 | K39: 2024-08-23T23:12:34.407+02:00 | M39: 9 | O39: 17.455917
A40: 45527 | B40: damejidlo | C40: ready_pickup | D40: 364 | E40: 0 | G40: external-delivery | H40: online | I40: 2024-08-23T22:52:44.762+02:00 | J40: 2024-08-23T23:09:34.381+02:00 | K40: 2024-08-23T23:09:34.381+02:00 | M40: 8 | O40: 16.826983
...

Sheet August 2024
A1: Datum | B1: Název | C1: Jména Instor | D1: Začátek směny Instor | E1: Konec směny Instor | F1: Pauza Instor | G1: Počet hodin Instor | H1: Jména Kurýr | I1: Začátek směny Kurýr | J1: Konec směny Kurýr | K1: Pauza Kurýr | L1: Počet hodin Kurýr | M1: Počet rozvozů Kurýr | N1: Vlastní vůz | O1: Vyplatit PHM | P1: Wolt drive | Q1: Otevíral | R1: Zavíral | S1: Online Platby - Wolt | T1: Online Platby - Bolt | U1: Online Platby - Dáme Jídlo | V1: Vlastní API | W1: Online Platby - Wolt cash | X1: Online Platby - DJ Cash | Y1: Terminál | Z1: Stravenky | AA1: Hotovost | AB1: Tržba | AC1: Pokladna - VÝSLEDEK | AD1: COL | AE1: Benzín | AF1: Auta | AG1: Suroviny | AH1: Ostatní | AI1: PHM - soukromé | AJ1: Zrušené obj. ks | AK1: Zrušené obj. $ | AL1: Počet zpožděných objednávek z webu +5 min | AM1: Průměrný make Time | AN1: Počet vydajových dokladů | AO1: Počet nezrušených celkem | AP1: Počet našich rozvozů | AQ1: Počet pozdě přiřazeným WoltDrive 5+ | AR1: Woltrdrive zpožděný kvůli našemu pozdnímu přiřazení | AS1: % zpožděných našich rozvozů +5 min | AT1: Počet zpožděných Woltdrivem | AU1: % doručených včas | AV1: % zpožděných Woltdrivem
A2: 45505 | B2: Čtvrtek | C2: Kinkorová Petra | D2: 10:00 | E2: 17:00 | G2: 07:00
A3: 45505 | B3: Čtvrtek | C3: Kořínek Dominik | D3: 17:00 | E3: 01:00 | G3: 08:00
A4: 45505 | B4: Čtvrtek | C4: Jáklová Dominika | D4: 17:00 | E4: 01:30 | G4: 08:30
A5: 45505 | B5: Čtvrtek | H5: Melmer David | I5: 11:00 | J5: 16:00 | L5: 05:00 | M5: 2
A6: 45505 | B6: Čtvrtek | H6: Čech Dominik | I6: 16:00 | J6: 00:30 | L6: 08:30 | M6: 9 | N6: TRUE | O6: 360
A7: 45505 | B7: Čtvrtek | P7: 0 | Q7: Kinkorová Petra | R7: Kořínek Dominik | S7: 10710 | T7: 6368 | U7: 10463 | V7: 4405 | W7: 0 | X7: 1370 | Y7: 2882 | AA7: 4173 | AB7: 39361 | AC7: 0 | AD7: 0.3331103 | AI7: 360 | AJ7: 3 | AK7: 713 | AL7: 1 | AM7: 11 min 17 s | AN7: 1 | AO7: 113 | AP7: 11 | AQ7: 0 | AR7: 0 | AS7: 0.090909091 | AT7: 0 | AU7: 0.90909091 | AV7: 0
A8: 45506 | B8: Pátek | C8: Kinkorová Petra | D8: 17:00 | E8: 03:00 | G8: 10:00
A9: 45506 | B9: Pátek | C9: Kořínek Dominik | D9: 10:00 | E9: 18:30 | G9: 08:30
A10: 45506 | B10: Pátek | C10: Mirga Simon | D10: 11:00 | E10: 17:00 | G10: 06:00
A11: 45506 | B11: Pátek | C11: Šebesta Tomáš | D11: 17:00 | E11: 03:00 | G11: 10:00
A12: 45506 | B12: Pátek | H12: Melmer David | I12: 11:00 | J12: 16:30 | L12: 05:30 | M12: 3
A13: 45506 | B13: Pátek | H13: Pešta Milan | I13: 16:30 | J13: 03:00 | L13: 10:30 | M13: 10 | N13: TRUE | O13: 400
A14: 45506 | B14: Pátek | P14: 7 | Q14: Kinkorová Petra | R14: Kořínek Dominik | S14: 16387 | T14: 8075 | U14: 15686 | V14: 6826 | W14: 707 | X14: 4103 | Y14: 5275 | AA14: 8394 | AB14: 61750 | AC14: 0 | AD14: 0.29030215 | AI14: 400 | AJ14: 2 | AK14: 663 | AL14: 12 | AM14: 10 min 45 s | AN14: 1 | AO14: 2
A15: 45507 | B15: Sobota | C15: Kinkorová Petra | D15: 17:00 | E15: 03:30 | G15: 10:30
A16: 45507 | B16: Sobota | C16: Jáklová Dominika | D16: 17:00 | E16: 03:30 | G16: 10:30
A17: 45507 | B17: Sobota | C17: Roth Stanislav | D17: 10:00 | E17: 17:00 | G17: 07:00
A18: 45507 | B18: Sobota | H18: Melmer David | I18: 11:00 | J18: 21:00 | L18: 10:00 | M18: 5
A19: 45507 | B19: Sobota | H19: Čech Dominik | I19: 21:00 | J19: 03:00 | L19: 06:00 | M19: 4 | N19: TRUE | O19: 160
A20: 45507 | B20: Sobota | P20: 0 | Q20: Kinkorová Petra | R20: Kořínek Dominik | S20: 15187 | T20: 9627 | U20: 12533 | V20: 4116 | W20: 0 | X20: 4197 | Y20: 4562 | AA20: 8437 | AB20: 55162 | AC20: 0 | AD20: 0.20956148 | AE20: 500 | AH20: 40 | AI20: 160 | AJ20: 1 | AK20: 264 | AL20: 14 | AM20: 11 min 32 s | AN20: 1 | AO20: 0
A21: 45508 | B21: Neděle | C21: Roth Stanislav | D21: 10:00 | E21: 17:00 | G21: 07:00
A22: 45508 | B22: Neděle | C22: Jáklová Dominika | D22: 17:00 | E22: 00:00 | G22: 07:00
A23: 45508 | B23: Neděle | C23: Kořínek Dominik | D23: 17:00 | E23: 00:00 | G23: 07:00
A24: 45508 | B24: Neděle | H24: Pešta Milan | I24: 10:00 | J24: 17:00 | L24: 07:00 | M24: 10 | N24: TRUE | O24: 400
A25: 45508 | B25: Neděle | H25: Čech Dominik | I25: 17:00 | J25: 23:00 | L25: 06:00 | M25: 5 | N25: TRUE | O25: 200
A26: 45508 | B26: Neděle | P26: 16 | Q26: Kinkorová Petra | R26: Kořínek Dominik | S26: 10961 | T26: 7550 | U26: 14196 | V26: 7557 | W26: 3607 | X26: 2303 | Y26: 2561 | Z26: 240 | AA26: 5774 | AB26: 53246 | AC26: 1 | AD26: 0.2559984 | AG26: 81 | AH26: 120 | AI26: 600 | AJ26: 0 | AK26: 0 | AL26: 15 | AM26: 10 min 57 s | AN26: 2 | AO26: 8
A27: 45509 | B27: Pondělí | C27: Kinkorová Petra | D27: 10:00 | E27: 01:30 | G27: 15:30
A28: 45509 | B28: Pondělí | C28: Jáklová Dominika | D28: 18:00 | E28: 01:30 | G28: 07:30
A29: 45509 | B29: Pondělí | H29: Melmer David | I29: 10:00 | J29: 18:00 | L29: 08:00 | M29: 8
A30: 45509 | B30: Pondělí | H30: Čech Dominik | I30: 18:00 | J30: 00:00 | L30: 06:00 | M30: 3 | N30: TRUE | O30: 120
A31: 45509 | B31: Pondělí | P31: 3 | Q31: Kinkorová Petra | R31: Kořínek Dominik | S31: 9277 | T31: 5550 | U31: 5997 | V31: 3848 | W31: 0 | X31: 2114 | Y31: 3868 | AA31: 6651 | AB31: 35425 | AC31: 0 | AD31: 0.35296289 | AG31: 74 | AH31: 40 | AI31: 120 | AJ31: 2 | AK31: 590 | AL31: 8 | AM31: 11 min 38 s | AN31: 1 | AO31: 3
A32: 45510 | B32: Úterý | C32: Kořínek Dominik | D32: 10:00 | E32: 01:30 | G32: 15:30
A33: 45510 | B33: Úterý | C33: Jáklová Dominika | D33: 17:00 | E33: 00:00 | G33: 07:00
A34: 45510 | B34: Úterý | H34: Melmer David | I34: 11:00 | J34: 19:00 | L34: 08:00 | M34: 9
A35: 45510 | B35: Úterý | H35: Pešta Milan | I35: 19:00 | J35: 01:30 | L35: 06:30 | M35: 4 | N35: TRUE | O35: 160
A36: 45510 | B36: Úterý | P36: 0 | S36: 5221 | T36: 2789 | U36: 8431 | V36: 4625 | W36: 0 | X36: 3139 | Y36: 3812 | AA36: 5201 | AB36: 30739 | AC36: 0 | AD36: 0.41711239 | AE36: 500 | AI36: 160 | AJ36: 1 | AK36: 249 | AL36: 2 | AM36: 8 min 57 s | AN36: 1 | AO36: 0
A37: 45511 | B37: Středa | C37: Kořínek Dominik | D37: 10:00 | E37: 01:30 | G37: 15:30
A38: 45511 | B38: Středa | C38: Jáklová Dominika | D38: 17:00 | E38: 00:00 | G38: 07:00
A39: 45511 | B39: Středa | H39: Čech Dominik | I39: 17:00 | J39: 01:00 | L39: 08:00 | M39: 12 | N39: TRUE | O39: 480
A40: 45511 | B40: Středa | H40: Pešta Milan | I40: 11:00 | J40: 17:00 | L40: 06:00 | M40: 2 | N40: TRUE | O40: 80
...

Sheet Report
B1: Malešice | C1: Datum | D1: 46004 | F1: COL | I1: Tržba | L1: Online Platby
F2: =IFERROR(__xludf.DUMMYFUNCTION("IF(I2>0, 100 / (I2 / 112 * 100 / ((SUM(A12:A21, A25:A31) + (M17 + I32) + IFERROR(SUM(FILTER(HR!W5:W48, LEN(HR!A5:A48) > 0)), 0)) / 100)), ""Zadej tržbu"") "),"Zadej tržbu") -> Zadej tržbu | I2: =SUM(RestiaCSV!C:C) - SUMIFS(RestiaCSV!C:C, RestiaCSV!B:B, "canceled") -> 0 | L2: Wolt | M2: =SUMIFS(RestiaCSV!C:C, RestiaCSV!A:A, Report!L2, RestiaCSV!B:B, "<>canceled") -> 0
B3: =CHOOSE(WEEKDAY(D1), "Neděle", "Pondělí", "Úterý", "Středa", "Čtvrtek", "Pátek", "Sobota") -> Sobota | L3: Bolt | M3: =SUMIFS(RestiaCSV!C:C, RestiaCSV!A:A, Report!L3, RestiaCSV!B:B, "<>canceled") -> 0
L4: Dáme jídlo | M4: =SUMIFS(RestiaCSV!C:C, RestiaCSV!A:A, "damejidlo", RestiaCSV!G:G, "online", RestiaCSV!B:B, "<>canceled") -> 0
B5: Napiš vzkaz ⬇️ 📖 Deník 📖 ⬇️ Včerejší vzkaz | L5: Web | M5: =SUMIFS(RestiaCSV!C:C, RestiaCSV!A:A, "generic", RestiaCSV!G:G, "online", RestiaCSV!B:B, "<>canceled") -> 0
L6: Wolt drive cash | M6: =SUMIFS(RestiaCSV!C:C, RestiaCSV!E:E, "wolt kurýr", RestiaCSV!A:A, "<>wolt", RestiaCSV!G:G, "cash", RestiaCSV!B:B, "<>canceled") -> 0
B7: dfdfdfdfdf | L7: DJ Cash | M7: =SUMIFS(RestiaCSV!C:C, RestiaCSV!A:A, "damejidlo", RestiaCSV!G:G, "cash", RestiaCSV!B:B, "<>canceled") -> 0
L8: Hotovost
L9: Terminál
B10: Instor | G10: Otevíral | J10: Pokladna | L10: Stravenky
B11: Jméno | C11: Začátek směny | D11: Konec směny | E11: pauza | F11: Počet hodin | J11: =M2+M3+M4+M5+M6+M13+M14+M15+M16+M17+M9+M10+M11-I2 -> 0 | L11: Hotovost
A12: {=IF(ISBLANK(B12), 0, IF(ISNUMBER(MATCH(B12, HR!A:A, 0)), 0, IF(ISNUMBER(MATCH(B12, HR!B:B, 0)), INDEX(HR!V:V, MATCH(B12, HR!B:B, 0)) * (F12 * 24), 0)))} -> 0 | B12: Kinkorová Petra | C12: 10:00 | D12: 18:00 | F12: =IF(OR(ISBLANK(B12), ISBLANK(D12), D12=0), "0:00", TEXT((IF(AND(TIMEVALUE(IF(ISBLANK(D12), "00:00", D12))>=TIMEVALUE("00:00"), TIMEVALUE(IF(ISBLANK(D12), "00:00", D12))<=TIMEVALUE("06:00")), TIMEVALUE(IF(ISBLANK(D12), "00:00", D12))+1, TIMEVALUE(IF(ISBLANK(D12), "00:00", D12))) - TIMEVALUE(IF(ISBLANK(C12), "00:00", C12)) - TIMEVALUE(IF(ISBLANK(E12), "00:00", E12))), "hh:mm")) -> 08:00 | L12: Výdaje
A13: {=IF(ISBLANK(B13), 0, IF(ISNUMBER(MATCH(B13, HR!A:A, 0)), 0, IF(ISNUMBER(MATCH(B13, HR!B:B, 0)), INDEX(HR!V:V, MATCH(B13, HR!B:B, 0)) * (F13 * 24), 0)))} -> 0 | B13: Yarushynskyi Vladyslav | C13: 17:30 | D13: 3:00 | F13: =IF(OR(ISBLANK(B13), ISBLANK(D13), D13=0), "0:00", TEXT((IF(AND(TIMEVALUE(IF(ISBLANK(D13), "00:00", D13))>=TIMEVALUE("00:00"), TIMEVALUE(IF(ISBLANK(D13), "00:00", D13))<=TIMEVALUE("06:00")), TIMEVALUE(IF(ISBLANK(D13), "00:00", D13))+1, TIMEVALUE(IF(ISBLANK(D13), "00:00", D13))) - TIMEVALUE(IF(ISBLANK(C13), "00:00", C13)) - TIMEVALUE(IF(ISBLANK(E13), "00:00", E13))), "hh:mm")) -> 09:30 | L13: Benzín
A14: {=IF(ISBLANK(B14), 0, IF(ISNUMBER(MATCH(B14, HR!A:A, 0)), 0, IF(ISNUMBER(MATCH(B14, HR!B:B, 0)), INDEX(HR!V:V, MATCH(B14, HR!B:B, 0)) * (F14 * 24), 0)))} -> 0 | F14: =IF(OR(ISBLANK(B14), ISBLANK(D14), D14=0), "0:00", TEXT((IF(AND(TIMEVALUE(IF(ISBLANK(D14), "00:00", D14))>=TIMEVALUE("00:00"), TIMEVALUE(IF(ISBLANK(D14), "00:00", D14))<=TIMEVALUE("06:00")), TIMEVALUE(IF(ISBLANK(D14), "00:00", D14))+1, TIMEVALUE(IF(ISBLANK(D14), "00:00", D14))) - TIMEVALUE(IF(ISBLANK(C14), "00:00", C14)) - TIMEVALUE(IF(ISBLANK(E14), "00:00", E14))), "hh:mm")) -> 0:00 | L14: Auta
A15: {=IF(ISBLANK(B15), 0, IF(ISNUMBER(MATCH(B15, HR!A:A, 0)), 0, IF(ISNUMBER(MATCH(B15, HR!B:B, 0)), INDEX(HR!V:V, MATCH(B15, HR!B:B, 0)) * (F15 * 24), 0)))} -> 0 | B15: Mirga Simon | C15: 11:00 | D15: 18:00 | F15: =IF(OR(ISBLANK(B15), ISBLANK(D15), D15=0), "0:00", TEXT((IF(AND(TIMEVALUE(IF(ISBLANK(D15), "00:00", D15))>=TIMEVALUE("00:00"), TIMEVALUE(IF(ISBLANK(D15), "00:00", D15))<=TIMEVALUE("06:00")), TIMEVALUE(IF(ISBLANK(D15), "00:00", D15))+1, TIMEVALUE(IF(ISBLANK(D15), "00:00", D15))) - TIMEVALUE(IF(ISBLANK(C15), "00:00", C15)) - TIMEVALUE(IF(ISBLANK(E15), "00:00", E15))), "hh:mm")) -> 07:00 | L15: Suroviny
A16: {=IF(ISBLANK(B16), 0, IF(ISNUMBER(MATCH(B16, HR!A:A, 0)), 0, IF(ISNUMBER(MATCH(B16, HR!B:B, 0)), INDEX(HR!V:V, MATCH(B16, HR!B:B, 0)) * (F16 * 24), 0)))} -> 0 | F16: =IF(OR(ISBLANK(B16), ISBLANK(D16), D16=0), "0:00", TEXT((IF(AND(TIMEVALUE(IF(ISBLANK(D16), "00:00", D16))>=TIMEVALUE("00:00"), TIMEVALUE(IF(ISBLANK(D16), "00:00", D16))<=TIMEVALUE("06:00")), TIMEVALUE(IF(ISBLANK(D16), "00:00", D16))+1, TIMEVALUE(IF(ISBLANK(D16), "00:00", D16))) - TIMEVALUE(IF(ISBLANK(C16), "00:00", C16)) - TIMEVALUE(IF(ISBLANK(E16), "00:00", E16))), "hh:mm")) -> 0:00 | L16: Ostatní
A17: {=IF(ISBLANK(B17), 0, IF(ISNUMBER(MATCH(B17, HR!A:A, 0)), 0, IF(ISNUMBER(MATCH(B17, HR!B:B, 0)), INDEX(HR!V:V, MATCH(B17, HR!B:B, 0)) * (F17 * 24), 0)))} -> 0 | F17: =IF(OR(ISBLANK(B17), ISBLANK(D17), D17=0), "0:00", TEXT((IF(AND(TIMEVALUE(IF(ISBLANK(D17), "00:00", D17))>=TIMEVALUE("00:00"), TIMEVALUE(IF(ISBLANK(D17), "00:00", D17))<=TIMEVALUE("06:00")), TIMEVALUE(IF(ISBLANK(D17), "00:00", D17))+1, TIMEVALUE(IF(ISBLANK(D17), "00:00", D17))) - TIMEVALUE(IF(ISBLANK(C17), "00:00", C17)) - TIMEVALUE(IF(ISBLANK(E17), "00:00", E17))), "hh:mm")) -> 0:00 | L17: PHM - soukromé | M17: =sum(I25:I31) -> 0
A18: {=IF(ISBLANK(B18), 0, IF(ISNUMBER(MATCH(B18, HR!A:A, 0)), 0, IF(ISNUMBER(MATCH(B18, HR!B:B, 0)), INDEX(HR!V:V, MATCH(B18, HR!B:B, 0)) * (F18 * 24), 0)))} -> 0 | F18: =IF(OR(ISBLANK(B18), ISBLANK(D18), D18=0), "0:00", TEXT((IF(AND(TIMEVALUE(IF(ISBLANK(D18), "00:00", D18))>=TIMEVALUE("00:00"), TIMEVALUE(IF(ISBLANK(D18), "00:00", D18))<=TIMEVALUE("06:00")), TIMEVALUE(IF(ISBLANK(D18), "00:00", D18))+1, TIMEVALUE(IF(ISBLANK(D18), "00:00", D18))) - TIMEVALUE(IF(ISBLANK(C18), "00:00", C18)) - TIMEVALUE(IF(ISBLANK(E18), "00:00", E18))), "hh:mm")) -> 0:00 | G18: Zavíral
A19: {=IF(ISBLANK(B19), 0, IF(ISNUMBER(MATCH(B19, HR!A:A, 0)), 0, IF(ISNUMBER(MATCH(B19, HR!B:B, 0)), INDEX(HR!V:V, MATCH(B19, HR!B:B, 0)) * (F19 * 24), 0)))} -> 0 | F19: =IF(OR(ISBLANK(B19), ISBLANK(D19), D19=0), "0:00", TEXT((IF(AND(TIMEVALUE(IF(ISBLANK(D19), "00:00", D19))>=TIMEVALUE("00:00"), TIMEVALUE(IF(ISBLANK(D19), "00:00", D19))<=TIMEVALUE("06:00")), TIMEVALUE(IF(ISBLANK(D19), "00:00", D19))+1, TIMEVALUE(IF(ISBLANK(D19), "00:00", D19))) - TIMEVALUE(IF(ISBLANK(C19), "00:00", C19)) - TIMEVALUE(IF(ISBLANK(E19), "00:00", E19))), "hh:mm")) -> 0:00
A20: {=IF(ISBLANK(B20), 0, IF(ISNUMBER(MATCH(B20, HR!A:A, 0)), 0, IF(ISNUMBER(MATCH(B20, HR!B:B, 0)), INDEX(HR!V:V, MATCH(B20, HR!B:B, 0)) * (F20 * 24), 0)))} -> 0 | F20: =IF(OR(ISBLANK(B20), ISBLANK(D20), D20=0), "0:00", TEXT((IF(AND(TIMEVALUE(IF(ISBLANK(D20), "00:00", D20))>=TIMEVALUE("00:00"), TIMEVALUE(IF(ISBLANK(D20), "00:00", D20))<=TIMEVALUE("06:00")), TIMEVALUE(IF(ISBLANK(D20), "00:00", D20))+1, TIMEVALUE(IF(ISBLANK(D20), "00:00", D20))) - TIMEVALUE(IF(ISBLANK(C20), "00:00", C20)) - TIMEVALUE(IF(ISBLANK(E20), "00:00", E20))), "hh:mm")) -> 0:00
A21: {=IF(ISBLANK(B21), 0, IF(ISNUMBER(MATCH(B21, HR!A:A, 0)), 0, IF(ISNUMBER(MATCH(B21, HR!B:B, 0)), INDEX(HR!V:V, MATCH(B21, HR!B:B, 0)) * (F21 * 24), 0)))} -> 0 | F21: =IF(OR(ISBLANK(B21), ISBLANK(D21), D21=0), "0:00", TEXT((IF(AND(TIMEVALUE(IF(ISBLANK(D21), "00:00", D21))>=TIMEVALUE("00:00"), TIMEVALUE(IF(ISBLANK(D21), "00:00", D21))<=TIMEVALUE("06:00")), TIMEVALUE(IF(ISBLANK(D21), "00:00", D21))+1, TIMEVALUE(IF(ISBLANK(D21), "00:00", D21))) - TIMEVALUE(IF(ISBLANK(C21), "00:00", C21)) - TIMEVALUE(IF(ISBLANK(E21), "00:00", E21))), "hh:mm")) -> 0:00
J22: Zrušené obj. ks | K22: Zrušené obj. $ | L22: Počet zpožděných našich rozvozů +5 min | M22: Průměrný make Time
B23: Kurýr | J23: =COUNTIF(RestiaCSV!B:B, "canceled") -> 0 | K23: =SUMIF(RestiaCSV!B:B, "canceled", RestiaCSV!C:C) -> 0 | L23: =COUNTIFS(RestiaCSV!L:L, ">5", RestiaCSV!F:F, "delivery") -> 0 | M23: =INT(AVERAGEIFS(RestiaCSV!N:N, RestiaCSV!N:N, ">=5", RestiaCSV!N:N, "<=30")) & " min " & TEXT(MOD(AVERAGEIFS(RestiaCSV!N:N, RestiaCSV!N:N, ">=5", RestiaCSV!N:N, "<=30") * 60, 60), "00") & " s" -> #DIV/0!
B24: Jméno | C24: Začátek směny | D24: Konec směny | E24: pauza | F24: Počet hodin | G24: Počet rozvozů | H24: Vlastní vůz | I24: Vyplatit PHM | J24: počet výdajových dokadů | K24: Počet nezrušených celkem | L24: Počet našich rozvozů | M24: Počet pozdě přiřazeným WoltDrive 5+
A25: {=IF(ISBLANK(B25), 0, IF(ISNUMBER(MATCH(B25, HR!A:A, 0)), 0, IF(ISNUMBER(MATCH(B25, HR!B:B, 0)), INDEX(HR!V:V, MATCH(B25, HR!B:B, 0)) * (F25 * 24), 0)))} -> 0 | B25: Hendrych Rostislav | C25: 11:00 | D25: 03:00 | F25: =IF(OR(ISBLANK(B25), ISBLANK(D25), D25=0), "0:00", TEXT((IF(AND(TIMEVALUE(IF(ISBLANK(D25), "00:00", D25))>=TIMEVALUE("00:00"), TIMEVALUE(IF(ISBLANK(D25), "00:00", D25))<=TIMEVALUE("06:00")), TIMEVALUE(IF(ISBLANK(D25), "00:00", D25))+1, TIMEVALUE(IF(ISBLANK(D25), "00:00", D25))) - TIMEVALUE(IF(ISBLANK(C25), "00:00", C25)) - TIMEVALUE(IF(ISBLANK(E25), "00:00", E25))), "hh:mm")) -> 16:00 | G25: =COUNTIF(RestiaCSV!E:E, B25) -> 0 | H25: FALSE | I25: =IF(H25,G25*40, 0) -> 0
A26: {=IF(ISBLANK(B26), 0, IF(ISNUMBER(MATCH(B26, HR!A:A, 0)), 0, IF(ISNUMBER(MATCH(B26, HR!B:B, 0)), INDEX(HR!V:V, MATCH(B26, HR!B:B, 0)) * (F26 * 24), 0)))} -> 0 | F26: =IF(OR(ISBLANK(B26), ISBLANK(D26), D26=0), "0:00", TEXT((IF(AND(TIMEVALUE(IF(ISBLANK(D26), "00:00", D26))>=TIMEVALUE("00:00"), TIMEVALUE(IF(ISBLANK(D26), "00:00", D26))<=TIMEVALUE("06:00")), TIMEVALUE(IF(ISBLANK(D26), "00:00", D26))+1, TIMEVALUE(IF(ISBLANK(D26), "00:00", D26))) - TIMEVALUE(IF(ISBLANK(C26), "00:00", C26)) - TIMEVALUE(IF(ISBLANK(E26), "00:00", E26))), "hh:mm")) -> 0:00 | G26: =COUNTIF(RestiaCSV!E:E, B26) -> 0 | H26: FALSE | I26: =IF(H26,G26*40, 0) -> 0 | J26: =COUNTIF(I25:I31, ">0") -> 0 | K26: =IFERROR(__xludf.DUMMYFUNCTION("COUNTA(FILTER(RestiaCSV!B2:B32, RestiaCSV!B2:B32 <> ""canceled""))"),0.0) -> 0 | L26: =COUNTIF(RestiaCSV!F1:F32, "delivery") -> 0 | M26: =COUNTIFS(RestiaCSV!M:M, ">5",RestiaCSV!A:A, "<>wolt") -> 0
A27: {=IF(ISBLANK(B27), 0, IF(ISNUMBER(MATCH(B27, HR!A:A, 0)), 0, IF(ISNUMBER(MATCH(B27, HR!B:B, 0)), INDEX(HR!V:V, MATCH(B27, HR!B:B, 0)) * (F27 * 24), 0)))} -> 0 | F27: =IF(OR(ISBLANK(B27), ISBLANK(D27), D27=0), "0:00", TEXT((IF(AND(TIMEVALUE(IF(ISBLANK(D27), "00:00", D27))>=TIMEVALUE("00:00"), TIMEVALUE(IF(ISBLANK(D27), "00:00", D27))<=TIMEVALUE("06:00")), TIMEVALUE(IF(ISBLANK(D27), "00:00", D27))+1, TIMEVALUE(IF(ISBLANK(D27), "00:00", D27))) - TIMEVALUE(IF(ISBLANK(C27), "00:00", C27)) - TIMEVALUE(IF(ISBLANK(E27), "00:00", E27))), "hh:mm")) -> 0:00 | G27: =COUNTIF(RestiaCSV!E:E, B27) -> 0 | H27: FALSE | I27: =IF(H27,G27*40, 0) -> 0 | J27: Woltrdive zpožděný kvůli našemu pozdnímu přiřazení | L27: % zpožděných našich rozvozů +5 min | M27: Počet zpožděných Woltdrivem
A28: {=IF(ISBLANK(B28), 0, IF(ISNUMBER(MATCH(B28, HR!A:A, 0)), 0, IF(ISNUMBER(MATCH(B28, HR!B:B, 0)), INDEX(HR!V:V, MATCH(B28, HR!B:B, 0)) * (F28 * 24), 0)))} -> 0 | F28: =IF(OR(ISBLANK(B28), ISBLANK(D28), D28=0), "0:00", TEXT((IF(AND(TIMEVALUE(IF(ISBLANK(D28), "00:00", D28))>=TIMEVALUE("00:00"), TIMEVALUE(IF(ISBLANK(D28), "00:00", D28))<=TIMEVALUE("06:00")), TIMEVALUE(IF(ISBLANK(D28), "00:00", D28))+1, TIMEVALUE(IF(ISBLANK(D28), "00:00", D28))) - TIMEVALUE(IF(ISBLANK(C28), "00:00", C28)) - TIMEVALUE(IF(ISBLANK(E28), "00:00", E28))), "hh:mm")) -> 0:00 | G28: =COUNTIF(RestiaCSV!E:E, B28) -> 0 | H28: FALSE | I28: =IF(H28,G28*40, 0) -> 0
A29: {=IF(ISBLANK(B29), 0, IF(ISNUMBER(MATCH(B29, HR!A:A, 0)), 0, IF(ISNUMBER(MATCH(B29, HR!B:B, 0)), INDEX(HR!V:V, MATCH(B29, HR!B:B, 0)) * (F29 * 24), 0)))} -> 0 | F29: =IF(OR(ISBLANK(B29), ISBLANK(D29), D29=0), "0:00", TEXT((IF(AND(TIMEVALUE(IF(ISBLANK(D29), "00:00", D29))>=TIMEVALUE("00:00"), TIMEVALUE(IF(ISBLANK(D29), "00:00", D29))<=TIMEVALUE("06:00")), TIMEVALUE(IF(ISBLANK(D29), "00:00", D29))+1, TIMEVALUE(IF(ISBLANK(D29), "00:00", D29))) - TIMEVALUE(IF(ISBLANK(C29), "00:00", C29)) - TIMEVALUE(IF(ISBLANK(E29), "00:00", E29))), "hh:mm")) -> 0:00 | G29: =COUNTIF(RestiaCSV!E:E, B29) -> 0 | H29: FALSE | I29: =IF(H29,G29*40, 0) -> 0 | J29: =COUNTIFS(RestiaCSV!M:M, ">5", RestiaCSV!L:L, ">5") -> 0 | L29: =L23/L26 -> #DIV/0! | M29: =COUNTIFS(RestiaCSV!L:L, ">5", RestiaCSV!F:F, "delivery", RestiaCSV!E:E, "Wolt Kurýr") -> 0
A30: {=IF(ISBLANK(B30), 0, IF(ISNUMBER(MATCH(B30, HR!A:A, 0)), 0, IF(ISNUMBER(MATCH(B30, HR!B:B, 0)), INDEX(HR!V:V, MATCH(B30, HR!B:B, 0)) * (F30 * 24), 0)))} -> 0 | F30: =IF(OR(ISBLANK(B30), ISBLANK(D30), D30=0), "0:00", TEXT((IF(AND(TIMEVALUE(IF(ISBLANK(D30), "00:00", D30))>=TIMEVALUE("00:00"), TIMEVALUE(IF(ISBLANK(D30), "00:00", D30))<=TIMEVALUE("06:00")), TIMEVALUE(IF(ISBLANK(D30), "00:00", D30))+1, TIMEVALUE(IF(ISBLANK(D30), "00:00", D30))) - TIMEVALUE(IF(ISBLANK(C30), "00:00", C30)) - TIMEVALUE(IF(ISBLANK(E30), "00:00", E30))), "hh:mm")) -> 0:00 | G30: =COUNTIF(RestiaCSV!E:E, B30) -> 0 | H30: FALSE | I30: =IF(H30,G30*40, 0) -> 0 | L30: % doručených včas | M30: % zpožděných Woltdrivem
A31: {=IF(ISBLANK(B31), 0, IF(ISNUMBER(MATCH(B31, HR!A:A, 0)), 0, IF(ISNUMBER(MATCH(B31, HR!B:B, 0)), INDEX(HR!V:V, MATCH(B31, HR!B:B, 0)) * (F31 * 24), 0)))} -> 0 | F31: =IF(OR(ISBLANK(B31), ISBLANK(D31), D31=0), "0:00", TEXT((IF(AND(TIMEVALUE(IF(ISBLANK(D31), "00:00", D31))>=TIMEVALUE("00:00"), TIMEVALUE(IF(ISBLANK(D31), "00:00", D31))<=TIMEVALUE("06:00")), TIMEVALUE(IF(ISBLANK(D31), "00:00", D31))+1, TIMEVALUE(IF(ISBLANK(D31), "00:00", D31))) - TIMEVALUE(IF(ISBLANK(C31), "00:00", C31)) - TIMEVALUE(IF(ISBLANK(E31), "00:00", E31))), "hh:mm")) -> 0:00 | G31: =COUNTIF(RestiaCSV!E:E, B31) -> 0 | H31: FALSE | I31: =IF(H31,G31*40, 0) -> 0
B32: Wolt Kurýr | C32: Wolt drive | G32: =COUNTIFS(RestiaCSV!E:E, "wolt kurýr", RestiaCSV!A:A, "<>wolt") -> 0 | H32: TRUE | I32: =G32*127 -> 0 | L32: =100%-L29 -> #DIV/0! | M32: =M29/L26 -> #DIV/0!

Sheet Kontrola
B1: =Report!B1 -> Malešice | C1: 45992 | D1: Vyber datum <----------> | E1: 46022 | F1: COL | I1: Tržba | L1: Online Platby
F2: 0.23458273 | I2: 53227 | L2: Wolt | M2: 19883
B3: =CHOOSE(WEEKDAY(C1), "Neděle", "Pondělí", "Úterý", "Středa", "Čtvrtek", "Pátek", "Sobota") -> Pondělí | D3: =CHOOSE(WEEKDAY(E1), "Neděle", "Pondělí", "Úterý", "Středa", "Čtvrtek", "Pátek", "Sobota") -> Středa | L3: Bolt | M3: 4753
L4: Dáme jídlo | M4: 11402
B5: Celkem hodin Instor | F5: Celkem hodin Kurýr | L5: Web | M5: 8978
L6: Wolt drive cash | M6: 680
B7: =TEXT(SUMPRODUCT((IFERROR(LEFT(D10:D30, FIND(":", D10:D30) - 1) * 60, 0) + IFERROR(MID(D10:D30, FIND(":", D10:D30) + 1, LEN(D10:D30) - FIND(":", D10:D30)), 0))), "[h]:mm")/60 -> 28.5 | F7: =TEXT(SUMPRODUCT((IFERROR(LEFT(H10:H30, FIND(":", H10:H30) - 1) * 60, 0) + IFERROR(MID(H10:H30, FIND(":", H10:H30) + 1, LEN(H10:H30) - FIND(":", H10:H30)), 0))), "[h]:mm")/60 -> 14 | L7: DJ Cash | M7: 2720
B8: Instor | F8: Kurýr | J8: Pokladna | L8: Hotovost
B9: Jméno | C9: Počet dní | D9: Počet hodin | F9: Jméno | G9: Počet dní | H9: Počet hodin | I9: Počet rozvozů | J9: 0 | L9: Terminál | M9: 2495
B10: Yarushynskyi Vladyslav | C10: 1 | D10: 6:00 | E10: 29:00 | F10: Hendrych Rostislav | G10: 1 | H10: 14:00 | I10: 16 | L10: Stravenky | M10: 0
B11: Strauss Daniel | C11: 1 | D11: 7:30 | E11: 23:00 | L11: Hotovost | M11: 4536
B12: Kinkorová Petra | C12: 1 | D12: 8:00 | E12: 13:00 | L12: Výdaje
B13: Mirga Simon | C13: 1 | D13: 7:00 | E13: 13:00 | L13: Benzín | M13: 500
E14: 7:00 | L14: Auta | M14: 0
E15: 7:00 | L15: Suroviny | M15: 0
L16: Ostatní | M16: 0
L17: PHM - soukromé | M17: 0
J19: Zrušené obj. ks | K19: Zrušené obj. $ | L19: Počet zpožděných našich rozvozů +5 min | M19: Průměrný make Time
J21: 2 | K21: 427 | L21: 4 | M21: 11 min 38 s
J22: počet výdajových dokadů | K22: Počet nezrušených celkem | L22: Počet našich rozvozů | M22: Počet pozdě přiřazeným WoltDrive 5+
J24: 0 | K24: 123 | L24: 21 | M24: 3
J25: Woltrdive zpožděný kvůli našemu pozdnímu přiřazení | L25: % zpožděných našich rozvozů +5 min | M25: Počet zpožděných Woltdrivem
J27: 1 | L27: 0.19047619 | M27: 1
L28: % doručených včas | M28: % zpožděných Woltdrivem
L30: 0.80952381 | M30: 0.047619048

Sheet Směny
A1: Sem zadej směnu pro tento týden z CSV - Směny -> Naplánované směny -> Aktuální nebo Následující týden -> Stáhnout CSV (v pravo nahoře ) -> otevřív v excelu -> oznacit všechny buňky a dvojklikem na dělící přepážku mezi A a B přizpůsob buňky velikosti textu. Poté tabulku zkopíruj do této tabulky do bunky A2, označeno modře.
A2: Pracovníci | B2: Pondělí | C2: Úterý | D2: Středa | E2: Čtvrtek | F2: Pátek | G2: Sobota | H2: Neděle
A3: Kinkorová Petra | B3: 10:00 - 1:00 (Instor) | E3: 10:00 - 17:00 (Instor) | F3: 17:00 - 3:00 (Instor) | G3: 17:00 - 3:00 (Instor)
A4: Yarushynskyi Vladyslav | B4: 17:00 - 1:00 (Instor) | D4: 10:00 - 17:00 (Instor) | F4: 17:00 - 3:00 (Instor) | G4: 17:00 - 3:00 (Instor) | H4: 17:00 - 0:00 (Instor)
A5: Reischl Jan | B5: 11:00 - 17:00 (Kurýr) | D5: 11:00 - 17:00 (Kurýr) | H5: 11:00 - 17:00 (Kurýr)
A6: Hanibal Filip | B6: 17:00 - 1:00 (Kurýr) | D6: 17:00 - 1:00 (Kurýr) | F6: 11:00 - 17:00 (Kurýr) | G6: 11:00 - 17:00 (Kurýr)
A7: Strauss Daniel | C7: 10:00 - 1:00 (Instor) | D7: 17:00 - 1:00 (Instor) | E7: 17:00 - 1:00 (Instor) | G7: 10:00 - 17:00 (Instor) | H7: 10:00 - 17:00 (Instor)
A8: Fux Vojtěch | C8: 17:00 - 1:00 (Instor) | D8: 17:00 - 1:00 (Instor) | E8: 17:00 - 1:00 (Instor) | F8: 10:00 - 17:00 (Instor) | H8: 17:00 - 0:00 (Instor)
A9: Pergl Jan | C9: 11:00 - 17:00 (Kurýr) | E9: 11:00 - 17:00 (Kurýr)
A10: Kalina Filip | C10: 17:00 - 1:00 (Kurýr) | H10: 17:00 - 0:00 (Kurýr)
A11: Mirga Simon | G11: 11:00 - 17:00 (Instor) | H11: 11:00 - 17:00 (Instor)
AB20: 0
AB26: 0
AB29: 0
AB36: 0
AB45: 0
AB47: 0
AB50: 0
AB53: 0
AB54: 0
AB76: 0
AB78: 0
AB80: 0
... AB138: 0

Sheet RestiaCSV

Sheet HR
C1: =IFERROR(__xludf.DUMMYFUNCTION("IMPORTRANGE(""1TpIiNTfR1pnpn85VWQTTdvQ2Xcr0GStmWJ2UvfKxG_A"", ""Mzdy!A1:F200"")"),"#REF!") -> #REF! | V1: =IFERROR(__xludf.DUMMYFUNCTION("IMPORTRANGE(""1TpIiNTfR1pnpn85VWQTTdvQ2Xcr0GStmWJ2UvfKxG_A"", ""Mzdy!ac1:ad200"")"),"#REF!") -> #REF!
A4: Manažeři | B4: Zamestnanci pobocky
A5: =IF(AND(B5<>"", C5=TRUE, E5=Report!$B$1), B5, "") | B5: =IF(OR(E5=Report!$B$1, F5=Report!$B$1, G5=Report!$B$1, H5=Report!$B$1), D5, "")
A6: =IF(AND(B6<>"", C6=TRUE, E6=Report!$B$1), B6, "") | B6: =IF(OR(E6=Report!$B$1, F6=Report!$B$1, G6=Report!$B$1, H6=Report!$B$1), D6, "")
A7: =IF(AND(B7<>"", C7=TRUE, E7=Report!$B$1), B7, "") | B7: =IF(OR(E7=Report!$B$1, F7=Report!$B$1, G7=Report!$B$1, H7=Report!$B$1), D7, "")
A8: =IF(AND(B8<>"", C8=TRUE, E8=Report!$B$1), B8, "") | B8: =IF(OR(E8=Report!$B$1, F8=Report!$B$1, G8=Report!$B$1, H8=Report!$B$1), D8, "")
A9: =IF(AND(B9<>"", C9=TRUE, E9=Report!$B$1), B9, "") | B9: =IF(OR(E9=Report!$B$1, F9=Report!$B$1, G9=Report!$B$1, H9=Report!$B$1), D9, "")
A10: =IF(AND(B10<>"", C10=TRUE, E10=Report!$B$1), B10, "") | B10: =IF(OR(E10=Report!$B$1, F10=Report!$B$1, G10=Report!$B$1, H10=Report!$B$1), D10, "")
A11: =IF(AND(B11<>"", C11=TRUE, E11=Report!$B$1), B11, "") | B11: =IF(OR(E11=Report!$B$1, F11=Report!$B$1, G11=Report!$B$1, H11=Report!$B$1), D11, "")
A12: =IF(AND(B12<>"", C12=TRUE, E12=Report!$B$1), B12, "") | B12: =IF(OR(E12=Report!$B$1, F12=Report!$B$1, G12=Report!$B$1, H12=Report!$B$1), D12, "")
A13: =IF(AND(B13<>"", C13=TRUE, E13=Report!$B$1), B13, "") | B13: =IF(OR(E13=Report!$B$1, F13=Report!$B$1, G13=Report!$B$1, H13=Report!$B$1), D13, "")
A14: =IF(AND(B14<>"", C14=TRUE, E14=Report!$B$1), B14, "") | B14: =IF(OR(E14=Report!$B$1, F14=Report!$B$1, G14=Report!$B$1, H14=Report!$B$1), D14, "")
A15: =IF(AND(B15<>"", C15=TRUE, E15=Report!$B$1), B15, "") | B15: =IF(OR(E15=Report!$B$1, F15=Report!$B$1, G15=Report!$B$1, H15=Report!$B$1), D15, "")
A16: =IF(AND(B16<>"", C16=TRUE, E16=Report!$B$1), B16, "") | B16: =IF(OR(E16=Report!$B$1, F16=Report!$B$1, G16=Report!$B$1, H16=Report!$B$1), D16, "")
... A43: =IF(AND(B43<>"", C43=TRUE, E43=Report!$B$1), B43, "") | B43: =IF(OR(E43=Report!$B$1, F43=Report!$B$1, G43=Report!$B$1, H43=Report!$B$1), D43, "")
B44: =IF(OR(E44=Report!$B$1, F44=Report!$B$1, G44=Report!$B$1, H44=Report!$B$1), D44, "")
B45: =IF(OR(E45=Report!$B$1, F45=Report!$B$1, G45=Report!$B$1, H45=Report!$B$1), D45, "")
B46: =IF(OR(E46=Report!$B$1, F46=Report!$B$1, G46=Report!$B$1, H46=Report!$B$1), D46, "")
B47: =IF(OR(E47=Report!$B$1, F47=Report!$B$1, G47=Report!$B$1, H47=Report!$B$1), D47, "")
B48: =IF(OR(E48=Report!$B$1, F48=Report!$B$1, G48=Report!$B$1, H48=Report!$B$1), D48, "")
B49: =IF(OR(E49=Report!$B$1, F49=Report!$B$1, G49=Report!$B$1, H49=Report!$B$1), D49, "")
B50: =IF(OR(E50=Report!$B$1, F50=Report!$B$1, G50=Report!$B$1, H50=Report!$B$1), D50, "")
B51: =IF(OR(E51=Report!$B$1, F51=Report!$B$1, G51=Report!$B$1, H51=Report!$B$1), D51, "")
B52: =IF(OR(E52=Report!$B$1, F52=Report!$B$1, G52=Report!$B$1, H52=Report!$B$1), D52, "")
B53: =IF(OR(E53=Report!$B$1, F53=Report!$B$1, G53=Report!$B$1, H53=Report!$B$1), D53, "")
B54: =IF(OR(E54=Report!$B$1, F54=Report!$B$1, G54=Report!$B$1, H54=Report!$B$1), D54, "")
B55: =IF(OR(E55=Report!$B$1, F55=Report!$B$1, G55=Report!$B$1, H55=Report!$B$1), D55, "")
... B179: =IF(OR(E179=Report!$B$1, F179=Report!$B$1, G179=Report!$B$1, H179=Report!$B$1), D179, "")

Sheet Denik
