Workbook

Sheet Report
B1: Výroba | C1: Datum | D1: 46207 | F1: Náklad v kč
F2: =IFERROR(__xludf.DUMMYFUNCTION("SUM(A14:A20) + SUM(FILTER(HR!W5:W48, HR!A5:A48 <> """")) + J13 + J15"),40004.0) -> 40004
B3: =CHOOSE(WEEKDAY(D1), "Neděle", "Pondělí", "Úterý", "Středa", "Čtvrtek", "Pátek", "Sobota") -> Sobota
B5: Napiš vzkaz ⬇️ 📖 Deník 📖 ⬇️ Včerejší vzkaz
B12: Směny | G12: Výdaje
B13: Jméno | C13: Začátek směny | D13: Konec směny | E13: pauza | F13: Počet hodin | G13: Benzín / nafta
A14: {=IF(ISBLANK(B14), 0, IF(ISNUMBER(MATCH(B14, HR!A:A, 0)), 0, IF(ISNUMBER(MATCH(B14, HR!B:B, 0)), INDEX(HR!V:V, MATCH(B14, HR!B:B, 0)) * (F14 * 24), 0)))} -> 0 | F14: =IF(OR(ISBLANK(B14), ISBLANK(D14), D14=0), "0:00", TEXT((IF(AND(TIMEVALUE(IF(ISBLANK(D14), "00:00", D14))>=TIMEVALUE("00:00"), TIMEVALUE(IF(ISBLANK(D14), "00:00", D14))<=TIMEVALUE("06:00")), TIMEVALUE(IF(ISBLANK(D14), "00:00", D14))+1, TIMEVALUE(IF(ISBLANK(D14), "00:00", D14))) - TIMEVALUE(IF(ISBLANK(C14), "00:00", C14)) - TIMEVALUE(IF(ISBLANK(E14), "00:00", E14))), "hh:mm")) -> 0:00 | G14: Suroviny
A15: {=IF(ISBLANK(B15), 0, IF(ISNUMBER(MATCH(B15, HR!A:A, 0)), 0, IF(ISNUMBER(MATCH(B15, HR!B:B, 0)), INDEX(HR!V:V, MATCH(B15, HR!B:B, 0)) * (F15 * 24), 0)))} -> 0 | F15: =IF(OR(ISBLANK(B15), ISBLANK(D15), D15=0), "0:00", TEXT((IF(AND(TIMEVALUE(IF(ISBLANK(D15), "00:00", D15))>=TIMEVALUE("00:00"), TIMEVALUE(IF(ISBLANK(D15), "00:00", D15))<=TIMEVALUE("06:00")), TIMEVALUE(IF(ISBLANK(D15), "00:00", D15))+1, TIMEVALUE(IF(ISBLANK(D15), "00:00", D15))) - TIMEVALUE(IF(ISBLANK(C15), "00:00", C15)) - TIMEVALUE(IF(ISBLANK(E15), "00:00", E15))), "hh:mm")) -> 0:00 | G15: Ostatní
A16: {=IF(ISBLANK(B16), 0, IF(ISNUMBER(MATCH(B16, HR!A:A, 0)), 0, IF(ISNUMBER(MATCH(B16, HR!B:B, 0)), INDEX(HR!V:V, MATCH(B16, HR!B:B, 0)) * (F16 * 24), 0)))} -> 0 | F16: =IF(OR(ISBLANK(B16), ISBLANK(D16), D16=0), "0:00", TEXT((IF(AND(TIMEVALUE(IF(ISBLANK(D16), "00:00", D16))>=TIMEVALUE("00:00"), TIMEVALUE(IF(ISBLANK(D16), "00:00", D16))<=TIMEVALUE("06:00")), TIMEVALUE(IF(ISBLANK(D16), "00:00", D16))+1, TIMEVALUE(IF(ISBLANK(D16), "00:00", D16))) - TIMEVALUE(IF(ISBLANK(C16), "00:00", C16)) - TIMEVALUE(IF(ISBLANK(E16), "00:00", E16))), "hh:mm")) -> 0:00
A17: {=IF(ISBLANK(B17), 0, IF(ISNUMBER(MATCH(B17, HR!A:A, 0)), 0, IF(ISNUMBER(MATCH(B17, HR!B:B, 0)), INDEX(HR!V:V, MATCH(B17, HR!B:B, 0)) * (F17 * 24), 0)))} -> 0 | F17: =IF(OR(ISBLANK(B17), ISBLANK(D17), D17=0), "0:00", TEXT((IF(AND(TIMEVALUE(IF(ISBLANK(D17), "00:00", D17))>=TIMEVALUE("00:00"), TIMEVALUE(IF(ISBLANK(D17), "00:00", D17))<=TIMEVALUE("06:00")), TIMEVALUE(IF(ISBLANK(D17), "00:00", D17))+1, TIMEVALUE(IF(ISBLANK(D17), "00:00", D17))) - TIMEVALUE(IF(ISBLANK(C17), "00:00", C17)) - TIMEVALUE(IF(ISBLANK(E17), "00:00", E17))), "hh:mm")) -> 0:00
A18: {=IF(ISBLANK(B18), 0, IF(ISNUMBER(MATCH(B18, HR!A:A, 0)), 0, IF(ISNUMBER(MATCH(B18, HR!B:B, 0)), INDEX(HR!V:V, MATCH(B18, HR!B:B, 0)) * (F18 * 24), 0)))} -> 0 | F18: =IF(OR(ISBLANK(B18), ISBLANK(D18), D18=0), "0:00", TEXT((IF(AND(TIMEVALUE(IF(ISBLANK(D18), "00:00", D18))>=TIMEVALUE("00:00"), TIMEVALUE(IF(ISBLANK(D18), "00:00", D18))<=TIMEVALUE("06:00")), TIMEVALUE(IF(ISBLANK(D18), "00:00", D18))+1, TIMEVALUE(IF(ISBLANK(D18), "00:00", D18))) - TIMEVALUE(IF(ISBLANK(C18), "00:00", C18)) - TIMEVALUE(IF(ISBLANK(E18), "00:00", E18))), "hh:mm")) -> 0:00
A19: {=IF(ISBLANK(B19), 0, IF(ISNUMBER(MATCH(B19, HR!A:A, 0)), 0, IF(ISNUMBER(MATCH(B19, HR!B:B, 0)), INDEX(HR!V:V, MATCH(B19, HR!B:B, 0)) * (F19 * 24), 0)))} -> 0 | F19: =IF(OR(ISBLANK(B19), ISBLANK(D19), D19=0), "0:00", TEXT((IF(AND(TIMEVALUE(IF(ISBLANK(D19), "00:00", D19))>=TIMEVALUE("00:00"), TIMEVALUE(IF(ISBLANK(D19), "00:00", D19))<=TIMEVALUE("06:00")), TIMEVALUE(IF(ISBLANK(D19), "00:00", D19))+1, TIMEVALUE(IF(ISBLANK(D19), "00:00", D19))) - TIMEVALUE(IF(ISBLANK(C19), "00:00", C19)) - TIMEVALUE(IF(ISBLANK(E19), "00:00", E19))), "hh:mm")) -> 0:00
A20: {=IF(ISBLANK(B20), 0, IF(ISNUMBER(MATCH(B20, HR!A:A, 0)), 0, IF(ISNUMBER(MATCH(B20, HR!B:B, 0)), INDEX(HR!V:V, MATCH(B20, HR!B:B, 0)) * (F20 * 24), 0)))} -> 0 | F20: =IF(OR(ISBLANK(B20), ISBLANK(D20), D20=0), "0:00", TEXT((IF(AND(TIMEVALUE(IF(ISBLANK(D20), "00:00", D20))>=TIMEVALUE("00:00"), TIMEVALUE(IF(ISBLANK(D20), "00:00", D20))<=TIMEVALUE("06:00")), TIMEVALUE(IF(ISBLANK(D20), "00:00", D20))+1, TIMEVALUE(IF(ISBLANK(D20), "00:00", D20))) - TIMEVALUE(IF(ISBLANK(C20), "00:00", C20)) - TIMEVALUE(IF(ISBLANK(E20), "00:00", E20))), "hh:mm")) -> 0:00

Sheet Kontrola
B1: =Report!B1 -> Výroba | C1: 46174 | D1: Vyber datum <----------> | E1: 46203 | F1: Náklad v kč
F2: 1237482
B3: =CHOOSE(WEEKDAY(C1), "Neděle", "Pondělí", "Úterý", "Středa", "Čtvrtek", "Pátek", "Sobota") -> Pondělí | D3: =CHOOSE(WEEKDAY(E1), "Neděle", "Pondělí", "Úterý", "Středa", "Čtvrtek", "Pátek", "Sobota") -> Úterý
B5: Celkem hodin | F5: Výdaje
F6: Benzín / nafta | I6: 0
B7: =TEXT(SUMPRODUCT((IFERROR(LEFT(D8:D30, FIND(":", D8:D30) - 1) * 60, 0) + IFERROR(MID(D8:D30, FIND(":", D8:D30) + 1, LEN(D8:D30) - FIND(":", D8:D30)), 0))), "[h]:mm")/60 -> 0 | F7: Suroviny | I7: 0
B8: Směny | F8: Ostatní | I8: 0
B9: Jméno | C9: Počet dní | D9: Počet hodin
B10: Paziak Viktoriia | C10: 22 | D10: 181
B11: Kursheva Diana | C11: 22 | D11: 181
B12: Ahurieva Viktoriia | C12: 13 | D12: 110
B13: Hřebík Martin | C13: 12 | D13: 128
B14: Lažek Jaroslav | C14: 2 | D14: 20
B15: Koteliuk Maryna | C15: 2 | D15: 18

Sheet HR
C1: =IFERROR(__xludf.DUMMYFUNCTION("IMPORTRANGE(""1TpIiNTfR1pnpn85VWQTTdvQ2Xcr0GStmWJ2UvfKxG_A"", ""Mzdy!A1:F200"")")," ") | V1: =IFERROR(__xludf.DUMMYFUNCTION("IMPORTRANGE(""1TpIiNTfR1pnpn85VWQTTdvQ2Xcr0GStmWJ2UvfKxG_A"", ""Mzdy!u1:v200"")"),46204.0) -> 46204
A4: Manažeři | B4: Zamestnanci pobocky | C4: =IFERROR(__xludf.DUMMYFUNCTION("""COMPUTED_VALUE"""),"Manažer") -> Manažer | D4: =IFERROR(__xludf.DUMMYFUNCTION("""COMPUTED_VALUE"""),"Instore") -> Instore | E4: =IFERROR(__xludf.DUMMYFUNCTION("""COMPUTED_VALUE"""),"První domácí, Pobočky max 4") -> První domácí, Pobočky max 4 | V4: =IFERROR(__xludf.DUMMYFUNCTION("""COMPUTED_VALUE"""),"Suma hod.") -> Suma hod. | W4: =IFERROR(__xludf.DUMMYFUNCTION("""COMPUTED_VALUE"""),"Čistá mzda") -> Čistá mzda
A5: =IF(AND(B5<>"", C5=TRUE, E5=Report!$B$1), B5, "") | B5: =IF(OR(E5=Report!$B$1, F5=Report!$B$1, G5=Report!$B$1, H5=Report!$B$1), D5, "") | C5: =IFERROR(__xludf.DUMMYFUNCTION("""COMPUTED_VALUE"""),TRUE) -> TRUE | D5: =IFERROR(__xludf.DUMMYFUNCTION("""COMPUTED_VALUE"""),"Nedbal Michal") -> Nedbal Michal | E5: =IFERROR(__xludf.DUMMYFUNCTION("""COMPUTED_VALUE"""),"Zličín") -> Zličín | F5: =IFERROR(__xludf.DUMMYFUNCTION("""COMPUTED_VALUE"""),"Malešice") -> Malešice | G5: =IFERROR(__xludf.DUMMYFUNCTION("""COMPUTED_VALUE"""),"Prosek") -> Prosek | V5: =IFERROR(__xludf.DUMMYFUNCTION("""COMPUTED_VALUE"""),0.0) -> 0 | W5: =IFERROR(__xludf.DUMMYFUNCTION("""COMPUTED_VALUE"""),50001.08) -> 50001.08
A6: =IF(AND(B6<>"", C6=TRUE, E6=Report!$B$1), B6, "") | B6: =IF(OR(E6=Report!$B$1, F6=Report!$B$1, G6=Report!$B$1, H6=Report!$B$1), D6, "") -> Sova Martin | C6: =IFERROR(__xludf.DUMMYFUNCTION("""COMPUTED_VALUE"""),TRUE) -> TRUE | D6: =IFERROR(__xludf.DUMMYFUNCTION("""COMPUTED_VALUE"""),"Sova Martin") -> Sova Martin | E6: =IFERROR(__xludf.DUMMYFUNCTION("""COMPUTED_VALUE"""),"Chodov") -> Chodov | F6: =IFERROR(__xludf.DUMMYFUNCTION("""COMPUTED_VALUE"""),"Libuš") -> Libuš | G6: =IFERROR(__xludf.DUMMYFUNCTION("""COMPUTED_VALUE"""),"Výroba") -> Výroba | V6: =IFERROR(__xludf.DUMMYFUNCTION("""COMPUTED_VALUE"""),0.0) -> 0 | W6: =IFERROR(__xludf.DUMMYFUNCTION("""COMPUTED_VALUE"""),50001.08) -> 50001.08
A7: =IF(AND(B7<>"", C7=TRUE, E7=Report!$B$1), B7, "") -> Paziak Viktoriia | B7: =IF(OR(E7=Report!$B$1, F7=Report!$B$1, G7=Report!$B$1, H7=Report!$B$1), D7, "") -> Paziak Viktoriia | C7: =IFERROR(__xludf.DUMMYFUNCTION("""COMPUTED_VALUE"""),TRUE) -> TRUE | D7: =IFERROR(__xludf.DUMMYFUNCTION("""COMPUTED_VALUE"""),"Paziak Viktoriia") -> Paziak Viktoriia | E7: =IFERROR(__xludf.DUMMYFUNCTION("""COMPUTED_VALUE"""),"Výroba") -> Výroba | V7: =IFERROR(__xludf.DUMMYFUNCTION("""COMPUTED_VALUE"""),0.0) -> 0 | W7: =IFERROR(__xludf.DUMMYFUNCTION("""COMPUTED_VALUE"""),40004.0) -> 40004
A8: =IF(AND(B8<>"", C8=TRUE, E8=Report!$B$1), B8, "") | B8: =IF(OR(E8=Report!$B$1, F8=Report!$B$1, G8=Report!$B$1, H8=Report!$B$1), D8, "") -> Ahurieva Viktoriia | C8: =IFERROR(__xludf.DUMMYFUNCTION("""COMPUTED_VALUE"""),FALSE) -> FALSE | D8: =IFERROR(__xludf.DUMMYFUNCTION("""COMPUTED_VALUE"""),"Ahurieva Viktoriia") -> Ahurieva Viktoriia | E8: =IFERROR(__xludf.DUMMYFUNCTION("""COMPUTED_VALUE"""),"Libuš") -> Libuš | F8: =IFERROR(__xludf.DUMMYFUNCTION("""COMPUTED_VALUE"""),"Malešice") -> Malešice | G8: =IFERROR(__xludf.DUMMYFUNCTION("""COMPUTED_VALUE"""),"Výroba") -> Výroba | H8: =IFERROR(__xludf.DUMMYFUNCTION("""COMPUTED_VALUE"""),"Prosek") -> Prosek | V8: =IFERROR(__xludf.DUMMYFUNCTION("""COMPUTED_VALUE"""),0.0) -> 0 | W8: =IFERROR(__xludf.DUMMYFUNCTION("""COMPUTED_VALUE"""),50001.08) -> 50001.08
A9: =IF(AND(B9<>"", C9=TRUE, E9=Report!$B$1), B9, "") | B9: =IF(OR(E9=Report!$B$1, F9=Report!$B$1, G9=Report!$B$1, H9=Report!$B$1), D9, "") | C9: =IFERROR(__xludf.DUMMYFUNCTION("""COMPUTED_VALUE"""),TRUE) -> TRUE | D9: =IFERROR(__xludf.DUMMYFUNCTION("""COMPUTED_VALUE"""),"Pešová Hana") -> Pešová Hana | E9: =IFERROR(__xludf.DUMMYFUNCTION("""COMPUTED_VALUE"""),"Chodov") -> Chodov | F9: =IFERROR(__xludf.DUMMYFUNCTION("""COMPUTED_VALUE"""),"Prosek") -> Prosek | V9: =IFERROR(__xludf.DUMMYFUNCTION("""COMPUTED_VALUE"""),0.0) -> 0 | W9: =IFERROR(__xludf.DUMMYFUNCTION("""COMPUTED_VALUE"""),40004.0) -> 40004
A10: =IF(AND(B10<>"", C10=TRUE, E10=Report!$B$1), B10, "") | B10: =IF(OR(E10=Report!$B$1, F10=Report!$B$1, G10=Report!$B$1, H10=Report!$B$1), D10, "") | C10: =IFERROR(__xludf.DUMMYFUNCTION("""COMPUTED_VALUE"""),TRUE) -> TRUE | D10: =IFERROR(__xludf.DUMMYFUNCTION("""COMPUTED_VALUE"""),"Šebesta Tomáš") -> Šebesta Tomáš | E10: =IFERROR(__xludf.DUMMYFUNCTION("""COMPUTED_VALUE"""),"Prosek") -> Prosek | F10: =IFERROR(__xludf.DUMMYFUNCTION("""COMPUTED_VALUE"""),"Libuš") -> Libuš | G10: =IFERROR(__xludf.DUMMYFUNCTION("""COMPUTED_VALUE"""),"Malešice") -> Malešice | H10: =IFERROR(__xludf.DUMMYFUNCTION("""COMPUTED_VALUE"""),"Chodov") -> Chodov | V10: =IFERROR(__xludf.DUMMYFUNCTION("""COMPUTED_VALUE"""),0.0) -> 0 | W10: =IFERROR(__xludf.DUMMYFUNCTION("""COMPUTED_VALUE"""),50001.08) -> 50001.08
A11: =IF(AND(B11<>"", C11=TRUE, E11=Report!$B$1), B11, "") | B11: =IF(OR(E11=Report!$B$1, F11=Report!$B$1, G11=Report!$B$1, H11=Report!$B$1), D11, "") | C11: =IFERROR(__xludf.DUMMYFUNCTION("""COMPUTED_VALUE"""),FALSE) -> FALSE | D11: =IFERROR(__xludf.DUMMYFUNCTION("""COMPUTED_VALUE"""),"Hanakova Ayuna") -> Hanakova Ayuna | E11: =IFERROR(__xludf.DUMMYFUNCTION("""COMPUTED_VALUE"""),"Zličín") -> Zličín | V11: =IFERROR(__xludf.DUMMYFUNCTION("""COMPUTED_VALUE"""),0.0) -> 0 | W11: =IFERROR(__xludf.DUMMYFUNCTION("""COMPUTED_VALUE"""),0.0) -> 0
A12: =IF(AND(B12<>"", C12=TRUE, E12=Report!$B$1), B12, "") | B12: =IF(OR(E12=Report!$B$1, F12=Report!$B$1, G12=Report!$B$1, H12=Report!$B$1), D12, "") | C12: =IFERROR(__xludf.DUMMYFUNCTION("""COMPUTED_VALUE"""),FALSE) -> FALSE | D12: =IFERROR(__xludf.DUMMYFUNCTION("""COMPUTED_VALUE"""),"Vondráček Lukáš") -> Vondráček Lukáš | V12: =IFERROR(__xludf.DUMMYFUNCTION("""COMPUTED_VALUE"""),0.0) -> 0 | W12: =IFERROR(__xludf.DUMMYFUNCTION("""COMPUTED_VALUE"""),78000.0) -> 78000
A13: =IF(AND(B13<>"", C13=TRUE, E13=Report!$B$1), B13, "") | B13: =IF(OR(E13=Report!$B$1, F13=Report!$B$1, G13=Report!$B$1, H13=Report!$B$1), D13, "") | C13: =IFERROR(__xludf.DUMMYFUNCTION("""COMPUTED_VALUE"""),TRUE) -> TRUE | D13: =IFERROR(__xludf.DUMMYFUNCTION("""COMPUTED_VALUE"""),"Veselý Ondřej") -> Veselý Ondřej | E13: =IFERROR(__xludf.DUMMYFUNCTION("""COMPUTED_VALUE"""),"Zličín") -> Zličín | F13: =IFERROR(__xludf.DUMMYFUNCTION("""COMPUTED_VALUE"""),"Malešice") -> Malešice | V13: =IFERROR(__xludf.DUMMYFUNCTION("""COMPUTED_VALUE"""),0.0) -> 0 | W13: =IFERROR(__xludf.DUMMYFUNCTION("""COMPUTED_VALUE"""),40004.0) -> 40004
A14: =IF(AND(B14<>"", C14=TRUE, E14=Report!$B$1), B14, "") | B14: =IF(OR(E14=Report!$B$1, F14=Report!$B$1, G14=Report!$B$1, H14=Report!$B$1), D14, "") | C14: =IFERROR(__xludf.DUMMYFUNCTION("""COMPUTED_VALUE"""),FALSE) -> FALSE | D14: =IFERROR(__xludf.DUMMYFUNCTION("""COMPUTED_VALUE"""),"Coufal Jakub") -> Coufal Jakub | E14: =IFERROR(__xludf.DUMMYFUNCTION("""COMPUTED_VALUE"""),"Libuš") -> Libuš | F14: =IFERROR(__xludf.DUMMYFUNCTION("""COMPUTED_VALUE"""),"Malešice") -> Malešice | G14: =IFERROR(__xludf.DUMMYFUNCTION("""COMPUTED_VALUE"""),"Prosek") -> Prosek | V14: =IFERROR(__xludf.DUMMYFUNCTION("""COMPUTED_VALUE"""),0.0) -> 0 | W14: =IFERROR(__xludf.DUMMYFUNCTION("""COMPUTED_VALUE"""),0.0) -> 0
A15: =IF(AND(B15<>"", C15=TRUE, E15=Report!$B$1), B15, "") | B15: =IF(OR(E15=Report!$B$1, F15=Report!$B$1, G15=Report!$B$1, H15=Report!$B$1), D15, "") | C15: =IFERROR(__xludf.DUMMYFUNCTION("""COMPUTED_VALUE"""),TRUE) -> TRUE | D15: =IFERROR(__xludf.DUMMYFUNCTION("""COMPUTED_VALUE"""),"Kinkorová Petra") -> Kinkorová Petra | E15: =IFERROR(__xludf.DUMMYFUNCTION("""COMPUTED_VALUE"""),"Malešice") -> Malešice | F15: =IFERROR(__xludf.DUMMYFUNCTION("""COMPUTED_VALUE"""),"Bolevec") -> Bolevec | V15: =IFERROR(__xludf.DUMMYFUNCTION("""COMPUTED_VALUE"""),0.0) -> 0 | W15: =IFERROR(__xludf.DUMMYFUNCTION("""COMPUTED_VALUE"""),40004.0) -> 40004
A16: =IF(AND(B16<>"", C16=TRUE, E16=Report!$B$1), B16, "") | B16: =IF(OR(E16=Report!$B$1, F16=Report!$B$1, G16=Report!$B$1, H16=Report!$B$1), D16, "") | C16: =IFERROR(__xludf.DUMMYFUNCTION("""COMPUTED_VALUE"""),TRUE) -> TRUE | D16: =IFERROR(__xludf.DUMMYFUNCTION("""COMPUTED_VALUE"""),"Nováková Adéla") -> Nováková Adéla | E16: =IFERROR(__xludf.DUMMYFUNCTION("""COMPUTED_VALUE"""),"Prosek") -> Prosek | F16: =IFERROR(__xludf.DUMMYFUNCTION("""COMPUTED_VALUE"""),"Malešice") -> Malešice | V16: =IFERROR(__xludf.DUMMYFUNCTION("""COMPUTED_VALUE"""),0.0) -> 0 | W16: =IFERROR(__xludf.DUMMYFUNCTION("""COMPUTED_VALUE"""),40004.0) -> 40004
A17: =IF(AND(B17<>"", C17=TRUE, E17=Report!$B$1), B17, "") | B17: =IF(OR(E17=Report!$B$1, F17=Report!$B$1, G17=Report!$B$1, H17=Report!$B$1), D17, "") | C17: =IFERROR(__xludf.DUMMYFUNCTION("""COMPUTED_VALUE"""),FALSE) -> FALSE | D17: =IFERROR(__xludf.DUMMYFUNCTION("""COMPUTED_VALUE"""),"Pechová Barbora") -> Pechová Barbora | E17: =IFERROR(__xludf.DUMMYFUNCTION("""COMPUTED_VALUE"""),"Zličín") -> Zličín | V17: =IFERROR(__xludf.DUMMYFUNCTION("""COMPUTED_VALUE"""),0.0) -> 0 | W17: =IFERROR(__xludf.DUMMYFUNCTION("""COMPUTED_VALUE"""),0.0) -> 0
A18: =IF(AND(B18<>"", C18=TRUE, E18=Report!$B$1), B18, "") | B18: =IF(OR(E18=Report!$B$1, F18=Report!$B$1, G18=Report!$B$1, H18=Report!$B$1), D18, "") | C18: =IFERROR(__xludf.DUMMYFUNCTION("""COMPUTED_VALUE"""),FALSE) -> FALSE | D18: =IFERROR(__xludf.DUMMYFUNCTION("""COMPUTED_VALUE"""),"Pánková Vendula") -> Pánková Vendula | E18: =IFERROR(__xludf.DUMMYFUNCTION("""COMPUTED_VALUE"""),"Zličín") -> Zličín | V18: =IFERROR(__xludf.DUMMYFUNCTION("""COMPUTED_VALUE"""),0.0) -> 0 | W18: =IFERROR(__xludf.DUMMYFUNCTION("""COMPUTED_VALUE"""),0.0) -> 0
A19: =IF(AND(B19<>"", C19=TRUE, E19=Report!$B$1), B19, "") | B19: =IF(OR(E19=Report!$B$1, F19=Report!$B$1, G19=Report!$B$1, H19=Report!$B$1), D19, "") | C19: =IFERROR(__xludf.DUMMYFUNCTION("""COMPUTED_VALUE"""),TRUE) -> TRUE | D19: =IFERROR(__xludf.DUMMYFUNCTION("""COMPUTED_VALUE"""),"Hegedüs Erik") -> Hegedüs Erik | E19: =IFERROR(__xludf.DUMMYFUNCTION("""COMPUTED_VALUE"""),"Libuš") -> Libuš | F19: =IFERROR(__xludf.DUMMYFUNCTION("""COMPUTED_VALUE"""),"Chodov") -> Chodov | G19: =IFERROR(__xludf.DUMMYFUNCTION("""COMPUTED_VALUE"""),"Malešice") -> Malešice | H19: =IFERROR(__xludf.DUMMYFUNCTION("""COMPUTED_VALUE"""),"Zličín") -> Zličín | V19: =IFERROR(__xludf.DUMMYFUNCTION("""COMPUTED_VALUE"""),0.0) -> 0 | W19: =IFERROR(__xludf.DUMMYFUNCTION("""COMPUTED_VALUE"""),50001.08) -> 50001.08
A20: =IF(AND(B20<>"", C20=TRUE, E20=Report!$B$1), B20, "") | B20: =IF(OR(E20=Report!$B$1, F20=Report!$B$1, G20=Report!$B$1, H20=Report!$B$1), D20, "") | C20: =IFERROR(__xludf.DUMMYFUNCTION("""COMPUTED_VALUE"""),TRUE) -> TRUE | D20: =IFERROR(__xludf.DUMMYFUNCTION("""COMPUTED_VALUE"""),"Roth Stanislav ml.") -> Roth Stanislav ml. | E20: =IFERROR(__xludf.DUMMYFUNCTION("""COMPUTED_VALUE"""),"Bolevec") -> Bolevec | V20: =IFERROR(__xludf.DUMMYFUNCTION("""COMPUTED_VALUE"""),0.0) -> 0 | W20: =IFERROR(__xludf.DUMMYFUNCTION("""COMPUTED_VALUE"""),50001.08) -> 50001.08
A21: =IF(AND(B21<>"", C21=TRUE, E21=Report!$B$1), B21, "") | B21: =IF(OR(E21=Report!$B$1, F21=Report!$B$1, G21=Report!$B$1, H21=Report!$B$1), D21, "") | C21: =IFERROR(__xludf.DUMMYFUNCTION("""COMPUTED_VALUE"""),FALSE) -> FALSE | D21: =IFERROR(__xludf.DUMMYFUNCTION("""COMPUTED_VALUE"""),"Bubník Martin") -> Bubník Martin | E21: =IFERROR(__xludf.DUMMYFUNCTION("""COMPUTED_VALUE"""),"Libuš") -> Libuš | F21: =IFERROR(__xludf.DUMMYFUNCTION("""COMPUTED_VALUE"""),"Malešice") -> Malešice | V21: =IFERROR(__xludf.DUMMYFUNCTION("""COMPUTED_VALUE"""),0.0) -> 0 | W21: =IFERROR(__xludf.DUMMYFUNCTION("""COMPUTED_VALUE"""),0.0) -> 0
A22: =IF(AND(B22<>"", C22=TRUE, E22=Report!$B$1), B22, "") | B22: =IF(OR(E22=Report!$B$1, F22=Report!$B$1, G22=Report!$B$1, H22=Report!$B$1), D22, "") | C22: =IFERROR(__xludf.DUMMYFUNCTION("""COMPUTED_VALUE"""),FALSE) -> FALSE | D22: =IFERROR(__xludf.DUMMYFUNCTION("""COMPUTED_VALUE"""),"Berdar Vasyl") -> Berdar Vasyl | E22: =IFERROR(__xludf.DUMMYFUNCTION("""COMPUTED_VALUE"""),"Libuš") -> Libuš | V22: =IFERROR(__xludf.DUMMYFUNCTION("""COMPUTED_VALUE"""),0.0) -> 0 | W22: =IFERROR(__xludf.DUMMYFUNCTION("""COMPUTED_VALUE"""),0.0) -> 0
A23: =IF(AND(B23<>"", C23=TRUE, E23=Report!$B$1), B23, "") | B23: =IF(OR(E23=Report!$B$1, F23=Report!$B$1, G23=Report!$B$1, H23=Report!$B$1), D23, "") | C23: =IFERROR(__xludf.DUMMYFUNCTION("""COMPUTED_VALUE"""),FALSE) -> FALSE | D23: =IFERROR(__xludf.DUMMYFUNCTION("""COMPUTED_VALUE"""),"Yarushynskyi Vladyslav") -> Yarushynskyi Vladyslav | E23: =IFERROR(__xludf.DUMMYFUNCTION("""COMPUTED_VALUE"""),"Malešice") -> Malešice | F23: =IFERROR(__xludf.DUMMYFUNCTION("""COMPUTED_VALUE"""),"Chodov") -> Chodov | G23: =IFERROR(__xludf.DUMMYFUNCTION("""COMPUTED_VALUE"""),"Zličín") -> Zličín | H23: =IFERROR(__xludf.DUMMYFUNCTION("""COMPUTED_VALUE"""),"Prosek") -> Prosek | V23: =IFERROR(__xludf.DUMMYFUNCTION("""COMPUTED_VALUE"""),0.0) -> 0 | W23: =IFERROR(__xludf.DUMMYFUNCTION("""COMPUTED_VALUE"""),0.0) -> 0
A24: =IF(AND(B24<>"", C24=TRUE, E24=Report!$B$1), B24, "") | B24: =IF(OR(E24=Report!$B$1, F24=Report!$B$1, G24=Report!$B$1, H24=Report!$B$1), D24, "") | C24: =IFERROR(__xludf.DUMMYFUNCTION("""COMPUTED_VALUE"""),FALSE) -> FALSE | D24: =IFERROR(__xludf.DUMMYFUNCTION("""COMPUTED_VALUE"""),"Židek Petr") -> Židek Petr | E24: =IFERROR(__xludf.DUMMYFUNCTION("""COMPUTED_VALUE"""),"Chodov") -> Chodov | F24: =IFERROR(__xludf.DUMMYFUNCTION("""COMPUTED_VALUE"""),"Malešice") -> Malešice | V24: =IFERROR(__xludf.DUMMYFUNCTION("""COMPUTED_VALUE"""),0.0) -> 0 | W24: =IFERROR(__xludf.DUMMYFUNCTION("""COMPUTED_VALUE"""),0.0) -> 0
A25: =IF(AND(B25<>"", C25=TRUE, E25=Report!$B$1), B25, "") | B25: =IF(OR(E25=Report!$B$1, F25=Report!$B$1, G25=Report!$B$1, H25=Report!$B$1), D25, "") | C25: =IFERROR(__xludf.DUMMYFUNCTION("""COMPUTED_VALUE"""),FALSE) -> FALSE | D25: =IFERROR(__xludf.DUMMYFUNCTION("""COMPUTED_VALUE"""),"Gorol Patrik") -> Gorol Patrik | E25: =IFERROR(__xludf.DUMMYFUNCTION("""COMPUTED_VALUE"""),"Malešice") -> Malešice | F25: =IFERROR(__xludf.DUMMYFUNCTION("""COMPUTED_VALUE"""),"Libuš") -> Libuš | G25: =IFERROR(__xludf.DUMMYFUNCTION("""COMPUTED_VALUE"""),"Prosek") -> Prosek | V25: =IFERROR(__xludf.DUMMYFUNCTION("""COMPUTED_VALUE"""),0.0) -> 0 | W25: =IFERROR(__xludf.DUMMYFUNCTION("""COMPUTED_VALUE"""),0.0) -> 0
A26: =IF(AND(B26<>"", C26=TRUE, E26=Report!$B$1), B26, "") | B26: =IF(OR(E26=Report!$B$1, F26=Report!$B$1, G26=Report!$B$1, H26=Report!$B$1), D26, "") | C26: =IFERROR(__xludf.DUMMYFUNCTION("""COMPUTED_VALUE"""),FALSE) -> FALSE | D26: =IFERROR(__xludf.DUMMYFUNCTION("""COMPUTED_VALUE"""),"Hegedüs Gergö") -> Hegedüs Gergö | E26: =IFERROR(__xludf.DUMMYFUNCTION("""COMPUTED_VALUE"""),"Libuš") -> Libuš | V26: =IFERROR(__xludf.DUMMYFUNCTION("""COMPUTED_VALUE"""),0.0) -> 0 | W26: =IFERROR(__xludf.DUMMYFUNCTION("""COMPUTED_VALUE"""),0.0) -> 0
A27: =IF(AND(B27<>"", C27=TRUE, E27=Report!$B$1), B27, "") | B27: =IF(OR(E27=Report!$B$1, F27=Report!$B$1, G27=Report!$B$1, H27=Report!$B$1), D27, "") | C27: =IFERROR(__xludf.DUMMYFUNCTION("""COMPUTED_VALUE"""),FALSE) -> FALSE | D27: =IFERROR(__xludf.DUMMYFUNCTION("""COMPUTED_VALUE"""),"Barvínková Eliška") -> Barvínková Eliška | E27: =IFERROR(__xludf.DUMMYFUNCTION("""COMPUTED_VALUE"""),"Libuš") -> Libuš | V27: =IFERROR(__xludf.DUMMYFUNCTION("""COMPUTED_VALUE"""),0.0) -> 0 | W27: =IFERROR(__xludf.DUMMYFUNCTION("""COMPUTED_VALUE"""),0.0) -> 0
A28: =IF(AND(B28<>"", C28=TRUE, E28=Report!$B$1), B28, "") | B28: =IF(OR(E28=Report!$B$1, F28=Report!$B$1, G28=Report!$B$1, H28=Report!$B$1), D28, "") -> Kursheva Diana | C28: =IFERROR(__xludf.DUMMYFUNCTION("""COMPUTED_VALUE"""),FALSE) -> FALSE | D28: =IFERROR(__xludf.DUMMYFUNCTION("""COMPUTED_VALUE"""),"Kursheva Diana") -> Kursheva Diana | E28: =IFERROR(__xludf.DUMMYFUNCTION("""COMPUTED_VALUE"""),"Výroba") -> Výroba | F28: =IFERROR(__xludf.DUMMYFUNCTION("""COMPUTED_VALUE"""),"Chodov") -> Chodov | V28: =IFERROR(__xludf.DUMMYFUNCTION("""COMPUTED_VALUE"""),0.0) -> 0 | W28: =IFERROR(__xludf.DUMMYFUNCTION("""COMPUTED_VALUE"""),0.0) -> 0
A29: =IF(AND(B29<>"", C29=TRUE, E29=Report!$B$1), B29, "") | B29: =IF(OR(E29=Report!$B$1, F29=Report!$B$1, G29=Report!$B$1, H29=Report!$B$1), D29, "") | C29: =IFERROR(__xludf.DUMMYFUNCTION("""COMPUTED_VALUE"""),FALSE) -> FALSE | D29: =IFERROR(__xludf.DUMMYFUNCTION("""COMPUTED_VALUE"""),"Kubík Martin") -> Kubík Martin | E29: =IFERROR(__xludf.DUMMYFUNCTION("""COMPUTED_VALUE"""),"Libuš") -> Libuš | V29: =IFERROR(__xludf.DUMMYFUNCTION("""COMPUTED_VALUE"""),0.0) -> 0 | W29: =IFERROR(__xludf.DUMMYFUNCTION("""COMPUTED_VALUE"""),0.0) -> 0
A30: =IF(AND(B30<>"", C30=TRUE, E30=Report!$B$1), B30, "") | B30: =IF(OR(E30=Report!$B$1, F30=Report!$B$1, G30=Report!$B$1, H30=Report!$B$1), D30, "") | C30: =IFERROR(__xludf.DUMMYFUNCTION("""COMPUTED_VALUE"""),FALSE) -> FALSE | D30: =IFERROR(__xludf.DUMMYFUNCTION("""COMPUTED_VALUE"""),"Putna Jaroslav") -> Putna Jaroslav | E30: =IFERROR(__xludf.DUMMYFUNCTION("""COMPUTED_VALUE"""),"Zličín") -> Zličín | F30: =IFERROR(__xludf.DUMMYFUNCTION("""COMPUTED_VALUE"""),"Prosek") -> Prosek | V30: =IFERROR(__xludf.DUMMYFUNCTION("""COMPUTED_VALUE"""),0.0) -> 0 | W30: =IFERROR(__xludf.DUMMYFUNCTION("""COMPUTED_VALUE"""),0.0) -> 0
A31: =IF(AND(B31<>"", C31=TRUE, E31=Report!$B$1), B31, "") | B31: =IF(OR(E31=Report!$B$1, F31=Report!$B$1, G31=Report!$B$1, H31=Report!$B$1), D31, "") | C31: =IFERROR(__xludf.DUMMYFUNCTION("""COMPUTED_VALUE"""),FALSE) -> FALSE | D31: =IFERROR(__xludf.DUMMYFUNCTION("""COMPUTED_VALUE"""),"Kopic Jakub") -> Kopic Jakub | E31: =IFERROR(__xludf.DUMMYFUNCTION("""COMPUTED_VALUE"""),"Malešice") -> Malešice | F31: =IFERROR(__xludf.DUMMYFUNCTION("""COMPUTED_VALUE"""),"Prosek") -> Prosek | G31: =IFERROR(__xludf.DUMMYFUNCTION("""COMPUTED_VALUE"""),"Libuš") -> Libuš | H31: =IFERROR(__xludf.DUMMYFUNCTION("""COMPUTED_VALUE"""),"Prosek") -> Prosek | V31: =IFERROR(__xludf.DUMMYFUNCTION("""COMPUTED_VALUE"""),0.0) -> 0 | W31: =IFERROR(__xludf.DUMMYFUNCTION("""COMPUTED_VALUE"""),0.0) -> 0
A32: =IF(AND(B32<>"", C32=TRUE, E32=Report!$B$1), B32, "") | B32: =IF(OR(E32=Report!$B$1, F32=Report!$B$1, G32=Report!$B$1, H32=Report!$B$1), D32, "") | C32: =IFERROR(__xludf.DUMMYFUNCTION("""COMPUTED_VALUE"""),FALSE) -> FALSE | D32: =IFERROR(__xludf.DUMMYFUNCTION("""COMPUTED_VALUE"""),"Fáberová Kateřina") -> Fáberová Kateřina | E32: =IFERROR(__xludf.DUMMYFUNCTION("""COMPUTED_VALUE"""),"Prosek") -> Prosek | V32: =IFERROR(__xludf.DUMMYFUNCTION("""COMPUTED_VALUE"""),0.0) -> 0 | W32: =IFERROR(__xludf.DUMMYFUNCTION("""COMPUTED_VALUE"""),0.0) -> 0
A33: =IF(AND(B33<>"", C33=TRUE, E33=Report!$B$1), B33, "") | B33: =IF(OR(E33=Report!$B$1, F33=Report!$B$1, G33=Report!$B$1, H33=Report!$B$1), D33, "") | C33: =IFERROR(__xludf.DUMMYFUNCTION("""COMPUTED_VALUE"""),FALSE) -> FALSE | D33: =IFERROR(__xludf.DUMMYFUNCTION("""COMPUTED_VALUE"""),"Chlubnová Adéla") -> Chlubnová Adéla | E33: =IFERROR(__xludf.DUMMYFUNCTION("""COMPUTED_VALUE"""),"Chodov") -> Chodov | V33: =IFERROR(__xludf.DUMMYFUNCTION("""COMPUTED_VALUE"""),0.0) -> 0 | W33: =IFERROR(__xludf.DUMMYFUNCTION("""COMPUTED_VALUE"""),0.0) -> 0
A34: =IF(AND(B34<>"", C34=TRUE, E34=Report!$B$1), B34, "") | B34: =IF(OR(E34=Report!$B$1, F34=Report!$B$1, G34=Report!$B$1, H34=Report!$B$1), D34, "") | C34: =IFERROR(__xludf.DUMMYFUNCTION("""COMPUTED_VALUE"""),FALSE) -> FALSE | D34: =IFERROR(__xludf.DUMMYFUNCTION("""COMPUTED_VALUE"""),"Prošek Václav") -> Prošek Václav | E34: =IFERROR(__xludf.DUMMYFUNCTION("""COMPUTED_VALUE"""),"Libuš") -> Libuš | V34: =IFERROR(__xludf.DUMMYFUNCTION("""COMPUTED_VALUE"""),0.0) -> 0 | W34: =IFERROR(__xludf.DUMMYFUNCTION("""COMPUTED_VALUE"""),0.0) -> 0
A35: =IF(AND(B35<>"", C35=TRUE, E35=Report!$B$1), B35, "") | B35: =IF(OR(E35=Report!$B$1, F35=Report!$B$1, G35=Report!$B$1, H35=Report!$B$1), D35, "") | C35: =IFERROR(__xludf.DUMMYFUNCTION("""COMPUTED_VALUE"""),FALSE) -> FALSE | D35: =IFERROR(__xludf.DUMMYFUNCTION("""COMPUTED_VALUE"""),"Millington Emmanuel") -> Millington Emmanuel | E35: =IFERROR(__xludf.DUMMYFUNCTION("""COMPUTED_VALUE"""),"Libuš") -> Libuš | V35: =IFERROR(__xludf.DUMMYFUNCTION("""COMPUTED_VALUE"""),0.0) -> 0 | W35: =IFERROR(__xludf.DUMMYFUNCTION("""COMPUTED_VALUE"""),0.0) -> 0
A36: =IF(AND(B36<>"", C36=TRUE, E36=Report!$B$1), B36, "") | B36: =IF(OR(E36=Report!$B$1, F36=Report!$B$1, G36=Report!$B$1, H36=Report!$B$1), D36, "") | C36: =IFERROR(__xludf.DUMMYFUNCTION("""COMPUTED_VALUE"""),FALSE) -> FALSE | D36: =IFERROR(__xludf.DUMMYFUNCTION("""COMPUTED_VALUE"""),"Kašpárek Jan") -> Kašpárek Jan | E36: =IFERROR(__xludf.DUMMYFUNCTION("""COMPUTED_VALUE"""),"Libuš") -> Libuš | V36: =IFERROR(__xludf.DUMMYFUNCTION("""COMPUTED_VALUE"""),0.0) -> 0 | W36: =IFERROR(__xludf.DUMMYFUNCTION("""COMPUTED_VALUE"""),0.0) -> 0
A37: =IF(AND(B37<>"", C37=TRUE, E37=Report!$B$1), B37, "") | B37: =IF(OR(E37=Report!$B$1, F37=Report!$B$1, G37=Report!$B$1, H37=Report!$B$1), D37, "") -> Koteliuk Maryna | C37: =IFERROR(__xludf.DUMMYFUNCTION("""COMPUTED_VALUE"""),FALSE) -> FALSE | D37: =IFERROR(__xludf.DUMMYFUNCTION("""COMPUTED_VALUE"""),"Koteliuk Maryna") -> Koteliuk Maryna | E37: =IFERROR(__xludf.DUMMYFUNCTION("""COMPUTED_VALUE"""),"Výroba") -> Výroba | V37: =IFERROR(__xludf.DUMMYFUNCTION("""COMPUTED_VALUE"""),0.0) -> 0 | W37: =IFERROR(__xludf.DUMMYFUNCTION("""COMPUTED_VALUE"""),0.0) -> 0
A38: =IF(AND(B38<>"", C38=TRUE, E38=Report!$B$1), B38, "") | B38: =IF(OR(E38=Report!$B$1, F38=Report!$B$1, G38=Report!$B$1, H38=Report!$B$1), D38, "") | C38: =IFERROR(__xludf.DUMMYFUNCTION("""COMPUTED_VALUE"""),FALSE) -> FALSE | D38: =IFERROR(__xludf.DUMMYFUNCTION("""COMPUTED_VALUE"""),"Remač Jiří") -> Remač Jiří | E38: =IFERROR(__xludf.DUMMYFUNCTION("""COMPUTED_VALUE"""),"Libuš") -> Libuš | V38: =IFERROR(__xludf.DUMMYFUNCTION("""COMPUTED_VALUE"""),0.0) -> 0 | W38: =IFERROR(__xludf.DUMMYFUNCTION("""COMPUTED_VALUE"""),0.0) -> 0
A39: =IF(AND(B39<>"", C39=TRUE, E39=Report!$B$1), B39, "") | B39: =IF(OR(E39=Report!$B$1, F39=Report!$B$1, G39=Report!$B$1, H39=Report!$B$1), D39, "") | C39: =IFERROR(__xludf.DUMMYFUNCTION("""COMPUTED_VALUE"""),FALSE) -> FALSE | V39: =IFERROR(__xludf.DUMMYFUNCTION("""COMPUTED_VALUE"""),0.0) -> 0 | W39: =IFERROR(__xludf.DUMMYFUNCTION("""COMPUTED_VALUE"""),0.0) -> 0
A40: =IF(AND(B40<>"", C40=TRUE, E40=Report!$B$1), B40, "") | B40: =IF(OR(E40=Report!$B$1, F40=Report!$B$1, G40=Report!$B$1, H40=Report!$B$1), D40, "") | C40: =IFERROR(__xludf.DUMMYFUNCTION("""COMPUTED_VALUE"""),FALSE) -> FALSE | V40: =IFERROR(__xludf.DUMMYFUNCTION("""COMPUTED_VALUE"""),0.0) -> 0 | W40: =IFERROR(__xludf.DUMMYFUNCTION("""COMPUTED_VALUE"""),0.0) -> 0
A41: =IF(AND(B41<>"", C41=TRUE, E41=Report!$B$1), B41, "") | B41: =IF(OR(E41=Report!$B$1, F41=Report!$B$1, G41=Report!$B$1, H41=Report!$B$1), D41, "") | C41: =IFERROR(__xludf.DUMMYFUNCTION("""COMPUTED_VALUE"""),FALSE) -> FALSE | V41: =IFERROR(__xludf.DUMMYFUNCTION("""COMPUTED_VALUE"""),0.0) -> 0 | W41: =IFERROR(__xludf.DUMMYFUNCTION("""COMPUTED_VALUE"""),0.0) -> 0
A42: =IF(AND(B42<>"", C42=TRUE, E42=Report!$B$1), B42, "") | B42: =IF(OR(E42=Report!$B$1, F42=Report!$B$1, G42=Report!$B$1, H42=Report!$B$1), D42, "") | C42: =IFERROR(__xludf.DUMMYFUNCTION("""COMPUTED_VALUE"""),FALSE) -> FALSE | V42: =IFERROR(__xludf.DUMMYFUNCTION("""COMPUTED_VALUE"""),0.0) -> 0 | W42: =IFERROR(__xludf.DUMMYFUNCTION("""COMPUTED_VALUE"""),0.0) -> 0
...

Sheet August 2024
A1: Datum | B1: Den v týdnu | C1: Směny | D1: Začátek směny | E1: Konec směny | F1: Pauza | G1: Počet hodin | H1: Mzdový náklad | I1: Benzín | J1: Suroviny | K1: Ostatní
A2: 45528 | B2: Sobota | C2: Viktoriia Paziak | D2: 20:00 | E2: 21:00 | F2: 00:00 | G2: 01:00 | H2: 3728
A3: 45528 | B3: Sobota | C3: Stepanenko Solomiia | D3: 10:00 | E3: 11:00 | F3: 00:00 | G3: 01:00 | H3: 3728
A4: 45528 | B4: Sobota | C4: Hřebík Martin | D4: 05:00 | E4: 10:00 | G4: 05:00 | H4: 3728
A5: 45528 | B5: Sobota | I5: 12 | J5: 15 | K5: 14
A6: 45526 | B6: Čtvrtek | C6: Viktoriia Paziak | D6: 20:00 | E6: 21:00 | F6: 00:00 | G6: 01:00 | H6: 3728
A7: 45526 | B7: Čtvrtek | C7: Stepanenko Solomiia | D7: 10:00 | E7: 11:00 | F7: 00:00 | G7: 01:00 | H7: 3728
A8: 45526 | B8: Čtvrtek | C8: Hřebík Martin | D8: 05:00 | E8: 10:00 | G8: 05:00 | H8: 3728
A9: 45526 | B9: Čtvrtek | I9: 12 | J9: 15 | K9: 14
A10: 45526 | B10: Čtvrtek | C10: Viktoriia Paziak | D10: 20:00 | E10: 21:00 | F10: 00:00 | G10: 01:00 | H10: 3728
A11: 45526 | B11: Čtvrtek | C11: Stepanenko Solomiia | D11: 10:00 | E11: 11:00 | F11: 00:00 | G11: 01:00 | H11: 3728
A12: 45526 | B12: Čtvrtek | C12: Hřebík Martin | D12: 05:00 | E12: 10:00 | G12: 05:00 | H12: 3728
A13: 45526 | B13: Čtvrtek | I13: 12 | J13: 15 | K13: 14
A14: 45532 | B14: Středa
A15: 45533 | B15: Čtvrtek
A16: 45534 | B16: Pátek
A17: 45535 | B17: Sobota

Sheet Denik

Sheet Směny
A1: Sem zadej směnu pro tento týden z CSV - Směny -> Naplánované směny -> Aktuální nebo Následující týden -> Stáhnout CSV (v pravo nahoře ) -> otevřív v excelu -> oznacit všechny buňky a dvojklikem na dělící přepážku mezi A a B přizpůsob buňky velikosti textu. Poté tabulku zkopíruj do této tabulky do bunky A2, označeno modře.
AB14: 3
AB15: -8
AB16: -5
AB17: -6
AB18: 2
AA19: 2024-08-09T22:19:02.895+02:00 | AB19: -11
AB20: 0
AB21: 5
AB22: -7
AB23: 1
AB24: -2
AB25: -1
AB26: 0
AB27: -7
AB28: -9
AB29: 0
AA30: 2024-08-09T20:59:02.480+02:00 | AB30: -8
AB31: -7
AB32: -2
AB33: -8
AA34: 2024-08-09T20:46:02.837+02:00 | AB34: 0
AB35: 1
AB36: 0
AB37: 4
AA38: 2024-08-09T20:34:02.891+02:00 | AB38: -12
AA39: 2024-08-09T20:47:12.087+02:00 | AB39: 0
AB40: -2
AB41: -10
AA42: 2024-08-09T20:23:02.590+02:00 | AB42: 6
AB43: -7
AB44: -2
AB45: 0
AB46: -2
AB47: 0
AA48: 2024-08-09T20:03:02.507+02:00 | AB48: -13
AB49: -6
AB50: 0
AB51: -6
AA52: 2024-08-09T19:56:02.899+02:00 | AB52: 5
...
