Workbook

Sheet Mzdy po týdnech
AA1: Týden spadá do různých měsíců, pozor na výpočet ! | AY1: Týden spadá do různých měsíců, pozor na výpočet ! | DA1: Týden spadá do různých měsíců, pozor na výpočet ! | DY1: Týden spadá do různých měsíců, pozor na výpočet !
C3: ='m3'!E3 -> 43892 | E3: =C3+6 -> 43898 | F3: týden | G3: =WEEKNUM(C3, 2) -> 10 | I3: ='m3'!S3 -> 43899 | K3: =I3+6 -> 43905 | L3: týden | M3: =WEEKNUM(I3, 2) -> 11 | O3: ='m3'!AG3 -> 43906 | Q3: =O3+6 -> 43912 | R3: týden | S3: =WEEKNUM(O3, 2) -> 12 | U3: ='m3'!AU3 -> 43913 | W3: =U3+6 -> 43919 | X3: týden | Y3: =WEEKNUM(U3, 2) -> 13 | AA3: ='m3'!BI3 -> 43920 | AC3: =AA3+6 -> 43926 | AD3: týden | AE3: =WEEKNUM(AA3, 2) -> 14 | AG3: ='m4'!M3 -> 43927 | AI3: =AG3+6 -> 43933 | AJ3: týden | AK3: =WEEKNUM(AG3, 2) -> 15 | AM3: ='m4'!AA3 -> 43934 | AO3: =AM3+6 -> 43940 | AP3: týden | AQ3: =WEEKNUM(AM3, 2) -> 16 | AS3: ='m4'!AO3 -> 43941 | AU3: =AS3+6 -> 43947 | AV3: týden | AW3: =WEEKNUM(AS3, 2) -> 17 | AY3: ='m4'!BC3 -> 43948 | BA3: =AY3+6 -> 43954 | BB3: týden | BC3: =WEEKNUM(AY3, 2) -> 18 | BE3: ='m5'!GS3 -> 43955 | BG3: =BE3+6 -> 43961 | BH3: týden | BI3: =WEEKNUM(BE3, 2) -> 19 | BK3: ='m5'!W3 -> 43962 | BM3: =BK3+6 -> 43968 | BN3: týden | BO3: =WEEKNUM(BK3, 2) -> 20 | BQ3: ='m5'!AK3 -> 43969 | BS3: =BQ3+6 -> 43975 | BT3: týden | BU3: =WEEKNUM(BQ3, 2) -> 21 | BW3: ='m5'!AY3 -> 43976 | BY3: =BW3+6 -> 43982 | BZ3: týden | CA3: =WEEKNUM(BW3, 2) -> 22 | CB3: =Seznam!C17 -> https://docs.google.com/spreadsheets/d/1W52vv31RNiRHjJvdvg-OqpTOxqq1YbezHKqfjfxsc5c | CC3: ='m6'!C3 -> 43983 | CE3: =CC3+6 -> 43989 | CF3: týden | CG3: =WEEKNUM(CC3, 2) -> 23 | CI3: ='m6'!Q3 -> 43990 | CK3: =CI3+6 -> 43996 | CL3: týden | CM3: =WEEKNUM(CI3, 2) -> 24 | CO3: ='m6'!AE3 -> 43997 | CQ3: =CO3+6 -> 44003 | CR3: týden | CS3: =WEEKNUM(CO3, 2) -> 25 | CU3: ='m6'!AS3 -> 44004 | CW3: =CU3+6 -> 44010 | CX3: týden | CY3: =WEEKNUM(CU3, 2) -> 26 | DA3: ='m6'!BG3 -> 44011 | DC3: =DA3+6 -> 44017 | DD3: týden | DE3: =WEEKNUM(DA3, 2) -> 27 | DF3: =Seznam!C22 -> https://docs.google.com/spreadsheets/d/1UzIlczFUSO9uu2jGaWa2JqlpRtAp2dN5CrNFI637zGY | DG3: ='m7'!M3 -> 44018 | DI3: =DG3+6 -> 44024 | DJ3: týden | DK3: =WEEKNUM(DG3, 2) -> 28 | DM3: ='m7'!AA3 -> 44025 | DO3: =DM3+6 -> 44031 | DP3: týden | DQ3: =WEEKNUM(DM3, 2) -> 29 | DS3: ='m7'!AO3 -> 44032 | DU3: =DS3+6 -> 44038 | DV3: týden | DW3: =WEEKNUM(DS3, 2) -> 30 | DY3: ='m7'!BC3 -> 44039 | EA3: =DY3+6 -> 44045 | EB3: týden | EC3: =WEEKNUM(DY3, 2) -> 31 | ED3: =Seznam!C27 -> https://docs.google.com/spreadsheets/d/1Pi_khZoUmlY4AyzfPAAxXep1gqFMFz9ALGi86Hk5APk | EE3: ='m8'!G3 -> 44046 | EG3: =EE3+6 -> 44052 | EH3: týden | EI3: =WEEKNUM(EE3, 2) -> 32 | EK3: ='m8'!U3 -> 44053 | EM3: =EK3+6 -> 44059 | EN3: týden | EO3: =WEEKNUM(EK3, 2) -> 33 | EQ3: ='m8'!AI3 -> 44060 | ES3: =EQ3+6 -> 44066 | ET3: týden | EU3: =WEEKNUM(EQ3, 2) -> 34 | EW3: ='m8'!AW3 -> 44067 | EY3: =EW3+6 -> 44073 | EZ3: týden | FA3: =WEEKNUM(EW3, 2) -> 35 | FC3: ='m8'!BK3 -> 44074 | FE3: =FC3+6 -> 44080 | FF3: týden | FG3: =WEEKNUM(FC3, 2) -> 36 | FH3: =Seznam!C32 -> https://docs.google.com/spreadsheets/d/13CSRejyoXdd2n4TXeaZfqj1qM-tilVcnlMypc0x1xe0 | FI3: ='m9'!O3 -> 44081 | FK3: =FI3+6 -> 44087 | FL3: týden | FM3: =WEEKNUM(FI3, 2) -> 37 | FO3: ='m9'!AC3 -> 44088 | FQ3: =FO3+6 -> 44094 | FR3: týden | FS3: =WEEKNUM(FO3, 2) -> 38 | FU3: ='m9'!AQ3 -> 44095 | FW3: =FU3+6 -> 44101 | FX3: týden | FY3: =WEEKNUM(FU3, 2) -> 39 | GA3: ='m9'!BE3 -> 44102 | GC3: =GA3+6 -> 44108 | GD3: týden | GE3: =WEEKNUM(GA3, 2) -> 40 | GF3: =Seznam!C37 -> https://docs.google.com/spreadsheets/d/1A1C7ak5N3IfdH-gvOToPTjrHDYjQVuOSKk3nI04CPnk | GG3: ='m10'!K3 -> 44109 | GI3: =GG3+6 -> 44115 | GJ3: týden | GK3: =WEEKNUM(GG3, 2) -> 41 | GM3: ='m10'!Y3 -> 44116 | GO3: =GM3+6 -> 44122 | GP3: týden | GQ3: =WEEKNUM(GM3, 2) -> 42 | GS3: ='m10'!AM3 -> 44123 | GU3: =GS3+6 -> 44129 | GV3: týden | GW3: =WEEKNUM(GS3, 2) -> 43 | GY3: ='m10'!BA3 -> 44130 | HA3: =GY3+6 -> 44136 | HB3: týden | HC3: =WEEKNUM(GY3, 2) -> 44 | HD3: =Seznam!C42 -> https://docs.google.com/spreadsheets/d/1A5HjH_1G7_z7bigkYfrx94YbCMtZ4uHBlf5FdHqej6U | HE3: ='m11'!E3 -> 44137 | HG3: =HE3+6 -> 44143 | HH3: týden | HI3: =WEEKNUM(HE3, 2) -> 45 | HK3: ='m11'!S3 -> 44144 | HM3: =HK3+6 -> 44150 | HN3: týden | HO3: =WEEKNUM(HK3, 2) -> 46 | HQ3: ='m11'!AG3 -> 44151 | HS3: =HQ3+6 -> 44157 | HT3: týden | HU3: =WEEKNUM(HQ3, 2) -> 47 | HW3: ='m11'!AU3 -> 44158 | HY3: =HW3+6 -> 44164 | HZ3: týden | IA3: =WEEKNUM(HW3, 2) -> 48 | IB3: =Seznam!C47 -> https://docs.google.com/spreadsheets/d/1shMrdlE-v4TgmShGJEX5IrXyolj8bVkHdxPh0z_Owww | IC3: ='m11'!BI3 -> 44165 | IE3: =IC3+6 -> 44171 | IF3: týden | IG3: =WEEKNUM(IC3, 2) -> 49 | II3: ='m12'!O3 -> 44172 | IK3: =II3+6 -> 44178 | IL3: týden | IM3: =WEEKNUM(II3, 2) -> 50 | IO3: ='m12'!AC3 -> 44179 | IQ3: =IO3+6 -> 44185 | IR3: týden | IS3: =WEEKNUM(IO3, 2) -> 51 | IU3: ='m12'!AQ3 -> 44186 | IW3: =IU3+6 -> 44192 | IX3: týden | IY3: =WEEKNUM(IU3, 2) -> 52 | JA3: ='m12'!BE3 -> 44193 | JC3: =JA3+6 -> 44199 | JD3: týden | JE3: =WEEKNUM(JA3, 2) -> 53
A4: =IFERROR(__xludf.DUMMYFUNCTION("IMPORTRANGE(Seznam!C47, ""Mzdy!A3:A43"")"),"Instore") -> Instore | B4: =IFERROR(__xludf.DUMMYFUNCTION("IMPORTRANGE(""https://docs.google.com/spreadsheets/d/10XKjMp3ipXrP4qWZ8UcqYNKQUDKvV3yJJNYsqZ2J4uU"", ""Mzdy!M3:M20"")"),"Mzda/h") -> Mzda/h | C4: hodin | D4: mzda | E4: záloha | F4: doplaceno | G4: rozdíl | I4: hodin | J4: mzda | K4: záloha | L4: doplaceno | M4: rozdíl | O4: hodin | P4: mzda | Q4: záloha | R4: doplaceno | S4: rozdíl | U4: hodin | V4: mzda | W4: záloha | X4: doplaceno | Y4: rozdíl | AA4: hodin | AB4: mzda | AC4: záloha | AD4: doplaceno | AE4: rozdíl | AF4: =IFERROR(__xludf.DUMMYFUNCTION("IMPORTRANGE(""https://docs.google.com/spreadsheets/d/1_VR4l2o9docdH4BpmZ6xVL9eFirbKl95Qel6RJTY-Qw"", ""Mzdy!M3:M17"")"),"Mzda/h") -> Mzda/h | AG4: hodin | AH4: mzda | AI4: záloha | AJ4: doplaceno | AK4: rozdíl | AM4: hodin | AN4: mzda | AO4: záloha | AP4: doplaceno | AQ4: rozdíl | AS4: hodin | AT4: mzda | AU4: záloha | AV4: doplaceno | AW4: rozdíl | AY4: hodin | AZ4: mzda | BA4: záloha | BB4: doplaceno | BC4: rozdíl | BD4: =IFERROR(__xludf.DUMMYFUNCTION("IMPORTRANGE(""https://docs.google.com/spreadsheets/d/1VRfz8ELmM5lZo00qm9MdMXMmDFEsCvB5AkS7pSVYxcY"", ""Mzdy!AE3:AE25"")"),"Mzda/h") -> Mzda/h | BE4: hodin | BF4: mzda | BG4: záloha | BH4: doplaceno | BI4: rozdíl | BK4: hodin | BL4: mzda | BM4: záloha | BN4: doplaceno | BO4: rozdíl | BQ4: hodin | BR4: mzda | BS4: záloha | BT4: doplaceno | BU4: rozdíl | BW4: hodin | BX4: mzda | BY4: záloha | BZ4: doplaceno | CA4: rozdíl | CB4: =IFERROR(__xludf.DUMMYFUNCTION("IMPORTRANGE(CB3, ""Mzdy!AE3:AE33"")"),"Mzda/h") -> Mzda/h | CC4: hodin | CD4: mzda | CE4: záloha | CF4: doplaceno | CG4: rozdíl | CI4: hodin | CJ4: mzda | CK4: záloha | CL4: doplaceno | CM4: rozdíl | CO4: hodin | CP4: mzda | CQ4: záloha | CR4: doplaceno | CS4: rozdíl | CU4: hodin | CV4: mzda | CW4: záloha | CX4: doplaceno | CY4: rozdíl | DA4: hodin | DB4: mzda | DC4: záloha | DD4: doplaceno | DE4: rozdíl | DF4: =IFERROR(__xludf.DUMMYFUNCTION("IMPORTRANGE(DF3, ""Mzdy!AE3:AE33"")"),"Mzda/h") -> Mzda/h | DG4: hodin | DH4: mzda | DI4: záloha | DJ4: doplaceno | DK4: rozdíl | DM4: hodin | DN4: mzda | DO4: záloha | DP4: doplaceno | DQ4: rozdíl | DS4: hodin | DT4: mzda | DU4: záloha | DV4: doplaceno | DW4: rozdíl | DY4: hodin | DZ4: mzda | EA4: záloha | EB4: doplaceno | EC4: rozdíl | ED4: =IFERROR(__xludf.DUMMYFUNCTION("IMPORTRANGE(ED3, ""Mzdy!AE3:AE33"")"),"Mzda/h") -> Mzda/h | EE4: hodin | EF4: mzda | EG4: záloha | EH4: doplaceno | EI4: rozdíl | EK4: hodin | EL4: mzda | EM4: záloha | EN4: doplaceno | EO4: rozdíl | EQ4: hodin | ER4: mzda | ES4: záloha | ET4: doplaceno | EU4: rozdíl | EW4: hodin | EX4: mzda | EY4: záloha | EZ4: doplaceno | FA4: rozdíl | FC4: hodin | FD4: mzda | FE4: záloha | FF4: doplaceno | FG4: rozdíl | FH4: =IFERROR(__xludf.DUMMYFUNCTION("IMPORTRANGE(FH3, ""Mzdy!AE3:AE33"")"),"Mzda/h") -> Mzda/h | FI4: hodin | FJ4: mzda | FK4: záloha | FL4: doplaceno | FM4: rozdíl | FO4: hodin | FP4: mzda | FQ4: záloha | FR4: doplaceno | FS4: rozdíl | FU4: hodin | FV4: mzda | FW4: záloha | FX4: doplaceno | FY4: rozdíl | GA4: hodin | GB4: mzda | GC4: záloha | GD4: doplaceno | GE4: rozdíl | GF4: =IFERROR(__xludf.DUMMYFUNCTION("IMPORTRANGE(GF3, ""Mzdy!AE3:AE43"")"),"Mzda/h") -> Mzda/h | GG4: hodin | GH4: mzda | GI4: záloha | GJ4: doplaceno | GK4: rozdíl | GM4: hodin | GN4: mzda | GO4: záloha | GP4: doplaceno | GQ4: rozdíl | GS4: hodin | GT4: mzda | GU4: záloha | GV4: doplaceno | GW4: rozdíl | GY4: hodin | GZ4: mzda | HA4: záloha | HB4: doplaceno | HC4: rozdíl | HD4: =IFERROR(__xludf.DUMMYFUNCTION("IMPORTRANGE(HD3, ""Mzdy!AE3:AE43"")"),"Mzda/h") -> Mzda/h | HE4: hodin | HF4: mzda | HG4: záloha | HH4: doplaceno | HI4: rozdíl | HK4: hodin | HL4: mzda | HM4: záloha | HN4: doplaceno | HO4: rozdíl | HQ4: hodin | HR4: mzda | HS4: záloha | HT4: doplaceno | HU4: rozdíl | HW4: hodin | HX4: mzda | HY4: záloha | HZ4: doplaceno | IA4: rozdíl | IB4: =IFERROR(__xludf.DUMMYFUNCTION("IMPORTRANGE(IB3, ""Mzdy!AE3:AE43"")"),"Mzda/h") -> Mzda/h | IC4: hodin | ID4: mzda | IE4: záloha | IF4: doplaceno | IG4: rozdíl | II4: hodin | IJ4: mzda | IK4: záloha | IL4: doplaceno | IM4: rozdíl | IO4: hodin | IP4: mzda | IQ4: záloha | IR4: doplaceno | IS4: rozdíl | IU4: hodin | IV4: mzda | IW4: záloha | IX4: doplaceno | IY4: rozdíl | JA4: hodin | JB4: mzda | JC4: záloha | JD4: doplaceno | JE4: rozdíl
A5: =IFERROR(__xludf.DUMMYFUNCTION("""COMPUTED_VALUE"""),"Stanislav Roth") -> Stanislav Roth | B5: =IFERROR(__xludf.DUMMYFUNCTION("""COMPUTED_VALUE"""),1290.3225806451612) -> 1290.3226 | C5: ='m3'!E5+'m3'!G5+'m3'!I5+'m3'!K5+'m3'!M5+'m3'!O5+'m3'!Q5 -> 29 | E5: ='m3'!F5+'m3'!H5+'m3'!J5+'m3'!L5+'m3'!N5+'m3'!P5+'m3'!R5 -> 7500 | I5: ='m3'!S5+'m3'!U5+'m3'!W5+'m3'!Y5+'m3'!AA5+'m3'!AC5+'m3'!AE5 -> 31 | K5: ='m3'!T5+'m3'!V5+'m3'!X5+'m3'!Z5+'m3'!AB5+'m3'!AD5+'m3'!AF5 -> 4000 | O5: ='m3'!AG5+'m3'!AI5+'m3'!AK5+'m3'!AM5+'m3'!AO5+'m3'!AQ5+'m3'!AS5 -> 13 | Q5: ='m3'!AH5+'m3'!AJ5+'m3'!AL5+'m3'!AN5+'m3'!AP5+'m3'!AR5+'m3'!AT5 -> 0 | U5: ='m3'!DF5+'m3'!DH5+'m3'!DJ5+'m3'!DL5+'m3'!DN5+'m3'!DP5+'m3'!DR5 -> 18 | W5: ='m3'!DG5+'m3'!DI5+'m3'!DK5+'m3'!DM5+'m3'!DO5+'m3'!DQ5+'m3'!DS5 -> 15000 | AA5: ='m3'!BI5+'m3'!BK5+'m4'!C5+'m4'!E5+'m4'!G5+'m4'!I5+'m4'!K5 -> 18 | AC5: ='m3'!BJ5+'m3'!BL5+'m4'!D5+'m4'!F5+'m4'!H5+'m4'!J5+'m4'!L5 -> 0 | AF5: =IFERROR(__xludf.DUMMYFUNCTION("""COMPUTED_VALUE"""),1333.3333333333333) -> 1333.3333 | AG5: ='m4'!M5+'m4'!O5+'m4'!Q5+'m4'!S5+'m4'!U5+'m4'!W5+'m4'!Y5 -> 18 | AH5: ='m3'!M5*AG5 -> 0 | AI5: ='m4'!N5+'m4'!P5+'m4'!R5+'m4'!T5+'m4'!V5+'m4'!X5+'m4'!Z5 -> 0 | AM5: ='m4'!AA5+'m4'!AC5+'m4'!AE5+'m4'!AG5+'m4'!AI5+'m4'!AK5+'m4'!AM5 -> 19 | AO5: ='m4'!AB5+'m4'!AD5+'m4'!AF5+'m4'!AH5+'m4'!AJ5+'m4'!AL5+'m4'!AN5 -> 0 | AS5: ='m4'!AO5+'m4'!AQ5+'m4'!AS5+'m4'!AU5+'m4'!AW5+'m4'!AY5+'m4'!BA5 -> 14 | AU5: ='m4'!AP5+'m4'!AR5+'m4'!AT5+'m4'!AV5+'m4'!AX5+'m4'!AZ5+'m4'!BB5 -> 0 | AY5: ='m4'!BC5+'m4'!BE5+'m4'!BG5+'m4'!BI5+'m5'!C5+'m5'!E5+'m5'!G5 -> 0 | BA5: ='m4'!BD5+'m4'!BF5+'m4'!BH5+'m4'!BJ5+'m5'!D5+'m5'!F5+'m5'!H5 -> 0 | BD5: =IFERROR(__xludf.DUMMYFUNCTION("""COMPUTED_VALUE"""),1290.3225806451612) -> 1290.3226 | BE5: ='m5'!I5+'m5'!K5+'m5'!M5+'m5'!O5+'m5'!Q5+'m5'!S5+'m5'!U5 -> 8 | BG5: ='m5'!J5+'m5'!L5+'m5'!N5+'m5'!P5+'m5'!R5+'m5'!T5+'m5'!V5 -> 0 | BK5: ='m5'!W5+'m5'!Y5+'m5'!AA5+'m5'!AC5+'m5'!AE5+'m5'!AG5+'m5'!AI5 -> 35 | BM5: ='m5'!X5+'m5'!Z5+'m5'!AB5+'m5'!AD5+'m5'!AF5+'m5'!AH5+'m5'!AJ5 -> 0 | BQ5: ='m5'!AK5+'m5'!AM5+'m5'!AO5+'m5'!AQ5+'m5'!AS5+'m5'!AU5+'m5'!AW5 -> 3 | BS5: ='m5'!AL5+'m5'!AN5+'m5'!AP5+'m5'!AR5+'m5'!AT5+'m5'!AV5+'m5'!AX5 -> 1000 | BW5: ='m5'!AY5+'m5'!BA5+'m5'!BC5+'m5'!BE5+'m5'!BG5+'m5'!BI5+'m5'!BK5 -> 58 | BY5: ='m5'!AZ5+'m5'!BB5+'m5'!BD5+'m5'!BF5+'m5'!BH5+'m5'!BJ5+'m5'!BL5 -> 0 | CB5: =IFERROR(__xludf.DUMMYFUNCTION("""COMPUTED_VALUE"""),1333.3333333333333) -> 1333.3333 | CC5: ='m6'!C5+'m6'!E5+'m6'!G5+'m6'!I5+'m6'!K5+'m6'!M5+'m6'!O5 -> 26 | CE5: ='m6'!D5+'m6'!F5+'m6'!H5+'m6'!J5+'m6'!L5+'m6'!N5+'m6'!P5 -> 200 | CI5: ='m6'!Q5+'m6'!S5+'m6'!U5+'m6'!W5+'m6'!Y5+'m6'!AA5+'m6'!AC5 -> 36 | CK5: ='m6'!R5+'m6'!T5+'m6'!V5+'m6'!X5+'m6'!Z5+'m6'!AB5+'m6'!AD5 -> 0 | CO5: ='m6'!AE5+'m6'!AG5+'m6'!AI5+'m6'!AK5+'m6'!AM5+'m6'!AO5+'m6'!AQ5 -> 50.5 | CQ5: ='m6'!AF5+'m6'!AH5+'m6'!AJ5+'m6'!AL5+'m6'!AN5+'m6'!AP5+'m6'!AR5 -> 0 | CU5: ='m6'!AS5+'m6'!AU5+'m6'!AW5+'m6'!AY5+'m6'!BA5+'m6'!BC5+'m6'!BE5 -> 37 | CW5: ='m6'!AT5+'m6'!AV5+'m6'!AX5+'m6'!AZ5+'m6'!BB5+'m6'!BD5+'m6'!BF5 -> 780 | DA5: ='m6'!BG5+'m6'!BI5+'m7'!C5+'m7'!E5+'m7'!G5+'m7'!I5+'m7'!K5 -> 45.5 | DC5: ='m6'!BH5+'m6'!BJ5+'m7'!D5+'m7'!F5+'m7'!H5+'m7'!J5+'m7'!L5 -> 2000 | DF5: =IFERROR(__xludf.DUMMYFUNCTION("""COMPUTED_VALUE"""),1290.3225806451612) -> 1290.3226 | DG5: ='m7'!M5+'m7'!O5+'m7'!Q5+'m7'!S5+'m7'!U5+'m7'!W5+'m7'!Y5 -> 51.5 | DI5: ='m7'!N5+'m7'!P5+'m7'!R5+'m7'!T5+'m7'!V5+'m7'!X5+'m7'!Z5 -> 2500 | DM5: ='m7'!AA5+'m7'!AC5+'m7'!AE5+'m7'!AG5+'m7'!AI5+'m7'!AK5+'m7'!AM5 -> 39.5 | DO5: ='m7'!AB5+'m7'!AD5+'m7'!AF5+'m7'!AH5+'m7'!AJ5+'m7'!AL5+'m7'!AN5 -> 2000 | DS5: ='m7'!AO5+'m7'!AQ5+'m7'!AS5+'m7'!AU5+'m7'!AW5+'m7'!AY5+'m7'!BA5 -> 24 | DU5: ='m7'!AP5+'m7'!AR5+'m7'!AT5+'m7'!AV5+'m7'!AX5+'m7'!AZ5+'m7'!BB5 -> 0 | DY5: ='m7'!BC5+'m7'!BE5+'m7'!BG5+'m7'!BI5+'m7'!BK5+'m8'!C5+'m8'!E5 -> 32 | EA5: ='m7'!BD5+'m7'!BF5+'m7'!BH5+'m7'!BJ5+'m7'!BL5+'m8'!D5+'m8'!F5 -> 0 | ED5: =IFERROR(__xludf.DUMMYFUNCTION("""COMPUTED_VALUE"""),1290.3225806451612) -> 1290.3226 | EE5: ='m8'!G5+'m8'!I5+'m8'!K5+'m8'!M5+'m8'!O5+'m8'!Q5+'m8'!S5 -> 47 | EG5: ='m8'!H5+'m8'!J5+'m8'!L5+'m8'!N5+'m8'!P5+'m8'!R5+'m8'!T5 -> 2000 | EK5: ='m8'!U5+'m8'!W5+'m8'!Y5+'m8'!AA5+'m8'!AC5+'m8'!AE5+'m8'!AG5 -> 43 | EM5: ='m8'!V5+'m8'!X5+'m8'!Z5+'m8'!AB5+'m8'!AD5+'m8'!AF5+'m8'!AH5 -> 2393 | EQ5: ='m8'!AI5+'m8'!AK5+'m8'!AM5+'m8'!AO5+'m8'!AQ5+'m8'!AS5+'m8'!AU5 -> 39 | ES5: ='m8'!AJ5+'m8'!AL5+'m8'!AN5+'m8'!AP5+'m8'!AR5+'m8'!AT5+'m8'!AV5 -> 0 | EW5: ='m8'!AW5+'m8'!AY5+'m8'!BA5+'m8'!BC5+'m8'!BE5+'m8'!BG5+'m8'!BI5 -> 0 | EY5: ='m8'!AX5+'m8'!AZ5+'m8'!BB5+'m8'!BD5+'m8'!BF5+'m8'!BH5+'m8'!BJ5 -> 0 | FC5: ='m8'!BK5+'m9'!C5+'m9'!E5+'m9'!G5+'m9'!I5+'m9'!K5+'m9'!M5 -> 5.5 | FE5: ='m8'!BL5+'m9'!D5+'m9'!F5+'m9'!H5+'m9'!J5+'m9'!L5+'m9'!N5 -> 0 | FH5: =IFERROR(__xludf.DUMMYFUNCTION("""COMPUTED_VALUE"""),1333.3333333333333) -> 1333.3333 | FI5: ='m9'!O5+'m9'!Q5+'m9'!S5+'m9'!U5+'m9'!W5+'m9'!Y5+'m9'!AA5 -> 44.5 | FK5: ='m9'!P5+'m9'!R5+'m9'!T5+'m9'!V5+'m9'!X5+'m9'!Z5+'m9'!AB5 -> 1500 | FO5: ='m9'!AC5+'m9'!AE5+'m9'!AG5+'m9'!AI5+'m9'!AK5+'m9'!AM5+'m9'!AO5 -> 52 | FQ5: ='m9'!AD5+'m9'!AF5+'m9'!AH5+'m9'!AJ5+'m9'!AL5+'m9'!AN5+'m9'!AP5 -> 324 | FU5: ='m9'!AQ5+'m9'!AS5+'m9'!AU5+'m9'!AW5+'m9'!AY5+'m9'!BA5+'m9'!BC5 -> 53 | FW5: ='m9'!AR5+'m9'!AT5+'m9'!AV5+'m9'!AX5+'m9'!AZ5+'m9'!BB5+'m9'!BD5 -> 0 | GA5: ='m9'!BE5+'m9'!BG5+'m9'!BI5+'m10'!C5+'m10'!E5+'m10'!G5+'m10'!I5 -> 50 | GC5: ='m9'!BF5+'m9'!BH5+'m9'!BJ5+'m10'!D5+'m10'!F5+'m10'!H5+'m10'!J5 -> 1200 | GF5: =IFERROR(__xludf.DUMMYFUNCTION("""COMPUTED_VALUE"""),1290.3225806451612) -> 1290.3226 | GG5: ='m10'!K5+'m10'!M5+'m10'!O5+'m10'!Q5+'m10'!S5+'m10'!U5+'m10'!W5 -> 48 | GI5: ='m10'!L5+'m10'!N5+'m10'!P5+'m10'!R5+'m10'!T5+'m10'!V5+'m10'!X5 -> 3200 | GM5: ='m10'!Y5+'m10'!AA5+'m10'!AC5+'m10'!AE5+'m10'!AG5+'m10'!AI5+'m10'!AK5 -> 66 | GO5: ='m10'!Z5+'m10'!AB5+'m10'!AD5+'m10'!AF5+'m10'!AH5+'m10'!AJ5+'m10'!AL5 -> 0 | GS5: ='m10'!AM5+'m10'!AO5+'m10'!AQ5+'m10'!AS5+'m10'!AU5+'m10'!AW5+'m10'!AY5 -> 68 | GU5: ='m10'!AN5+'m10'!AP5+'m10'!AR5+'m10'!AT5+'m10'!AV5+'m10'!AX5+'m10'!AZ5 -> 0 | GY5: ='m10'!BA5+'m10'!BC5+'m10'!BE5+'m10'!BG5+'m10'!BI5+'m10'!BK5+'m11'!C5 -> 50 | HA5: ='m10'!BB5+'m10'!BD5+'m10'!BF5+'m10'!BH5+'m10'!BJ5+'m10'!BL5+'m11'!D5 -> 0 | HD5: =IFERROR(__xludf.DUMMYFUNCTION("""COMPUTED_VALUE"""),1333.3333333333333) -> 1333.3333 | HE5: ='m11'!E5+'m11'!G5+'m11'!I5+'m11'!K5+'m11'!M5+'m11'!O5+'m11'!Q5 -> 37 | HG5: ='m11'!F5+'m11'!H5+'m11'!J5+'m11'!L5+'m11'!N5+'m11'!P5+'m11'!R5 -> 427 | HK5: ='m11'!S5+'m11'!U5+'m11'!W5+'m11'!Y5+'m11'!AA5+'m11'!AC5+'m11'!AE5 -> 26 | HM5: ='m11'!T5+'m11'!V5+'m11'!X5+'m11'!Z5+'m11'!AB5+'m11'!AD5+'m11'!AF5 -> 0 | HQ5: ='m11'!AG5+'m11'!AI5+'m11'!AK5+'m11'!AM5+'m11'!AO5+'m11'!AQ5+'m11'!AS5 -> 31.5 | HS5: ='m11'!AH5+'m11'!AJ5+'m11'!AL5+'m11'!AN5+'m11'!AP5+'m11'!AR5+'m11'!AT5 -> 0 | HW5: ='m11'!AU5+'m11'!AW5+'m11'!AY5+'m11'!BA5+'m11'!BC5+'m11'!BE5+'m11'!BG5 -> 34.5 | HY5: ='m11'!AV5+'m11'!AX5+'m11'!AZ5+'m11'!BB5+'m11'!BD5+'m11'!BF5+'m11'!BH5 -> 0 | IB5: =IFERROR(__xludf.DUMMYFUNCTION("""COMPUTED_VALUE"""),1290.3225806451612) -> 1290.3226 | IC5: ='m11'!BI5+'m12'!C5+'m12'!E5+'m12'!G5+'m12'!I5+'m12'!K5+'m12'!M5 -> 38.5 | IE5: ='m11'!BJ5+'m12'!D5+'m12'!F5+'m12'!H5+'m12'!J5+'m12'!L5+'m12'!N5 -> 0 | II5: ='m12'!O5+'m12'!Q5+'m12'!S5+'m12'!U5+'m12'!W5+'m12'!Y5+'m12'!AA5 -> 32 | IK5: ='m12'!P5+'m12'!R5+'m12'!T5+'m12'!V5+'m12'!X5+'m12'!Z5+'m12'!AB5 -> 0 | IO5: ='m12'!AC5+'m12'!AE5+'m12'!AG5+'m12'!AI5+'m12'!AK5+'m12'!AM5+'m12'!AO5 -> 43 | IQ5: ='m12'!AD5+'m12'!AF5+'m12'!AH5+'m12'!AJ5+'m12'!AL5+'m12'!AN5+'m12'!AP5 -> 0 | IU5: ='m12'!AQ5+'m12'!AS5+'m12'!AU5+'m12'!AW5+'m12'!AY5+'m12'!BA5+'m12'!BC5 -> 33 | IW5: ='m12'!AR5+'m12'!AT5+'m12'!AV5+'m12'!AX5+'m12'!AZ5+'m12'!BB5+'m12'!BD5 -> 0 | JA5: ='m12'!BE5+'m12'!BG5+'m12'!BI5+'m12'!BK5 -> 26 | JC5: ='m12'!BF5+'m12'!BH5+'m12'!BJ5+'m12'!BL5 -> 0
A6: =IFERROR(__xludf.DUMMYFUNCTION("""COMPUTED_VALUE"""),"Anastasia Rothová") -> Anastasia Rothová | B6: =IFERROR(__xludf.DUMMYFUNCTION("""COMPUTED_VALUE"""),150.0) -> 150 | C6: ='m3'!E6+'m3'!G6+'m3'!I6+'m3'!K6+'m3'!M6+'m3'!O6+'m3'!Q6 -> 29 | D6: ='m3'!A6*C6 -> 4350 | E6: ='m3'!F6+'m3'!H6+'m3'!J6+'m3'!L6+'m3'!N6+'m3'!P6+'m3'!R6 -> 0 | G6: =E6+F6-D6 -> -4350 | I6: ='m3'!S6+'m3'!U6+'m3'!W6+'m3'!Y6+'m3'!AA6+'m3'!AC6+'m3'!AE6 -> 23 | J6: ='m3'!A6*I6 -> 3450 | K6: ='m3'!T6+'m3'!V6+'m3'!X6+'m3'!Z6+'m3'!AB6+'m3'!AD6+'m3'!AF6 -> 0 | M6: =K6+L6-J6 -> -3450 | O6: ='m3'!AG6+'m3'!AI6+'m3'!AK6+'m3'!AM6+'m3'!AO6+'m3'!AQ6+'m3'!AS6 -> 36 | P6: ='m3'!A6*O6 -> 5400 | Q6: ='m3'!AH6+'m3'!AJ6+'m3'!AL6+'m3'!AN6+'m3'!AP6+'m3'!AR6+'m3'!AT6 -> 0 | S6: =Q6+R6-P6 -> -5400 | U6: ='m3'!AU6+'m3'!AW6+'m3'!AY6+'m3'!BA6+'m3'!BC6+'m3'!BE6+'m3'!BG6 -> 10 | V6: ='m3'!A6*U6 -> 1500 | W6: ='m3'!DG6+'m3'!DI6+'m3'!DK6+'m3'!DM6+'m3'!DO6+'m3'!DQ6+'m3'!DS6 -> 0 | Y6: =W6+X6-V6 -> -1500 | AA6: ='m3'!BI6+'m3'!BK6+'m4'!C6+'m4'!E6+'m4'!G6+'m4'!I6+'m4'!K6 -> 0 | AB6: =('m3'!BI6+'m3'!BK6)*'m3'!A6+('m4'!C6+'m4'!E6+'m4'!G6+'m4'!I6+'m4'!K6)*'m4'!A6 -> 0 | AC6: ='m3'!BJ6+'m3'!BL6+'m4'!D6+'m4'!F6+'m4'!H6+'m4'!J6+'m4'!L6 -> 0 | AE6: =AC6+AD6-AB6 -> 0 | AF6: =IFERROR(__xludf.DUMMYFUNCTION("""COMPUTED_VALUE"""),150.0) -> 150 | AG6: ='m4'!M6+'m4'!O6+'m4'!Q6+'m4'!S6+'m4'!U6+'m4'!W6+'m4'!Y6 -> 0 | AH6: ='m4'!A6*AG6 -> 0 | AI6: ='m4'!N6+'m4'!P6+'m4'!R6+'m4'!T6+'m4'!V6+'m4'!X6+'m4'!Z6 -> 0 | AK6: =AI6+AJ6-AH6 -> 0 | AM6: ='m4'!AA6+'m4'!AC6+'m4'!AE6+'m4'!AG6+'m4'!AI6+'m4'!AK6+'m4'!AM6 -> 8 | AN6: ='m4'!A6*AM6 -> 1200 | AO6: ='m4'!AB6+'m4'!AD6+'m4'!AF6+'m4'!AH6+'m4'!AJ6+'m4'!AL6+'m4'!AN6 -> 0 | AQ6: =AO6+AP6-AN6 -> -1200 | AS6: ='m4'!AO6+'m4'!AQ6+'m4'!AS6+'m4'!AU6+'m4'!AW6+'m4'!AY6+'m4'!BA6 -> 0 | AT6: ='m4'!A6*AS6 -> 0 | AU6: ='m4'!AP6+'m4'!AR6+'m4'!AT6+'m4'!AV6+'m4'!AX6+'m4'!AZ6+'m4'!BB6 -> 0 | AW6: =AV6+AU6-AT6 -> 0 | AY6: ='m4'!BC6+'m4'!BE6+'m4'!BG6+'m4'!BI6+'m5'!C6+'m5'!E6+'m5'!G6 -> 0 | AZ6: =('m4'!BC6+'m4'!BE6+'m4'!BG6+'m4'!BI6)*'m4'!A6+('m5'!C6+'m5'!E6+'m5'!G6)*'m5'!A6 -> 0 | BA6: ='m4'!BD6+'m4'!BF6+'m4'!BH6+'m4'!BJ6+'m5'!D6+'m5'!F6+'m5'!H6 -> 0 | BC6: =BB6+BA6-AZ6 -> 0 | BD6: =IFERROR(__xludf.DUMMYFUNCTION("""COMPUTED_VALUE"""),150.0) -> 150 | BE6: ='m5'!I6+'m5'!K6+'m5'!M6+'m5'!O6+'m5'!Q6+'m5'!S6+'m5'!U6 -> 0 | BF6: ='m5'!A6*BE6 -> 0 | BG6: ='m5'!J6+'m5'!L6+'m5'!N6+'m5'!P6+'m5'!R6+'m5'!T6+'m5'!V6 -> 0 | BI6: =BH6+BG6-BF6 -> 0 | BK6: ='m5'!W6+'m5'!Y6+'m5'!AA6+'m5'!AC6+'m5'!AE6+'m5'!AG6+'m5'!AI6 -> 0 | BL6: ='m5'!A6*BK6 -> 0 | BM6: ='m5'!X6+'m5'!Z6+'m5'!AB6+'m5'!AD6+'m5'!AF6+'m5'!AH6+'m5'!AJ6 -> 0 | BO6: =BN6+BM6-BL6 -> 0 | BQ6: ='m5'!AK6+'m5'!AM6+'m5'!AO6+'m5'!AQ6+'m5'!AS6+'m5'!AU6+'m5'!AW6 -> 67 | BR6: ='m5'!A6*BQ6 -> 10050 | BS6: ='m5'!AL6+'m5'!AN6+'m5'!AP6+'m5'!AR6+'m5'!AT6+'m5'!AV6+'m5'!AX6 -> 0 | BU6: =BT6+BS6-BR6 -> -10050 | BW6: ='m5'!AY6+'m5'!BA6+'m5'!BC6+'m5'!BE6+'m5'!BG6+'m5'!BI6+'m5'!BK6 -> 45 | BX6: ='m5'!A6*BW6 -> 6750 | BY6: ='m5'!AZ6+'m5'!BB6+'m5'!BD6+'m5'!BF6+'m5'!BH6+'m5'!BJ6+'m5'!BL6 -> 0 | CA6: =BZ6+BY6-BX6 -> -6750 | CB6: =IFERROR(__xludf.DUMMYFUNCTION("""COMPUTED_VALUE"""),150.0) -> 150 | CC6: ='m6'!C6+'m6'!E6+'m6'!G6+'m6'!I6+'m6'!K6+'m6'!M6+'m6'!O6 -> 47 | CD6: =CC6*CB6 -> 7050 | CE6: ='m6'!D6+'m6'!F6+'m6'!H6+'m6'!J6+'m6'!L6+'m6'!N6+'m6'!P6 -> 0 | CG6: =CF6+CE6-CD6 -> -7050 | CI6: ='m6'!Q6+'m6'!S6+'m6'!U6+'m6'!W6+'m6'!Y6+'m6'!AA6+'m6'!AC6 -> 33 | CJ6: =CI6*CB6 -> 4950 | CK6: ='m6'!R6+'m6'!T6+'m6'!V6+'m6'!X6+'m6'!Z6+'m6'!AB6+'m6'!AD6 -> 0 | CM6: =CL6+CK6-CJ6 -> -4950 | CO6: ='m6'!AE6+'m6'!AG6+'m6'!AI6+'m6'!AK6+'m6'!AM6+'m6'!AO6+'m6'!AQ6 -> 23 | CP6: =CO6*CB6 -> 3450 | CQ6: ='m6'!AF6+'m6'!AH6+'m6'!AJ6+'m6'!AL6+'m6'!AN6+'m6'!AP6+'m6'!AR6 -> 0 | CS6: =CR6+CQ6-CP6 -> -3450 | CU6: ='m6'!AS6+'m6'!AU6+'m6'!AW6+'m6'!AY6+'m6'!BA6+'m6'!BC6+'m6'!BE6 -> 7 | CV6: =CU6*CB6 -> 1050 | CW6: ='m6'!AT6+'m6'!AV6+'m6'!AX6+'m6'!AZ6+'m6'!BB6+'m6'!BD6+'m6'!BF6 -> 1000 | CY6: =CX6+CW6-CV6 -> -50 | DA6: ='m6'!BG6+'m6'!BI6+'m7'!C6+'m7'!E6+'m7'!G6+'m7'!I6+'m7'!K6 -> 22 | DB6: =('m6'!BG6+'m6'!BI6)*'m6'!A6+('m7'!C6+'m7'!E6+'m7'!G6+'m7'!I6+'m7'!K6)*'m7'!A6 -> 3300 | DC6: ='m6'!BH6+'m6'!BJ6+'m7'!D6+'m7'!F6+'m7'!H6+'m7'!J6+'m7'!L6 -> 0 | DE6: =DD6+DC6-DB6 -> -3300 | DF6: =IFERROR(__xludf.DUMMYFUNCTION("""COMPUTED_VALUE"""),150.0) -> 150 | DG6: ='m7'!M6+'m7'!O6+'m7'!Q6+'m7'!S6+'m7'!U6+'m7'!W6+'m7'!Y6 -> 36 | DH6: =DG6*DF6 -> 5400 | DI6: ='m7'!N6+'m7'!P6+'m7'!R6+'m7'!T6+'m7'!V6+'m7'!X6+'m7'!Z6 -> 1000 | DK6: =DJ6+DI6-DH6 -> -4400 | DM6: ='m7'!AA6+'m7'!AC6+'m7'!AE6+'m7'!AG6+'m7'!AI6+'m7'!AK6+'m7'!AM6 -> 48 | DN6: =DM6*DF6 -> 7200 | DO6: ='m7'!AB6+'m7'!AD6+'m7'!AF6+'m7'!AH6+'m7'!AJ6+'m7'!AL6+'m7'!AN6 -> 0 | DQ6: =DP6+DO6-DN6 -> -7200 | DS6: ='m7'!AO6+'m7'!AQ6+'m7'!AS6+'m7'!AU6+'m7'!AW6+'m7'!AY6+'m7'!BA6 -> 36 | DT6: =DS6*DF6 -> 5400 | DU6: ='m7'!AP6+'m7'!AR6+'m7'!AT6+'m7'!AV6+'m7'!AX6+'m7'!AZ6+'m7'!BB6 -> 0 | DW6: =DV6+DU6-DT6 -> -5400 | DY6: ='m7'!BC6+'m7'!BE6+'m7'!BG6+'m7'!BI6+'m7'!BK6+'m8'!C6+'m8'!E6 -> 42 | DZ6: =('m7'!BC6+'m7'!BE6+'m7'!BG6+'m7'!BI6+'m7'!BK6)*DF6+('m8'!C6+'m8'!E6)*ED6 -> 6300 | EA6: ='m7'!BD6+'m7'!BF6+'m7'!BH6+'m7'!BJ6+'m7'!BL6+'m8'!D6+'m8'!F6 -> 1000 | EC6: =EB6+EA6-DZ6 -> -5300 | ED6: =IFERROR(__xludf.DUMMYFUNCTION("""COMPUTED_VALUE"""),150.0) -> 150 | EE6: ='m8'!G6+'m8'!I6+'m8'!K6+'m8'!M6+'m8'!O6+'m8'!Q6+'m8'!S6 -> 46 | EF6: =EE6*ED6 -> 6900 | EG6: ='m8'!H6+'m8'!J6+'m8'!L6+'m8'!N6+'m8'!P6+'m8'!R6+'m8'!T6 -> 1000 | EI6: =EH6+EG6-EF6 -> -5900 | EK6: ='m8'!U6+'m8'!W6+'m8'!Y6+'m8'!AA6+'m8'!AC6+'m8'!AE6+'m8'!AG6 -> 49 | EL6: =EK6*ED6 -> 7350 | EM6: ='m8'!V6+'m8'!X6+'m8'!Z6+'m8'!AB6+'m8'!AD6+'m8'!AF6+'m8'!AH6 -> 0 | EO6: =EN6+EM6-EL6 -> -7350 | EQ6: ='m8'!AI6+'m8'!AK6+'m8'!AM6+'m8'!AO6+'m8'!AQ6+'m8'!AS6+'m8'!AU6 -> 26 | ER6: =EQ6*ED6 -> 3900 | ES6: ='m8'!AJ6+'m8'!AL6+'m8'!AN6+'m8'!AP6+'m8'!AR6+'m8'!AT6+'m8'!AV6 -> 0 | EU6: =ET6+ES6-ER6 -> -3900 | EW6: ='m8'!AW6+'m8'!AY6+'m8'!BA6+'m8'!BC6+'m8'!BE6+'m8'!BG6+'m8'!BI6 -> 0 | EX6: =EW6*ED6 -> 0 | EY6: ='m8'!AX6+'m8'!AZ6+'m8'!BB6+'m8'!BD6+'m8'!BF6+'m8'!BH6+'m8'!BJ6 -> 0 | FA6: =EZ6+EY6-EX6 -> 0 | FC6: ='m8'!BK6+'m9'!C6+'m9'!E6+'m9'!G6+'m9'!I6+'m9'!K6+'m9'!M6 -> 0 | FD6: ='m8'!BK6*ED6+'m9'!C6*FH6+'m9'!E6*FH6+'m9'!G6*FH6+'m9'!I6*FH6+'m9'!K6*FH6+'m9'!M6*FH6 -> 0 | FE6: ='m8'!BL6+'m9'!D6+'m9'!F6+'m9'!H6+'m9'!J6+'m9'!L6+'m9'!N6 -> 0 | FG6: =FF6+FE6-FD6 -> 0 | FH6: =IFERROR(__xludf.DUMMYFUNCTION("""COMPUTED_VALUE"""),150.0) -> 150 | FI6: ='m9'!O6+'m9'!Q6+'m9'!S6+'m9'!U6+'m9'!W6+'m9'!Y6+'m9'!AA6 -> 38 | FJ6: =FI6*FH6 -> 5700 | FK6: ='m9'!P6+'m9'!R6+'m9'!T6+'m9'!V6+'m9'!X6+'m9'!Z6+'m9'!AB6 -> 0 | FM6: =FL6+FK6-FJ6 -> -5700 | FO6: ='m9'!AC6+'m9'!AE6+'m9'!AG6+'m9'!AI6+'m9'!AK6+'m9'!AM6+'m9'!AO6 -> 40 | FP6: =FO6*FH6 -> 6000 | FQ6: ='m9'!AD6+'m9'!AF6+'m9'!AH6+'m9'!AJ6+'m9'!AL6+'m9'!AN6+'m9'!AP6 -> 0 | FS6: =FR6+FQ6-FP6 -> -6000 | FU6: ='m9'!AQ6+'m9'!AS6+'m9'!AU6+'m9'!AW6+'m9'!AY6+'m9'!BA6+'m9'!BC6 -> 32 | FV6: =FU6*FH6 -> 4800 | FW6: ='m9'!AR6+'m9'!AT6+'m9'!AV6+'m9'!AX6+'m9'!AZ6+'m9'!BB6+'m9'!BD6 -> 0 | FY6: =FX6+FW6-FV6 -> -4800 | GA6: ='m9'!BE6+'m9'!BG6+'m9'!BI6 -> 16 | GB6: =GA6*FH6 -> 2400 | GC6: ='m9'!BF6+'m9'!BH6+'m9'!BJ6+'m10'!D6+'m10'!F6+'m10'!H6+'m10'!J6 -> 2000 | GE6: =GD6+GC6-GB6 -> -400 | GF6: =IFERROR(__xludf.DUMMYFUNCTION("""COMPUTED_VALUE"""),1290.3225806451612) -> 1290.3226 | GG6: ='m10'!K6+'m10'!M6+'m10'!O6+'m10'!Q6+'m10'!S6+'m10'!U6+'m10'!W6 -> 53 | GI6: ='m10'!L6+'m10'!N6+'m10'!P6+'m10'!R6+'m10'!T6+'m10'!V6+'m10'!X6 -> 0 | GM6: ='m10'!Y6+'m10'!AA6+'m10'!AC6+'m10'!AE6+'m10'!AG6+'m10'!AI6+'m10'!AK6 -> 31 | GO6: ='m10'!Z6+'m10'!AB6+'m10'!AD6+'m10'!AF6+'m10'!AH6+'m10'!AJ6+'m10'!AL6 -> 0 | GS6: ='m10'!AM6+'m10'!AO6+'m10'!AQ6+'m10'!AS6+'m10'!AU6+'m10'!AW6+'m10'!AY6 -> 46 | GU6: ='m10'!AN6+'m10'!AP6+'m10'!AR6+'m10'!AT6+'m10'!AV6+'m10'!AX6+'m10'!AZ6 -> 0 | GY6: ='m10'!BA6+'m10'!BC6+'m10'!BE6+'m10'!BG6+'m10'!BI6+'m10'!BK6+'m11'!C6 -> 34 | HA6: ='m10'!BB6+'m10'!BD6+'m10'!BF6+'m10'!BH6+'m10'!BJ6+'m10'!BL6+'m11'!D6 -> 1500 | HD6: =IFERROR(__xludf.DUMMYFUNCTION("""COMPUTED_VALUE"""),1333.3333333333333) -> 1333.3333 | HE6: ='m11'!E6+'m11'!G6+'m11'!I6+'m11'!K6+'m11'!M6+'m11'!O6+'m11'!Q6 -> 50 | HG6: ='m11'!F6+'m11'!H6+'m11'!J6+'m11'!L6+'m11'!N6+'m11'!P6+'m11'!R6 -> 0 | HK6: ='m11'!S6+'m11'!U6+'m11'!W6+'m11'!Y6+'m11'!AA6+'m11'!AC6+'m11'!AE6 -> 55 | HM6: ='m11'!T6+'m11'!V6+'m11'!X6+'m11'!Z6+'m11'!AB6+'m11'!AD6+'m11'!AF6 -> 0 | HQ6: ='m11'!AG6+'m11'!AI6+'m11'!AK6+'m11'!AM6+'m11'!AO6+'m11'!AQ6+'m11'!AS6 -> 36 | HS6: ='m11'!AH6+'m11'!AJ6+'m11'!AL6+'m11'!AN6+'m11'!AP6+'m11'!AR6+'m11'!AT6 -> 0 | HW6: ='m11'!AU6+'m11'!AW6+'m11'!AY6+'m11'!BA6+'m11'!BC6+'m11'!BE6+'m11'!BG6 -> 56 | HY6: ='m11'!AV6+'m11'!AX6+'m11'!AZ6+'m11'!BB6+'m11'!BD6+'m11'!BF6+'m11'!BH6 -> 0 | IB6: =IFERROR(__xludf.DUMMYFUNCTION("""COMPUTED_VALUE"""),1290.3225806451612) -> 1290.3226 | IC6: ='m11'!BI6+'m12'!C6+'m12'!E6+'m12'!G6+'m12'!I6+'m12'!K6+'m12'!M6 -> 48 | IE6: ='m11'!BJ6+'m12'!D6+'m12'!F6+'m12'!H6+'m12'!J6+'m12'!L6+'m12'!N6 -> 0 | II6: ='m12'!O6+'m12'!Q6+'m12'!S6+'m12'!U6+'m12'!W6+'m12'!Y6+'m12'!AA6 -> 0 | IK6: ='m12'!P6+'m12'!R6+'m12'!T6+'m12'!V6+'m12'!X6+'m12'!Z6+'m12'!AB6 -> 0 | IO6: ='m12'!AC6+'m12'!AE6+'m12'!AG6+'m12'!AI6+'m12'!AK6+'m12'!AM6+'m12'!AO6 -> 42 | IQ6: ='m12'!AD6+'m12'!AF6+'m12'!AH6+'m12'!AJ6+'m12'!AL6+'m12'!AN6+'m12'!AP6 -> 0 | IU6: ='m12'!AQ6+'m12'!AS6+'m12'!AU6+'m12'!AW6+'m12'!AY6+'m12'!BA6+'m12'!BC6 -> 38 | IW6: ='m12'!AR6+'m12'!AT6+'m12'!AV6+'m12'!AX6+'m12'!AZ6+'m12'!BB6+'m12'!BD6 -> 0 | JA6: ='m12'!BE6+'m12'!BG6+'m12'!BI6+'m12'!BK6 -> 20 | JC6: ='m12'!BF6+'m12'!BH6+'m12'!BJ6+'m12'!BL6 -> 0
A7: =IFERROR(__xludf.DUMMYFUNCTION("""COMPUTED_VALUE"""),"Petr Wolf") -> Petr Wolf | B7: =IFERROR(__xludf.DUMMYFUNCTION("""COMPUTED_VALUE"""),150.0) -> 150 | C7: ='m3'!E7+'m3'!G7+'m3'!I7+'m3'!K7+'m3'!M7+'m3'!O7+'m3'!Q7 -> 41 | D7: ='m3'!A7*C7 -> 6150 | E7: ='m3'!F7+'m3'!H7+'m3'!J7+'m3'!L7+'m3'!N7+'m3'!P7+'m3'!R7 -> 6150 | G7: =E7+F7-D7 -> 0 | I7: ='m3'!S7+'m3'!U7+'m3'!W7+'m3'!Y7+'m3'!AA7+'m3'!AC7+'m3'!AE7 -> 0 | J7: ='m3'!A7*I7 -> 0 | K7: ='m3'!T7+'m3'!V7+'m3'!X7+'m3'!Z7+'m3'!AB7+'m3'!AD7+'m3'!AF7 -> 0 | M7: =K7+L7-J7 -> 0 | O7: ='m3'!AG7+'m3'!AI7+'m3'!AK7+'m3'!AM7+'m3'!AO7+'m3'!AQ7+'m3'!AS7 -> 0 | P7: ='m3'!A7*O7 -> 0 | Q7: ='m3'!AH7+'m3'!AJ7+'m3'!AL7+'m3'!AN7+'m3'!AP7+'m3'!AR7+'m3'!AT7 -> 0 | S7: =Q7+R7-P7 -> 0 | U7: ='m3'!AU7+'m3'!AW7+'m3'!AY7+'m3'!BA7+'m3'!BC7+'m3'!BE7+'m3'!BG7 -> 51.5 | V7: ='m3'!A7*U7 -> 7725 | W7: ='m3'!DG7+'m3'!DI7+'m3'!DK7+'m3'!DM7+'m3'!DO7+'m3'!DQ7+'m3'!DS7 -> 0 | X7: 7725 | Y7: =W7+X7-V7 -> 0 | AA7: ='m3'!BI7+'m3'!BK7+'m4'!C7+'m4'!E7+'m4'!G7+'m4'!I7+'m4'!K7 -> 51.5 | AB7: =('m3'!BI7+'m3'!BK7)*'m3'!A7+('m4'!C7+'m4'!E7+'m4'!G7+'m4'!I7+'m4'!K7)*'m4'!A7 -> 7725 | AC7: ='m3'!BJ7+'m3'!BL7+'m4'!D7+'m4'!F7+'m4'!H7+'m4'!J7+'m4'!L7 -> 0 | AD7: 7725 | AE7: =AC7+AD7-AB7 -> 0 | AF7: =IFERROR(__xludf.DUMMYFUNCTION("""COMPUTED_VALUE"""),150.0) -> 150 | AG7: ='m4'!M7+'m4'!O7+'m4'!Q7+'m4'!S7+'m4'!U7+'m4'!W7+'m4'!Y7 -> 44.5 | AH7: ='m4'!A7*AG7 -> 6675 | AI7: ='m4'!N7+'m4'!P7+'m4'!R7+'m4'!T7+'m4'!V7+'m4'!X7+'m4'!Z7 -> 0 | AJ7: 6675 | AK7: =AI7+AJ7-AH7 -> 0 | AM7: ='m4'!AA7+'m4'!AC7+'m4'!AE7+'m4'!AG7+'m4'!AI7+'m4'!AK7+'m4'!AM7 -> 45.5 | AN7: ='m4'!A7*AM7 -> 6825 | AO7: ='m4'!AB7+'m4'!AD7+'m4'!AF7+'m4'!AH7+'m4'!AJ7+'m4'!AL7+'m4'!AN7 -> 0 | AP7: 6825 | AQ7: =AO7+AP7-AN7 -> 0 | AS7: ='m4'!AO7+'m4'!AQ7+'m4'!AS7+'m4'!AU7+'m4'!AW7+'m4'!AY7+'m4'!BA7 -> 36 | AT7: ='m4'!A7*AS7 -> 5400 | AU7: ='m4'!AP7+'m4'!AR7+'m4'!AT7+'m4'!AV7+'m4'!AX7+'m4'!AZ7+'m4'!BB7 -> 0 | AV7: 5400 | AW7: =AV7+AU7-AT7 -> 0 | AY7: ='m4'!BC7+'m4'!BE7+'m4'!BG7+'m4'!BI7+'m5'!C7+'m5'!E7+'m5'!G7 -> 42.5 | AZ7: =('m4'!BC7+'m4'!BE7+'m4'!BG7+'m4'!BI7)*'m4'!A7+('m5'!C7+'m5'!E7+'m5'!G7)*'m5'!A7 -> 6375 | BA7: ='m4'!BD7+'m4'!BF7+'m4'!BH7+'m4'!BJ7+'m5'!D7+'m5'!F7+'m5'!H7 -> 0 | BB7: 6375 | BC7: =BB7+BA7-AZ7 -> 0 | BD7: =IFERROR(__xludf.DUMMYFUNCTION("""COMPUTED_VALUE"""),150.0) -> 150 | BE7: ='m5'!I7+'m5'!K7+'m5'!M7+'m5'!O7+'m5'!Q7+'m5'!S7+'m5'!U7 -> 39 | BF7: ='m5'!A7*BE7 -> 5850 | BG7: ='m5'!J7+'m5'!L7+'m5'!N7+'m5'!P7+'m5'!R7+'m5'!T7+'m5'!V7 -> 0 | BH7: 5850 | BI7: =BH7+BG7-BF7 -> 0 | BK7: ='m5'!W7+'m5'!Y7+'m5'!AA7+'m5'!AC7+'m5'!AE7+'m5'!AG7+'m5'!AI7 -> 42.5 | BL7: ='m5'!A7*BK7 -> 6375 | BM7: ='m5'!X7+'m5'!Z7+'m5'!AB7+'m5'!AD7+'m5'!AF7+'m5'!AH7+'m5'!AJ7 -> 0 | BO7: =BN7+BM7-BL7 -> -6375 | BQ7: ='m5'!AK7+'m5'!AM7+'m5'!AO7+'m5'!AQ7+'m5'!AS7+'m5'!AU7+'m5'!AW7 -> 34 | BR7: ='m5'!A7*BQ7 -> 5100 | BS7: ='m5'!AL7+'m5'!AN7+'m5'!AP7+'m5'!AR7+'m5'!AT7+'m5'!AV7+'m5'!AX7 -> 0 | BU7: =BT7+BS7-BR7 -> -5100 | BW7: ='m5'!AY7+'m5'!BA7+'m5'!BC7+'m5'!BE7+'m5'!BG7+'m5'!BI7+'m5'!BK7 -> 40.5 | BX7: ='m5'!A7*BW7 -> 6075 | BY7: ='m5'!AZ7+'m5'!BB7+'m5'!BD7+'m5'!BF7+'m5'!BH7+'m5'!BJ7+'m5'!BL7 -> 0 | CA7: =BZ7+BY7-BX7 -> -6075 | CB7: =IFERROR(__xludf.DUMMYFUNCTION("""COMPUTED_VALUE"""),150.0) -> 150 | CC7: ='m6'!C7+'m6'!E7+'m6'!G7+'m6'!I7+'m6'!K7+'m6'!M7+'m6'!O7 -> 57 | CD7: =CC7*CB7 -> 8550 | CE7: ='m6'!D7+'m6'!F7+'m6'!H7+'m6'!J7+'m6'!L7+'m6'!N7+'m6'!P7 -> 0 | CG7: =CF7+CE7-CD7 -> -8550 | CI7: ='m6'!Q7+'m6'!S7+'m6'!U7+'m6'!W7+'m6'!Y7+'m6'!AA7+'m6'!AC7 -> 49 | CJ7: =CI7*CB7 -> 7350 | CK7: ='m6'!R7+'m6'!T7+'m6'!V7+'m6'!X7+'m6'!Z7+'m6'!AB7+'m6'!AD7 -> 0 | CM7: =CL7+CK7-CJ7 -> -7350 | CO7: ='m6'!AE7+'m6'!AG7+'m6'!AI7+'m6'!AK7+'m6'!AM7+'m6'!AO7+'m6'!AQ7 -> 59.5 | CP7: =CO7*CB7 -> 8925 | CQ7: ='m6'!AF7+'m6'!AH7+'m6'!AJ7+'m6'!AL7+'m6'!AN7+'m6'!AP7+'m6'!AR7 -> 0 | CS7: =CR7+CQ7-CP7 -> -8925 | CU7: ='m6'!AS7+'m6'!AU7+'m6'!AW7+'m6'!AY7+'m6'!BA7+'m6'!BC7+'m6'!BE7 -> 57 | CV7: =CU7*CB7 -> 8550 | CW7: ='m6'!AT7+'m6'!AV7+'m6'!AX7+'m6'!AZ7+'m6'!BB7+'m6'!BD7+'m6'!BF7 -> 600 | CY7: =CX7+CW7-CV7 -> -7950 | DA7: ='m6'!BG7+'m6'!BI7+'m7'!C7+'m7'!E7+'m7'!G7+'m7'!I7+'m7'!K7 -> 62.5 | DB7: =('m6'!BG7+'m6'!BI7)*'m6'!A7+('m7'!C7+'m7'!E7+'m7'!G7+'m7'!I7+'m7'!K7)*'m7'!A7 -> 9375 | DC7: ='m6'!BH7+'m6'!BJ7+'m7'!D7+'m7'!F7+'m7'!H7+'m7'!J7+'m7'!L7 -> 585 | DE7: =DD7+DC7-DB7 -> -8790 | DF7: =IFERROR(__xludf.DUMMYFUNCTION("""COMPUTED_VALUE"""),150.0) -> 150 | DG7: ='m7'!M7+'m7'!O7+'m7'!Q7+'m7'!S7+'m7'!U7+'m7'!W7+'m7'!Y7 -> 48.5 | DH7: =DG7*DF7 -> 7275 | DI7: ='m7'!N7+'m7'!P7+'m7'!R7+'m7'!T7+'m7'!V7+'m7'!X7+'m7'!Z7 -> 0 | DK7: =DJ7+DI7-DH7 -> -7275 | DM7: ='m7'!AA7+'m7'!AC7+'m7'!AE7+'m7'!AG7+'m7'!AI7+'m7'!AK7+'m7'!AM7 -> 62.5 | DN7: =DM7*DF7 -> 9375 | DO7: ='m7'!AB7+'m7'!AD7+'m7'!AF7+'m7'!AH7+'m7'!AJ7+'m7'!AL7+'m7'!AN7 -> 0 | DQ7: =DP7+DO7-DN7 -> -9375 | DS7: ='m7'!AO7+'m7'!AQ7+'m7'!AS7+'m7'!AU7+'m7'!AW7+'m7'!AY7+'m7'!BA7 -> 49 | DT7: =DS7*DF7 -> 7350 | DU7: ='m7'!AP7+'m7'!AR7+'m7'!AT7+'m7'!AV7+'m7'!AX7+'m7'!AZ7+'m7'!BB7 -> 0 | DW7: =DV7+DU7-DT7 -> -7350 | DY7: ='m7'!BC7+'m7'!BE7+'m7'!BG7+'m7'!BI7+'m7'!BK7+'m8'!C7+'m8'!E7 -> 49 | DZ7: =('m7'!BC7+'m7'!BE7+'m7'!BG7+'m7'!BI7+'m7'!BK7)*DF7+('m8'!C7+'m8'!E7)*ED7 -> 7350 | EA7: ='m7'!BD7+'m7'!BF7+'m7'!BH7+'m7'!BJ7+'m7'!BL7+'m8'!D7+'m8'!F7 -> 0 | EC7: =EB7+EA7-DZ7 -> -7350 | ED7: =IFERROR(__xludf.DUMMYFUNCTION("""COMPUTED_VALUE"""),150.0) -> 150 | EE7: ='m8'!G7+'m8'!I7+'m8'!K7+'m8'!M7+'m8'!O7+'m8'!Q7+'m8'!S7 -> 0 | EF7: =EE7*ED7 -> 0 | EG7: ='m8'!H7+'m8'!J7+'m8'!L7+'m8'!N7+'m8'!P7+'m8'!R7+'m8'!T7 -> 0 | EI7: =EH7+EG7-EF7 -> 0 | EK7: ='m8'!U7+'m8'!W7+'m8'!Y7+'m8'!AA7+'m8'!AC7+'m8'!AE7+'m8'!AG7 -> 66.5 | EL7: =EK7*ED7 -> 9975 | EM7: ='m8'!V7+'m8'!X7+'m8'!Z7+'m8'!AB7+'m8'!AD7+'m8'!AF7+'m8'!AH7 -> 0 | EO7: =EN7+EM7-EL7 -> -9975 | EQ7: ='m8'!AI7+'m8'!AK7+'m8'!AM7+'m8'!AO7+'m8'!AQ7+'m8'!AS7+'m8'!AU7 -> 35 | ER7: =EQ7*ED7 -> 5250 | ES7: ='m8'!AJ7+'m8'!AL7+'m8'!AN7+'m8'!AP7+'m8'!AR7+'m8'!AT7+'m8'!AV7 -> 500 | EU7: =ET7+ES7-ER7 -> -4750 | EW7: ='m8'!AW7+'m8'!AY7+'m8'!BA7+'m8'!BC7+'m8'!BE7+'m8'!BG7+'m8'!BI7 -> 62.5 | EX7: =EW7*ED7 -> 9375 | EY7: ='m8'!AX7+'m8'!AZ7+'m8'!BB7+'m8'!BD7+'m8'!BF7+'m8'!BH7+'m8'!BJ7 -> 0 | FA7: =EZ7+EY7-EX7 -> -9375 | FC7: ='m8'!BK7+'m9'!C7+'m9'!E7+'m9'!G7+'m9'!I7+'m9'!K7+'m9'!M7 -> 37 | FD7: ='m8'!BK7*ED7+'m9'!C7*FH7+'m9'!E7*FH7+'m9'!G7*FH7+'m9'!I7*FH7+'m9'!K7*FH7+'m9'!M7*FH7 -> 5550 | FE7: ='m8'!BL7+'m9'!D7+'m9'!F7+'m9'!H7+'m9'!J7+'m9'!L7+'m9'!N7 -> 0 | FG7: =FF7+FE7-FD7 -> -5550 | FH7: =IFERROR(__xludf.DUMMYFUNCTION("""COMPUTED_VALUE"""),150.0) -> 150 | FI7: ='m9'!O7+'m9'!Q7+'m9'!S7+'m9'!U7+'m9'!W7+'m9'!Y7+'m9'!AA7 -> 63 | FJ7: =FI7*FH7 -> 9450 | FK7: ='m9'!P7+'m9'!R7+'m9'!T7+'m9'!V7+'m9'!X7+'m9'!Z7+'m9'!AB7 -> 0 | FM7: =FL7+FK7-FJ7 -> -9450 | FO7: ='m9'!AC7+'m9'!AE7+'m9'!AG7+'m9'!AI7+'m9'!AK7+'m9'!AM7+'m9'!AO7 -> 67 | FP7: =FO7*FH7 -> 10050 | FQ7: ='m9'!AD7+'m9'!AF7+'m9'!AH7+'m9'!AJ7+'m9'!AL7+'m9'!AN7+'m9'!AP7 -> 0 | FS7: =FR7+FQ7-FP7 -> -10050 | FU7: ='m9'!AQ7+'m9'!AS7+'m9'!AU7+'m9'!AW7+'m9'!AY7+'m9'!BA7+'m9'!BC7 -> 53.5 | FV7: =FU7*FH7 -> 8025 | FW7: ='m9'!AR7+'m9'!AT7+'m9'!AV7+'m9'!AX7+'m9'!AZ7+'m9'!BB7+'m9'!BD7 -> 0 | FY7: =FX7+FW7-FV7 -> -8025 | GA7: ='m9'!BE7+'m9'!BG7+'m9'!BI7+'m10'!C7+'m10'!E7+'m10'!G7+'m10'!I7 -> 70.5 | GB7: =GA7*FH7 -> 10575 | GC7: ='m9'!BF7+'m9'!BH7+'m9'!BJ7+'m10'!D7+'m10'!F7+'m10'!H7+'m10'!J7 -> 0 | GE7: =GD7+GC7-GB7 -> -10575 | GF7: =IFERROR(__xludf.DUMMYFUNCTION("""COMPUTED_VALUE"""),150.0) -> 150 | GG7: ='m10'!K7+'m10'!M7+'m10'!O7+'m10'!Q7+'m10'!S7+'m10'!U7+'m10'!W7 -> 60 | GH7: =GG7*GF7 -> 9000 | GI7: ='m10'!L7+'m10'!N7+'m10'!P7+'m10'!R7+'m10'!T7+'m10'!V7+'m10'!X7 -> 0 | GK7: =GJ7+GI7-GH7 -> -9000 | GM7: ='m10'!Y7+'m10'!AA7+'m10'!AC7+'m10'!AE7+'m10'!AG7+'m10'!AI7+'m10'!AK7 -> 44.5 | GN7: =GM7*GF7 -> 6675 | GO7: ='m10'!Z7+'m10'!AB7+'m10'!AD7+'m10'!AF7+'m10'!AH7+'m10'!AJ7+'m10'!AL7 -> 0 | GQ7: =GP7+GO7-GN7 -> -6675 | GS7: ='m10'!AM7+'m10'!AO7+'m10'!AQ7+'m10'!AS7+'m10'!AU7+'m10'!AW7+'m10'!AY7 -> 41 | GT7: =GS7*GF7 -> 6150 | GU7: ='m10'!AN7+'m10'!AP7+'m10'!AR7+'m10'!AT7+'m10'!AV7+'m10'!AX7+'m10'!AZ7 -> 0 | GW7: =GV7+GU7-GT7 -> -6150 | GY7: ='m10'!BA7+'m10'!BC7+'m10'!BE7+'m10'!BG7+'m10'!BI7+'m10'!BK7+'m11'!C7 -> 30 | GZ7: =GY7*GF7 -> 4500 | HA7: ='m10'!BB7+'m10'!BD7+'m10'!BF7+'m10'!BH7+'m10'!BJ7+'m10'!BL7+'m11'!D7 -> 0 | HC7: =HB7+HA7-GZ7 -> -4500 | HD7: =IFERROR(__xludf.DUMMYFUNCTION("""COMPUTED_VALUE"""),150.0) -> 150 | HE7: ='m11'!E7+'m11'!G7+'m11'!I7+'m11'!K7+'m11'!M7+'m11'!O7+'m11'!Q7 -> 47 | HF7: =HE7*HD7 -> 7050 | HG7: ='m11'!F7+'m11'!H7+'m11'!J7+'m11'!L7+'m11'!N7+'m11'!P7+'m11'!R7 -> 0 | HI7: =HH7+HG7-HF7 -> -7050 | HK7: ='m11'!S7+'m11'!U7+'m11'!W7+'m11'!Y7+'m11'!AA7+'m11'!AC7+'m11'!AE7 -> 48 | HL7: =HK7*HD7 -> 7200 | HM7: ='m11'!T7+'m11'!V7+'m11'!X7+'m11'!Z7+'m11'!AB7+'m11'!AD7+'m11'!AF7 -> 400 | HO7: =HN7+HM7-HL7 -> -6800 | HQ7: ='m11'!AG7+'m11'!AI7+'m11'!AK7+'m11'!AM7+'m11'!AO7+'m11'!AQ7+'m11'!AS7 -> 60 | HR7: =HQ7*HD7 -> 9000 | HS7: ='m11'!AH7+'m11'!AJ7+'m11'!AL7+'m11'!AN7+'m11'!AP7+'m11'!AR7+'m11'!AT7 -> 0 | HU7: =HT7+HS7-HR7 -> -9000 | HW7: ='m11'!AU7+'m11'!AW7+'m11'!AY7+'m11'!BA7+'m11'!BC7+'m11'!BE7+'m11'!BG7 -> 47 | HX7: =HW7*HD7 -> 7050 | HY7: ='m11'!AV7+'m11'!AX7+'m11'!AZ7+'m11'!BB7+'m11'!BD7+'m11'!BF7+'m11'!BH7 -> 0 | IA7: =HZ7+HY7-HX7 -> -7050 | IB7: =IFERROR(__xludf.DUMMYFUNCTION("""COMPUTED_VALUE"""),150.0) -> 150 | IC7: ='m11'!BI7+'m12'!C7+'m12'!E7+'m12'!G7+'m12'!I7+'m12'!K7+'m12'!M7 -> 60 | ID7: =IC7*IB7 -> 9000 | IE7: ='m11'!BJ7+'m12'!D7+'m12'!F7+'m12'!H7+'m12'!J7+'m12'!L7+'m12'!N7 -> 0 | IG7: =IF7+IE7-ID7 -> -9000 | II7: ='m12'!O7+'m12'!Q7+'m12'!S7+'m12'!U7+'m12'!W7+'m12'!Y7+'m12'!AA7 -> 47 | IJ7: =II7*IB7 -> 7050 | IK7: ='m12'!P7+'m12'!R7+'m12'!T7+'m12'!V7+'m12'!X7+'m12'!Z7+'m12'!AB7 -> 0 | IM7: =IL7+IK7-IJ7 -> -7050 | IO7: ='m12'!AC7+'m12'!AE7+'m12'!AG7+'m12'!AI7+'m12'!AK7+'m12'!AM7+'m12'!AO7 -> 60 | IP7: =IO7*IB7 -> 9000 | IQ7: ='m12'!AD7+'m12'!AF7+'m12'!AH7+'m12'!AJ7+'m12'!AL7+'m12'!AN7+'m12'!AP7 -> 0 | IS7: =IR7+IQ7-IP7 -> -9000 | IU7: ='m12'!AQ7+'m12'!AS7+'m12'!AU7+'m12'!AW7+'m12'!AY7+'m12'!BA7+'m12'!BC7 -> 0 | IV7: =IU7*IB7 -> 0 | IW7: ='m12'!AR7+'m12'!AT7+'m12'!AV7+'m12'!AX7+'m12'!AZ7+'m12'!BB7+'m12'!BD7 -> 0 | IY7: =IX7+IW7-IV7 -> 0 | JA7: ='m12'!BE7+'m12'!BG7+'m12'!BI7+'m12'!BK7 -> 30 | JB7: =JA7*IB7 -> 4500 | JC7: ='m12'!BF7+'m12'!BH7+'m12'!BJ7+'m12'!BL7 -> 0 | JE7: =JD7+JC7-JB7 -> -4500
A8: =IFERROR(__xludf.DUMMYFUNCTION("""COMPUTED_VALUE"""),"David Kropáč") -> David Kropáč | B8: =IFERROR(__xludf.DUMMYFUNCTION("""COMPUTED_VALUE"""),150.0) -> 150 | C8: ='m3'!E8+'m3'!G8+'m3'!I8+'m3'!K8+'m3'!M8+'m3'!O8+'m3'!Q8 -> 52.5 | D8: ='m3'!A8*C8 -> 7875 | E8: ='m3'!F8+'m3'!H8+'m3'!J8+'m3'!L8+'m3'!N8+'m3'!P8+'m3'!R8 -> 7875 | G8: =E8+F8-D8 -> 0 | I8: ='m3'!S8+'m3'!U8+'m3'!W8+'m3'!Y8+'m3'!AA8+'m3'!AC8+'m3'!AE8 -> 39 | J8: ='m3'!A8*I8 -> 5850 | K8: ='m3'!T8+'m3'!V8+'m3'!X8+'m3'!Z8+'m3'!AB8+'m3'!AD8+'m3'!AF8 -> 5850 | M8: =K8+L8-J8 -> 0 | O8: ='m3'!AG8+'m3'!AI8+'m3'!AK8+'m3'!AM8+'m3'!AO8+'m3'!AQ8+'m3'!AS8 -> 51 | P8: ='m3'!A8*O8 -> 7650 | Q8: ='m3'!AH8+'m3'!AJ8+'m3'!AL8+'m3'!AN8+'m3'!AP8+'m3'!AR8+'m3'!AT8 -> 1200 | R8: 6450 | S8: =Q8+R8-P8 -> 0 | U8: ='m3'!AU8+'m3'!AW8+'m3'!AY8+'m3'!BA8+'m3'!BC8+'m3'!BE8+'m3'!BG8 -> 42 | V8: ='m3'!A8*U8 -> 6300 | W8: ='m3'!DG8+'m3'!DI8+'m3'!DK8+'m3'!DM8+'m3'!DO8+'m3'!DQ8+'m3'!DS8 -> 0 | X8: 6300 | Y8: =W8+X8-V8 -> 0 | AA8: ='m3'!BI8+'m3'!BK8+'m4'!C8+'m4'!E8+'m4'!G8+'m4'!I8+'m4'!K8 -> 51 | AB8: =('m3'!BI8+'m3'!BK8)*'m3'!A8+('m4'!C8+'m4'!E8+'m4'!G8+'m4'!I8+'m4'!K8)*'m4'!A8 -> 7650 | AC8: ='m3'!BJ8+'m3'!BL8+'m4'!D8+'m4'!F8+'m4'!H8+'m4'!J8+'m4'!L8 -> 0 | AD8: 7650 | AE8: =AC8+AD8-AB8 -> 0 | AF8: =IFERROR(__xludf.DUMMYFUNCTION("""COMPUTED_VALUE"""),150.0) -> 150 | AG8: ='m4'!M8+'m4'!O8+'m4'!Q8+'m4'!S8+'m4'!U8+'m4'!W8+'m4'!Y8 -> 45 | AH8: ='m4'!A8*AG8 -> 6750 | AI8: ='m4'!N8+'m4'!P8+'m4'!R8+'m4'!T8+'m4'!V8+'m4'!X8+'m4'!Z8 -> 0 | AJ8: 6750 | AK8: =AI8+AJ8-AH8 -> 0 | AM8: ='m4'!AA8+'m4'!AC8+'m4'!AE8+'m4'!AG8+'m4'!AI8+'m4'!AK8+'m4'!AM8 -> 41 | AN8: ='m4'!A8*AM8 -> 6150 | AO8: ='m4'!AB8+'m4'!AD8+'m4'!AF8+'m4'!AH8+'m4'!AJ8+'m4'!AL8+'m4'!AN8 -> 0 | AP8: 6150 | AQ8: =AO8+AP8-AN8 -> 0 | AS8: ='m4'!AO8+'m4'!AQ8+'m4'!AS8+'m4'!AU8+'m4'!AW8+'m4'!AY8+'m4'!BA8 -> 58.5 | AT8: ='m4'!A8*AS8 -> 8775 | AU8: ='m4'!AP8+'m4'!AR8+'m4'!AT8+'m4'!AV8+'m4'!AX8+'m4'!AZ8+'m4'!BB8 -> 0 | AV8: 8775 | AW8: =AV8+AU8-AT8 -> 0 | AY8: ='m4'!BC8+'m4'!BE8+'m4'!BG8+'m4'!BI8+'m5'!C8+'m5'!E8+'m5'!G8 -> 41.5 | AZ8: =('m4'!BC8+'m4'!BE8+'m4'!BG8+'m4'!BI8)*'m4'!A8+('m5'!C8+'m5'!E8+'m5'!G8)*'m5'!A8 -> 6225 | BA8: ='m4'!BD8+'m4'!BF8+'m4'!BH8+'m4'!BJ8+'m5'!D8+'m5'!F8+'m5'!H8 -> 0 | BB8: 6225 | BC8: =BB8+BA8-AZ8 -> 0 | BD8: =IFERROR(__xludf.DUMMYFUNCTION("""COMPUTED_VALUE"""),150.0) -> 150 | BE8: ='m5'!I8+'m5'!K8+'m5'!M8+'m5'!O8+'m5'!Q8+'m5'!S8+'m5'!U8 -> 32 | BF8: ='m5'!A8*BE8 -> 4800 | BG8: ='m5'!J8+'m5'!L8+'m5'!N8+'m5'!P8+'m5'!R8+'m5'!T8+'m5'!V8 -> 0 | BH8: 4800 | BI8: =BH8+BG8-BF8 -> 0 | BK8: ='m5'!W8+'m5'!Y8+'m5'!AA8+'m5'!AC8+'m5'!AE8+'m5'!AG8+'m5'!AI8 -> 48 | BL8: ='m5'!A8*BK8 -> 7200 | BM8: ='m5'!X8+'m5'!Z8+'m5'!AB8+'m5'!AD8+'m5'!AF8+'m5'!AH8+'m5'!AJ8 -> 0 | BO8: =BN8+BM8-BL8 -> -7200 | BQ8: ='m5'!AK8+'m5'!AM8+'m5'!AO8+'m5'!AQ8+'m5'!AS8+'m5'!AU8+'m5'!AW8 -> 43.5 | BR8: ='m5'!A8*BQ8 -> 6525 | BS8: ='m5'!AL8+'m5'!AN8+'m5'!AP8+'m5'!AR8+'m5'!AT8+'m5'!AV8+'m5'!AX8 -> 0 | BU8: =BT8+BS8-BR8 -> -6525 | BW8: ='m5'!AY8+'m5'!BA8+'m5'!BC8+'m5'!BE8+'m5'!BG8+'m5'!BI8+'m5'!BK8 -> 45 | BX8: ='m5'!A8*BW8 -> 6750 | BY8: ='m5'!AZ8+'m5'!BB8+'m5'!BD8+'m5'!BF8+'m5'!BH8+'m5'!BJ8+'m5'!BL8 -> 1000 | CA8: =BZ8+BY8-BX8 -> -5750 | CB8: =IFERROR(__xludf.DUMMYFUNCTION("""COMPUTED_VALUE"""),150.0) -> 150 | CC8: ='m6'!C8+'m6'!E8+'m6'!G8+'m6'!I8+'m6'!K8+'m6'!M8+'m6'!O8 -> 51 | CD8: =CC8*CB8 -> 7650 | CE8: ='m6'!D8+'m6'!F8+'m6'!H8+'m6'!J8+'m6'!L8+'m6'!N8+'m6'!P8 -> 0 | CG8: =CF8+CE8-CD8 -> -7650 | CI8: ='m6'!Q8+'m6'!S8+'m6'!U8+'m6'!W8+'m6'!Y8+'m6'!AA8+'m6'!AC8 -> 43 | CJ8: =CI8*CB8 -> 6450 | CK8: ='m6'!R8+'m6'!T8+'m6'!V8+'m6'!X8+'m6'!Z8+'m6'!AB8+'m6'!AD8 -> 600 | CM8: =CL8+CK8-CJ8 -> -5850 | CO8: ='m6'!AE8+'m6'!AG8+'m6'!AI8+'m6'!AK8+'m6'!AM8+'m6'!AO8+'m6'!AQ8 -> 52 | CP8: =CO8*CB8 -> 7800 | CQ8: ='m6'!AF8+'m6'!AH8+'m6'!AJ8+'m6'!AL8+'m6'!AN8+'m6'!AP8+'m6'!AR8 -> 500 | CS8: =CR8+CQ8-CP8 -> -7300 | CU8: ='m6'!AS8+'m6'!AU8+'m6'!AW8+'m6'!AY8+'m6'!BA8+'m6'!BC8+'m6'!BE8 -> 50 | CV8: =CU8*CB8 -> 7500 | CW8: ='m6'!AT8+'m6'!AV8+'m6'!AX8+'m6'!AZ8+'m6'!BB8+'m6'!BD8+'m6'!BF8 -> 1000 | CY8: =CX8+CW8-CV8 -> -6500 | DA8: ='m6'!BG8+'m6'!BI8+'m7'!C8+'m7'!E8+'m7'!G8+'m7'!I8+'m7'!K8 -> 53 | DB8: =('m6'!BG8+'m6'!BI8)*'m6'!A8+('m7'!C8+'m7'!E8+'m7'!G8+'m7'!I8+'m7'!K8)*'m7'!A8 -> 7950 | DC8: ='m6'!BH8+'m6'!BJ8+'m7'!D8+'m7'!F8+'m7'!H8+'m7'!J8+'m7'!L8 -> 1000 | DE8: =DD8+DC8-DB8 -> -6950 | DF8: =IFERROR(__xludf.DUMMYFUNCTION("""COMPUTED_VALUE"""),150.0) -> 150 | DG8: ='m7'!M8+'m7'!O8+'m7'!Q8+'m7'!S8+'m7'!U8+'m7'!W8+'m7'!Y8 -> 79 | DH8: =DG8*DF8 -> 11850 | DI8: ='m7'!N8+'m7'!P8+'m7'!R8+'m7'!T8+'m7'!V8+'m7'!X8+'m7'!Z8 -> 19800 | DK8: =DJ8+DI8-DH8 -> 7950 | DM8: ='m7'!AA8+'m7'!AC8+'m7'!AE8+'m7'!AG8+'m7'!AI8+'m7'!AK8+'m7'!AM8 -> 62 | DN8: =DM8*DF8 -> 9300 | DO8: ='m7'!AB8+'m7'!AD8+'m7'!AF8+'m7'!AH8+'m7'!AJ8+'m7'!AL8+'m7'!AN8 -> 0 | DQ8: =DP8+DO8-DN8 -> -9300 | DS8: ='m7'!AO8+'m7'!AQ8+'m7'!AS8+'m7'!AU8+'m7'!AW8+'m7'!AY8+'m7'!BA8 -> 77 | DT8: =DS8*DF8 -> 11550 | DU8: ='m7'!AP8+'m7'!AR8+'m7'!AT8+'m7'!AV8+'m7'!AX8+'m7'!AZ8+'m7'!BB8 -> 20000 | DW8: =DV8+DU8-DT8 -> 8450 | DY8: ='m7'!BC8+'m7'!BE8+'m7'!BG8+'m7'!BI8+'m7'!BK8+'m8'!C8+'m8'!E8 -> 68 | DZ8: =('m7'!BC8+'m7'!BE8+'m7'!BG8+'m7'!BI8+'m7'!BK8)*DF8+('m8'!C8+'m8'!E8)*ED8 -> 10200 | EA8: ='m7'!BD8+'m7'!BF8+'m7'!BH8+'m7'!BJ8+'m7'!BL8+'m8'!D8+'m8'!F8 -> 0 | EC8: =EB8+EA8-DZ8 -> -10200 | ED8: =IFERROR(__xludf.DUMMYFUNCTION("""COMPUTED_VALUE"""),150.0) -> 150 | EE8: ='m8'!G8+'m8'!I8+'m8'!K8+'m8'!M8+'m8'!O8+'m8'!Q8+'m8'!S8 -> 67 | EF8: =EE8*ED8 -> 10050 | EG8: ='m8'!H8+'m8'!J8+'m8'!L8+'m8'!N8+'m8'!P8+'m8'!R8+'m8'!T8 -> 4000 | EI8: =EH8+EG8-EF8 -> -6050 | EK8: ='m8'!U8+'m8'!W8+'m8'!Y8+'m8'!AA8+'m8'!AC8+'m8'!AE8+'m8'!AG8 -> 54 | EL8: =EK8*ED8 -> 8100 | EM8: ='m8'!V8+'m8'!X8+'m8'!Z8+'m8'!AB8+'m8'!AD8+'m8'!AF8+'m8'!AH8 -> 0 | EO8: =EN8+EM8-EL8 -> -8100 | EQ8: ='m8'!AI8+'m8'!AK8+'m8'!AM8+'m8'!AO8+'m8'!AQ8+'m8'!AS8+'m8'!AU8 -> 52 | ER8: =EQ8*ED8 -> 7800 | ES8: ='m8'!AJ8+'m8'!AL8+'m8'!AN8+'m8'!AP8+'m8'!AR8+'m8'!AT8+'m8'!AV8 -> 0 | EU8: =ET8+ES8-ER8 -> -7800 | EW8: ='m8'!AW8+'m8'!AY8+'m8'!BA8+'m8'!BC8+'m8'!BE8+'m8'!BG8+'m8'!BI8 -> 55 | EX8: =EW8*ED8 -> 8250 | EY8: ='m8'!AX8+'m8'!AZ8+'m8'!BB8+'m8'!BD8+'m8'!BF8+'m8'!BH8+'m8'!BJ8 -> 1000 | FA8: =EZ8+EY8-EX8 -> -7250 | FC8: ='m8'!BK8+'m9'!C8+'m9'!E8+'m9'!G8+'m9'!I8+'m9'!K8+'m9'!M8 -> 59 | FD8: ='m8'!BK8*ED8+'m9'!C8*FH8+'m9'!E8*FH8+'m9'!G8*FH8+'m9'!I8*FH8+'m9'!K8*FH8+'m9'!M8*FH8 -> 8850 | FE8: ='m8'!BL8+'m9'!D8+'m9'!F8+'m9'!H8+'m9'!J8+'m9'!L8+'m9'!N8 -> 170 | FG8: =FF8+FE8-FD8 -> -8680 | FH8: =IFERROR(__xludf.DUMMYFUNCTION("""COMPUTED_VALUE"""),150.0) -> 150 | FI8: ='m9'!O8+'m9'!Q8+'m9'!S8+'m9'!U8+'m9'!W8+'m9'!Y8+'m9'!AA8 -> 46 | FJ8: =FI8*FH8 -> 6900 | FK8: ='m9'!P8+'m9'!R8+'m9'!T8+'m9'!V8+'m9'!X8+'m9'!Z8+'m9'!AB8 -> 0 | FM8: =FL8+FK8-FJ8 -> -6900 | FO8: ='m9'!AC8+'m9'!AE8+'m9'!AG8+'m9'!AI8+'m9'!AK8+'m9'!AM8+'m9'!AO8 -> 55 | FP8: =FO8*FH8 -> 8250 | FQ8: ='m9'!AD8+'m9'!AF8+'m9'!AH8+'m9'!AJ8+'m9'!AL8+'m9'!AN8+'m9'!AP8 -> 0 | FS8: =FR8+FQ8-FP8 -> -8250 | FU8: ='m9'!AQ8+'m9'!AS8+'m9'!AU8+'m9'!AW8+'m9'!AY8+'m9'!BA8+'m9'!BC8 -> 55 | FV8: =FU8*FH8 -> 8250 | FW8: ='m9'!AR8+'m9'!AT8+'m9'!AV8+'m9'!AX8+'m9'!AZ8+'m9'!BB8+'m9'!BD8 -> 0 | FY8: =FX8+FW8-FV8 -> -8250 | GA8: ='m9'!BE8+'m9'!BG8+'m9'!BI8+'m10'!C8+'m10'!E8+'m10'!G8+'m10'!I8 -> 50 | GB8: =GA8*FH8 -> 7500 | GC8: ='m9'!BF8+'m9'!BH8+'m9'!BJ8+'m10'!D8+'m10'!F8+'m10'!H8+'m10'!J8 -> 0 | GE8: =GD8+GC8-GB8 -> -7500 | GF8: =IFERROR(__xludf.DUMMYFUNCTION("""COMPUTED_VALUE"""),150.0) -> 150 | GG8: ='m10'!K8+'m10'!M8+'m10'!O8+'m10'!Q8+'m10'!S8+'m10'!U8+'m10'!W8 -> 35.5 | GH8: =GG8*GF8 -> 5325 | GI8: ='m10'!L8+'m10'!N8+'m10'!P8+'m10'!R8+'m10'!T8+'m10'!V8+'m10'!X8 -> 0 | GK8: =GJ8+GI8-GH8 -> -5325 | GM8: ='m10'!Y8+'m10'!AA8+'m10'!AC8+'m10'!AE8+'m10'!AG8+'m10'!AI8+'m10'!AK8 -> 53.5 | GN8: =GM8*GF8 -> 8025 | GO8: ='m10'!Z8+'m10'!AB8+'m10'!AD8+'m10'!AF8+'m10'!AH8+'m10'!AJ8+'m10'!AL8 -> 0 | GQ8: =GP8+GO8-GN8 -> -8025 | GS8: ='m10'!AM8+'m10'!AO8+'m10'!AQ8+'m10'!AS8+'m10'!AU8+'m10'!AW8+'m10'!AY8 -> 36 | GT8: =GS8*GF8 -> 5400 | GU8: ='m10'!AN8+'m10'!AP8+'m10'!AR8+'m10'!AT8+'m10'!AV8+'m10'!AX8+'m10'!AZ8 -> 0 | GW8: =GV8+GU8-GT8 -> -5400 | GY8: ='m10'!BA8+'m10'!BC8+'m10'!BE8+'m10'!BG8+'m10'!BI8+'m10'!BK8+'m11'!C8 -> 41.5 | GZ8: =GY8*GF8 -> 6225 | HA8: ='m10'!BB8+'m10'!BD8+'m10'!BF8+'m10'!BH8+'m10'!BJ8+'m10'!BL8+'m11'!D8 -> 0 | HC8: =HB8+HA8-GZ8 -> -6225 | HD8: =IFERROR(__xludf.DUMMYFUNCTION("""COMPUTED_VALUE"""),150.0) -> 150 | HE8: ='m11'!E8+'m11'!G8+'m11'!I8+'m11'!K8+'m11'!M8+'m11'!O8+'m11'!Q8 -> 49 | HF8: =HE8*HD8 -> 7350 | HG8: ='m11'!F8+'m11'!H8+'m11'!J8+'m11'!L8+'m11'!N8+'m11'!P8+'m11'!R8 -> 0 | HI8: =HH8+HG8-HF8 -> -7350 | HK8: ='m11'!S8+'m11'!U8+'m11'!W8+'m11'!Y8+'m11'!AA8+'m11'!AC8+'m11'!AE8 -> 53 | HL8: =HK8*HD8 -> 7950 | HM8: ='m11'!T8+'m11'!V8+'m11'!X8+'m11'!Z8+'m11'!AB8+'m11'!AD8+'m11'!AF8 -> 0 | HO8: =HN8+HM8-HL8 -> -7950 | HQ8: ='m11'!AG8+'m11'!AI8+'m11'!AK8+'m11'!AM8+'m11'!AO8+'m11'!AQ8+'m11'!AS8 -> 57 | HR8: =HQ8*HD8 -> 8550 | HS8: ='m11'!AH8+'m11'!AJ8+'m11'!AL8+'m11'!AN8+'m11'!AP8+'m11'!AR8+'m11'!AT8 -> 1000 | HU8: =HT8+HS8-HR8 -> -7550 | HW8: ='m11'!AU8+'m11'!AW8+'m11'!AY8+'m11'!BA8+'m11'!BC8+'m11'!BE8+'m11'!BG8 -> 42 | HX8: =HW8*HD8 -> 6300 | HY8: ='m11'!AV8+'m11'!AX8+'m11'!AZ8+'m11'!BB8+'m11'!BD8+'m11'!BF8+'m11'!BH8 -> 0 | IA8: =HZ8+HY8-HX8 -> -6300 | IB8: =IFERROR(__xludf.DUMMYFUNCTION("""COMPUTED_VALUE"""),150.0) -> 150 | IC8: ='m11'!BI8+'m12'!C8+'m12'!E8+'m12'!G8+'m12'!I8+'m12'!K8+'m12'!M8 -> 32 | ID8: =IC8*IB8 -> 4800 | IE8: ='m11'!BJ8+'m12'!D8+'m12'!F8+'m12'!H8+'m12'!J8+'m12'!L8+'m12'!N8 -> 0 | IG8: =IF8+IE8-ID8 -> -4800 | II8: ='m12'!O8+'m12'!Q8+'m12'!S8+'m12'!U8+'m12'!W8+'m12'!Y8+'m12'!AA8 -> 40 | IJ8: =II8*IB8 -> 6000 | IK8: ='m12'!P8+'m12'!R8+'m12'!T8+'m12'!V8+'m12'!X8+'m12'!Z8+'m12'!AB8 -> 0 | IM8: =IL8+IK8-IJ8 -> -6000 | IO8: ='m12'!AC8+'m12'!AE8+'m12'!AG8+'m12'!AI8+'m12'!AK8+'m12'!AM8+'m12'!AO8 -> 40 | IP8: =IO8*IB8 -> 6000 | IQ8: ='m12'!AD8+'m12'!AF8+'m12'!AH8+'m12'!AJ8+'m12'!AL8+'m12'!AN8+'m12'!AP8 -> 1000 | IS8: =IR8+IQ8-IP8 -> -5000 | IU8: ='m12'!AQ8+'m12'!AS8+'m12'!AU8+'m12'!AW8+'m12'!AY8+'m12'!BA8+'m12'!BC8 -> 8 | IV8: =IU8*IB8 -> 1200 | IW8: ='m12'!AR8+'m12'!AT8+'m12'!AV8+'m12'!AX8+'m12'!AZ8+'m12'!BB8+'m12'!BD8 -> 0 | IY8: =IX8+IW8-IV8 -> -1200 | JA8: ='m12'!BE8+'m12'!BG8+'m12'!BI8+'m12'!BK8 -> 0 | JB8: =JA8*IB8 -> 0 | JC8: ='m12'!BF8+'m12'!BH8+'m12'!BJ8+'m12'!BL8 -> 0 | JE8: =JD8+JC8-JB8 -> 0
A9: =IFERROR(__xludf.DUMMYFUNCTION("""COMPUTED_VALUE"""),"Oksana Dynysenko") -> Oksana Dynysenko | B9: =IFERROR(__xludf.DUMMYFUNCTION("""COMPUTED_VALUE"""),130.0) -> 130 | C9: ='m3'!E9+'m3'!G9+'m3'!I9+'m3'!K9+'m3'!M9+'m3'!O9+'m3'!Q9 -> 77.5 | D9: ='m3'!A9*C9 -> 10075 | E9: ='m3'!F9+'m3'!H9+'m3'!J9+'m3'!L9+'m3'!N9+'m3'!P9+'m3'!R9 -> 0 | G9: =E9+F9-D9 -> -10075 | I9: ='m3'!S9+'m3'!U9+'m3'!W9+'m3'!Y9+'m3'!AA9+'m3'!AC9+'m3'!AE9 -> 72 | J9: ='m3'!A9*I9 -> 9360 | K9: ='m3'!T9+'m3'!V9+'m3'!X9+'m3'!Z9+'m3'!AB9+'m3'!AD9+'m3'!AF9 -> 0 | M9: =K9+L9-J9 -> -9360 | O9: ='m3'!AG9+'m3'!AI9+'m3'!AK9+'m3'!AM9+'m3'!AO9+'m3'!AQ9+'m3'!AS9 -> 52 | P9: ='m3'!A9*O9 -> 6760 | Q9: ='m3'!AH9+'m3'!AJ9+'m3'!AL9+'m3'!AN9+'m3'!AP9+'m3'!AR9+'m3'!AT9 -> 0 | S9: =Q9+R9-P9 -> -6760 | U9: ='m3'!AU9+'m3'!AW9+'m3'!AY9+'m3'!BA9+'m3'!BC9+'m3'!BE9+'m3'!BG9 -> 52 | V9: ='m3'!A9*U9 -> 6760 | W9: ='m3'!DG9+'m3'!DI9+'m3'!DK9+'m3'!DM9+'m3'!DO9+'m3'!DQ9+'m3'!DS9 -> 0 | Y9: =W9+X9-V9 -> -6760 | AA9: ='m3'!BI9+'m3'!BK9+'m4'!C9+'m4'!E9+'m4'!G9+'m4'!I9+'m4'!K9 -> 73.5 | AB9: =('m3'!BI9+'m3'!BK9)*'m3'!A9+('m4'!C9+'m4'!E9+'m4'!G9+'m4'!I9+'m4'!K9)*'m4'!A9 -> 9555 | AC9: ='m3'!BJ9+'m3'!BL9+'m4'!D9+'m4'!F9+'m4'!H9+'m4'!J9+'m4'!L9 -> 0 | AE9: =AC9+AD9-AB9 -> -9555 | AF9: =IFERROR(__xludf.DUMMYFUNCTION("""COMPUTED_VALUE"""),130.0) -> 130 | AG9: ='m4'!M9+'m4'!O9+'m4'!Q9+'m4'!S9+'m4'!U9+'m4'!W9+'m4'!Y9 -> 62 | AH9: ='m4'!A9*AG9 -> 8060 | AI9: ='m4'!N9+'m4'!P9+'m4'!R9+'m4'!T9+'m4'!V9+'m4'!X9+'m4'!Z9 -> 0 | AK9: =AI9+AJ9-AH9 -> -8060 | AM9: ='m4'!AA9+'m4'!AC9+'m4'!AE9+'m4'!AG9+'m4'!AI9+'m4'!AK9+'m4'!AM9 -> 72 | AN9: ='m4'!A9*AM9 -> 9360 | AO9: ='m4'!AB9+'m4'!AD9+'m4'!AF9+'m4'!AH9+'m4'!AJ9+'m4'!AL9+'m4'!AN9 -> 0 | AQ9: =AO9+AP9-AN9 -> -9360 | AS9: ='m4'!AO9+'m4'!AQ9+'m4'!AS9+'m4'!AU9+'m4'!AW9+'m4'!AY9+'m4'!BA9 -> 75 | AT9: ='m4'!A9*AS9 -> 9750 | AU9: ='m4'!AP9+'m4'!AR9+'m4'!AT9+'m4'!AV9+'m4'!AX9+'m4'!AZ9+'m4'!BB9 -> 0 | AW9: =AV9+AU9-AT9 -> -9750 | AY9: ='m4'!BC9+'m4'!BE9+'m4'!BG9+'m4'!BI9+'m5'!C9+'m5'!E9+'m5'!G9 -> 59 | AZ9: =('m4'!BC9+'m4'!BE9+'m4'!BG9+'m4'!BI9)*'m4'!A9+('m5'!C9+'m5'!E9+'m5'!G9)*'m5'!A9 -> 7670 | BA9: ='m4'!BD9+'m4'!BF9+'m4'!BH9+'m4'!BJ9+'m5'!D9+'m5'!F9+'m5'!H9 -> 0 | BC9: =BB9+BA9-AZ9 -> -7670 | BD9: =IFERROR(__xludf.DUMMYFUNCTION("""COMPUTED_VALUE"""),130.0) -> 130 | BE9: ='m5'!I9+'m5'!K9+'m5'!M9+'m5'!O9+'m5'!Q9+'m5'!S9+'m5'!U9 -> 57 | BF9: ='m5'!A9*BE9 -> 7410 | BG9: ='m5'!J9+'m5'!L9+'m5'!N9+'m5'!P9+'m5'!R9+'m5'!T9+'m5'!V9 -> 0 | BI9: =BH9+BG9-BF9 -> -7410 | BK9: ='m5'!W9+'m5'!Y9+'m5'!AA9+'m5'!AC9+'m5'!AE9+'m5'!AG9+'m5'!AI9 -> 56 | BL9: ='m5'!A9*BK9 -> 7280 | BM9: ='m5'!X9+'m5'!Z9+'m5'!AB9+'m5'!AD9+'m5'!AF9+'m5'!AH9+'m5'!AJ9 -> 0 | BO9: =BN9+BM9-BL9 -> -7280 | BQ9: ='m5'!AK9+'m5'!AM9+'m5'!AO9+'m5'!AQ9+'m5'!AS9+'m5'!AU9+'m5'!AW9 -> 54 | BR9: ='m5'!A9*BQ9 -> 7020 | BS9: ='m5'!AL9+'m5'!AN9+'m5'!AP9+'m5'!AR9+'m5'!AT9+'m5'!AV9+'m5'!AX9 -> 0 | BU9: =BT9+BS9-BR9 -> -7020 | BW9: ='m5'!AY9+'m5'!BA9+'m5'!BC9+'m5'!BE9+'m5'!BG9+'m5'!BI9+'m5'!BK9 -> 44 | BX9: ='m5'!A9*BW9 -> 5720 | BY9: ='m5'!AZ9+'m5'!BB9+'m5'!BD9+'m5'!BF9+'m5'!BH9+'m5'!BJ9+'m5'!BL9 -> 0 | CA9: =BZ9+BY9-BX9 -> -5720 | CB9: =IFERROR(__xludf.DUMMYFUNCTION("""COMPUTED_VALUE"""),130.0) -> 130 | CC9: ='m6'!C9+'m6'!E9+'m6'!G9+'m6'!I9+'m6'!K9+'m6'!M9+'m6'!O9 -> 64 | CD9: =CC9*CB9 -> 8320 | CE9: ='m6'!D9+'m6'!F9+'m6'!H9+'m6'!J9+'m6'!L9+'m6'!N9+'m6'!P9 -> 0 | CG9: =CF9+CE9-CD9 -> -8320 | CI9: ='m6'!Q9+'m6'!S9+'m6'!U9+'m6'!W9+'m6'!Y9+'m6'!AA9+'m6'!AC9 -> 62 | CJ9: =CI9*CB9 -> 8060 | CK9: ='m6'!R9+'m6'!T9+'m6'!V9+'m6'!X9+'m6'!Z9+'m6'!AB9+'m6'!AD9 -> 0 | CM9: =CL9+CK9-CJ9 -> -8060 | CO9: ='m6'!AE9+'m6'!AG9+'m6'!AI9+'m6'!AK9+'m6'!AM9+'m6'!AO9+'m6'!AQ9 -> 61 | CP9: =CO9*CB9 -> 7930 | CQ9: ='m6'!AF9+'m6'!AH9+'m6'!AJ9+'m6'!AL9+'m6'!AN9+'m6'!AP9+'m6'!AR9 -> 0 | CS9: =CR9+CQ9-CP9 -> -7930 | CU9: ='m6'!AS9+'m6'!AU9+'m6'!AW9+'m6'!AY9+'m6'!BA9+'m6'!BC9+'m6'!BE9 -> 73 | CV9: =CU9*CB9 -> 9490 | CW9: ='m6'!AT9+'m6'!AV9+'m6'!AX9+'m6'!AZ9+'m6'!BB9+'m6'!BD9+'m6'!BF9 -> 0 | CY9: =CX9+CW9-CV9 -> -9490 | DA9: ='m6'!BG9+'m6'!BI9+'m7'!C9+'m7'!E9+'m7'!G9+'m7'!I9+'m7'!K9 -> 15 | DB9: =('m6'!BG9+'m6'!BI9)*'m6'!A9+('m7'!C9+'m7'!E9+'m7'!G9+'m7'!I9+'m7'!K9)*'m7'!A9 -> 1950 | DC9: ='m6'!BH9+'m6'!BJ9+'m7'!D9+'m7'!F9+'m7'!H9+'m7'!J9+'m7'!L9 -> 0 | DE9: =DD9+DC9-DB9 -> -1950 | DF9: =IFERROR(__xludf.DUMMYFUNCTION("""COMPUTED_VALUE"""),130.0) -> 130 | DG9: ='m7'!M9+'m7'!O9+'m7'!Q9+'m7'!S9+'m7'!U9+'m7'!W9+'m7'!Y9 -> 0 | DH9: =DG9*DF9 -> 0 | DI9: ='m7'!N9+'m7'!P9+'m7'!R9+'m7'!T9+'m7'!V9+'m7'!X9+'m7'!Z9 -> 0 | DK9: =DJ9+DI9-DH9 -> 0 | DM9: ='m7'!AA9+'m7'!AC9+'m7'!AE9+'m7'!AG9+'m7'!AI9+'m7'!AK9+'m7'!AM9 -> 0 | DN9: =DM9*DF9 -> 0 | DO9: ='m7'!AB9+'m7'!AD9+'m7'!AF9+'m7'!AH9+'m7'!AJ9+'m7'!AL9+'m7'!AN9 -> 0 | DQ9: =DP9+DO9-DN9 -> 0 | DS9: ='m7'!AO9+'m7'!AQ9+'m7'!AS9+'m7'!AU9+'m7'!AW9+'m7'!AY9+'m7'!BA9 -> 0 | DT9: =DS9*DF9 -> 0 | DU9: ='m7'!AP9+'m7'!AR9+'m7'!AT9+'m7'!AV9+'m7'!AX9+'m7'!AZ9+'m7'!BB9 -> 0 | DW9: =DV9+DU9-DT9 -> 0 | DY9: ='m7'!BC9+'m7'!BE9+'m7'!BG9+'m7'!BI9+'m7'!BK9+'m8'!C9+'m8'!E9 -> 0 | DZ9: =('m7'!BC9+'m7'!BE9+'m7'!BG9+'m7'!BI9+'m7'!BK9)*DF9+('m8'!C9+'m8'!E9)*ED9 -> 0 | EA9: ='m7'!BD9+'m7'!BF9+'m7'!BH9+'m7'!BJ9+'m7'!BL9+'m8'!D9+'m8'!F9 -> 0 | EC9: =EB9+EA9-DZ9 -> 0 | ED9: =IFERROR(__xludf.DUMMYFUNCTION("""COMPUTED_VALUE"""),130.0) -> 130 | EE9: ='m8'!G9+'m8'!I9+'m8'!K9+'m8'!M9+'m8'!O9+'m8'!Q9+'m8'!S9 -> 0 | EF9: =EE9*ED9 -> 0 | EG9: ='m8'!H9+'m8'!J9+'m8'!L9+'m8'!N9+'m8'!P9+'m8'!R9+'m8'!T9 -> 0 | EI9: =EH9+EG9-EF9 -> 0 | EK9: ='m8'!U9+'m8'!W9+'m8'!Y9+'m8'!AA9+'m8'!AC9+'m8'!AE9+'m8'!AG9 -> 41 | EL9: =EK9*ED9 -> 5330 | EM9: ='m8'!V9+'m8'!X9+'m8'!Z9+'m8'!AB9+'m8'!AD9+'m8'!AF9+'m8'!AH9 -> 0 | EO9: =EN9+EM9-EL9 -> -5330 | EQ9: ='m8'!AI9+'m8'!AK9+'m8'!AM9+'m8'!AO9+'m8'!AQ9+'m8'!AS9+'m8'!AU9 -> 53 | ER9: =EQ9*ED9 -> 6890 | ES9: ='m8'!AJ9+'m8'!AL9+'m8'!AN9+'m8'!AP9+'m8'!AR9+'m8'!AT9+'m8'!AV9 -> 0 | EU9: =ET9+ES9-ER9 -> -6890 | EW9: ='m8'!AW9+'m8'!AY9+'m8'!BA9+'m8'!BC9+'m8'!BE9+'m8'!BG9+'m8'!BI9 -> 64 | EX9: =EW9*ED9 -> 8320 | EY9: ='m8'!AX9+'m8'!AZ9+'m8'!BB9+'m8'!BD9+'m8'!BF9+'m8'!BH9+'m8'!BJ9 -> 0 | FA9: =EZ9+EY9-EX9 -> -8320 | FC9: ='m8'!BK9+'m9'!C9+'m9'!E9+'m9'!G9+'m9'!I9+'m9'!K9+'m9'!M9 -> 84 | FD9: ='m8'!BK9*ED9+'m9'!C9*FH9+'m9'!E9*FH9+'m9'!G9*FH9+'m9'!I9*FH9+'m9'!K9*FH9+'m9'!M9*FH9 -> 10920 | FE9: ='m8'!BL9+'m9'!D9+'m9'!F9+'m9'!H9+'m9'!J9+'m9'!L9+'m9'!N9 -> 170 | FG9: =FF9+FE9-FD9 -> -10750 | FH9: =IFERROR(__xludf.DUMMYFUNCTION("""COMPUTED_VALUE"""),130.0) -> 130 | FI9: ='m9'!O9+'m9'!Q9+'m9'!S9+'m9'!U9+'m9'!W9+'m9'!Y9+'m9'!AA9 -> 53 | FJ9: =FI9*FH9 -> 6890 | FK9: ='m9'!P9+'m9'!R9+'m9'!T9+'m9'!V9+'m9'!X9+'m9'!Z9+'m9'!AB9 -> 200 | FM9: =FL9+FK9-FJ9 -> -6690 | FO9: ='m9'!AC9+'m9'!AE9+'m9'!AG9+'m9'!AI9+'m9'!AK9+'m9'!AM9+'m9'!AO9 -> 62 | FP9: =FO9*FH9 -> 8060 | FQ9: ='m9'!AD9+'m9'!AF9+'m9'!AH9+'m9'!AJ9+'m9'!AL9+'m9'!AN9+'m9'!AP9 -> 0 | FS9: =FR9+FQ9-FP9 -> -8060 | FU9: ='m9'!AQ9+'m9'!AS9+'m9'!AU9+'m9'!AW9+'m9'!AY9+'m9'!BA9+'m9'!BC9 -> 59 | FV9: =FU9*FH9 -> 7670 | FW9: ='m9'!AR9+'m9'!AT9+'m9'!AV9+'m9'!AX9+'m9'!AZ9+'m9'!BB9+'m9'!BD9 -> 0 | FY9: =FX9+FW9-FV9 -> -7670 | GA9: ='m9'!BE9+'m9'!BG9+'m9'!BI9+'m10'!C9+'m10'!E9+'m10'!G9+'m10'!I9 -> 52 | GB9: =GA9*FH9 -> 6760 | GC9: ='m9'!BF9+'m9'!BH9+'m9'!BJ9+'m10'!D9+'m10'!F9+'m10'!H9+'m10'!J9 -> 0 | GE9: =GD9+GC9-GB9 -> -6760 | GF9: =IFERROR(__xludf.DUMMYFUNCTION("""COMPUTED_VALUE"""),150.0) -> 150 | GG9: ='m10'!K9+'m10'!M9+'m10'!O9+'m10'!Q9+'m10'!S9+'m10'!U9+'m10'!W9 -> 40 | GH9: =GG9*GF9 -> 6000 | GI9: ='m10'!L9+'m10'!N9+'m10'!P9+'m10'!R9+'m10'!T9+'m10'!V9+'m10'!X9 -> 0 | GK9: =GJ9+GI9-GH9 -> -6000 | GM9: ='m10'!Y9+'m10'!AA9+'m10'!AC9+'m10'!AE9+'m10'!AG9+'m10'!AI9+'m10'!AK9 -> 62 | GN9: =GM9*GF9 -> 9300 | GO9: ='m10'!Z9+'m10'!AB9+'m10'!AD9+'m10'!AF9+'m10'!AH9+'m10'!AJ9+'m10'!AL9 -> 0 | GQ9: =GP9+GO9-GN9 -> -9300 | GS9: ='m10'!AM9+'m10'!AO9+'m10'!AQ9+'m10'!AS9+'m10'!AU9+'m10'!AW9+'m10'!AY9 -> 60.5 | GT9: =GS9*GF9 -> 9075 | GU9: ='m10'!AN9+'m10'!AP9+'m10'!AR9+'m10'!AT9+'m10'!AV9+'m10'!AX9+'m10'!AZ9 -> 0 | GW9: =GV9+GU9-GT9 -> -9075 | GY9: ='m10'!BA9+'m10'!BC9+'m10'!BE9+'m10'!BG9+'m10'!BI9+'m10'!BK9+'m11'!C9 -> 53 | GZ9: =GY9*GF9 -> 7950 | HA9: ='m10'!BB9+'m10'!BD9+'m10'!BF9+'m10'!BH9+'m10'!BJ9+'m10'!BL9+'m11'!D9 -> 0 | HC9: =HB9+HA9-GZ9 -> -7950 | HD9: =IFERROR(__xludf.DUMMYFUNCTION("""COMPUTED_VALUE"""),150.0) -> 150 | HE9: ='m11'!E9+'m11'!G9+'m11'!I9+'m11'!K9+'m11'!M9+'m11'!O9+'m11'!Q9 -> 11 | HF9: =HE9*HD9 -> 1650 | HG9: ='m11'!F9+'m11'!H9+'m11'!J9+'m11'!L9+'m11'!N9+'m11'!P9+'m11'!R9 -> 0 | HI9: =HH9+HG9-HF9 -> -1650 | HK9: ='m11'!S9+'m11'!U9+'m11'!W9+'m11'!Y9+'m11'!AA9+'m11'!AC9+'m11'!AE9 -> 0 | HL9: =HK9*HD9 -> 0 | HM9: ='m11'!T9+'m11'!V9+'m11'!X9+'m11'!Z9+'m11'!AB9+'m11'!AD9+'m11'!AF9 -> 0 | HO9: =HN9+HM9-HL9 -> 0 | HQ9: ='m11'!AG9+'m11'!AI9+'m11'!AK9+'m11'!AM9+'m11'!AO9+'m11'!AQ9+'m11'!AS9 -> 0 | HR9: =HQ9*HD9 -> 0 | HS9: ='m11'!AH9+'m11'!AJ9+'m11'!AL9+'m11'!AN9+'m11'!AP9+'m11'!AR9+'m11'!AT9 -> 0 | HU9: =HT9+HS9-HR9 -> 0 | HW9: ='m11'!AU9+'m11'!AW9+'m11'!AY9+'m11'!BA9+'m11'!BC9+'m11'!BE9+'m11'!BG9 -> 0 | HX9: =HW9*HD9 -> 0 | HY9: ='m11'!AV9+'m11'!AX9+'m11'!AZ9+'m11'!BB9+'m11'!BD9+'m11'!BF9+'m11'!BH9 -> 0 | IA9: =HZ9+HY9-HX9 -> 0 | IB9: =IFERROR(__xludf.DUMMYFUNCTION("""COMPUTED_VALUE"""),150.0) -> 150 | IC9: ='m11'!BI9+'m12'!C9+'m12'!E9+'m12'!G9+'m12'!I9+'m12'!K9+'m12'!M9 -> 10 | ID9: =IC9*IB9 -> 1500 | IE9: ='m11'!BJ9+'m12'!D9+'m12'!F9+'m12'!H9+'m12'!J9+'m12'!L9+'m12'!N9 -> 0 | IG9: =IF9+IE9-ID9 -> -1500 | II9: ='m12'!O9+'m12'!Q9+'m12'!S9+'m12'!U9+'m12'!W9+'m12'!Y9+'m12'!AA9 -> 70.5 | IJ9: =II9*IB9 -> 10575 | IK9: ='m12'!P9+'m12'!R9+'m12'!T9+'m12'!V9+'m12'!X9+'m12'!Z9+'m12'!AB9 -> 0 | IM9: =IL9+IK9-IJ9 -> -10575 | IO9: ='m12'!AC9+'m12'!AE9+'m12'!AG9+'m12'!AI9+'m12'!AK9+'m12'!AM9+'m12'!AO9 -> 40 | IP9: =IO9*IB9 -> 6000 | IQ9: ='m12'!AD9+'m12'!AF9+'m12'!AH9+'m12'!AJ9+'m12'!AL9+'m12'!AN9+'m12'!AP9 -> 0 | IS9: =IR9+IQ9-IP9 -> -6000 | IU9: ='m12'!AQ9+'m12'!AS9+'m12'!AU9+'m12'!AW9+'m12'!AY9+'m12'!BA9+'m12'!BC9 -> 48 | IV9: =IU9*IB9 -> 7200 | IW9: ='m12'!AR9+'m12'!AT9+'m12'!AV9+'m12'!AX9+'m12'!AZ9+'m12'!BB9+'m12'!BD9 -> 0 | IY9: =IX9+IW9-IV9 -> -7200 | JA9: ='m12'!BE9+'m12'!BG9+'m12'!BI9+'m12'!BK9 -> 47 | JB9: =JA9*IB9 -> 7050 | JC9: ='m12'!BF9+'m12'!BH9+'m12'!BJ9+'m12'!BL9 -> 0 | JE9: =JD9+JC9-JB9 -> -7050
