Workbook

Sheet DatabaseRestia
A1: Datum | B1: Platforma | C1: Stav | D1: Cena | E1: Sleva | F1: Kurýr | G1: Doručení | H1: Platba | I1: Vytvořeno | J1: Připraveno v | K1: Dokončeno v | L1: Přenos do dispecinku | M1: Zpoždění | N1: Přiřazení WoltDrivu | O1: Make Time
A2: 45531 | B2: wolt | C2: delivered | D2: 289 | E2: 0 | F2: Wolt Kurýr | G2: external-delivery | H2: online | I2: 2024-08-19T23:58:58.749+02:00 | J2: 2024-08-20T00:10:47.895+02:00 | K2: 2024-08-20T00:10:47.895+02:00 | M2: -3 | O2: 11.8191
A3: 45531 | B3: generic | C3: delivered | D3: 400 | E3: 47 | F3: David Sarkozi | G3: delivery | H3: online | I3: 2024-08-19T23:58:03.178+02:00 | J3: 2024-08-20T00:08:47.664+02:00 | K3: 2024-08-20T00:25:53.970+02:00 | L3: 2024-08-19T23:58:03.744+02:00 | M3: 0 | N3: 0.0094333333 | O3: 10.741433
A4: 45531 | B4: wolt | C4: delivered | D4: 464 | E4: 0 | F4: Wolt Kurýr | G4: external-delivery | H4: online | I4: 2024-08-19T23:56:29.395+02:00 | J4: 2024-08-20T00:06:31.879+02:00 | K4: 2024-08-20T00:06:31.879+02:00 | M4: -4 | O4: 10.0414
A5: 45531 | B5: bolt | C5: ready_pickup | D5: 329 | E5: 0 | F5: Rakib | G5: external-delivery | H5: online | I5: 2024-08-19T23:48:48.507+02:00 | J5: 2024-08-20T00:01:52.755+02:00 | K5: 2024-08-20T00:01:52.755+02:00 | M5: -1 | O5: 13.0708
A6: 45531 | B6: bolt | C6: ready_pickup | D6: 329 | E6: 0 | F6: Karel | G6: external-delivery | H6: online | I6: 2024-08-19T23:42:56.580+02:00 | J6: 2024-08-19T23:51:37.779+02:00 | K6: 2024-08-19T23:51:37.779+02:00 | M6: -6 | O6: 8.68665
A7: 45531 | B7: wolt | C7: delivered | D7: 321 | E7: 0 | F7: Wolt Kurýr | G7: external-delivery | H7: online | I7: 2024-08-19T23:33:49.070+02:00 | J7: 2024-08-19T23:47:07.826+02:00 | K7: 2024-08-19T23:47:07.826+02:00 | M7: -2 | O7: 13.3126
A8: 45531 | B8: bolt | C8: ready_pickup | D8: 321 | E8: 0 | F8: Rakib | G8: external-delivery | H8: online | I8: 2024-08-19T23:31:39.363+02:00 | J8: 2024-08-19T23:43:55.743+02:00 | K8: 2024-08-19T23:43:55.743+02:00 | M8: -2 | O8: 12.273
A9: 45531 | B9: generic | C9: delivered | D9: 299 | E9: 0 | F9: David Sarkozi | G9: delivery | H9: cash | I9: 2024-08-19T23:25:03.311+02:00 | J9: 2024-08-19T23:36:43.715+02:00 | K9: 2024-08-20T00:04:51.283+02:00 | L9: 2024-08-19T23:25:03.917+02:00 | M9: 10 | N9: 0.0101 | O9: 11.6734
A10: 45531 | B10: generic | C10: delivered | D10: 288 | E10: 0 | F10: David Sarkozi | G10: delivery | H10: cash | I10: 2024-08-19T23:23:03.045+02:00 | J10: 2024-08-19T23:33:28.787+02:00 | K10: 2024-08-19T23:50:59.104+02:00 | L10: 2024-08-19T23:23:03.542+02:00 | M10: -1 | N10: 0.0082833333 | O10: 10.429033
A11: 45531 | B11: wolt | C11: delivered | D11: 394 | E11: 0 | F11: Wolt Kurýr | G11: external-delivery | H11: online | I11: 2024-08-19T23:15:42.317+02:00 | J11: 2024-08-19T23:32:08.801+02:00 | K11: 2024-08-19T23:32:08.801+02:00 | M11: 1 | O11: 16.4414
A12: 45531 | B12: damejidlo | C12: ready_pickup | D12: 264 | E12: 0 | G12: external-delivery | H12: cash | I12: 2024-08-19T23:14:58.535+02:00 | J12: 2024-08-19T23:26:49.035+02:00 | K12: 2024-08-19T23:26:49.035+02:00 | M12: 1 | O12: 11.841667
A13: 45531 | B13: damejidlo | C13: ready_pickup | D13: 264 | E13: 0 | G13: external-delivery | H13: cash | I13: 2024-08-19T23:14:57.369+02:00 | J13: 2024-08-19T23:24:50.897+02:00 | K13: 2024-08-19T23:24:50.897+02:00 | M13: 0 | O13: 9.8921333
A14: 45531 | B14: generic | C14: delivered | D14: 309 | E14: 0 | F14: David Sarkozi | G14: delivery | H14: online | I14: 2024-08-19T23:08:04.305+02:00 | J14: 2024-08-19T23:19:10.937+02:00 | K14: 2024-08-19T23:35:16.750+02:00 | L14: 2024-08-19T23:08:04.797+02:00 | M14: 1 | N14: 0.0082 | O14: 11.110533
A15: 45531 | B15: generic | C15: delivered | D15: 250 | E15: 0 | F15: David Sarkozi | G15: delivery | H15: online | I15: 2024-08-19T22:39:03.895+02:00 | J15: 2024-08-19T22:50:36.631+02:00 | K15: 2024-08-19T23:02:14.652+02:00 | L15: 2024-08-19T22:39:04.429+02:00 | M15: -5 | N15: 0.0089 | O15: 11.5456
A16: 45531 | B16: damejidlo | C16: delivered | D16: 394 | E16: 0 | G16: external-delivery | H16: online | I16: 2024-08-19T22:37:31.754+02:00 | J16: 2024-08-19T22:50:32.912+02:00 | K16: 2024-08-19T22:50:32.912+02:00 | M16: 0 | O16: 13.0193
A17: 45531 | B17: damejidlo | C17: delivered | D17: 358 | E17: 0 | G17: external-delivery | H17: online | I17: 2024-08-19T22:31:31.556+02:00 | J17: 2024-08-19T22:42:33.025+02:00 | K17: 2024-08-19T22:42:33.025+02:00 | M17: 0 | O17: 11.024483
A18: 45531 | B18: bolt | C18: ready_pickup | D18: 329 | E18: 0 | F18: Tibor | G18: external-delivery | H18: online | I18: 2024-08-19T22:23:03.166+02:00 | J18: 2024-08-19T22:34:31.850+02:00 | K18: 2024-08-19T22:34:31.850+02:00 | M18: -3 | O18: 11.478067
A19: 45531 | B19: wolt | C19: delivered | D19: 264 | E19: 0 | F19: Wolt Kurýr | G19: external-delivery | H19: online | I19: 2024-08-19T22:19:15.867+02:00 | J19: 2024-08-19T22:29:46.834+02:00 | K19: 2024-08-19T22:29:46.834+02:00 | M19: -4 | O19: 10.516117
A20: 45531 | B20: generic | C20: delivered | D20: 267 | E20: 67 | G20: pickup | H20: online | I20: 2024-08-19T21:48:04.353+02:00 | J20: 2024-08-19T21:56:38.613+02:00 | K20: 2024-08-19T21:56:38.613+02:00 | M20: -8 | O20: 8.571
A21: 45531 | B21: generic | C21: canceled | D21: 267 | E21: 67 | G21: pickup | H21: card | I21: 2024-08-19T21:47:02.850+02:00 | M21: 0
A22: 45531 | B22: damejidlo | C22: ready_pickup | D22: 394 | E22: 0 | G22: external-delivery | H22: cash | I22: 2024-08-19T21:30:32.106+02:00 | J22: 2024-08-19T21:40:49.932+02:00 | K22: 2024-08-19T21:40:49.932+02:00 | M22: -2 | O22: 10.2971
A23: 45531 | B23: wolt | C23: delivered | D23: 264 | E23: 0 | F23: Wolt Kurýr | G23: external-delivery | H23: online | I23: 2024-08-19T21:28:30.881+02:00 | J23: 2024-08-19T21:36:34.908+02:00 | K23: 2024-08-19T21:36:34.908+02:00 | M23: -6 | O23: 8.0671167
A24: 45531 | B24: damejidlo | C24: ready_pickup | D24: 368 | E24: 0 | G24: external-delivery | H24: online | I24: 2024-08-19T21:22:33.441+02:00 | J24: 2024-08-19T21:32:09.961+02:00 | K24: 2024-08-19T21:32:09.961+02:00 | M24: -2 | O24: 9.6086667
A25: 45531 | B25: generic | C25: delivered | D25: 426 | E25: 0 | F25: David Sarkozi | G25: delivery | H25: cash | I25: 2024-08-19T21:18:02.700+02:00 | J25: 2024-08-19T21:29:30.638+02:00 | K25: 2024-08-19T22:03:06.023+02:00 | L25: 2024-08-19T21:18:03.357+02:00 | M25: 15 | N25: 0.01095 | O25: 11.465633
A26: 45531 | B26: generic | C26: delivered | D26: 329 | E26: 0 | F26: David Sarkozi | G26: delivery | H26: cash | I26: 2024-08-19T21:13:03.392+02:00 | J26: 2024-08-19T21:22:03.603+02:00 | K26: 2024-08-19T21:42:09.652+02:00 | L26: 2024-08-19T21:13:04.041+02:00 | M26: 0 | N26: 0.010816667 | O26: 9.0035167
A27: 45531 | B27: manual | C27: delivered | D27: 90 | E27: 0 | G27: pickup | H27: cash | I27: 2024-08-19T21:11:22.100+02:00 | J27: 2024-08-19T21:11:59.916+02:00 | K27: 2024-08-19T21:11:59.916+02:00 | M27: -4 | O27: 0.63026667
A28: 45531 | B28: generic | C28: delivered | D28: 374 | E28: 0 | F28: David Sarkozi | G28: delivery | H28: online | I28: 2024-08-19T21:09:04.030+02:00 | J28: 2024-08-19T21:19:12.666+02:00 | K28: 2024-08-19T21:33:57.270+02:00 | L28: 2024-08-19T21:09:04.521+02:00 | M28: -3 | N28: 0.0081833333 | O28: 10.143933
A29: 45531 | B29: damejidlo | C29: ready_pickup | D29: 264 | E29: 0 | G29: external-delivery | H29: online | I29: 2024-08-19T21:05:33.242+02:00 | J29: 2024-08-19T21:14:33.054+02:00 | K29: 2024-08-19T21:14:33.054+02:00 | M29: -1 | O29: 8.9968667
A30: 45531 | B30: damejidlo | C30: ready_pickup | D30: 294 | E30: 0 | G30: external-delivery | H30: online | I30: 2024-08-19T20:59:31.975+02:00 | J30: 2024-08-19T21:08:47.014+02:00 | K30: 2024-08-19T21:08:47.014+02:00 | M30: -2 | O30: 9.25065
A31: 45531 | B31: bolt | C31: ready_pickup | D31: 368 | E31: 0 | F31: Shehryar | G31: external-delivery | H31: online | I31: 2024-08-19T20:54:46.747+02:00 | J31: 2024-08-19T21:06:05.751+02:00 | K31: 2024-08-19T21:06:05.751+02:00 | M31: -3 | O31: 11.316733
A32: 45531 | B32: damejidlo | C32: ready_pickup | D32: 264 | E32: 0 | G32: external-delivery | H32: online | I32: 2024-08-19T20:54:33.919+02:00 | J32: 2024-08-19T21:05:41.884+02:00 | K32: 2024-08-19T21:05:41.884+02:00 | M32: 0 | O32: 11.13275
A33: 45531 | B33: wolt | C33: delivered | D33: 258 | E33: 0 | F33: Wolt Kurýr | G33: external-delivery | H33: online | I33: 2024-08-19T20:51:13.748+02:00 | J33: 2024-08-19T20:52:07.867+02:00 | K33: 2024-08-19T20:52:07.867+02:00 | M33: -14 | O33: 0.90198333
A34: 45531 | B34: manual | C34: delivered | D34: 309 | E34: 0 | G34: pickup | H34: cash | I34: 2024-08-19T20:43:28.341+02:00 | J34: 2024-08-19T20:57:27.636+02:00 | K34: 2024-08-19T20:57:27.636+02:00 | M34: 8 | O34: 13.98825
A35: 45531 | B35: manual | C35: delivered | D35: 209 | E35: 0 | G35: pickup | H35: cash | I35: 2024-08-19T20:42:30.337+02:00 | J35: 2024-08-19T20:54:22.604+02:00 | K35: 2024-08-19T20:54:22.604+02:00 | M35: 6 | O35: 11.871117
A36: 45531 | B36: generic | C36: delivered | D36: 199 | E36: 50 | G36: pickup | H36: card | I36: 2024-08-19T20:38:02.760+02:00 | J36: 2024-08-19T20:53:17.576+02:00 | K36: 2024-08-19T20:53:17.576+02:00 | M36: -4 | O36: 15.246933
A37: 45531 | B37: generic | C37: delivered | D37: 279 | E37: 70 | G37: pickup | H37: cash | I37: 2024-08-19T20:37:03.327+02:00 | J37: 2024-08-19T20:52:01.586+02:00 | K37: 2024-08-19T20:52:01.586+02:00 | M37: -4 | O37: 14.970983
A38: 45531 | B38: manual | C38: canceled | D38: 249 | E38: 0 | G38: pickup | H38: cash | I38: 2024-08-19T20:26:05.863+02:00 | J38: 2024-08-19T20:38:57.692+02:00 | K38: 2024-08-19T20:38:57.692+02:00 | M38: 7 | O38: 12.863817
A39: 45531 | B39: generic | C39: delivered | D39: 247 | E39: 62 | G39: pickup | H39: cash | I39: 2024-08-19T20:25:02.914+02:00 | J39: 2024-08-19T20:37:44.580+02:00 | K39: 2024-08-19T20:37:44.580+02:00 | M39: -6 | O39: 12.694433
A40: 45531 | B40: wolt | C40: delivered | D40: 313 | E40: 0 | F40: Wolt Kurýr | G40: external-delivery | H40: online | I40: 2024-08-19T20:24:34.143+02:00 | J40: 2024-08-19T20:44:20.765+02:00 | K40: 2024-08-19T20:44:20.765+02:00 | M40: 4 | O40: 19.777033
...

Sheet Report
B1: Prosek | C1: Datum | D1: 46100 | F1: COL | I1: Tržba | L1: Online Platby
F2: =IFERROR(__xludf.DUMMYFUNCTION("IF(I2>0, 100 / (I2 / 112 * 100 / ((SUM(A12:A21, A25:A31) + (M17 + I32) + IFERROR(SUM(FILTER(HR!W5:W48, LEN(HR!A5:A48) > 0)), 0)) / 100)), ""Zadej tržbu"") "),"Zadej tržbu") -> Zadej tržbu | I2: =SUM(RestiaCSV!C:C) - SUMIFS(RestiaCSV!C:C, RestiaCSV!B:B, "canceled") -> 0 | L2: Wolt | M2: =SUMIFS(RestiaCSV!C:C, RestiaCSV!A:A, Report!L2, RestiaCSV!B:B, "<>canceled") -> 0
B3: =CHOOSE(WEEKDAY(D1), "Neděle", "Pondělí", "Úterý", "Středa", "Čtvrtek", "Pátek", "Sobota") -> Čtvrtek | L3: Bolt | M3: =SUMIFS(RestiaCSV!C:C, RestiaCSV!A:A, Report!L3, RestiaCSV!B:B, "<>canceled") -> 0
L4: Dáme jídlo | M4: =SUMIFS(RestiaCSV!C:C, RestiaCSV!A:A, "damejidlo", RestiaCSV!G:G, "online", RestiaCSV!B:B, "<>canceled") -> 0
B5: Napiš vzkaz ⬇️ 📖 Deník 📖 ⬇️ Včerejší vzkaz | L5: Web | M5: =SUMIFS(RestiaCSV!C:C, RestiaCSV!A:A, "generic", RestiaCSV!G:G, "online", RestiaCSV!B:B, "<>canceled") -> 0
L6: Wolt drive cash | M6: =SUMIFS(RestiaCSV!C:C, RestiaCSV!E:E, "wolt kurýr", RestiaCSV!A:A, "<>wolt", RestiaCSV!G:G, "cash", RestiaCSV!B:B, "<>canceled") -> 0
L7: DJ Cash | M7: =SUMIFS(RestiaCSV!C:C, RestiaCSV!A:A, "damejidlo", RestiaCSV!G:G, "cash", RestiaCSV!B:B, "<>canceled") -> 0
L8: Hotovost
L9: Terminál
B10: Instor | G10: Otevíral | J10: Pokladna | L10: Stravenky
B11: Jméno | C11: Začátek směny | D11: Konec směny | E11: pauza | F11: Počet hodin | J11: =M2+M3+M4+M5+M6+M13+M14+M15+M16+M17+M9+M10+M11-I2 -> 0 | L11: Hotovost
A12: {=IF(ISBLANK(B12), 0, IF(ISNUMBER(MATCH(B12, HR!A:A, 0)), 0, IF(ISNUMBER(MATCH(B12, HR!B:B, 0)), INDEX(HR!V:V, MATCH(B12, HR!B:B, 0)) * (F12 * 24), 0)))} -> 0 | F12: =IF(OR(ISBLANK(B12), ISBLANK(D12), D12=0), "0:00", TEXT((IF(AND(TIMEVALUE(IF(ISBLANK(D12), "00:00", D12))>=TIMEVALUE("00:00"), TIMEVALUE(IF(ISBLANK(D12), "00:00", D12))<=TIMEVALUE("06:00")), TIMEVALUE(IF(ISBLANK(D12), "00:00", D12))+1, TIMEVALUE(IF(ISBLANK(D12), "00:00", D12))) - TIMEVALUE(IF(ISBLANK(C12), "00:00", C12)) - TIMEVALUE(IF(ISBLANK(E12), "00:00", E12))), "hh:mm")) -> 0:00 | L12: Výdaje
A13: {=IF(ISBLANK(B13), 0, IF(ISNUMBER(MATCH(B13, HR!A:A, 0)), 0, IF(ISNUMBER(MATCH(B13, HR!B:B, 0)), INDEX(HR!V:V, MATCH(B13, HR!B:B, 0)) * (F13 * 24), 0)))} -> 0 | F13: =IF(OR(ISBLANK(B13), ISBLANK(D13), D13=0), "0:00", TEXT((IF(AND(TIMEVALUE(IF(ISBLANK(D13), "00:00", D13))>=TIMEVALUE("00:00"), TIMEVALUE(IF(ISBLANK(D13), "00:00", D13))<=TIMEVALUE("06:00")), TIMEVALUE(IF(ISBLANK(D13), "00:00", D13))+1, TIMEVALUE(IF(ISBLANK(D13), "00:00", D13))) - TIMEVALUE(IF(ISBLANK(C13), "00:00", C13)) - TIMEVALUE(IF(ISBLANK(E13), "00:00", E13))), "hh:mm")) -> 0:00 | L13: Benzín
A14: {=IF(ISBLANK(B14), 0, IF(ISNUMBER(MATCH(B14, HR!A:A, 0)), 0, IF(ISNUMBER(MATCH(B14, HR!B:B, 0)), INDEX(HR!V:V, MATCH(B14, HR!B:B, 0)) * (F14 * 24), 0)))} -> 0 | F14: =IF(OR(ISBLANK(B14), ISBLANK(D14), D14=0), "0:00", TEXT((IF(AND(TIMEVALUE(IF(ISBLANK(D14), "00:00", D14))>=TIMEVALUE("00:00"), TIMEVALUE(IF(ISBLANK(D14), "00:00", D14))<=TIMEVALUE("06:00")), TIMEVALUE(IF(ISBLANK(D14), "00:00", D14))+1, TIMEVALUE(IF(ISBLANK(D14), "00:00", D14))) - TIMEVALUE(IF(ISBLANK(C14), "00:00", C14)) - TIMEVALUE(IF(ISBLANK(E14), "00:00", E14))), "hh:mm")) -> 0:00 | L14: Auta
A15: {=IF(ISBLANK(B15), 0, IF(ISNUMBER(MATCH(B15, HR!A:A, 0)), 0, IF(ISNUMBER(MATCH(B15, HR!B:B, 0)), INDEX(HR!V:V, MATCH(B15, HR!B:B, 0)) * (F15 * 24), 0)))} -> 0 | F15: =IF(OR(ISBLANK(B15), ISBLANK(D15), D15=0), "0:00", TEXT((IF(AND(TIMEVALUE(IF(ISBLANK(D15), "00:00", D15))>=TIMEVALUE("00:00"), TIMEVALUE(IF(ISBLANK(D15), "00:00", D15))<=TIMEVALUE("06:00")), TIMEVALUE(IF(ISBLANK(D15), "00:00", D15))+1, TIMEVALUE(IF(ISBLANK(D15), "00:00", D15))) - TIMEVALUE(IF(ISBLANK(C15), "00:00", C15)) - TIMEVALUE(IF(ISBLANK(E15), "00:00", E15))), "hh:mm")) -> 0:00 | L15: Suroviny
A16: {=IF(ISBLANK(B16), 0, IF(ISNUMBER(MATCH(B16, HR!A:A, 0)), 0, IF(ISNUMBER(MATCH(B16, HR!B:B, 0)), INDEX(HR!V:V, MATCH(B16, HR!B:B, 0)) * (F16 * 24), 0)))} -> 0 | F16: =IF(OR(ISBLANK(B16), ISBLANK(D16), D16=0), "0:00", TEXT((IF(AND(TIMEVALUE(IF(ISBLANK(D16), "00:00", D16))>=TIMEVALUE("00:00"), TIMEVALUE(IF(ISBLANK(D16), "00:00", D16))<=TIMEVALUE("06:00")), TIMEVALUE(IF(ISBLANK(D16), "00:00", D16))+1, TIMEVALUE(IF(ISBLANK(D16), "00:00", D16))) - TIMEVALUE(IF(ISBLANK(C16), "00:00", C16)) - TIMEVALUE(IF(ISBLANK(E16), "00:00", E16))), "hh:mm")) -> 0:00 | L16: Ostatní
A17: {=IF(ISBLANK(B17), 0, IF(ISNUMBER(MATCH(B17, HR!A:A, 0)), 0, IF(ISNUMBER(MATCH(B17, HR!B:B, 0)), INDEX(HR!V:V, MATCH(B17, HR!B:B, 0)) * (F17 * 24), 0)))} -> 0 | F17: =IF(OR(ISBLANK(B17), ISBLANK(D17), D17=0), "0:00", TEXT((IF(AND(TIMEVALUE(IF(ISBLANK(D17), "00:00", D17))>=TIMEVALUE("00:00"), TIMEVALUE(IF(ISBLANK(D17), "00:00", D17))<=TIMEVALUE("06:00")), TIMEVALUE(IF(ISBLANK(D17), "00:00", D17))+1, TIMEVALUE(IF(ISBLANK(D17), "00:00", D17))) - TIMEVALUE(IF(ISBLANK(C17), "00:00", C17)) - TIMEVALUE(IF(ISBLANK(E17), "00:00", E17))), "hh:mm")) -> 0:00 | L17: PHM - soukromé | M17: =sum(I25:I31) -> 0
A18: {=IF(ISBLANK(B18), 0, IF(ISNUMBER(MATCH(B18, HR!A:A, 0)), 0, IF(ISNUMBER(MATCH(B18, HR!B:B, 0)), INDEX(HR!V:V, MATCH(B18, HR!B:B, 0)) * (F18 * 24), 0)))} -> 0 | F18: =IF(OR(ISBLANK(B18), ISBLANK(D18), D18=0), "0:00", TEXT((IF(AND(TIMEVALUE(IF(ISBLANK(D18), "00:00", D18))>=TIMEVALUE("00:00"), TIMEVALUE(IF(ISBLANK(D18), "00:00", D18))<=TIMEVALUE("06:00")), TIMEVALUE(IF(ISBLANK(D18), "00:00", D18))+1, TIMEVALUE(IF(ISBLANK(D18), "00:00", D18))) - TIMEVALUE(IF(ISBLANK(C18), "00:00", C18)) - TIMEVALUE(IF(ISBLANK(E18), "00:00", E18))), "hh:mm")) -> 0:00 | G18: Zavíral
A19: {=IF(ISBLANK(B19), 0, IF(ISNUMBER(MATCH(B19, HR!A:A, 0)), 0, IF(ISNUMBER(MATCH(B19, HR!B:B, 0)), INDEX(HR!V:V, MATCH(B19, HR!B:B, 0)) * (F19 * 24), 0)))} -> 0 | F19: =IF(OR(ISBLANK(B19), ISBLANK(D19), D19=0), "0:00", TEXT((IF(AND(TIMEVALUE(IF(ISBLANK(D19), "00:00", D19))>=TIMEVALUE("00:00"), TIMEVALUE(IF(ISBLANK(D19), "00:00", D19))<=TIMEVALUE("06:00")), TIMEVALUE(IF(ISBLANK(D19), "00:00", D19))+1, TIMEVALUE(IF(ISBLANK(D19), "00:00", D19))) - TIMEVALUE(IF(ISBLANK(C19), "00:00", C19)) - TIMEVALUE(IF(ISBLANK(E19), "00:00", E19))), "hh:mm")) -> 0:00
A20: {=IF(ISBLANK(B20), 0, IF(ISNUMBER(MATCH(B20, HR!A:A, 0)), 0, IF(ISNUMBER(MATCH(B20, HR!B:B, 0)), INDEX(HR!V:V, MATCH(B20, HR!B:B, 0)) * (F20 * 24), 0)))} -> 0 | F20: =IF(OR(ISBLANK(B20), ISBLANK(D20), D20=0), "0:00", TEXT((IF(AND(TIMEVALUE(IF(ISBLANK(D20), "00:00", D20))>=TIMEVALUE("00:00"), TIMEVALUE(IF(ISBLANK(D20), "00:00", D20))<=TIMEVALUE("06:00")), TIMEVALUE(IF(ISBLANK(D20), "00:00", D20))+1, TIMEVALUE(IF(ISBLANK(D20), "00:00", D20))) - TIMEVALUE(IF(ISBLANK(C20), "00:00", C20)) - TIMEVALUE(IF(ISBLANK(E20), "00:00", E20))), "hh:mm")) -> 0:00
A21: {=IF(ISBLANK(B21), 0, IF(ISNUMBER(MATCH(B21, HR!A:A, 0)), 0, IF(ISNUMBER(MATCH(B21, HR!B:B, 0)), INDEX(HR!V:V, MATCH(B21, HR!B:B, 0)) * (F21 * 24), 0)))} -> 0 | F21: =IF(OR(ISBLANK(B21), ISBLANK(D21), D21=0), "0:00", TEXT((IF(AND(TIMEVALUE(IF(ISBLANK(D21), "00:00", D21))>=TIMEVALUE("00:00"), TIMEVALUE(IF(ISBLANK(D21), "00:00", D21))<=TIMEVALUE("06:00")), TIMEVALUE(IF(ISBLANK(D21), "00:00", D21))+1, TIMEVALUE(IF(ISBLANK(D21), "00:00", D21))) - TIMEVALUE(IF(ISBLANK(C21), "00:00", C21)) - TIMEVALUE(IF(ISBLANK(E21), "00:00", E21))), "hh:mm")) -> 0:00
J22: Zrušené obj. ks | K22: Zrušené obj. $ | L22: Počet zpožděných našich rozvozů +5 min | M22: Průměrný make Time
B23: Kurýr | J23: =COUNTIF(RestiaCSV!B:B, "canceled") -> 0 | K23: =SUMIF(RestiaCSV!B:B, "canceled", RestiaCSV!C:C) -> 0 | L23: =COUNTIFS(RestiaCSV!L:L, ">5", RestiaCSV!F:F, "delivery") -> 0 | M23: =INT(AVERAGEIFS(RestiaCSV!N:N, RestiaCSV!N:N, ">=5", RestiaCSV!N:N, "<=30")) & " min " & TEXT(MOD(AVERAGEIFS(RestiaCSV!N:N, RestiaCSV!N:N, ">=5", RestiaCSV!N:N, "<=30") * 60, 60), "00") & " s" -> #DIV/0!
B24: Jméno | C24: Začátek směny | D24: Konec směny | E24: pauza | F24: Počet hodin | G24: Počet rozvozů | H24: Vlastní vůz | I24: Vyplatit PHM | J24: počet výdajových dokadů | K24: Počet nezrušených celkem | L24: Počet našich rozvozů | M24: Počet pozdě přiřazeným WoltDrive 5+
A25: {=IF(ISBLANK(B25), 0, IF(ISNUMBER(MATCH(B25, HR!A:A, 0)), 0, IF(ISNUMBER(MATCH(B25, HR!B:B, 0)), INDEX(HR!V:V, MATCH(B25, HR!B:B, 0)) * (F25 * 24), 0)))} -> 0 | F25: =IF(OR(ISBLANK(B25), ISBLANK(D25), D25=0), "0:00", TEXT((IF(AND(TIMEVALUE(IF(ISBLANK(D25), "00:00", D25))>=TIMEVALUE("00:00"), TIMEVALUE(IF(ISBLANK(D25), "00:00", D25))<=TIMEVALUE("06:00")), TIMEVALUE(IF(ISBLANK(D25), "00:00", D25))+1, TIMEVALUE(IF(ISBLANK(D25), "00:00", D25))) - TIMEVALUE(IF(ISBLANK(C25), "00:00", C25)) - TIMEVALUE(IF(ISBLANK(E25), "00:00", E25))), "hh:mm")) -> 0:00 | G25: =COUNTIF(RestiaCSV!E:E, B25) -> 0 | H25: TRUE | I25: =IF(H25,G25*40, 0) -> 0
A26: {=IF(ISBLANK(B26), 0, IF(ISNUMBER(MATCH(B26, HR!A:A, 0)), 0, IF(ISNUMBER(MATCH(B26, HR!B:B, 0)), INDEX(HR!V:V, MATCH(B26, HR!B:B, 0)) * (F26 * 24), 0)))} -> 0 | F26: =IF(OR(ISBLANK(B26), ISBLANK(D26), D26=0), "0:00", TEXT((IF(AND(TIMEVALUE(IF(ISBLANK(D26), "00:00", D26))>=TIMEVALUE("00:00"), TIMEVALUE(IF(ISBLANK(D26), "00:00", D26))<=TIMEVALUE("06:00")), TIMEVALUE(IF(ISBLANK(D26), "00:00", D26))+1, TIMEVALUE(IF(ISBLANK(D26), "00:00", D26))) - TIMEVALUE(IF(ISBLANK(C26), "00:00", C26)) - TIMEVALUE(IF(ISBLANK(E26), "00:00", E26))), "hh:mm")) -> 0:00 | G26: =COUNTIF(RestiaCSV!E:E, B26) -> 0 | H26: TRUE | I26: =IF(H26,G26*40, 0) -> 0 | J26: =COUNTIF(I25:I31, ">0") -> 0 | K26: =IFERROR(__xludf.DUMMYFUNCTION("COUNTA(FILTER(RestiaCSV!B2:B32, RestiaCSV!B2:B32 <> ""canceled""))"),0.0) -> 0 | L26: =COUNTIF(RestiaCSV!F1:F32, "delivery") -> 0 | M26: =COUNTIFS(RestiaCSV!M:M, ">5",RestiaCSV!A:A, "<>wolt") -> 0
A27: {=IF(ISBLANK(B27), 0, IF(ISNUMBER(MATCH(B27, HR!A:A, 0)), 0, IF(ISNUMBER(MATCH(B27, HR!B:B, 0)), INDEX(HR!V:V, MATCH(B27, HR!B:B, 0)) * (F27 * 24), 0)))} -> 0 | F27: =IF(OR(ISBLANK(B27), ISBLANK(D27), D27=0), "0:00", TEXT((IF(AND(TIMEVALUE(IF(ISBLANK(D27), "00:00", D27))>=TIMEVALUE("00:00"), TIMEVALUE(IF(ISBLANK(D27), "00:00", D27))<=TIMEVALUE("06:00")), TIMEVALUE(IF(ISBLANK(D27), "00:00", D27))+1, TIMEVALUE(IF(ISBLANK(D27), "00:00", D27))) - TIMEVALUE(IF(ISBLANK(C27), "00:00", C27)) - TIMEVALUE(IF(ISBLANK(E27), "00:00", E27))), "hh:mm")) -> 0:00 | G27: =COUNTIF(RestiaCSV!E:E, B27) -> 0 | H27: TRUE | I27: =IF(H27,G27*40, 0) -> 0 | J27: Woltrdive zpožděný kvůli našemu pozdnímu přiřazení | L27: % zpožděných našich rozvozů +5 min | M27: Počet zpožděných Woltdrivem
A28: {=IF(ISBLANK(B28), 0, IF(ISNUMBER(MATCH(B28, HR!A:A, 0)), 0, IF(ISNUMBER(MATCH(B28, HR!B:B, 0)), INDEX(HR!V:V, MATCH(B28, HR!B:B, 0)) * (F28 * 24), 0)))} -> 0 | F28: =IF(OR(ISBLANK(B28), ISBLANK(D28), D28=0), "0:00", TEXT((IF(AND(TIMEVALUE(IF(ISBLANK(D28), "00:00", D28))>=TIMEVALUE("00:00"), TIMEVALUE(IF(ISBLANK(D28), "00:00", D28))<=TIMEVALUE("06:00")), TIMEVALUE(IF(ISBLANK(D28), "00:00", D28))+1, TIMEVALUE(IF(ISBLANK(D28), "00:00", D28))) - TIMEVALUE(IF(ISBLANK(C28), "00:00", C28)) - TIMEVALUE(IF(ISBLANK(E28), "00:00", E28))), "hh:mm")) -> 0:00 | G28: =COUNTIF(RestiaCSV!E:E, B28) -> 0 | H28: FALSE | I28: =IF(H28,G28*40, 0) -> 0
A29: {=IF(ISBLANK(B29), 0, IF(ISNUMBER(MATCH(B29, HR!A:A, 0)), 0, IF(ISNUMBER(MATCH(B29, HR!B:B, 0)), INDEX(HR!V:V, MATCH(B29, HR!B:B, 0)) * (F29 * 24), 0)))} -> 0 | F29: =IF(OR(ISBLANK(B29), ISBLANK(D29), D29=0), "0:00", TEXT((IF(AND(TIMEVALUE(IF(ISBLANK(D29), "00:00", D29))>=TIMEVALUE("00:00"), TIMEVALUE(IF(ISBLANK(D29), "00:00", D29))<=TIMEVALUE("06:00")), TIMEVALUE(IF(ISBLANK(D29), "00:00", D29))+1, TIMEVALUE(IF(ISBLANK(D29), "00:00", D29))) - TIMEVALUE(IF(ISBLANK(C29), "00:00", C29)) - TIMEVALUE(IF(ISBLANK(E29), "00:00", E29))), "hh:mm")) -> 0:00 | G29: =COUNTIF(RestiaCSV!E:E, B29) -> 0 | H29: FALSE | I29: =IF(H29,G29*40, 0) -> 0 | J29: =COUNTIFS(RestiaCSV!M:M, ">5", RestiaCSV!L:L, ">5") -> 0 | L29: =L23/L26 -> #DIV/0! | M29: =COUNTIFS(RestiaCSV!L:L, ">5", RestiaCSV!F:F, "delivery", RestiaCSV!E:E, "Wolt Kurýr") -> 0
A30: {=IF(ISBLANK(B30), 0, IF(ISNUMBER(MATCH(B30, HR!A:A, 0)), 0, IF(ISNUMBER(MATCH(B30, HR!B:B, 0)), INDEX(HR!V:V, MATCH(B30, HR!B:B, 0)) * (F30 * 24), 0)))} -> 0 | F30: =IF(OR(ISBLANK(B30), ISBLANK(D30), D30=0), "0:00", TEXT((IF(AND(TIMEVALUE(IF(ISBLANK(D30), "00:00", D30))>=TIMEVALUE("00:00"), TIMEVALUE(IF(ISBLANK(D30), "00:00", D30))<=TIMEVALUE("06:00")), TIMEVALUE(IF(ISBLANK(D30), "00:00", D30))+1, TIMEVALUE(IF(ISBLANK(D30), "00:00", D30))) - TIMEVALUE(IF(ISBLANK(C30), "00:00", C30)) - TIMEVALUE(IF(ISBLANK(E30), "00:00", E30))), "hh:mm")) -> 0:00 | G30: =COUNTIF(RestiaCSV!E:E, B30) -> 0 | H30: FALSE | I30: =IF(H30,G30*40, 0) -> 0 | L30: % doručených včas | M30: % zpožděných Woltdrivem
A31: {=IF(ISBLANK(B31), 0, IF(ISNUMBER(MATCH(B31, HR!A:A, 0)), 0, IF(ISNUMBER(MATCH(B31, HR!B:B, 0)), INDEX(HR!V:V, MATCH(B31, HR!B:B, 0)) * (F31 * 24), 0)))} -> 0 | F31: =IF(OR(ISBLANK(B31), ISBLANK(D31), D31=0), "0:00", TEXT((IF(AND(TIMEVALUE(IF(ISBLANK(D31), "00:00", D31))>=TIMEVALUE("00:00"), TIMEVALUE(IF(ISBLANK(D31), "00:00", D31))<=TIMEVALUE("06:00")), TIMEVALUE(IF(ISBLANK(D31), "00:00", D31))+1, TIMEVALUE(IF(ISBLANK(D31), "00:00", D31))) - TIMEVALUE(IF(ISBLANK(C31), "00:00", C31)) - TIMEVALUE(IF(ISBLANK(E31), "00:00", E31))), "hh:mm")) -> 0:00 | G31: =COUNTIF(RestiaCSV!E:E, B31) -> 0 | H31: FALSE | I31: =IF(H31,G31*40, 0) -> 0
B32: Wolt Kurýr | C32: Wolt drive | G32: =COUNTIFS(RestiaCSV!E:E, "wolt kurýr", RestiaCSV!A:A, "<>wolt") -> 0 | H32: TRUE | I32: =G32*127 -> 0 | L32: =100%-L29 -> #DIV/0! | M32: =M29/L26 -> #DIV/0!

Sheet Kontrola
B1: =Report!B1 -> Prosek | C1: 46082 | D1: Vyber datum <----------> | E1: 46112 | F1: COL | I1: Tržba | L1: Online Platby
F2: 0.39907517 | I2: 485584.5 | L2: Wolt | M2: 184256
B3: =CHOOSE(WEEKDAY(C1), "Neděle", "Pondělí", "Úterý", "Středa", "Čtvrtek", "Pátek", "Sobota") -> Neděle | D3: =CHOOSE(WEEKDAY(E1), "Neděle", "Pondělí", "Úterý", "Středa", "Čtvrtek", "Pátek", "Sobota") -> Úterý | L3: Bolt | M3: 86095
L4: Dáme jídlo | M4: 67098
B5: Celkem hodin Instor | F5: Celkem hodin Kurýr | L5: Web | M5: 80755
L6: Wolt drive cash | M6: 2671
B7: =TEXT(SUMPRODUCT((IFERROR(LEFT(D10:D30, FIND(":", D10:D30) - 1) * 60, 0) + IFERROR(MID(D10:D30, FIND(":", D10:D30) + 1, LEN(D10:D30) - FIND(":", D10:D30)), 0))), "[h]:mm")/60 -> 290.5 | F7: =TEXT(SUMPRODUCT((IFERROR(LEFT(H10:H30, FIND(":", H10:H30) - 1) * 60, 0) + IFERROR(MID(H10:H30, FIND(":", H10:H30) + 1, LEN(H10:H30) - FIND(":", H10:H30)), 0))), "[h]:mm")/60 -> 260.75 | L7: DJ Cash | M7: 0
B8: Instor | F8: Kurýr | J8: Pokladna | L8: Hotovost
B9: Jméno | C9: Počet dní | D9: Počet hodin | F9: Jméno | G9: Počet dní | H9: Počet hodin | I9: Počet rozvozů | J9: 21 | L9: Terminál | M9: 32864.5
B10: Šebesta Tomáš | C10: 11 | D10: 97:30 | E10: 29:00 | F10: Dvořák Radim | G10: 4 | H10: 56:00 | I10: 48 | L10: Stravenky | M10: 0
B11: Nováková Adéla | C11: 10 | D11: 123:00 | E11: 23:00 | F11: Vychivskyi Volodymyr | G11: 9 | H11: 121:00 | I11: 55 | L11: Hotovost | M11: 15004
B12: Makula Radek | C12: 7 | D12: 54:00 | E12: 13:00 | F12: Kináč Jozef | G12: 3 | H12: 26:00 | I12: 11 | L12: Výdaje
B13: Kopic Jakub | C13: 1 | D13: 12:00 | E13: 13:00 | F13: Novák Dalibor | G13: 1 | H13: 14:00 | I13: 0 | L13: Benzín | M13: 2000
B14: Bušek Pavel | C14: 1 | D14: 4:00 | E14: 7:00 | F14: Bednařík Peter | G14: 3 | H14: 43:45 | I14: 29 | L14: Auta | M14: 0
E15: 7:00 | L15: Suroviny | M15: 143
L16: Ostatní | M16: 10879
L17: PHM - soukromé | M17: 3840
J19: Zrušené obj. ks | K19: Zrušené obj. $ | L19: Počet zpožděných našich rozvozů +5 min | M19: Průměrný make Time
J21: 8 | K21: 5747 | L21: 47 | M21: 11 min 07 s
J22: počet výdajových dokadů | K22: Počet nezrušených celkem | L22: Počet našich rozvozů | M22: Počet pozdě přiřazeným WoltDrive 5+
J24: 12 | K24: 1169 | L24: 160 | M24: 11
J25: Woltrdive zpožděný kvůli našemu pozdnímu přiřazení | L25: % zpožděných našich rozvozů +5 min | M25: Počet zpožděných Woltdrivem
J27: 7 | L27: 0.23634237 | M27: 6
L28: % doručených včas | M28: % zpožděných Woltdrivem
L30: 0.76365763 | M30: 0.024754902

Sheet RestiaCSV

Sheet HR
C1: =IFERROR(__xludf.DUMMYFUNCTION("IMPORTRANGE(""1TpIiNTfR1pnpn85VWQTTdvQ2Xcr0GStmWJ2UvfKxG_A"", ""Mzdy!A1:F200"")"),"#REF!") -> #REF! | V1: =IFERROR(__xludf.DUMMYFUNCTION("IMPORTRANGE(""1TpIiNTfR1pnpn85VWQTTdvQ2Xcr0GStmWJ2UvfKxG_A"", ""Mzdy!ac1:ad200"")"),"#REF!") -> #REF!
A4: Manažeři | B4: Zamestnanci pobocky
A5: =IF(AND(B5<>"", C5=TRUE, E5=Report!$B$1), B5, "") | B5: =IF(OR(E5=Report!$B$1, F5=Report!$B$1, G5=Report!$B$1, H5=Report!$B$1), D5, "")
A6: =IF(AND(B6<>"", C6=TRUE, E6=Report!$B$1), B6, "") | B6: =IF(OR(E6=Report!$B$1, F6=Report!$B$1, G6=Report!$B$1, H6=Report!$B$1), D6, "")
A7: =IF(AND(B7<>"", C7=TRUE, E7=Report!$B$1), B7, "") | B7: =IF(OR(E7=Report!$B$1, F7=Report!$B$1, G7=Report!$B$1, H7=Report!$B$1), D7, "")
A8: =IF(AND(B8<>"", C8=TRUE, E8=Report!$B$1), B8, "") | B8: =IF(OR(E8=Report!$B$1, F8=Report!$B$1, G8=Report!$B$1, H8=Report!$B$1), D8, "")
A9: =IF(AND(B9<>"", C9=TRUE, E9=Report!$B$1), B9, "") | B9: =IF(OR(E9=Report!$B$1, F9=Report!$B$1, G9=Report!$B$1, H9=Report!$B$1), D9, "")
A10: =IF(AND(B10<>"", C10=TRUE, E10=Report!$B$1), B10, "") | B10: =IF(OR(E10=Report!$B$1, F10=Report!$B$1, G10=Report!$B$1, H10=Report!$B$1), D10, "")
A11: =IF(AND(B11<>"", C11=TRUE, E11=Report!$B$1), B11, "") | B11: =IF(OR(E11=Report!$B$1, F11=Report!$B$1, G11=Report!$B$1, H11=Report!$B$1), D11, "")
A12: =IF(AND(B12<>"", C12=TRUE, E12=Report!$B$1), B12, "") | B12: =IF(OR(E12=Report!$B$1, F12=Report!$B$1, G12=Report!$B$1, H12=Report!$B$1), D12, "")
A13: =IF(AND(B13<>"", C13=TRUE, E13=Report!$B$1), B13, "") | B13: =IF(OR(E13=Report!$B$1, F13=Report!$B$1, G13=Report!$B$1, H13=Report!$B$1), D13, "")
A14: =IF(AND(B14<>"", C14=TRUE, E14=Report!$B$1), B14, "") | B14: =IF(OR(E14=Report!$B$1, F14=Report!$B$1, G14=Report!$B$1, H14=Report!$B$1), D14, "")
A15: =IF(AND(B15<>"", C15=TRUE, E15=Report!$B$1), B15, "") | B15: =IF(OR(E15=Report!$B$1, F15=Report!$B$1, G15=Report!$B$1, H15=Report!$B$1), D15, "")
A16: =IF(AND(B16<>"", C16=TRUE, E16=Report!$B$1), B16, "") | B16: =IF(OR(E16=Report!$B$1, F16=Report!$B$1, G16=Report!$B$1, H16=Report!$B$1), D16, "")
... A43: =IF(AND(B43<>"", C43=TRUE, E43=Report!$B$1), B43, "") | B43: =IF(OR(E43=Report!$B$1, F43=Report!$B$1, G43=Report!$B$1, H43=Report!$B$1), D43, "")
B44: =IF(OR(E44=Report!$B$1, F44=Report!$B$1, G44=Report!$B$1, H44=Report!$B$1), D44, "")
B45: =IF(OR(E45=Report!$B$1, F45=Report!$B$1, G45=Report!$B$1, H45=Report!$B$1), D45, "")
B46: =IF(OR(E46=Report!$B$1, F46=Report!$B$1, G46=Report!$B$1, H46=Report!$B$1), D46, "")
B47: =IF(OR(E47=Report!$B$1, F47=Report!$B$1, G47=Report!$B$1, H47=Report!$B$1), D47, "")
B48: =IF(OR(E48=Report!$B$1, F48=Report!$B$1, G48=Report!$B$1, H48=Report!$B$1), D48, "")
B49: =IF(OR(E49=Report!$B$1, F49=Report!$B$1, G49=Report!$B$1, H49=Report!$B$1), D49, "")
B50: =IF(OR(E50=Report!$B$1, F50=Report!$B$1, G50=Report!$B$1, H50=Report!$B$1), D50, "")
B51: =IF(OR(E51=Report!$B$1, F51=Report!$B$1, G51=Report!$B$1, H51=Report!$B$1), D51, "")
B52: =IF(OR(E52=Report!$B$1, F52=Report!$B$1, G52=Report!$B$1, H52=Report!$B$1), D52, "")
B53: =IF(OR(E53=Report!$B$1, F53=Report!$B$1, G53=Report!$B$1, H53=Report!$B$1), D53, "")
B54: =IF(OR(E54=Report!$B$1, F54=Report!$B$1, G54=Report!$B$1, H54=Report!$B$1), D54, "")
B55: =IF(OR(E55=Report!$B$1, F55=Report!$B$1, G55=Report!$B$1, H55=Report!$B$1), D55, "")
... B179: =IF(OR(E179=Report!$B$1, F179=Report!$B$1, G179=Report!$B$1, H179=Report!$B$1), D179, "")

Sheet Denik

Sheet Směny
A1: Sem zadej směnu pro tento týden z CSV - Směny -> Naplánované směny -> Aktuální nebo Následující týden -> Stáhnout CSV (v pravo nahoře ) -> otevřív v excelu -> oznacit všechny buňky a dvojklikem na dělící přepážku mezi A a B přizpůsob buňky velikosti textu. Poté tabulku zkopíruj do této tabulky do bunky A2, označeno modře.
A2: Pracovníci | B2: Pondělí | C2: Úterý | D2: Středa | E2: Čtvrtek | F2: Pátek | G2: Sobota | H2: Neděle | AA2: Přenos do dispecinku | AB2: Zpoždění
A3: Míla Pekárková | B3: 10:00 - 1:00 (Instor) | E3: 10:00 - 1:00 (Instor) | G3: 10:00 - 3:00 (Instor) | H3: 10:00 - 0:00 (Instor) | AB3: 0
A4: Volodymyr Vychivskyi | B4: 11:00 - 1:00 (Kurýr) | C4: 11:00 - 1:00 (Kurýr) | E4: 11:00 - 17:00 (Kurýr) | F4: 17:00 - 3:00 (Kurýr) | AB4: 0
A5: Adéla Nováková | C5: 10:00 - 1:00 (Instor) | D5: 10:00 - 1:00 (Instor) | F5: 10:00 - 3:00 (Instor) | AB5: -8
A6: Martin Hřebík | D6: 11:00 - 17:00 (Kurýr) | F6: 11:00 - 17:00 (Kurýr) | AB6: -9
A7: Pavel Hochman | D7: 17:00 - 1:00 (Kurýr) | E7: 17:00 - 1:00 (Kurýr) | AB7: -38
A8: Michal Nedbal | D8: 17:00 - 22:00 (Instor) | H8: 17:00 - 22:00 (Instor) | AB8: -6
A9: Daniel Suchánek | E9: 17:00 - 1:00 (Instor) | F9: 17:00 - 1:00 (Instor) | G9: 17:00 - 1:00 (Instor) | AB9: 1
A10: Lukáš Petržilka | G10: 11:00 - 3:00 (Kurýr) | H10: 11:00 - 23:00 (Kurýr) | AB10: -7
AB11: 2
AB12: -2
AB13: 4
AB14: 3
AB15: -8
AB16: -5
AB17: -6
AB18: 2
AA19: 2024-08-09T22:19:02.895+02:00 | AB19: -11
AB20: 0
AB21: 5
AB22: -7
AB23: 1
AB24: -2
AB25: -1
AB26: 0
AB27: -7
AB28: -9
AB29: 0
AA30: 2024-08-09T20:59:02.480+02:00 | AB30: -8
AB31: -7
AB32: -2
AB33: -8
AA34: 2024-08-09T20:46:02.837+02:00 | AB34: 0
AB35: 1
AB36: 0
AB37: 4
AA38: 2024-08-09T20:34:02.891+02:00 | AB38: -12
AA39: 2024-08-09T20:47:12.087+02:00 | AB39: 0
AB40: -2
...
