Workbook

Sheet July 2024
A1: Datum | B1: Název | C1: Jména Instor | D1: Začátek směny Instor | E1: Konec směny Instor | F1: Pauza Instor | G1: Počet hodin Instor | H1: Jména Kurýr | I1: Začátek směny Kurýr | J1: Konec směny Kurýr | K1: Pauza Kurýr | L1: Počet hodin Kurýr | M1: Počet rozvozů Kurýr | N1: TRUE | O1: Vyplatit PHM | P1: Wolt drive | Q1: Otevíral | R1: Zavíral | S1: Online Platby - Wolt | T1: Online Platby - Bolt | U1: Online Platby - Dáme Jídlo | V1: Vlastní API | W1: Online Platby - Wolt cash | X1: Online Platby - DJ Cash | Y1: Terminál | Z1: Stravenky | AA1: Hotovost | AB1: Tržba | AC1: Pokladna - VÝSLEDEK | AD1: COL | AE1: Benzín | AF1: Auta | AG1: Suroviny | AH1: Ostatní | AI1: PHM - soukromé | AJ1: Zrušené obj. ks | AK1: Zrušené obj. $ | AL1: Počet zpožděných objednávek z webu +5 min | AM1: Průměrný make Time | AN1: Počet vydajových dokladů
A2: 45499 | B2: Pátek | C2: Veselý Ondřej | D2: 10:00 | E2: 22:00 | G2: 12:00
A3: 45499 | B3: Pátek | C3: Michal Nedbal | D3: 17:00 | E3: 1:00 | G3: 08:00
A4: 45499 | B4: Pátek | C4: Suchánek Daniel | D4: 10:00 | E4: 23:00 | G4: 13:00
A5: 45499 | B5: Pátek | C5: Šebesta Tomáš | D5: 10:00 | E5: 23:00 | G5: 13:00
A6: 45499 | B6: Pátek | C6: Hanakova Ayuna | D6: 10:00 | E6: 17:00 | G6: 07:00
A7: 45499 | B7: Pátek | H7: Kučera Karel | I7: 17:00 | J7: 1:00 | L7: 08:00 | M7: 10 | N7: TRUE | O7: 400
A8: 45499 | B8: Pátek | H8: Černohorský Otakar | I8: 00:30 | J8: 00:00 | L8: 23:30 | M8: 1
A9: 45499 | B9: Pátek | S9: 10 | T9: 20 | U9: 30 | V9: 4 | W9: 5 | X9: 6 | Y9: 7 | Z9: 8 | AA9: 9 | AB9: 50000 | AC9: -37157 | AD9: 0.49276157 | AE9: 11 | AF9: 111 | AG9: 1111 | AH9: 11111 | AI9: 400 | AL9: 5 | AM9: 11 min 45 s | AN9: 1
A10: 45499 | B10: Pátek | AC10: 0 | AD10: Zadej tržbu | AI10: 0 | AN10: 1
A11: 45496 | B11: Úterý | C11: Kučera Karel | D11: 10:00 | E11: 17:00 | G11: 07:00 | AJ11: 1 | AK11: 5 | AM11: 11 min 45 s
A12: 45496 | B12: Úterý | C12: Veselý Ondřej | D12: 10:00 | E12: 20:00 | G12: 10:00 | AJ12: 1 | AK12: 2
A13: 45496 | B13: Úterý | C13: Michal Nedbal | D13: 17:00 | E13: 1:00 | G13: 08:00 | AJ13: 1 | AK13: 1 | AM13: 11 min 45 s | AN13: 2
A14: 45496 | B14: Úterý | H14: Černohorský Otakar | I14: 11:00 | J14: 17:00 | L14: 06:00
A15: 45496 | B15: Úterý | H15: Novák Jakub | I15: 17:00 | J15: 1:00 | L15: 08:00
A16: 45496 | B16: Úterý | S16: 9060 | T16: 3651 | U16: 14729 | V16: 10695 | W16: 374 | X16: 368 | AB16: 41872 | AC16: -2995 | AD16: 0.23834367 | AI16: 0 | AN16: 0
A17: 45501 | B17: Neděle | C17: Veselý Ondřej | D17: 17:00 | E17: 0:00 | G17: 07:00
A18: 45501 | B18: Neděle | C18: Michal Nedbal | D18: 17:00 | E18: 0:00 | G18: 07:00
A19: 45501 | B19: Neděle | H19: Kučera Karel | I19: 11:00 | J19: 17:00 | L19: 06:00
A20: 45501 | B20: Neděle | H20: Novák Jakub | I20: 17:00 | J20: 0:00 | L20: 07:00
A21: 45501 | B21: Neděle | AC21: 0 | AD21: Zadej tržbu | AI21: 0
A22: 45502 | B22: Pondělí | C22: Hanakova Ayuna | D22: 17:00 | E22: 0:00 | G22: 07:00
A23: 45502 | B23: Pondělí | C23: Černohorský Otakar | D23: 17:00 | E23: 0:00 | G23: 07:00
A24: 45502 | B24: Pondělí | H24: Kučera Karel | I24: 11:00 | J24: 18:00 | L24: 07:00
A25: 45502 | B25: Pondělí | H25: Jakub Zimmer | I25: 18:00 | J25: 0:00 | L25: 06:00
A26: 45502 | B26: Pondělí | AC26: 0 | AD26: Zadej tržbu | AI26: 0
A27: 45503 | B27: Úterý | C27: Kučera Karel | D27: 11:00 | E27: 17:00 | G27: 06:00
A28: 45503 | B28: Úterý | C28: Trachtová Martina | D28: 10:00 | E28: 17:00 | G28: 07:00
A29: 45503 | B29: Úterý | C29: Veselý Ondřej | D29: 17:00 | E29: 0:00 | G29: 07:00
A30: 45503 | B30: Úterý | H30: Novák Jakub | I30: 17:00 | J30: 0:00 | L30: 07:00
A31: 45503 | B31: Úterý | AC31: 0 | AD31: Zadej tržbu | AI31: 0
A32: 45504 | B32: Středa | C32: Hanakova Ayuna | D32: 17:00 | E32: 0:00 | G32: 07:00
A33: 45504 | B33: Středa | H33: Novák Jakub | I33: 11:00 | J33: 18:00 | L33: 07:00
A34: 45504 | B34: Středa | H34: Jakub Zimmer | L34: 0:00 | M34: 4
A35: 45504 | B35: Středa | P35: 3 | S35: 9414 | T35: 3907 | U35: 9081 | V35: 4024 | W35: 1310 | X35: 2052 | AB35: 38044 | AC35: -8256 | AD35: 0.25491082 | AI35: 0 | AN35: 0

Sheet DatabaseRestia
A1: Datum | B1: Platforma | C1: Stav | D1: Cena | E1: Sleva | F1: Kurýr | G1: Doručení | H1: Platba | I1: Vytvořeno | J1: Připraveno v | K1: Dokončeno v | L1: Přenos do dispecinku | M1: Zpoždění | N1: Přiřazení WoltDrivu | O1: Make Time
A2: 45531 | B2: wolt | C2: delivered | D2: 289 | E2: 0 | F2: Wolt Kurýr | G2: external-delivery | H2: online | I2: 2024-08-19T23:58:58.749+02:00 | J2: 2024-08-20T00:10:47.895+02:00 | K2: 2024-08-20T00:10:47.895+02:00 | M2: -3 | O2: 11.8191
A3: 45531 | B3: generic | C3: delivered | D3: 400 | E3: 47 | F3: David Sarkozi | G3: delivery | H3: online | I3: 2024-08-19T23:58:03.178+02:00 | J3: 2024-08-20T00:08:47.664+02:00 | K3: 2024-08-20T00:25:53.970+02:00 | L3: 2024-08-19T23:58:03.744+02:00 | M3: 0 | N3: 0.0094333333 | O3: 10.741433
A4: 45531 | B4: wolt | C4: delivered | D4: 464 | E4: 0 | F4: Wolt Kurýr | G4: external-delivery | H4: online | I4: 2024-08-19T23:56:29.395+02:00 | J4: 2024-08-20T00:06:31.879+02:00 | K4: 2024-08-20T00:06:31.879+02:00 | M4: -4 | O4: 10.0414
A5: 45531 | B5: bolt | C5: ready_pickup | D5: 329 | E5: 0 | F5: Rakib | G5: external-delivery | H5: online | I5: 2024-08-19T23:48:48.507+02:00 | J5: 2024-08-20T00:01:52.755+02:00 | K5: 2024-08-20T00:01:52.755+02:00 | M5: -1 | O5: 13.0708
A6: 45531 | B6: bolt | C6: ready_pickup | D6: 329 | E6: 0 | F6: Karel | G6: external-delivery | H6: online | I6: 2024-08-19T23:42:56.580+02:00 | J6: 2024-08-19T23:51:37.779+02:00 | K6: 2024-08-19T23:51:37.779+02:00 | M6: -6 | O6: 8.68665
A7: 45531 | B7: wolt | C7: delivered | D7: 321 | E7: 0 | F7: Wolt Kurýr | G7: external-delivery | H7: online | I7: 2024-08-19T23:33:49.070+02:00 | J7: 2024-08-19T23:47:07.826+02:00 | K7: 2024-08-19T23:47:07.826+02:00 | M7: -2 | O7: 13.3126
A8: 45531 | B8: bolt | C8: ready_pickup | D8: 321 | E8: 0 | F8: Rakib | G8: external-delivery | H8: online | I8: 2024-08-19T23:31:39.363+02:00 | J8: 2024-08-19T23:43:55.743+02:00 | K8: 2024-08-19T23:43:55.743+02:00 | M8: -2 | O8: 12.273
A9: 45531 | B9: generic | C9: delivered | D9: 299 | E9: 0 | F9: David Sarkozi | G9: delivery | H9: cash | I9: 2024-08-19T23:25:03.311+02:00 | J9: 2024-08-19T23:36:43.715+02:00 | K9: 2024-08-20T00:04:51.283+02:00 | L9: 2024-08-19T23:25:03.917+02:00 | M9: 10 | N9: 0.0101 | O9: 11.6734
A10: 45531 | B10: generic | C10: delivered | D10: 288 | E10: 0 | F10: David Sarkozi | G10: delivery | H10: cash | I10: 2024-08-19T23:23:03.045+02:00 | J10: 2024-08-19T23:33:28.787+02:00 | K10: 2024-08-19T23:50:59.104+02:00 | L10: 2024-08-19T23:23:03.542+02:00 | M10: -1 | N10: 0.0082833333 | O10: 10.429033
A11: 45531 | B11: wolt | C11: delivered | D11: 394 | E11: 0 | F11: Wolt Kurýr | G11: external-delivery | H11: online | I11: 2024-08-19T23:15:42.317+02:00 | J11: 2024-08-19T23:32:08.801+02:00 | K11: 2024-08-19T23:32:08.801+02:00 | M11: 1 | O11: 16.4414
A12: 45531 | B12: damejidlo | C12: ready_pickup | D12: 264 | E12: 0 | G12: external-delivery | H12: cash | I12: 2024-08-19T23:14:58.535+02:00 | J12: 2024-08-19T23:26:49.035+02:00 | K12: 2024-08-19T23:26:49.035+02:00 | M12: 1 | O12: 11.841667
A13: 45531 | B13: damejidlo | C13: ready_pickup | D13: 264 | E13: 0 | G13: external-delivery | H13: cash | I13: 2024-08-19T23:14:57.369+02:00 | J13: 2024-08-19T23:24:50.897+02:00 | K13: 2024-08-19T23:24:50.897+02:00 | M13: 0 | O13: 9.8921333
A14: 45531 | B14: generic | C14: delivered | D14: 309 | E14: 0 | F14: David Sarkozi | G14: delivery | H14: online | I14: 2024-08-19T23:08:04.305+02:00 | J14: 2024-08-19T23:19:10.937+02:00 | K14: 2024-08-19T23:35:16.750+02:00 | L14: 2024-08-19T23:08:04.797+02:00 | M14: 1 | N14: 0.0082 | O14: 11.110533
A15: 45531 | B15: generic | C15: delivered | D15: 250 | E15: 0 | F15: David Sarkozi | G15: delivery | H15: online | I15: 2024-08-19T22:39:03.895+02:00 | J15: 2024-08-19T22:50:36.631+02:00 | K15: 2024-08-19T23:02:14.652+02:00 | L15: 2024-08-19T22:39:04.429+02:00 | M15: -5 | N15: 0.0089 | O15: 11.5456
A16: 45531 | B16: damejidlo | C16: delivered | D16: 394 | E16: 0 | G16: external-delivery | H16: online | I16: 2024-08-19T22:37:31.754+02:00 | J16: 2024-08-19T22:50:32.912+02:00 | K16: 2024-08-19T22:50:32.912+02:00 | M16: 0 | O16: 13.0193
A17: 45531 | B17: damejidlo | C17: delivered | D17: 358 | E17: 0 | G17: external-delivery | H17: online | I17: 2024-08-19T22:31:31.556+02:00 | J17: 2024-08-19T22:42:33.025+02:00 | K17: 2024-08-19T22:42:33.025+02:00 | M17: 0 | O17: 11.024483
A18: 45531 | B18: bolt | C18: ready_pickup | D18: 329 | E18: 0 | F18: Tibor | G18: external-delivery | H18: online | I18: 2024-08-19T22:23:03.166+02:00 | J18: 2024-08-19T22:34:31.850+02:00 | K18: 2024-08-19T22:34:31.850+02:00 | M18: -3 | O18: 11.478067
A19: 45531 | B19: wolt | C19: delivered | D19: 264 | E19: 0 | F19: Wolt Kurýr | G19: external-delivery | H19: online | I19: 2024-08-19T22:19:15.867+02:00 | J19: 2024-08-19T22:29:46.834+02:00 | K19: 2024-08-19T22:29:46.834+02:00 | M19: -4 | O19: 10.516117
A20: 45531 | B20: generic | C20: delivered | D20: 267 | E20: 67 | G20: pickup | H20: online | I20: 2024-08-19T21:48:04.353+02:00 | J20: 2024-08-19T21:56:38.613+02:00 | K20: 2024-08-19T21:56:38.613+02:00 | M20: -8 | O20: 8.571
A21: 45531 | B21: generic | C21: canceled | D21: 267 | E21: 67 | G21: pickup | H21: card | I21: 2024-08-19T21:47:02.850+02:00 | M21: 0
A22: 45531 | B22: damejidlo | C22: ready_pickup | D22: 394 | E22: 0 | G22: external-delivery | H22: cash | I22: 2024-08-19T21:30:32.106+02:00 | J22: 2024-08-19T21:40:49.932+02:00 | K22: 2024-08-19T21:40:49.932+02:00 | M22: -2 | O22: 10.2971
A23: 45531 | B23: wolt | C23: delivered | D23: 264 | E23: 0 | F23: Wolt Kurýr | G23: external-delivery | H23: online | I23: 2024-08-19T21:28:30.881+02:00 | J23: 2024-08-19T21:36:34.908+02:00 | K23: 2024-08-19T21:36:34.908+02:00 | M23: -6 | O23: 8.0671167
A24: 45531 | B24: damejidlo | C24: ready_pickup | D24: 368 | E24: 0 | G24: external-delivery | H24: online | I24: 2024-08-19T21:22:33.441+02:00 | J24: 2024-08-19T21:32:09.961+02:00 | K24: 2024-08-19T21:32:09.961+02:00 | M24: -2 | O24: 9.6086667
A25: 45531 | B25: generic | C25: delivered | D25: 426 | E25: 0 | F25: David Sarkozi | G25: delivery | H25: cash | I25: 2024-08-19T21:18:02.700+02:00 | J25: 2024-08-19T21:29:30.638+02:00 | K25: 2024-08-19T22:03:06.023+02:00 | L25: 2024-08-19T21:18:03.357+02:00 | M25: 15 | N25: 0.01095 | O25: 11.465633
A26: 45531 | B26: generic | C26: delivered | D26: 329 | E26: 0 | F26: David Sarkozi | G26: delivery | H26: cash | I26: 2024-08-19T21:13:03.392+02:00 | J26: 2024-08-19T21:22:03.603+02:00 | K26: 2024-08-19T21:42:09.652+02:00 | L26: 2024-08-19T21:13:04.041+02:00 | M26: 0 | N26: 0.010816667 | O26: 9.0035167
A27: 45531 | B27: manual | C27: delivered | D27: 90 | E27: 0 | G27: pickup | H27: cash | I27: 2024-08-19T21:11:22.100+02:00 | J27: 2024-08-19T21:11:59.916+02:00 | K27: 2024-08-19T21:11:59.916+02:00 | M27: -4 | O27: 0.63026667
A28: 45531 | B28: generic | C28: delivered | D28: 374 | E28: 0 | F28: David Sarkozi | G28: delivery | H28: online | I28: 2024-08-19T21:09:04.030+02:00 | J28: 2024-08-19T21:19:12.666+02:00 | K28: 2024-08-19T21:33:57.270+02:00 | L28: 2024-08-19T21:09:04.521+02:00 | M28: -3 | N28: 0.0081833333 | O28: 10.143933
A29: 45531 | B29: damejidlo | C29: ready_pickup | D29: 264 | E29: 0 | G29: external-delivery | H29: online | I29: 2024-08-19T21:05:33.242+02:00 | J29: 2024-08-19T21:14:33.054+02:00 | K29: 2024-08-19T21:14:33.054+02:00 | M29: -1 | O29: 8.9968667
A30: 45531 | B30: damejidlo | C30: ready_pickup | D30: 294 | E30: 0 | G30: external-delivery | H30: online | I30: 2024-08-19T20:59:31.975+02:00 | J30: 2024-08-19T21:08:47.014+02:00 | K30: 2024-08-19T21:08:47.014+02:00 | M30: -2 | O30: 9.25065
A31: 45531 | B31: bolt | C31: ready_pickup | D31: 368 | E31: 0 | F31: Shehryar | G31: external-delivery | H31: online | I31: 2024-08-19T20:54:46.747+02:00 | J31: 2024-08-19T21:06:05.751+02:00 | K31: 2024-08-19T21:06:05.751+02:00 | M31: -3 | O31: 11.316733
A32: 45531 | B32: damejidlo | C32: ready_pickup | D32: 264 | E32: 0 | G32: external-delivery | H32: online | I32: 2024-08-19T20:54:33.919+02:00 | J32: 2024-08-19T21:05:41.884+02:00 | K32: 2024-08-19T21:05:41.884+02:00 | M32: 0 | O32: 11.13275
A33: 45531 | B33: wolt | C33: delivered | D33: 258 | E33: 0 | F33: Wolt Kurýr | G33: external-delivery | H33: online | I33: 2024-08-19T20:51:13.748+02:00 | J33: 2024-08-19T20:52:07.867+02:00 | K33: 2024-08-19T20:52:07.867+02:00 | M33: -14 | O33: 0.90198333
A34: 45531 | B34: manual | C34: delivered | D34: 309 | E34: 0 | G34: pickup | H34: cash | I34: 2024-08-19T20:43:28.341+02:00 | J34: 2024-08-19T20:57:27.636+02:00 | K34: 2024-08-19T20:57:27.636+02:00 | M34: 8 | O34: 13.98825
A35: 45531 | B35: manual | C35: delivered | D35: 209 | E35: 0 | G35: pickup | H35: cash | I35: 2024-08-19T20:42:30.337+02:00 | J35: 2024-08-19T20:54:22.604+02:00 | K35: 2024-08-19T20:54:22.604+02:00 | M35: 6 | O35: 11.871117
A36: 45531 | B36: generic | C36: delivered | D36: 199 | E36: 50 | G36: pickup | H36: card | I36: 2024-08-19T20:38:02.760+02:00 | J36: 2024-08-19T20:53:17.576+02:00 | K36: 2024-08-19T20:53:17.576+02:00 | M36: -4 | O36: 15.246933
A37: 45531 | B37: generic | C37: delivered | D37: 279 | E37: 70 | G37: pickup | H37: cash | I37: 2024-08-19T20:37:03.327+02:00 | J37: 2024-08-19T20:52:01.586+02:00 | K37: 2024-08-19T20:52:01.586+02:00 | M37: -4 | O37: 14.970983
A38: 45531 | B38: manual | C38: canceled | D38: 249 | E38: 0 | G38: pickup | H38: cash | I38: 2024-08-19T20:26:05.863+02:00 | J38: 2024-08-19T20:38:57.692+02:00 | K38: 2024-08-19T20:38:57.692+02:00 | M38: 7 | O38: 12.863817
A39: 45531 | B39: generic | C39: delivered | D39: 247 | E39: 62 | G39: pickup | H39: cash | I39: 2024-08-19T20:25:02.914+02:00 | J39: 2024-08-19T20:37:44.580+02:00 | K39: 2024-08-19T20:37:44.580+02:00 | M39: -6 | O39: 12.694433
A40: 45531 | B40: wolt | C40: delivered | D40: 313 | E40: 0 | F40: Wolt Kurýr | G40: external-delivery | H40: online | I40: 2024-08-19T20:24:34.143+02:00 | J40: 2024-08-19T20:44:20.765+02:00 | K40: 2024-08-19T20:44:20.765+02:00 | M40: 4 | O40: 19.777033
...

Sheet August 2024
A1: Datum | B1: Název | C1: Jména Instor | D1: Začátek směny Instor | E1: Konec směny Instor | F1: Pauza Instor | G1: Počet hodin Instor | H1: Jména Kurýr | I1: Začátek směny Kurýr | J1: Konec směny Kurýr | K1: Pauza Kurýr | L1: Počet hodin Kurýr | M1: Počet rozvozů Kurýr | N1: Vlastní vůz | O1: Vyplatit PHM | P1: Wolt drive | Q1: Otevíral | R1: Zavíral | S1: Online Platby - Wolt | T1: Online Platby - Bolt | U1: Online Platby - Dáme Jídlo | V1: Vlastní API | W1: Online Platby - Wolt cash | X1: Online Platby - DJ Cash | Y1: Terminál | Z1: Stravenky | AA1: Hotovost | AB1: Tržba | AC1: Pokladna - VÝSLEDEK | AD1: COL | AE1: Benzín | AF1: Auta | AG1: Suroviny | AH1: Ostatní | AI1: PHM - soukromé | AJ1: Zrušené obj. ks | AK1: Zrušené obj. $ | AL1: Počet zpožděných objednávek z webu +5 min | AM1: Průměrný make Time | AN1: Počet vydajových dokladů | AO1: Počet nezrušených celkem | AP1: Počet našich rozvozů | AQ1: Počet pozdě přiřazeným WoltDrive 5+ | AR1: Woltrdrive zpožděný kvůli našemu pozdnímu přiřazení | AS1: % zpožděných našich rozvozů +5 min | AT1: Počet zpožděných Woltdrivem | AU1: % doručených včas | AV1: % zpožděných Woltdrivem
A2: 45505 | B2: Čtvrtek | C2: Ahurieva Viktoriia | D2: 10:00 | E2: 21:00 | G2: 11:00
A3: 45505 | B3: Čtvrtek | C3: Jakub Coufal | D3: 17:00 | E3: 19:30 | G3: 02:30
A4: 45505 | B4: Čtvrtek | H4: Jakub Coufal | I4: 11:00 | J4: 14:00 | L4: 03:00
A5: 45505 | B5: Čtvrtek | H5: Pešová Hana | I5: 18:00 | J5: 01:00 | L5: 07:00 | M5: 9 | N5: TRUE | O5: 360
A6: 45505 | B6: Čtvrtek | H6: Hammer Jan | I6: 17:00 | J6: 01:00 | L6: 08:00 | M6: 10 | N6: TRUE | O6: 400
A7: 45505 | B7: Čtvrtek | P7: 2 | Q7: Martin Sova | R7: Ahurieva Viktoriia | S7: 7874 | T7: 4327 | U7: 13467 | V7: 8130 | W7: 0 | X7: 3209 | Y7: 4245 | AA7: 6221 | AB7: 46064 | AC7: -240 | AD7: 0.31400112 | AH7: 800 | AI7: 760 | AJ7: 2 | AK7: 826 | AL7: 8 | AM7: 14 min 14 s | AN7: 2 | AO7: 120 | AP7: 28 | AQ7: 0 | AR7: 0 | AS7: 0.28571429 | AT7: 0 | AU7: 0.71428571 | AV7: 0
A8: 45506 | B8: Pátek | C8: Ahurieva Viktoriia | D8: 10:00 | E8: 01:00 | G8: 15:00
A9: 45506 | B9: Pátek | C9: Hegedüs Erik | D9: 17:00 | E9: 03:30 | G9: 10:30
A10: 45506 | B10: Pátek | H10: Martin Jurkovič | I10: 11:00 | J10: 14:00 | L10: 03:00 | M10: 5 | N10: TRUE | O10: 200
A11: 45506 | B11: Pátek | H11: Ondřej Navrátil | I11: 11:00 | J11: 18:00 | L11: 07:00
A12: 45506 | B12: Pátek | H12: Hyský Aleš | I12: 11:00 | J12: 21:00 | L12: 10:00 | M12: 15 | N12: TRUE | O12: 600
A13: 45506 | B13: Pátek | H13: Eduard Doležal | I13: 18:30 | J13: 3:00 | L13: 08:30 | M13: 12 | N13: TRUE | O13: 480
A14: 45506 | B14: Pátek | P14: 1 | Q14: Ahurieva Viktoriia | R14: Hegedüs Erik | S14: 10222 | T14: 8521 | U14: 16447 | V14: 13790 | W14: 0 | X14: 2015 | Y14: 5577 | AA14: 5665 | AB14: 61834.5 | AC14: 4.5 | AD14: 0.34945994 | AH14: 337 | AI14: 1280 | AJ14: 0 | AK14: 0 | AL14: 12 | AM14: 17 min 37 s | AN14: 3 | AO14: 150 | AP14: 33 | AQ14: 0 | AR14: 0 | AS14: 0.36363636 | AT14: 1 | AU14: 0.63636364 | AV14: 0.03030303
A15: 45507 | B15: Sobota | C15: Martin Sova | D15: 10:00 | E15: 20:00 | G15: 10:00
A16: 45507 | B16: Sobota | C16: Šebesta Tomáš | D16: 14:00 | E16: 03:00 | G16: 13:00
A17: 45507 | B17: Sobota | H17: Martin Jurkovič | I17: 11:00 | J17: 16:00 | L17: 05:00 | M17: 5 | N17: TRUE | O17: 200
A18: 45507 | B18: Sobota | H18: Vladimír Nekolný | I18: 11:00 | J18: 15:00 | L18: 04:00 | M18: 5 | N18: TRUE | O18: 200
A19: 45507 | B19: Sobota | H19: Lanský Zoltan | I19: 11:00 | J19: 17:00 | L19: 06:00 | M19: 8 | N19: TRUE | O19: 320
A20: 45507 | B20: Sobota | H20: Eduard Doležal | I20: 17:00 | J20: 3:00 | L20: 10:00 | M20: 10 | N20: TRUE | O20: 400
A21: 45507 | B21: Sobota | P21: 0 | Q21: Ahurieva Viktoriia | R21: Hegedüs Erik | S21: 8565 | T21: 6171 | U21: 11683 | V21: 9243 | W21: 0 | X21: 543 | Y21: 2099 | AA21: 5864 | AB21: 46745 | AC21: 0 | AD21: 0.23751935 | AE21: 2000 | AI21: 1120 | AJ21: 0 | AK21: 0 | AL21: 6 | AM21: 14 min 00 s | AN21: 4 | AO21: 117 | AP21: 28 | AQ21: 0 | AR21: 0 | AS21: 0.21428571 | AT21: 0 | AU21: 0.78571429 | AV21: 0
A22: 45508 | B22: Neděle | C22: Martin Sova | D22: 10:00 | E22: 17:30 | G22: 07:30
A23: 45508 | B23: Neděle | C23: Ahurieva Viktoriia | D23: 17:30 | E23: 01:00 | G23: 07:30
A24: 45508 | B24: Neděle | C24: Hofmanová Jana | D24: 10:00 | E24: 17:30 | G24: 07:30
A25: 45508 | B25: Neděle | H25: Martin Jurkovič | I25: 10:00 | J25: 17:00 | L25: 07:00 | M25: 15 | N25: TRUE | O25: 600
A26: 45508 | B26: Neděle | H26: Ondřej Navrátil | I26: 10:00 | J26: 17:00 | L26: 07:00
A27: 45508 | B27: Neděle | H27: Zbyněk Hyský | I27: 17:00 | J27: 21:00 | L27: 04:00 | M27: 10 | N27: TRUE | O27: 400
A28: 45508 | B28: Neděle | H28: Vladimír Nekolný | I28: 18:00 | J28: 00:00 | L28: 06:00 | M28: 8 | N28: TRUE | O28: 320
A29: 45508 | B29: Neděle | P29: 2 | Q29: Hofmanová Jana | R29: Martin Sova | S29: 11702 | T29: 3756 | U29: 16469 | V29: 14491 | W29: 375 | X29: 1571 | Y29: 4709 | AA29: 6169 | AB29: 59490.5 | AC29: 0.5 | AD29: 0.29512388 | AE29: 500 | AI29: 1320 | AJ29: 0 | AK29: 0 | AL29: 5 | AM29: 13 min 48 s | AN29: 3 | AO29: 146 | AP29: 36 | AQ29: 2 | AR29: 0 | AS29: 0.13888889 | AT29: 0 | AU29: 0.86111111 | AV29: 0
A30: 45509 | B30: Pondělí | C30: Ahurieva Viktoriia | D30: 10:00 | E30: 01:00 | G30: 15:00
A31: 45509 | B31: Pondělí | H31: Ondřej Navrátil | I31: 10:00 | J31: 18:00 | L31: 08:00 | M31: 7
A32: 45509 | B32: Pondělí | H32: Pešová Hana | I32: 17:00 | J32: 01:00 | L32: 08:00
A33: 45509 | B33: Pondělí | H33: Eduard Doležal | I33: 18:00 | J33: 00:00 | L33: 06:00 | M33: 13 | N33: TRUE | O33: 520
A34: 45509 | B34: Pondělí | P34: 2 | Q34: Ahurieva Viktoriia | R34: Ahurieva Viktoriia | S34: 5067 | T34: 4145 | U34: 9858 | V34: 7572 | W34: 320 | X34: 2544 | Y34: 3479 | AA34: 1190 | AB34: 38287.5 | AC34: 0.5 | AD34: 0.43579842 | AE34: 500 | AG34: 5597 | AH34: 40 | AI34: 520 | AJ34: 1 | AK34: 247 | AL34: 7 | AM34: 16 min 38 s | AN34: 1 | AO34: 108 | AP34: 22 | AQ34: 1 | AR34: 1 | AS34: 0.31818182 | AT34: 1 | AU34: 0.68181818 | AV34: 0.045454545
A35: 45510 | B35: Úterý | C35: Martin Sova | D35: 10:00 | E35: 17:30 | G35: 07:30
A36: 45510 | B36: Úterý | C36: Šebesta Tomáš | D36: 17:00 | E36: 01:00 | G36: 08:00
A37: 45510 | B37: Úterý | H37: Ondřej Navrátil | I37: 11:00 | J37: 18:00 | L37: 07:00 | M37: 5
A38: 45510 | B38: Úterý | H38: Pešová Hana | I38: 17:00 | J38: 01:00 | L38: 08:00
A39: 45510 | B39: Úterý | H39: Hammer Jan | I39: 17:00 | J39: 00:00 | L39: 07:00 | M39: 9
A40: 45510 | B40: Úterý | L40: 0:00 | N40: TRUE
...

Sheet Report
B1: Libuš | C1: Datum | D1: 46130 | F1: COL | I1: Tržba | L1: Online Platby
F2: =IFERROR(__xludf.DUMMYFUNCTION("IF(I2>0, 100 / (I2 / 112 * 100 / ((SUM(A12:A21, A25:A31) + (M17 + I32) + IFERROR(SUM(FILTER(HR!W5:W48, LEN(HR!A5:A48) > 0)), 0)) / 100)), ""Zadej tržbu"") "),"Zadej tržbu") -> Zadej tržbu | I2: =SUM(RestiaCSV!C:C) - SUMIFS(RestiaCSV!C:C, RestiaCSV!B:B, "canceled") -> 0 | L2: Wolt | M2: =SUMIFS(RestiaCSV!C:C, RestiaCSV!A:A, Report!L2, RestiaCSV!B:B, "<>canceled") -> 0
B3: =CHOOSE(WEEKDAY(D1), "Neděle", "Pondělí", "Úterý", "Středa", "Čtvrtek", "Pátek", "Sobota") -> Sobota | L3: Bolt | M3: =SUMIFS(RestiaCSV!C:C, RestiaCSV!A:A, Report!L3, RestiaCSV!B:B, "<>canceled") -> 0
L4: Dáme jídlo | M4: =SUMIFS(RestiaCSV!C:C, RestiaCSV!A:A, "damejidlo", RestiaCSV!G:G, "online", RestiaCSV!B:B, "<>canceled") -> 0
B5: Napiš vzkaz ⬇️ 📖 Deník 📖 ⬇️ Včerejší vzkaz | L5: Web | M5: =SUMIFS(RestiaCSV!C:C, RestiaCSV!A:A, "generic", RestiaCSV!G:G, "online", RestiaCSV!B:B, "<>canceled") -> 0
L6: Wolt drive cash | M6: =SUMIFS(RestiaCSV!C:C, RestiaCSV!E:E, "wolt kurýr", RestiaCSV!A:A, "<>wolt", RestiaCSV!G:G, "cash", RestiaCSV!B:B, "<>canceled") -> 0
L7: DJ Cash | M7: =SUMIFS(RestiaCSV!C:C, RestiaCSV!A:A, "damejidlo", RestiaCSV!G:G, "cash", RestiaCSV!B:B, "<>canceled") -> 0
L8: Hotovost
L9: Terminál
B10: Instor | G10: Otevíral | J10: Pokladna | L10: Stravenky
B11: Jméno | C11: Začátek směny | D11: Konec směny | E11: pauza | F11: Počet hodin | J11: =M2+M3+M4+M5+M6+M13+M14+M15+M16+M17+M9+M11+M10-I2 -> 0 | L11: Hotovost
A12: {=IF(ISBLANK(B12), 0, IF(ISNUMBER(MATCH(B12, HR!A:A, 0)), 0, IF(ISNUMBER(MATCH(B12, HR!B:B, 0)), INDEX(HR!V:V, MATCH(B12, HR!B:B, 0)) * (F12 * 24), 0)))} -> 0 | B12: Hegedüs Erik | C12: 17:00 | D12: 3:00 | F12: =IF(OR(ISBLANK(B12), ISBLANK(D12), D12=0), "0:00", TEXT((IF(AND(TIMEVALUE(IF(ISBLANK(D12), "00:00", D12))>=TIMEVALUE("00:00"), TIMEVALUE(IF(ISBLANK(D12), "00:00", D12))<=TIMEVALUE("06:00")), TIMEVALUE(IF(ISBLANK(D12), "00:00", D12))+1, TIMEVALUE(IF(ISBLANK(D12), "00:00", D12))) - TIMEVALUE(IF(ISBLANK(C12), "00:00", C12)) - TIMEVALUE(IF(ISBLANK(E12), "00:00", E12))), "hh:mm")) -> 10:00 | L12: Výdaje
A13: {=IF(ISBLANK(B13), 0, IF(ISNUMBER(MATCH(B13, HR!A:A, 0)), 0, IF(ISNUMBER(MATCH(B13, HR!B:B, 0)), INDEX(HR!V:V, MATCH(B13, HR!B:B, 0)) * (F13 * 24), 0)))} -> 6484.617 | B13: Ahurieva Viktoriia | C13: 10:00 | D13: 1:00 | F13: =IF(OR(ISBLANK(B13), ISBLANK(D13), D13=0), "0:00", TEXT((IF(AND(TIMEVALUE(IF(ISBLANK(D13), "00:00", D13))>=TIMEVALUE("00:00"), TIMEVALUE(IF(ISBLANK(D13), "00:00", D13))<=TIMEVALUE("06:00")), TIMEVALUE(IF(ISBLANK(D13), "00:00", D13))+1, TIMEVALUE(IF(ISBLANK(D13), "00:00", D13))) - TIMEVALUE(IF(ISBLANK(C13), "00:00", C13)) - TIMEVALUE(IF(ISBLANK(E13), "00:00", E13))), "hh:mm")) -> 15:00 | L13: Benzín
A14: {=IF(ISBLANK(B14), 0, IF(ISNUMBER(MATCH(B14, HR!A:A, 0)), 0, IF(ISNUMBER(MATCH(B14, HR!B:B, 0)), INDEX(HR!V:V, MATCH(B14, HR!B:B, 0)) * (F14 * 24), 0)))} -> 0 | F14: =IF(OR(ISBLANK(B14), ISBLANK(D14), D14=0), "0:00", TEXT((IF(AND(TIMEVALUE(IF(ISBLANK(D14), "00:00", D14))>=TIMEVALUE("00:00"), TIMEVALUE(IF(ISBLANK(D14), "00:00", D14))<=TIMEVALUE("06:00")), TIMEVALUE(IF(ISBLANK(D14), "00:00", D14))+1, TIMEVALUE(IF(ISBLANK(D14), "00:00", D14))) - TIMEVALUE(IF(ISBLANK(C14), "00:00", C14)) - TIMEVALUE(IF(ISBLANK(E14), "00:00", E14))), "hh:mm")) -> 0:00 | L14: Auta
A15: {=IF(ISBLANK(B15), 0, IF(ISNUMBER(MATCH(B15, HR!A:A, 0)), 0, IF(ISNUMBER(MATCH(B15, HR!B:B, 0)), INDEX(HR!V:V, MATCH(B15, HR!B:B, 0)) * (F15 * 24), 0)))} -> 0 | F15: =IF(OR(ISBLANK(B15), ISBLANK(D15), D15=0), "0:00", TEXT((IF(AND(TIMEVALUE(IF(ISBLANK(D15), "00:00", D15))>=TIMEVALUE("00:00"), TIMEVALUE(IF(ISBLANK(D15), "00:00", D15))<=TIMEVALUE("06:00")), TIMEVALUE(IF(ISBLANK(D15), "00:00", D15))+1, TIMEVALUE(IF(ISBLANK(D15), "00:00", D15))) - TIMEVALUE(IF(ISBLANK(C14), "00:00", C14)) - TIMEVALUE(IF(ISBLANK(E15), "00:00", E15))), "hh:mm")) -> 0:00 | L15: Suroviny
A16: {=IF(ISBLANK(B16), 0, IF(ISNUMBER(MATCH(B16, HR!A:A, 0)), 0, IF(ISNUMBER(MATCH(B16, HR!B:B, 0)), INDEX(HR!V:V, MATCH(B16, HR!B:B, 0)) * (F16 * 24), 0)))} -> 0 | F16: =IF(OR(ISBLANK(B16), ISBLANK(D16), D16=0), "0:00", TEXT((IF(AND(TIMEVALUE(IF(ISBLANK(D16), "00:00", D16))>=TIMEVALUE("00:00"), TIMEVALUE(IF(ISBLANK(D16), "00:00", D16))<=TIMEVALUE("06:00")), TIMEVALUE(IF(ISBLANK(D16), "00:00", D16))+1, TIMEVALUE(IF(ISBLANK(D16), "00:00", D16))) - TIMEVALUE(IF(ISBLANK(C16), "00:00", C16)) - TIMEVALUE(IF(ISBLANK(E16), "00:00", E16))), "hh:mm")) -> 0:00 | L16: Ostatní
A17: {=IF(ISBLANK(B17), 0, IF(ISNUMBER(MATCH(B17, HR!A:A, 0)), 0, IF(ISNUMBER(MATCH(B17, HR!B:B, 0)), INDEX(HR!V:V, MATCH(B17, HR!B:B, 0)) * (F17 * 24), 0)))} -> 0 | F17: =IF(OR(ISBLANK(B17), ISBLANK(D17), D17=0), "0:00", TEXT((IF(AND(TIMEVALUE(IF(ISBLANK(D17), "00:00", D17))>=TIMEVALUE("00:00"), TIMEVALUE(IF(ISBLANK(D17), "00:00", D17))<=TIMEVALUE("06:00")), TIMEVALUE(IF(ISBLANK(D17), "00:00", D17))+1, TIMEVALUE(IF(ISBLANK(D17), "00:00", D17))) - TIMEVALUE(IF(ISBLANK(C17), "00:00", C17)) - TIMEVALUE(IF(ISBLANK(E17), "00:00", E17))), "hh:mm")) -> 0:00 | L17: PHM - soukromé | M17: =sum(I25:I31) -> 0
A18: {=IF(ISBLANK(B18), 0, IF(ISNUMBER(MATCH(B18, HR!A:A, 0)), 0, IF(ISNUMBER(MATCH(B18, HR!B:B, 0)), INDEX(HR!V:V, MATCH(B18, HR!B:B, 0)) * (F18 * 24), 0)))} -> 0 | F18: =IF(OR(ISBLANK(B18), ISBLANK(D18), D18=0), "0:00", TEXT((IF(AND(TIMEVALUE(IF(ISBLANK(D18), "00:00", D18))>=TIMEVALUE("00:00"), TIMEVALUE(IF(ISBLANK(D18), "00:00", D18))<=TIMEVALUE("06:00")), TIMEVALUE(IF(ISBLANK(D18), "00:00", D18))+1, TIMEVALUE(IF(ISBLANK(D18), "00:00", D18))) - TIMEVALUE(IF(ISBLANK(C18), "00:00", C18)) - TIMEVALUE(IF(ISBLANK(E18), "00:00", E18))), "hh:mm")) -> 0:00 | G18: Zavíral
A19: {=IF(ISBLANK(B19), 0, IF(ISNUMBER(MATCH(B19, HR!A:A, 0)), 0, IF(ISNUMBER(MATCH(B19, HR!B:B, 0)), INDEX(HR!V:V, MATCH(B19, HR!B:B, 0)) * (F19 * 24), 0)))} -> 0 | F19: =IF(OR(ISBLANK(B19), ISBLANK(D19), D19=0), "0:00", TEXT((IF(AND(TIMEVALUE(IF(ISBLANK(D19), "00:00", D19))>=TIMEVALUE("00:00"), TIMEVALUE(IF(ISBLANK(D19), "00:00", D19))<=TIMEVALUE("06:00")), TIMEVALUE(IF(ISBLANK(D19), "00:00", D19))+1, TIMEVALUE(IF(ISBLANK(D19), "00:00", D19))) - TIMEVALUE(IF(ISBLANK(C19), "00:00", C19)) - TIMEVALUE(IF(ISBLANK(E19), "00:00", E19))), "hh:mm")) -> 0:00
A20: {=IF(ISBLANK(B20), 0, IF(ISNUMBER(MATCH(B20, HR!A:A, 0)), 0, IF(ISNUMBER(MATCH(B20, HR!B:B, 0)), INDEX(HR!V:V, MATCH(B20, HR!B:B, 0)) * (F20 * 24), 0)))} -> 0 | F20: =IF(OR(ISBLANK(B20), ISBLANK(D20), D20=0), "0:00", TEXT((IF(AND(TIMEVALUE(IF(ISBLANK(D20), "00:00", D20))>=TIMEVALUE("00:00"), TIMEVALUE(IF(ISBLANK(D20), "00:00", D20))<=TIMEVALUE("06:00")), TIMEVALUE(IF(ISBLANK(D20), "00:00", D20))+1, TIMEVALUE(IF(ISBLANK(D20), "00:00", D20))) - TIMEVALUE(IF(ISBLANK(C20), "00:00", C20)) - TIMEVALUE(IF(ISBLANK(E20), "00:00", E20))), "hh:mm")) -> 0:00
A21: {=IF(ISBLANK(B21), 0, IF(ISNUMBER(MATCH(B21, HR!A:A, 0)), 0, IF(ISNUMBER(MATCH(B21, HR!B:B, 0)), INDEX(HR!V:V, MATCH(B21, HR!B:B, 0)) * (F21 * 24), 0)))} -> 0 | F21: =IF(OR(ISBLANK(B21), ISBLANK(D21), D21=0), "0:00", TEXT((IF(AND(TIMEVALUE(IF(ISBLANK(D21), "00:00", D21))>=TIMEVALUE("00:00"), TIMEVALUE(IF(ISBLANK(D21), "00:00", D21))<=TIMEVALUE("06:00")), TIMEVALUE(IF(ISBLANK(D21), "00:00", D21))+1, TIMEVALUE(IF(ISBLANK(D21), "00:00", D21))) - TIMEVALUE(IF(ISBLANK(C21), "00:00", C21)) - TIMEVALUE(IF(ISBLANK(E21), "00:00", E21))), "hh:mm")) -> 0:00
J22: Zrušené obj. ks | K22: Zrušené obj. $ | L22: Počet zpožděných našich rozvozů +5 min | M22: Průměrný make Time
B23: Kurýr | J23: =COUNTIF(RestiaCSV!B:B, "canceled") -> 0 | K23: =SUMIF(RestiaCSV!B:B, "canceled", RestiaCSV!C:C) -> 0 | L23: =COUNTIFS(RestiaCSV!L:L, ">5", RestiaCSV!F:F, "delivery") -> 0 | M23: =INT(AVERAGEIFS(RestiaCSV!N:N, RestiaCSV!N:N, ">=5", RestiaCSV!N:N, "<=30")) & " min " & TEXT(MOD(AVERAGEIFS(RestiaCSV!N:N, RestiaCSV!N:N, ">=5", RestiaCSV!N:N, "<=30") * 60, 60), "00") & " s" -> #DIV/0!
B24: Jméno | C24: Začátek směny | D24: Konec směny | E24: pauza | F24: Počet hodin | G24: Počet rozvozů | H24: Vlastní vůz | I24: Vyplatit PHM | J24: počet výdajových dokadů | K24: Počet nezrušených celkem | L24: Počet našich rozvozů | M24: Počet pozdě přiřazeným WoltDrive 5+
A25: {=IF(ISBLANK(B25), 0, IF(ISNUMBER(MATCH(B25, HR!A:A, 0)), 0, IF(ISNUMBER(MATCH(B25, HR!B:B, 0)), INDEX(HR!V:V, MATCH(B25, HR!B:B, 0)) * (F25 * 24), 0)))} -> 1157.37 | B25: Serin David | C25: 17:00 | D25: 22:00 | F25: =IF(OR(ISBLANK(B25), ISBLANK(D25), D25=0), "0:00", TEXT((IF(AND(TIMEVALUE(IF(ISBLANK(D25), "00:00", D25))>=TIMEVALUE("00:00"), TIMEVALUE(IF(ISBLANK(D25), "00:00", D25))<=TIMEVALUE("06:00")), TIMEVALUE(IF(ISBLANK(D25), "00:00", D25))+1, TIMEVALUE(IF(ISBLANK(D25), "00:00", D25))) - TIMEVALUE(IF(ISBLANK(C25), "00:00", C25)) - TIMEVALUE(IF(ISBLANK(E25), "00:00", E25))), "hh:mm")) -> 05:00 | G25: =COUNTIF(RestiaCSV!E:E, B25) -> 0 | H25: TRUE | I25: =IF(H25,G25*45, 0) -> 0
A26: {=IF(ISBLANK(B26), 0, IF(ISNUMBER(MATCH(B26, HR!A:A, 0)), 0, IF(ISNUMBER(MATCH(B26, HR!B:B, 0)), INDEX(HR!V:V, MATCH(B26, HR!B:B, 0)) * (F26 * 24), 0)))} -> 0 | F26: =IF(OR(ISBLANK(B26), ISBLANK(D26), D26=0), "0:00", TEXT((IF(AND(TIMEVALUE(IF(ISBLANK(D26), "00:00", D26))>=TIMEVALUE("00:00"), TIMEVALUE(IF(ISBLANK(D26), "00:00", D26))<=TIMEVALUE("06:00")), TIMEVALUE(IF(ISBLANK(D26), "00:00", D26))+1, TIMEVALUE(IF(ISBLANK(D26), "00:00", D26))) - TIMEVALUE(IF(ISBLANK(C26), "00:00", C26)) - TIMEVALUE(IF(ISBLANK(E26), "00:00", E26))), "hh:mm")) -> 0:00 | G26: =COUNTIF(RestiaCSV!E:E, B26) -> 0 | H26: TRUE | I26: =IF(H26,G26*45, 0) -> 0 | J26: =COUNTIF(I25:I31, ">0") -> 0 | K26: =IFERROR(__xludf.DUMMYFUNCTION("COUNTA(FILTER(RestiaCSV!B2:B32, RestiaCSV!B2:B32 <> ""canceled""))"),0.0) -> 0 | L26: =COUNTIF(RestiaCSV!F1:F32, "delivery") -> 0 | M26: =COUNTIFS(RestiaCSV!M:M, ">5",RestiaCSV!A:A, "<>wolt") -> 0
A27: {=IF(ISBLANK(B27), 0, IF(ISNUMBER(MATCH(B27, HR!A:A, 0)), 0, IF(ISNUMBER(MATCH(B27, HR!B:B, 0)), INDEX(HR!V:V, MATCH(B27, HR!B:B, 0)) * (F27 * 24), 0)))} -> 0 | F27: =IF(OR(ISBLANK(B27), ISBLANK(D27), D27=0), "0:00", TEXT((IF(AND(TIMEVALUE(IF(ISBLANK(D27), "00:00", D27))>=TIMEVALUE("00:00"), TIMEVALUE(IF(ISBLANK(D27), "00:00", D27))<=TIMEVALUE("06:00")), TIMEVALUE(IF(ISBLANK(D27), "00:00", D27))+1, TIMEVALUE(IF(ISBLANK(D27), "00:00", D27))) - TIMEVALUE(IF(ISBLANK(C27), "00:00", C27)) - TIMEVALUE(IF(ISBLANK(E27), "00:00", E27))), "hh:mm")) -> 0:00 | G27: =COUNTIF(RestiaCSV!E:E, B27) -> 0 | H27: TRUE | I27: =IF(H27,G27*45, 0) -> 0 | J27: Woltrdive zpožděný kvůli našemu pozdnímu přiřazení | L27: % zpožděných našich rozvozů +5 min | M27: Počet zpožděných Woltdrivem
A28: {=IF(ISBLANK(B28), 0, IF(ISNUMBER(MATCH(B28, HR!A:A, 0)), 0, IF(ISNUMBER(MATCH(B28, HR!B:B, 0)), INDEX(HR!V:V, MATCH(B28, HR!B:B, 0)) * (F28 * 24), 0)))} -> 0 | F28: =IF(OR(ISBLANK(B28), ISBLANK(D28), D28=0), "0:00", TEXT((IF(AND(TIMEVALUE(IF(ISBLANK(D28), "00:00", D28))>=TIMEVALUE("00:00"), TIMEVALUE(IF(ISBLANK(D28), "00:00", D28))<=TIMEVALUE("06:00")), TIMEVALUE(IF(ISBLANK(D28), "00:00", D28))+1, TIMEVALUE(IF(ISBLANK(D28), "00:00", D28))) - TIMEVALUE(IF(ISBLANK(C28), "00:00", C28)) - TIMEVALUE(IF(ISBLANK(E28), "00:00", E28))), "hh:mm")) -> 0:00 | G28: =COUNTIF(RestiaCSV!E:E, B28) -> 0 | H28: FALSE | I28: =IF(H28,G28*45, 0) -> 0
A29: {=IF(ISBLANK(B29), 0, IF(ISNUMBER(MATCH(B29, HR!A:A, 0)), 0, IF(ISNUMBER(MATCH(B29, HR!B:B, 0)), INDEX(HR!V:V, MATCH(B29, HR!B:B, 0)) * (F29 * 24), 0)))} -> 0 | F29: =IF(OR(ISBLANK(B29), ISBLANK(D29), D29=0), "0:00", TEXT((IF(AND(TIMEVALUE(IF(ISBLANK(D29), "00:00", D29))>=TIMEVALUE("00:00"), TIMEVALUE(IF(ISBLANK(D29), "00:00", D29))<=TIMEVALUE("06:00")), TIMEVALUE(IF(ISBLANK(D29), "00:00", D29))+1, TIMEVALUE(IF(ISBLANK(D29), "00:00", D29))) - TIMEVALUE(IF(ISBLANK(C29), "00:00", C29)) - TIMEVALUE(IF(ISBLANK(E29), "00:00", E29))), "hh:mm")) -> 0:00 | G29: =COUNTIF(RestiaCSV!E:E, B29) -> 0 | H29: FALSE | I29: =IF(H29,G29*45, 0) -> 0 | J29: =COUNTIFS(RestiaCSV!M:M, ">5", RestiaCSV!L:L, ">5") -> 0 | L29: =L23/L26 -> #DIV/0! | M29: =COUNTIFS(RestiaCSV!L:L, ">5", RestiaCSV!F:F, "delivery", RestiaCSV!E:E, "Wolt Kurýr") -> 0
A30: {=IF(ISBLANK(B30), 0, IF(ISNUMBER(MATCH(B30, HR!A:A, 0)), 0, IF(ISNUMBER(MATCH(B30, HR!B:B, 0)), INDEX(HR!V:V, MATCH(B30, HR!B:B, 0)) * (F30 * 24), 0)))} -> 0 | F30: =IF(OR(ISBLANK(B30), ISBLANK(D30), D30=0), "0:00", TEXT((IF(AND(TIMEVALUE(IF(ISBLANK(D30), "00:00", D30))>=TIMEVALUE("00:00"), TIMEVALUE(IF(ISBLANK(D30), "00:00", D30))<=TIMEVALUE("06:00")), TIMEVALUE(IF(ISBLANK(D30), "00:00", D30))+1, TIMEVALUE(IF(ISBLANK(D30), "00:00", D30))) - TIMEVALUE(IF(ISBLANK(C30), "00:00", C30)) - TIMEVALUE(IF(ISBLANK(E30), "00:00", E30))), "hh:mm")) -> 0:00 | G30: =COUNTIF(RestiaCSV!E:E, B30) -> 0 | H30: FALSE | I30: =IF(H30,G30*45, 0) -> 0 | L30: % doručených včas | M30: % zpožděných Woltdrivem
A31: {=IF(ISBLANK(B31), 0, IF(ISNUMBER(MATCH(B31, HR!A:A, 0)), 0, IF(ISNUMBER(MATCH(B31, HR!B:B, 0)), INDEX(HR!V:V, MATCH(B31, HR!B:B, 0)) * (F31 * 24), 0)))} -> 0 | F31: =IF(OR(ISBLANK(B31), ISBLANK(D31), D31=0), "0:00", TEXT((IF(AND(TIMEVALUE(IF(ISBLANK(D31), "00:00", D31))>=TIMEVALUE("00:00"), TIMEVALUE(IF(ISBLANK(D31), "00:00", D31))<=TIMEVALUE("06:00")), TIMEVALUE(IF(ISBLANK(D31), "00:00", D31))+1, TIMEVALUE(IF(ISBLANK(D31), "00:00", D31))) - TIMEVALUE(IF(ISBLANK(C31), "00:00", C31)) - TIMEVALUE(IF(ISBLANK(E31), "00:00", E31))), "hh:mm")) -> 0:00 | G31: =COUNTIF(RestiaCSV!E:E, B31) -> 0 | H31: FALSE | I31: =IF(H31,G31*45, 0) -> 0
B32: Wolt Kurýr | C32: Wolt drive | G32: =COUNTIFS(RestiaCSV!E:E, "wolt kurýr", RestiaCSV!A:A, "<>wolt") -> 0 | H32: TRUE | I32: =G32*127 -> 0 | L32: =100%-L29 -> #DIV/0! | M32: =M29/L26 -> #DIV/0!

Sheet Kontrola
B1: =Report!B1 -> Libuš | C1: 46113 | D1: Vyber datum <----------> | E1: 46113 | F1: COL | I1: Tržba | L1: Online Platby
F2: 0.24432488 | I2: 40920 | L2: Wolt | M2: 10559
B3: =CHOOSE(WEEKDAY(C1), "Neděle", "Pondělí", "Úterý", "Středa", "Čtvrtek", "Pátek", "Sobota") -> Středa | D3: =CHOOSE(WEEKDAY(E1), "Neděle", "Pondělí", "Úterý", "Středa", "Čtvrtek", "Pátek", "Sobota") -> Středa | L3: Bolt | M3: 6782
L4: Dáme jídlo | M4: 11769
B5: Celkem hodin Instor | F5: Celkem hodin Kurýr | L5: Web | M5: 4421
L6: Wolt drive cash | M6: 0
B7: =TEXT(SUMPRODUCT((IFERROR(LEFT(D10:D30, FIND(":", D10:D30) - 1) * 60, 0) + IFERROR(MID(D10:D30, FIND(":", D10:D30) + 1, LEN(D10:D30) - FIND(":", D10:D30)), 0))), "[h]:mm")/60 -> 8 | F7: =TEXT(SUMPRODUCT((IFERROR(LEFT(H10:H30, FIND(":", H10:H30) - 1) * 60, 0) + IFERROR(MID(H10:H30, FIND(":", H10:H30) + 1, LEN(H10:H30) - FIND(":", H10:H30)), 0))), "[h]:mm")/60 -> 14 | L7: DJ Cash | M7: 3241
B8: Instor | F8: Kurýr | J8: Pokladna | L8: Hotovost
B9: Jméno | C9: Počet dní | D9: Počet hodin | F9: Jméno | G9: Počet dní | H9: Počet hodin | I9: Počet rozvozů | J9: 0 | L9: Terminál | M9: 2777
B10: Bubník Martin | C10: 1 | D10: 8:00 | E10: 29:00 | F10: Dušek Sam | G10: 1 | H10: 14:00 | I10: 12 | L10: Stravenky | M10: 0
E11: 23:00 | L11: Hotovost | M11: 4072
E12: 13:00 | L12: Výdaje
E13: 13:00 | L13: Benzín | M13: 0
E14: 7:00 | L14: Auta | M14: 0
E15: 7:00 | L15: Suroviny | M15: 0
L16: Ostatní | M16: 0
L17: PHM - soukromé | M17: 540
J19: Zrušené obj. ks | K19: Zrušené obj. $ | L19: Počet zpožděných našich rozvozů +5 min | M19: Průměrný make Time
J21: 1 | K21: 528 | L21: 1 | M21: 15 min 43 s
J22: počet výdajových dokadů | K22: Počet nezrušených celkem | L22: Počet našich rozvozů | M22: Počet pozdě přiřazeným WoltDrive 5+
J24: 1 | K24: 91 | L24: 12 | M24: 1
J25: Woltrdive zpožděný kvůli našemu pozdnímu přiřazení | L25: % zpožděných našich rozvozů +5 min | M25: Počet zpožděných Woltdrivem
J27: 0 | L27: 0.083333333 | M27: 0
L28: % doručených včas | M28: % zpožděných Woltdrivem
L30: 0.91666667 | M30: 0

Sheet RestiaCSV

Sheet HR
C1: =IFERROR(__xludf.DUMMYFUNCTION("IMPORTRANGE(""1TpIiNTfR1pnpn85VWQTTdvQ2Xcr0GStmWJ2UvfKxG_A"", ""Mzdy!A1:F200"")")," ") | V1: =IFERROR(__xludf.DUMMYFUNCTION("IMPORTRANGE(""1TpIiNTfR1pnpn85VWQTTdvQ2Xcr0GStmWJ2UvfKxG_A"", ""Mzdy!ac1:ad200"")"),30.0) -> 30 | W1: =IFERROR(__xludf.DUMMYFUNCTION("""COMPUTED_VALUE"""),"dní") -> dní
B2: Vlož Souhrn mzdy
A4: Manažeři | B4: Zamestnanci pobocky | C4: =IFERROR(__xludf.DUMMYFUNCTION("""COMPUTED_VALUE"""),"Manažer") -> Manažer | D4: =IFERROR(__xludf.DUMMYFUNCTION("""COMPUTED_VALUE"""),"Instore") -> Instore | E4: =IFERROR(__xludf.DUMMYFUNCTION("""COMPUTED_VALUE"""),"První domácí, Pobočky max 4") -> První domácí, Pobočky max 4 | V4: =IFERROR(__xludf.DUMMYFUNCTION("""COMPUTED_VALUE"""),"Sp.hr. / h") -> Sp.hr. / h | W4: =IFERROR(__xludf.DUMMYFUNCTION("""COMPUTED_VALUE"""),"Sp.hr. / den") -> Sp.hr. / den
A5: =IF(AND(B5<>"", C5=TRUE, E5=Report!$B$1), B5, "") | B5: =IF(OR(E5=Report!$B$1, F5=Report!$B$1, G5=Report!$B$1, H5=Report!$B$1), D5, "") | C5: =IFERROR(__xludf.DUMMYFUNCTION("""COMPUTED_VALUE"""),TRUE) -> TRUE | D5: =IFERROR(__xludf.DUMMYFUNCTION("""COMPUTED_VALUE"""),"Nedbal Michal") -> Nedbal Michal | E5: =IFERROR(__xludf.DUMMYFUNCTION("""COMPUTED_VALUE"""),"Zličín") -> Zličín | F5: =IFERROR(__xludf.DUMMYFUNCTION("""COMPUTED_VALUE"""),"Malešice") -> Malešice | G5: =IFERROR(__xludf.DUMMYFUNCTION("""COMPUTED_VALUE"""),"Prosek") -> Prosek | V5: =IFERROR(__xludf.DUMMYFUNCTION("""COMPUTED_VALUE"""),432.3078) -> 432.3078 | W5: =IFERROR(__xludf.DUMMYFUNCTION("""COMPUTED_VALUE"""),2882.052) -> 2882.052
A6: =IF(AND(B6<>"", C6=TRUE, E6=Report!$B$1), B6, "") | B6: =IF(OR(E6=Report!$B$1, F6=Report!$B$1, G6=Report!$B$1, H6=Report!$B$1), D6, "") | C6: =IFERROR(__xludf.DUMMYFUNCTION("""COMPUTED_VALUE"""),FALSE) -> FALSE | V6: =IFERROR(__xludf.DUMMYFUNCTION("""COMPUTED_VALUE"""),0.0) -> 0 | W6: =IFERROR(__xludf.DUMMYFUNCTION("""COMPUTED_VALUE"""),0.0) -> 0
A7: =IF(AND(B7<>"", C7=TRUE, E7=Report!$B$1), B7, "") | B7: =IF(OR(E7=Report!$B$1, F7=Report!$B$1, G7=Report!$B$1, H7=Report!$B$1), D7, "") -> Sova Martin | C7: =IFERROR(__xludf.DUMMYFUNCTION("""COMPUTED_VALUE"""),TRUE) -> TRUE | D7: =IFERROR(__xludf.DUMMYFUNCTION("""COMPUTED_VALUE"""),"Sova Martin") -> Sova Martin | E7: =IFERROR(__xludf.DUMMYFUNCTION("""COMPUTED_VALUE"""),"Chodov") -> Chodov | F7: =IFERROR(__xludf.DUMMYFUNCTION("""COMPUTED_VALUE"""),"Libuš") -> Libuš | G7: =IFERROR(__xludf.DUMMYFUNCTION("""COMPUTED_VALUE"""),"Výroba") -> Výroba | V7: =IFERROR(__xludf.DUMMYFUNCTION("""COMPUTED_VALUE"""),432.3078) -> 432.3078 | W7: =IFERROR(__xludf.DUMMYFUNCTION("""COMPUTED_VALUE"""),2882.052) -> 2882.052
A8: =IF(AND(B8<>"", C8=TRUE, E8=Report!$B$1), B8, "") | B8: =IF(OR(E8=Report!$B$1, F8=Report!$B$1, G8=Report!$B$1, H8=Report!$B$1), D8, "") | C8: =IFERROR(__xludf.DUMMYFUNCTION("""COMPUTED_VALUE"""),TRUE) -> TRUE | D8: =IFERROR(__xludf.DUMMYFUNCTION("""COMPUTED_VALUE"""),"Paziak Viktoriia") -> Paziak Viktoriia | E8: =IFERROR(__xludf.DUMMYFUNCTION("""COMPUTED_VALUE"""),"Výroba") -> Výroba | V8: =IFERROR(__xludf.DUMMYFUNCTION("""COMPUTED_VALUE"""),341.19) -> 341.19 | W8: =IFERROR(__xludf.DUMMYFUNCTION("""COMPUTED_VALUE"""),2274.6) -> 2274.6
A9: =IF(AND(B9<>"", C9=TRUE, E9=Report!$B$1), B9, "") | B9: =IF(OR(E9=Report!$B$1, F9=Report!$B$1, G9=Report!$B$1, H9=Report!$B$1), D9, "") -> Ahurieva Viktoriia | C9: =IFERROR(__xludf.DUMMYFUNCTION("""COMPUTED_VALUE"""),FALSE) -> FALSE | D9: =IFERROR(__xludf.DUMMYFUNCTION("""COMPUTED_VALUE"""),"Ahurieva Viktoriia") -> Ahurieva Viktoriia | E9: =IFERROR(__xludf.DUMMYFUNCTION("""COMPUTED_VALUE"""),"Libuš") -> Libuš | F9: =IFERROR(__xludf.DUMMYFUNCTION("""COMPUTED_VALUE"""),"Malešice") -> Malešice | G9: =IFERROR(__xludf.DUMMYFUNCTION("""COMPUTED_VALUE"""),"Chodov") -> Chodov | H9: =IFERROR(__xludf.DUMMYFUNCTION("""COMPUTED_VALUE"""),"Prosek") -> Prosek | V9: =IFERROR(__xludf.DUMMYFUNCTION("""COMPUTED_VALUE"""),432.3078) -> 432.3078 | W9: =IFERROR(__xludf.DUMMYFUNCTION("""COMPUTED_VALUE"""),2882.052) -> 2882.052
A10: =IF(AND(B10<>"", C10=TRUE, E10=Report!$B$1), B10, "") | B10: =IF(OR(E10=Report!$B$1, F10=Report!$B$1, G10=Report!$B$1, H10=Report!$B$1), D10, "") | C10: =IFERROR(__xludf.DUMMYFUNCTION("""COMPUTED_VALUE"""),TRUE) -> TRUE | D10: =IFERROR(__xludf.DUMMYFUNCTION("""COMPUTED_VALUE"""),"Pešová Hana") -> Pešová Hana | E10: =IFERROR(__xludf.DUMMYFUNCTION("""COMPUTED_VALUE"""),"Chodov") -> Chodov | F10: =IFERROR(__xludf.DUMMYFUNCTION("""COMPUTED_VALUE"""),"Prosek") -> Prosek | V10: =IFERROR(__xludf.DUMMYFUNCTION("""COMPUTED_VALUE"""),341.19) -> 341.19 | W10: =IFERROR(__xludf.DUMMYFUNCTION("""COMPUTED_VALUE"""),2274.6) -> 2274.6
A11: =IF(AND(B11<>"", C11=TRUE, E11=Report!$B$1), B11, "") | B11: =IF(OR(E11=Report!$B$1, F11=Report!$B$1, G11=Report!$B$1, H11=Report!$B$1), D11, "") -> Šebesta Tomáš | C11: =IFERROR(__xludf.DUMMYFUNCTION("""COMPUTED_VALUE"""),TRUE) -> TRUE | D11: =IFERROR(__xludf.DUMMYFUNCTION("""COMPUTED_VALUE"""),"Šebesta Tomáš") -> Šebesta Tomáš | E11: =IFERROR(__xludf.DUMMYFUNCTION("""COMPUTED_VALUE"""),"Prosek") -> Prosek | F11: =IFERROR(__xludf.DUMMYFUNCTION("""COMPUTED_VALUE"""),"Libuš") -> Libuš | G11: =IFERROR(__xludf.DUMMYFUNCTION("""COMPUTED_VALUE"""),"Malešice") -> Malešice | H11: =IFERROR(__xludf.DUMMYFUNCTION("""COMPUTED_VALUE"""),"Chodov") -> Chodov | V11: =IFERROR(__xludf.DUMMYFUNCTION("""COMPUTED_VALUE"""),432.3078) -> 432.3078 | W11: =IFERROR(__xludf.DUMMYFUNCTION("""COMPUTED_VALUE"""),2882.052) -> 2882.052
A12: =IF(AND(B12<>"", C12=TRUE, E12=Report!$B$1), B12, "") | B12: =IF(OR(E12=Report!$B$1, F12=Report!$B$1, G12=Report!$B$1, H12=Report!$B$1), D12, "") | C12: =IFERROR(__xludf.DUMMYFUNCTION("""COMPUTED_VALUE"""),FALSE) -> FALSE | D12: =IFERROR(__xludf.DUMMYFUNCTION("""COMPUTED_VALUE"""),"Hanakova Ayuna") -> Hanakova Ayuna | E12: =IFERROR(__xludf.DUMMYFUNCTION("""COMPUTED_VALUE"""),"Zličín") -> Zličín | V12: =IFERROR(__xludf.DUMMYFUNCTION("""COMPUTED_VALUE"""),295.698) -> 295.698 | W12: =IFERROR(__xludf.DUMMYFUNCTION("""COMPUTED_VALUE"""),0.0) -> 0
A13: =IF(AND(B13<>"", C13=TRUE, E13=Report!$B$1), B13, "") | B13: =IF(OR(E13=Report!$B$1, F13=Report!$B$1, G13=Report!$B$1, H13=Report!$B$1), D13, "") | C13: =IFERROR(__xludf.DUMMYFUNCTION("""COMPUTED_VALUE"""),FALSE) -> FALSE | D13: =IFERROR(__xludf.DUMMYFUNCTION("""COMPUTED_VALUE"""),"Vondráček Lukáš") -> Vondráček Lukáš | V13: =IFERROR(__xludf.DUMMYFUNCTION("""COMPUTED_VALUE"""),0.0) -> 0 | W13: =IFERROR(__xludf.DUMMYFUNCTION("""COMPUTED_VALUE"""),0.0) -> 0
A14: =IF(AND(B14<>"", C14=TRUE, E14=Report!$B$1), B14, "") | B14: =IF(OR(E14=Report!$B$1, F14=Report!$B$1, G14=Report!$B$1, H14=Report!$B$1), D14, "") | C14: =IFERROR(__xludf.DUMMYFUNCTION("""COMPUTED_VALUE"""),TRUE) -> TRUE | D14: =IFERROR(__xludf.DUMMYFUNCTION("""COMPUTED_VALUE"""),"Veselý Ondřej") -> Veselý Ondřej | E14: =IFERROR(__xludf.DUMMYFUNCTION("""COMPUTED_VALUE"""),"Zličín") -> Zličín | F14: =IFERROR(__xludf.DUMMYFUNCTION("""COMPUTED_VALUE"""),"Malešice") -> Malešice | V14: =IFERROR(__xludf.DUMMYFUNCTION("""COMPUTED_VALUE"""),341.19) -> 341.19 | W14: =IFERROR(__xludf.DUMMYFUNCTION("""COMPUTED_VALUE"""),2274.6) -> 2274.6
A15: =IF(AND(B15<>"", C15=TRUE, E15=Report!$B$1), B15, "") | B15: =IF(OR(E15=Report!$B$1, F15=Report!$B$1, G15=Report!$B$1, H15=Report!$B$1), D15, "") -> Coufal Jakub | C15: =IFERROR(__xludf.DUMMYFUNCTION("""COMPUTED_VALUE"""),FALSE) -> FALSE | D15: =IFERROR(__xludf.DUMMYFUNCTION("""COMPUTED_VALUE"""),"Coufal Jakub") -> Coufal Jakub | E15: =IFERROR(__xludf.DUMMYFUNCTION("""COMPUTED_VALUE"""),"Libuš") -> Libuš | F15: =IFERROR(__xludf.DUMMYFUNCTION("""COMPUTED_VALUE"""),"Malešice") -> Malešice | V15: =IFERROR(__xludf.DUMMYFUNCTION("""COMPUTED_VALUE"""),250.20600000000002) -> 250.206 | W15: =IFERROR(__xludf.DUMMYFUNCTION("""COMPUTED_VALUE"""),0.0) -> 0
A16: =IF(AND(B16<>"", C16=TRUE, E16=Report!$B$1), B16, "") | B16: =IF(OR(E16=Report!$B$1, F16=Report!$B$1, G16=Report!$B$1, H16=Report!$B$1), D16, "") | C16: =IFERROR(__xludf.DUMMYFUNCTION("""COMPUTED_VALUE"""),FALSE) -> FALSE | D16: =IFERROR(__xludf.DUMMYFUNCTION("""COMPUTED_VALUE"""),"Pekárková Milena") -> Pekárková Milena | E16: =IFERROR(__xludf.DUMMYFUNCTION("""COMPUTED_VALUE"""),"Prosek") -> Prosek | F16: =IFERROR(__xludf.DUMMYFUNCTION("""COMPUTED_VALUE"""),"Malešice") -> Malešice | V16: =IFERROR(__xludf.DUMMYFUNCTION("""COMPUTED_VALUE"""),341.19) -> 341.19 | W16: =IFERROR(__xludf.DUMMYFUNCTION("""COMPUTED_VALUE"""),0.0) -> 0
A17: =IF(AND(B17<>"", C17=TRUE, E17=Report!$B$1), B17, "") | B17: =IF(OR(E17=Report!$B$1, F17=Report!$B$1, G17=Report!$B$1, H17=Report!$B$1), D17, "") | C17: =IFERROR(__xludf.DUMMYFUNCTION("""COMPUTED_VALUE"""),TRUE) -> TRUE | D17: =IFERROR(__xludf.DUMMYFUNCTION("""COMPUTED_VALUE"""),"Kinkorová Petra") -> Kinkorová Petra | E17: =IFERROR(__xludf.DUMMYFUNCTION("""COMPUTED_VALUE"""),"Malešice") -> Malešice | F17: =IFERROR(__xludf.DUMMYFUNCTION("""COMPUTED_VALUE"""),"Zličín") -> Zličín | V17: =IFERROR(__xludf.DUMMYFUNCTION("""COMPUTED_VALUE"""),341.19) -> 341.19 | W17: =IFERROR(__xludf.DUMMYFUNCTION("""COMPUTED_VALUE"""),2274.6) -> 2274.6
A18: =IF(AND(B18<>"", C18=TRUE, E18=Report!$B$1), B18, "") | B18: =IF(OR(E18=Report!$B$1, F18=Report!$B$1, G18=Report!$B$1, H18=Report!$B$1), D18, "") | C18: =IFERROR(__xludf.DUMMYFUNCTION("""COMPUTED_VALUE"""),TRUE) -> TRUE | D18: =IFERROR(__xludf.DUMMYFUNCTION("""COMPUTED_VALUE"""),"Nováková Adéla") -> Nováková Adéla | E18: =IFERROR(__xludf.DUMMYFUNCTION("""COMPUTED_VALUE"""),"Prosek") -> Prosek | F18: =IFERROR(__xludf.DUMMYFUNCTION("""COMPUTED_VALUE"""),"Malešice") -> Malešice | V18: =IFERROR(__xludf.DUMMYFUNCTION("""COMPUTED_VALUE"""),341.19) -> 341.19 | W18: =IFERROR(__xludf.DUMMYFUNCTION("""COMPUTED_VALUE"""),2274.6) -> 2274.6
A19: =IF(AND(B19<>"", C19=TRUE, E19=Report!$B$1), B19, "") | B19: =IF(OR(E19=Report!$B$1, F19=Report!$B$1, G19=Report!$B$1, H19=Report!$B$1), D19, "") | C19: =IFERROR(__xludf.DUMMYFUNCTION("""COMPUTED_VALUE"""),FALSE) -> FALSE | D19: =IFERROR(__xludf.DUMMYFUNCTION("""COMPUTED_VALUE"""),"Pechová Barbora") -> Pechová Barbora | E19: =IFERROR(__xludf.DUMMYFUNCTION("""COMPUTED_VALUE"""),"Zličín") -> Zličín | V19: =IFERROR(__xludf.DUMMYFUNCTION("""COMPUTED_VALUE"""),267.6) -> 267.6 | W19: =IFERROR(__xludf.DUMMYFUNCTION("""COMPUTED_VALUE"""),0.0) -> 0
A20: =IF(AND(B20<>"", C20=TRUE, E20=Report!$B$1), B20, "") | B20: =IF(OR(E20=Report!$B$1, F20=Report!$B$1, G20=Report!$B$1, H20=Report!$B$1), D20, "") | C20: =IFERROR(__xludf.DUMMYFUNCTION("""COMPUTED_VALUE"""),FALSE) -> FALSE | D20: =IFERROR(__xludf.DUMMYFUNCTION("""COMPUTED_VALUE"""),"Stepanenko Solomiia") -> Stepanenko Solomiia | E20: =IFERROR(__xludf.DUMMYFUNCTION("""COMPUTED_VALUE"""),"Výroba") -> Výroba | V20: =IFERROR(__xludf.DUMMYFUNCTION("""COMPUTED_VALUE"""),286.332) -> 286.332 | W20: =IFERROR(__xludf.DUMMYFUNCTION("""COMPUTED_VALUE"""),0.0) -> 0
A21: =IF(AND(B21<>"", C21=TRUE, E21=Report!$B$1), B21, "") | B21: =IF(OR(E21=Report!$B$1, F21=Report!$B$1, G21=Report!$B$1, H21=Report!$B$1), D21, "") | C21: =IFERROR(__xludf.DUMMYFUNCTION("""COMPUTED_VALUE"""),FALSE) -> FALSE | D21: =IFERROR(__xludf.DUMMYFUNCTION("""COMPUTED_VALUE"""),"Rothová Anastasia") -> Rothová Anastasia | E21: =IFERROR(__xludf.DUMMYFUNCTION("""COMPUTED_VALUE"""),"Bolevec") -> Bolevec | V21: =IFERROR(__xludf.DUMMYFUNCTION("""COMPUTED_VALUE"""),341.19) -> 341.19 | W21: =IFERROR(__xludf.DUMMYFUNCTION("""COMPUTED_VALUE"""),0.0) -> 0
A22: =IF(AND(B22<>"", C22=TRUE, E22=Report!$B$1), B22, "") | B22: =IF(OR(E22=Report!$B$1, F22=Report!$B$1, G22=Report!$B$1, H22=Report!$B$1), D22, "") | C22: =IFERROR(__xludf.DUMMYFUNCTION("""COMPUTED_VALUE"""),FALSE) -> FALSE | D22: =IFERROR(__xludf.DUMMYFUNCTION("""COMPUTED_VALUE"""),"Pánková Vendula") -> Pánková Vendula | E22: =IFERROR(__xludf.DUMMYFUNCTION("""COMPUTED_VALUE"""),"Zličín") -> Zličín | V22: =IFERROR(__xludf.DUMMYFUNCTION("""COMPUTED_VALUE"""),267.6) -> 267.6 | W22: =IFERROR(__xludf.DUMMYFUNCTION("""COMPUTED_VALUE"""),0.0) -> 0
A23: =IF(AND(B23<>"", C23=TRUE, E23=Report!$B$1), B23, "") | B23: =IF(OR(E23=Report!$B$1, F23=Report!$B$1, G23=Report!$B$1, H23=Report!$B$1), D23, "") | C23: =IFERROR(__xludf.DUMMYFUNCTION("""COMPUTED_VALUE"""),FALSE) -> FALSE | D23: =IFERROR(__xludf.DUMMYFUNCTION("""COMPUTED_VALUE"""),"Vostrý Daniel") -> Vostrý Daniel | E23: =IFERROR(__xludf.DUMMYFUNCTION("""COMPUTED_VALUE"""),"Bolevec") -> Bolevec | V23: =IFERROR(__xludf.DUMMYFUNCTION("""COMPUTED_VALUE"""),250.20600000000002) -> 250.206 | W23: =IFERROR(__xludf.DUMMYFUNCTION("""COMPUTED_VALUE"""),0.0) -> 0
A24: =IF(AND(B24<>"", C24=TRUE, E24=Report!$B$1), B24, "") -> Hegedüs Erik | B24: =IF(OR(E24=Report!$B$1, F24=Report!$B$1, G24=Report!$B$1, H24=Report!$B$1), D24, "") -> Hegedüs Erik | C24: =IFERROR(__xludf.DUMMYFUNCTION("""COMPUTED_VALUE"""),TRUE) -> TRUE | D24: =IFERROR(__xludf.DUMMYFUNCTION("""COMPUTED_VALUE"""),"Hegedüs Erik") -> Hegedüs Erik | E24: =IFERROR(__xludf.DUMMYFUNCTION("""COMPUTED_VALUE"""),"Libuš") -> Libuš | F24: =IFERROR(__xludf.DUMMYFUNCTION("""COMPUTED_VALUE"""),"Chodov") -> Chodov | G24: =IFERROR(__xludf.DUMMYFUNCTION("""COMPUTED_VALUE"""),"Malešice") -> Malešice | V24: =IFERROR(__xludf.DUMMYFUNCTION("""COMPUTED_VALUE"""),432.3078) -> 432.3078 | W24: =IFERROR(__xludf.DUMMYFUNCTION("""COMPUTED_VALUE"""),2882.052) -> 2882.052
A25: =IF(AND(B25<>"", C25=TRUE, E25=Report!$B$1), B25, "") | B25: =IF(OR(E25=Report!$B$1, F25=Report!$B$1, G25=Report!$B$1, H25=Report!$B$1), D25, "") | C25: =IFERROR(__xludf.DUMMYFUNCTION("""COMPUTED_VALUE"""),TRUE) -> TRUE | D25: =IFERROR(__xludf.DUMMYFUNCTION("""COMPUTED_VALUE"""),"Roth Stanislav ml.") -> Roth Stanislav ml. | E25: =IFERROR(__xludf.DUMMYFUNCTION("""COMPUTED_VALUE"""),"Bolevec") -> Bolevec | V25: =IFERROR(__xludf.DUMMYFUNCTION("""COMPUTED_VALUE"""),432.3078) -> 432.3078 | W25: =IFERROR(__xludf.DUMMYFUNCTION("""COMPUTED_VALUE"""),2882.052) -> 2882.052
A26: =IF(AND(B26<>"", C26=TRUE, E26=Report!$B$1), B26, "") | B26: =IF(OR(E26=Report!$B$1, F26=Report!$B$1, G26=Report!$B$1, H26=Report!$B$1), D26, "") | C26: =IFERROR(__xludf.DUMMYFUNCTION("""COMPUTED_VALUE"""),FALSE) -> FALSE | D26: =IFERROR(__xludf.DUMMYFUNCTION("""COMPUTED_VALUE"""),"Strauss Daniel") -> Strauss Daniel | E26: =IFERROR(__xludf.DUMMYFUNCTION("""COMPUTED_VALUE"""),"Malešice") -> Malešice | F26: =IFERROR(__xludf.DUMMYFUNCTION("""COMPUTED_VALUE"""),"Zličín") -> Zličín | V26: =IFERROR(__xludf.DUMMYFUNCTION("""COMPUTED_VALUE"""),250.20600000000002) -> 250.206 | W26: =IFERROR(__xludf.DUMMYFUNCTION("""COMPUTED_VALUE"""),0.0) -> 0
A27: =IF(AND(B27<>"", C27=TRUE, E27=Report!$B$1), B27, "") | B27: =IF(OR(E27=Report!$B$1, F27=Report!$B$1, G27=Report!$B$1, H27=Report!$B$1), D27, "") | C27: =IFERROR(__xludf.DUMMYFUNCTION("""COMPUTED_VALUE"""),FALSE) -> FALSE | D27: =IFERROR(__xludf.DUMMYFUNCTION("""COMPUTED_VALUE"""),"Makula Radek") -> Makula Radek | E27: =IFERROR(__xludf.DUMMYFUNCTION("""COMPUTED_VALUE"""),"Prosek") -> Prosek | V27: =IFERROR(__xludf.DUMMYFUNCTION("""COMPUTED_VALUE"""),250.20600000000002) -> 250.206 | W27: =IFERROR(__xludf.DUMMYFUNCTION("""COMPUTED_VALUE"""),0.0) -> 0
A28: =IF(AND(B28<>"", C28=TRUE, E28=Report!$B$1), B28, "") | B28: =IF(OR(E28=Report!$B$1, F28=Report!$B$1, G28=Report!$B$1, H28=Report!$B$1), D28, "") | C28: =IFERROR(__xludf.DUMMYFUNCTION("""COMPUTED_VALUE"""),FALSE) -> FALSE | D28: =IFERROR(__xludf.DUMMYFUNCTION("""COMPUTED_VALUE"""),"Pelikán Jan") -> Pelikán Jan | E28: =IFERROR(__xludf.DUMMYFUNCTION("""COMPUTED_VALUE"""),"Chodov") -> Chodov | V28: =IFERROR(__xludf.DUMMYFUNCTION("""COMPUTED_VALUE"""),214.08) -> 214.08 | W28: =IFERROR(__xludf.DUMMYFUNCTION("""COMPUTED_VALUE"""),0.0) -> 0
A29: =IF(AND(B29<>"", C29=TRUE, E29=Report!$B$1), B29, "") | B29: =IF(OR(E29=Report!$B$1, F29=Report!$B$1, G29=Report!$B$1, H29=Report!$B$1), D29, "") | C29: =IFERROR(__xludf.DUMMYFUNCTION("""COMPUTED_VALUE"""),FALSE) -> FALSE | D29: =IFERROR(__xludf.DUMMYFUNCTION("""COMPUTED_VALUE"""),"Horváth Petr") -> Horváth Petr | E29: =IFERROR(__xludf.DUMMYFUNCTION("""COMPUTED_VALUE"""),"Bolevec") -> Bolevec | V29: =IFERROR(__xludf.DUMMYFUNCTION("""COMPUTED_VALUE"""),250.20600000000002) -> 250.206 | W29: =IFERROR(__xludf.DUMMYFUNCTION("""COMPUTED_VALUE"""),0.0) -> 0
A30: =IF(AND(B30<>"", C30=TRUE, E30=Report!$B$1), B30, "") | B30: =IF(OR(E30=Report!$B$1, F30=Report!$B$1, G30=Report!$B$1, H30=Report!$B$1), D30, "") | C30: =IFERROR(__xludf.DUMMYFUNCTION("""COMPUTED_VALUE"""),FALSE) -> FALSE | D30: =IFERROR(__xludf.DUMMYFUNCTION("""COMPUTED_VALUE"""),"Klapperová Giulia Laura") -> Klapperová Giulia Laura | E30: =IFERROR(__xludf.DUMMYFUNCTION("""COMPUTED_VALUE"""),"Bolevec") -> Bolevec | V30: =IFERROR(__xludf.DUMMYFUNCTION("""COMPUTED_VALUE"""),250.20600000000002) -> 250.206 | W30: =IFERROR(__xludf.DUMMYFUNCTION("""COMPUTED_VALUE"""),0.0) -> 0
A31: =IF(AND(B31<>"", C31=TRUE, E31=Report!$B$1), B31, "") | B31: =IF(OR(E31=Report!$B$1, F31=Report!$B$1, G31=Report!$B$1, H31=Report!$B$1), D31, "") -> Bubník Martin | C31: =IFERROR(__xludf.DUMMYFUNCTION("""COMPUTED_VALUE"""),FALSE) -> FALSE | D31: =IFERROR(__xludf.DUMMYFUNCTION("""COMPUTED_VALUE"""),"Bubník Martin") -> Bubník Martin | E31: =IFERROR(__xludf.DUMMYFUNCTION("""COMPUTED_VALUE"""),"Libuš") -> Libuš | V31: =IFERROR(__xludf.DUMMYFUNCTION("""COMPUTED_VALUE"""),267.6) -> 267.6 | W31: =IFERROR(__xludf.DUMMYFUNCTION("""COMPUTED_VALUE"""),0.0) -> 0
A32: =IF(AND(B32<>"", C32=TRUE, E32=Report!$B$1), B32, "") | B32: =IF(OR(E32=Report!$B$1, F32=Report!$B$1, G32=Report!$B$1, H32=Report!$B$1), D32, "") | C32: =IFERROR(__xludf.DUMMYFUNCTION("""COMPUTED_VALUE"""),FALSE) -> FALSE | D32: =IFERROR(__xludf.DUMMYFUNCTION("""COMPUTED_VALUE"""),"Mirga Simon") -> Mirga Simon | E32: =IFERROR(__xludf.DUMMYFUNCTION("""COMPUTED_VALUE"""),"Malešice") -> Malešice | V32: =IFERROR(__xludf.DUMMYFUNCTION("""COMPUTED_VALUE"""),231.474) -> 231.474 | W32: =IFERROR(__xludf.DUMMYFUNCTION("""COMPUTED_VALUE"""),0.0) -> 0
A33: =IF(AND(B33<>"", C33=TRUE, E33=Report!$B$1), B33, "") | B33: =IF(OR(E33=Report!$B$1, F33=Report!$B$1, G33=Report!$B$1, H33=Report!$B$1), D33, "") | C33: =IFERROR(__xludf.DUMMYFUNCTION("""COMPUTED_VALUE"""),FALSE) -> FALSE | D33: =IFERROR(__xludf.DUMMYFUNCTION("""COMPUTED_VALUE"""),"Bušek Pavel") -> Bušek Pavel | E33: =IFERROR(__xludf.DUMMYFUNCTION("""COMPUTED_VALUE"""),"Prosek") -> Prosek | V33: =IFERROR(__xludf.DUMMYFUNCTION("""COMPUTED_VALUE"""),250.20600000000002) -> 250.206 | W33: =IFERROR(__xludf.DUMMYFUNCTION("""COMPUTED_VALUE"""),0.0) -> 0
A34: =IF(AND(B34<>"", C34=TRUE, E34=Report!$B$1), B34, "") | B34: =IF(OR(E34=Report!$B$1, F34=Report!$B$1, G34=Report!$B$1, H34=Report!$B$1), D34, "") -> Berdar Vasyl | C34: =IFERROR(__xludf.DUMMYFUNCTION("""COMPUTED_VALUE"""),FALSE) -> FALSE | D34: =IFERROR(__xludf.DUMMYFUNCTION("""COMPUTED_VALUE"""),"Berdar Vasyl") -> Berdar Vasyl | E34: =IFERROR(__xludf.DUMMYFUNCTION("""COMPUTED_VALUE"""),"Libuš") -> Libuš | V34: =IFERROR(__xludf.DUMMYFUNCTION("""COMPUTED_VALUE"""),286.332) -> 286.332 | W34: =IFERROR(__xludf.DUMMYFUNCTION("""COMPUTED_VALUE"""),0.0) -> 0
A35: =IF(AND(B35<>"", C35=TRUE, E35=Report!$B$1), B35, "") | B35: =IF(OR(E35=Report!$B$1, F35=Report!$B$1, G35=Report!$B$1, H35=Report!$B$1), D35, "") | C35: =IFERROR(__xludf.DUMMYFUNCTION("""COMPUTED_VALUE"""),FALSE) -> FALSE | D35: =IFERROR(__xludf.DUMMYFUNCTION("""COMPUTED_VALUE"""),"Yarushynskyi Vladyslav") -> Yarushynskyi Vladyslav | E35: =IFERROR(__xludf.DUMMYFUNCTION("""COMPUTED_VALUE"""),"Chodov") -> Chodov | F35: =IFERROR(__xludf.DUMMYFUNCTION("""COMPUTED_VALUE"""),"Malešice") -> Malešice | G35: =IFERROR(__xludf.DUMMYFUNCTION("""COMPUTED_VALUE"""),"Zličín") -> Zličín | V35: =IFERROR(__xludf.DUMMYFUNCTION("""COMPUTED_VALUE"""),267.6) -> 267.6 | W35: =IFERROR(__xludf.DUMMYFUNCTION("""COMPUTED_VALUE"""),0.0) -> 0
A36: =IF(AND(B36<>"", C36=TRUE, E36=Report!$B$1), B36, "") | B36: =IF(OR(E36=Report!$B$1, F36=Report!$B$1, G36=Report!$B$1, H36=Report!$B$1), D36, "") | C36: =IFERROR(__xludf.DUMMYFUNCTION("""COMPUTED_VALUE"""),FALSE) -> FALSE | D36: =IFERROR(__xludf.DUMMYFUNCTION("""COMPUTED_VALUE"""),"Raboch Tomáš") -> Raboch Tomáš | E36: =IFERROR(__xludf.DUMMYFUNCTION("""COMPUTED_VALUE"""),"Bolevec") -> Bolevec | V36: =IFERROR(__xludf.DUMMYFUNCTION("""COMPUTED_VALUE"""),250.20600000000002) -> 250.206 | W36: =IFERROR(__xludf.DUMMYFUNCTION("""COMPUTED_VALUE"""),0.0) -> 0
A37: =IF(AND(B37<>"", C37=TRUE, E37=Report!$B$1), B37, "") | B37: =IF(OR(E37=Report!$B$1, F37=Report!$B$1, G37=Report!$B$1, H37=Report!$B$1), D37, "") | C37: =IFERROR(__xludf.DUMMYFUNCTION("""COMPUTED_VALUE"""),FALSE) -> FALSE | D37: =IFERROR(__xludf.DUMMYFUNCTION("""COMPUTED_VALUE"""),"Židek Petr") -> Židek Petr | E37: =IFERROR(__xludf.DUMMYFUNCTION("""COMPUTED_VALUE"""),"Chodov") -> Chodov | V37: =IFERROR(__xludf.DUMMYFUNCTION("""COMPUTED_VALUE"""),250.20600000000002) -> 250.206 | W37: =IFERROR(__xludf.DUMMYFUNCTION("""COMPUTED_VALUE"""),0.0) -> 0
A38: =IF(AND(B38<>"", C38=TRUE, E38=Report!$B$1), B38, "") | B38: =IF(OR(E38=Report!$B$1, F38=Report!$B$1, G38=Report!$B$1, H38=Report!$B$1), D38, "") -> Gorol Patrik | C38: =IFERROR(__xludf.DUMMYFUNCTION("""COMPUTED_VALUE"""),FALSE) -> FALSE | D38: =IFERROR(__xludf.DUMMYFUNCTION("""COMPUTED_VALUE"""),"Gorol Patrik") -> Gorol Patrik | E38: =IFERROR(__xludf.DUMMYFUNCTION("""COMPUTED_VALUE"""),"Malešice") -> Malešice | F38: =IFERROR(__xludf.DUMMYFUNCTION("""COMPUTED_VALUE"""),"Libuš") -> Libuš | V38: =IFERROR(__xludf.DUMMYFUNCTION("""COMPUTED_VALUE"""),231.474) -> 231.474 | W38: =IFERROR(__xludf.DUMMYFUNCTION("""COMPUTED_VALUE"""),0.0) -> 0
A39: =IF(AND(B39<>"", C39=TRUE, E39=Report!$B$1), B39, "") | B39: =IF(OR(E39=Report!$B$1, F39=Report!$B$1, G39=Report!$B$1, H39=Report!$B$1), D39, "") | C39: =IFERROR(__xludf.DUMMYFUNCTION("""COMPUTED_VALUE"""),FALSE) -> FALSE | D39: =IFERROR(__xludf.DUMMYFUNCTION("""COMPUTED_VALUE"""),"Kratochvíl Kryštof") -> Kratochvíl Kryštof | E39: =IFERROR(__xludf.DUMMYFUNCTION("""COMPUTED_VALUE"""),"Bolevec") -> Bolevec | V39: =IFERROR(__xludf.DUMMYFUNCTION("""COMPUTED_VALUE"""),267.6) -> 267.6 | W39: =IFERROR(__xludf.DUMMYFUNCTION("""COMPUTED_VALUE"""),0.0) -> 0
A40: =IF(AND(B40<>"", C40=TRUE, E40=Report!$B$1), B40, "") | B40: =IF(OR(E40=Report!$B$1, F40=Report!$B$1, G40=Report!$B$1, H40=Report!$B$1), D40, "") -> Hegedüs Gergö | C40: =IFERROR(__xludf.DUMMYFUNCTION("""COMPUTED_VALUE"""),FALSE) -> FALSE | D40: =IFERROR(__xludf.DUMMYFUNCTION("""COMPUTED_VALUE"""),"Hegedüs Gergö") -> Hegedüs Gergö | E40: =IFERROR(__xludf.DUMMYFUNCTION("""COMPUTED_VALUE"""),"Libuš") -> Libuš | V40: =IFERROR(__xludf.DUMMYFUNCTION("""COMPUTED_VALUE"""),214.08) -> 214.08 | W40: =IFERROR(__xludf.DUMMYFUNCTION("""COMPUTED_VALUE"""),0.0) -> 0
A41: =IF(AND(B41<>"", C41=TRUE, E41=Report!$B$1), B41, "") | B41: =IF(OR(E41=Report!$B$1, F41=Report!$B$1, G41=Report!$B$1, H41=Report!$B$1), D41, "") -> Barvínková Eliška | C41: =IFERROR(__xludf.DUMMYFUNCTION("""COMPUTED_VALUE"""),FALSE) -> FALSE | D41: =IFERROR(__xludf.DUMMYFUNCTION("""COMPUTED_VALUE"""),"Barvínková Eliška") -> Barvínková Eliška | E41: =IFERROR(__xludf.DUMMYFUNCTION("""COMPUTED_VALUE"""),"Libuš") -> Libuš | V41: =IFERROR(__xludf.DUMMYFUNCTION("""COMPUTED_VALUE"""),231.474) -> 231.474 | W41: =IFERROR(__xludf.DUMMYFUNCTION("""COMPUTED_VALUE"""),0.0) -> 0
...

Sheet Denik

Sheet Směny
A1: Sem zadej směnu pro tento týden z CSV - Směny -> Naplánované směny -> Aktuální nebo Následující týden -> Stáhnout CSV (v pravo nahoře ) -> otevřív v excelu -> oznacit všechny buňky a dvojklikem na dělící přepážku mezi A a B přizpůsob buňky velikosti textu. Poté tabulku zkopíruj do této tabulky do bunky A2, označeno modře.
A2: Pracovníci | B2: Pondělí | C2: Úterý | D2: Středa | E2: Čtvrtek | F2: Pátek | G2: Sobota | H2: Neděle
A3: Eszenyiová Patrícia | B3: 10:00 - 17:00 (Instor) | C3: 10:00 - 17:00 (Instor) | E3: 10:00 - 17:00 (Instor) | F3: 17:00 - 23:00 (Instor) | H3: 17:00 - 0:00 (Instor)
