Workbook

Sheet July 2024
A1: Datum | B1: Název | C1: Jména Instor | D1: Začátek směny Instor | E1: Konec směny Instor | F1: Pauza Instor | G1: Počet hodin Instor | H1: Jména Kurýr | I1: Začátek směny Kurýr | J1: Konec směny Kurýr | K1: Pauza Kurýr | L1: Počet hodin Kurýr | M1: Počet rozvozů Kurýr | N1: TRUE | O1: Vyplatit PHM | P1: Wolt drive | Q1: Otevíral | R1: Zavíral | S1: Online Platby - Wolt | T1: Online Platby - Bolt | U1: Online Platby - Dáme Jídlo | V1: Vlastní API | W1: Online Platby - Wolt cash | X1: Online Platby - DJ Cash | Y1: Terminál | Z1: Stravenky | AA1: Hotovost | AB1: Tržba | AC1: Pokladna - VÝSLEDEK | AD1: COL | AE1: Benzín | AF1: Auta | AG1: Suroviny | AH1: Ostatní | AI1: PHM - soukromé | AJ1: Zrušené obj. ks | AK1: Zrušené obj. $ | AL1: Počet zpožděných objednávek z webu +5 min | AM1: Průměrný make Time | AN1: Počet vydajových dokladů
A2: 45499 | B2: Pátek | C2: Veselý Ondřej | D2: 10:00 | E2: 22:00 | G2: 12:00
A3: 45499 | B3: Pátek | C3: Michal Nedbal | D3: 17:00 | E3: 1:00 | G3: 08:00
A4: 45499 | B4: Pátek | C4: Suchánek Daniel | D4: 10:00 | E4: 23:00 | G4: 13:00
A5: 45499 | B5: Pátek | C5: Šebesta Tomáš | D5: 10:00 | E5: 23:00 | G5: 13:00
A6: 45499 | B6: Pátek | C6: Hanakova Ayuna | D6: 10:00 | E6: 17:00 | G6: 07:00
A7: 45499 | B7: Pátek | H7: Kučera Karel | I7: 17:00 | J7: 1:00 | L7: 08:00 | M7: 10 | N7: TRUE | O7: 400
A8: 45499 | B8: Pátek | H8: Černohorský Otakar | I8: 00:30 | J8: 00:00 | L8: 23:30 | M8: 1
A9: 45499 | B9: Pátek | S9: 10 | T9: 20 | U9: 30 | V9: 4 | W9: 5 | X9: 6 | Y9: 7 | Z9: 8 | AA9: 9 | AB9: 50000 | AC9: -37157 | AD9: 0.49276157 | AE9: 11 | AF9: 111 | AG9: 1111 | AH9: 11111 | AI9: 400 | AL9: 5 | AM9: 11 min 45 s | AN9: 1
A10: 45499 | B10: Pátek | AC10: 0 | AD10: Zadej tržbu | AI10: 0 | AN10: 1
A11: 45496 | B11: Úterý | C11: Kučera Karel | D11: 10:00 | E11: 17:00 | G11: 07:00 | AJ11: 1 | AK11: 5 | AM11: 11 min 45 s
A12: 45496 | B12: Úterý | C12: Veselý Ondřej | D12: 10:00 | E12: 20:00 | G12: 10:00 | AJ12: 1 | AK12: 2
A13: 45496 | B13: Úterý | C13: Michal Nedbal | D13: 17:00 | E13: 1:00 | G13: 08:00 | AJ13: 1 | AK13: 1 | AM13: 11 min 45 s | AN13: 2
A14: 45496 | B14: Úterý | H14: Černohorský Otakar | I14: 11:00 | J14: 17:00 | L14: 06:00
A15: 45496 | B15: Úterý | H15: Novák Jakub | I15: 17:00 | J15: 1:00 | L15: 08:00
A16: 45496 | B16: Úterý | S16: 9060 | T16: 3651 | U16: 14729 | V16: 10695 | W16: 374 | X16: 368 | AB16: 41872 | AC16: -2995 | AD16: 0.23834367 | AI16: 0 | AN16: 0
A17: 45501 | B17: Neděle | C17: Veselý Ondřej | D17: 17:00 | E17: 0:00 | G17: 07:00
A18: 45501 | B18: Neděle | C18: Michal Nedbal | D18: 17:00 | E18: 0:00 | G18: 07:00
A19: 45501 | B19: Neděle | H19: Kučera Karel | I19: 11:00 | J19: 17:00 | L19: 06:00
A20: 45501 | B20: Neděle | H20: Novák Jakub | I20: 17:00 | J20: 0:00 | L20: 07:00
A21: 45501 | B21: Neděle | AC21: 0 | AD21: Zadej tržbu | AI21: 0
A22: 45502 | B22: Pondělí | C22: Hanakova Ayuna | D22: 17:00 | E22: 0:00 | G22: 07:00
A23: 45502 | B23: Pondělí | C23: Černohorský Otakar | D23: 17:00 | E23: 0:00 | G23: 07:00
A24: 45502 | B24: Pondělí | H24: Kučera Karel | I24: 11:00 | J24: 18:00 | L24: 07:00
A25: 45502 | B25: Pondělí | H25: Jakub Zimmer | I25: 18:00 | J25: 0:00 | L25: 06:00
A26: 45502 | B26: Pondělí | AC26: 0 | AD26: Zadej tržbu | AI26: 0
A27: 45503 | B27: Úterý | C27: Kučera Karel | D27: 11:00 | E27: 17:00 | G27: 06:00
A28: 45503 | B28: Úterý | C28: Trachtová Martina | D28: 10:00 | E28: 17:00 | G28: 07:00
A29: 45503 | B29: Úterý | C29: Veselý Ondřej | D29: 17:00 | E29: 0:00 | G29: 07:00
A30: 45503 | B30: Úterý | H30: Novák Jakub | I30: 17:00 | J30: 0:00 | L30: 07:00
A31: 45503 | B31: Úterý | AC31: 0 | AD31: Zadej tržbu | AI31: 0
A32: 45504 | B32: Středa | C32: Hanakova Ayuna | D32: 17:00 | E32: 0:00 | G32: 07:00
A33: 45504 | B33: Středa | H33: Novák Jakub | I33: 11:00 | J33: 18:00 | L33: 07:00
A34: 45504 | B34: Středa | H34: Jakub Zimmer | L34: 0:00 | M34: 4
A35: 45504 | B35: Středa | P35: 3 | S35: 9414 | T35: 3907 | U35: 9081 | V35: 4024 | W35: 1310 | X35: 2052 | AB35: 38044 | AC35: -8256 | AD35: 0.25491082 | AI35: 0 | AN35: 0

Sheet DatabaseRestia
A1: Datum | B1: Platforma | C1: Stav | D1: Cena | E1: Sleva | F1: Kurýr | G1: Doručení | H1: Platba | I1: Vytvořeno | J1: Připraveno v | K1: Dokončeno v | L1: Přenos do dispecinku | M1: Zpoždění | N1: Přiřazení WoltDrivu | O1: Make Time
A2: 45527 | B2: wolt | C2: delivered | D2: 364 | E2: 0 | F2: Wolt Kurýr | G2: external-delivery | H2: online | I2: 2024-08-24T00:17:38.587+02:00 | J2: 2024-08-24T00:23:36.582+02:00 | K2: 2024-08-24T00:23:36.582+02:00 | M2: -9 | O2: 5.9665833
A3: 45527 | B3: generic | C3: delivered | D3: 355 | E3: 0 | F3: Čerešňák Michal | G3: delivery | H3: cash | I3: 2024-08-24T00:12:02.323+02:00 | J3: 2024-08-24T00:18:35.025+02:00 | K3: 2024-08-24T00:33:47.305+02:00 | L3: 2024-08-24T00:12:03.165+02:00 | M3: -12 | N3: 0.014033333 | O3: 6.5450333
A4: 45527 | B4: damejidlo | C4: ready_pickup | D4: 329 | E4: 0 | G4: external-delivery | H4: online | I4: 2024-08-24T00:03:45.643+02:00 | J4: 2024-08-24T00:11:09.248+02:00 | K4: 2024-08-24T00:11:09.248+02:00 | M4: 0 | O4: 7.3934167
A5: 45527 | B5: bolt | C5: ready_pickup | D5: 513 | E5: 0 | F5: Daniil | G5: external-delivery | H5: online | I5: 2024-08-23T23:53:41.282+02:00 | J5: 2024-08-24T00:00:49.237+02:00 | K5: 2024-08-24T00:00:49.237+02:00 | M5: -12 | O5: 7.1325833
A6: 45527 | B6: bolt | C6: ready_pickup | D6: 404 | E6: 0 | F6: Daniil | G6: external-delivery | H6: online | I6: 2024-08-23T23:49:52.305+02:00 | J6: 2024-08-23T23:55:58.105+02:00 | K6: 2024-08-23T23:55:58.105+02:00 | M6: -8 | O6: 6.0966667
A7: 45527 | B7: wolt | C7: delivered | D7: 129 | E7: 0 | F7: Wolt Kurýr | G7: external-delivery | H7: online | I7: 2024-08-23T23:44:27.224+02:00 | J7: 2024-08-23T23:48:53.249+02:00 | K7: 2024-08-23T23:48:53.249+02:00 | M7: -12 | O7: 4.43375
A8: 45527 | B8: damejidlo | C8: ready_pickup | D8: 621 | E8: 0 | G8: external-delivery | H8: online | I8: 2024-08-23T23:32:45.232+02:00 | J8: 2024-08-23T23:38:55.364+02:00 | K8: 2024-08-23T23:38:55.364+02:00 | M8: -2 | O8: 6.1688667
A9: 45527 | B9: wolt | C9: delivered | D9: 294 | E9: 0 | F9: Wolt Kurýr | G9: external-delivery | H9: online | I9: 2024-08-23T23:24:17.939+02:00 | J9: 2024-08-23T23:29:38.478+02:00 | K9: 2024-08-23T23:29:38.478+02:00 | M9: -9 | O9: 5.3423167
A10: 45527 | B10: generic | C10: ready_pickup | D10: 159 | E10: 0 | G10: pickup | H10: cash | I10: 2024-08-23T23:24:03.465+02:00 | J10: 2024-08-23T23:30:18.992+02:00 | K10: 2024-08-23T23:30:18.992+02:00 | M10: -13 | O10: 6.2587833
A11: 45527 | B11: damejidlo | C11: ready_pickup | D11: 336 | E11: 0 | G11: external-delivery | H11: online | I11: 2024-08-23T23:15:44.159+02:00 | J11: 2024-08-23T23:21:41.344+02:00 | K11: 2024-08-23T23:21:41.344+02:00 | M11: -1 | O11: 5.9530833
A12: 45527 | B12: wolt | C12: delivered | D12: 329 | E12: 0 | F12: Wolt Kurýr | G12: external-delivery | H12: online | I12: 2024-08-23T23:15:12.877+02:00 | J12: 2024-08-23T23:21:02.582+02:00 | K12: 2024-08-23T23:21:02.582+02:00 | M12: -9 | O12: 5.8284167
A13: 45527 | B13: generic | C13: delivered | D13: 652 | E13: 0 | F13: Čerešňák Michal | G13: delivery | H13: cash | I13: 2024-08-23T23:09:01.378+02:00 | J13: 2024-08-23T23:16:32.019+02:00 | K13: 2024-08-23T23:36:15.354+02:00 | L13: 2024-08-23T23:09:02.133+02:00 | M13: -12 | N13: 0.012583333 | O13: 7.5106833
A14: 45527 | B14: damejidlo | C14: ready_pickup | D14: 174 | E14: 0 | G14: external-delivery | H14: online | I14: 2024-08-23T22:58:44.512+02:00 | J14: 2024-08-23T23:04:40.407+02:00 | K14: 2024-08-23T23:04:40.407+02:00 | M14: 0 | O14: 5.9315833
A15: 45527 | B15: damejidlo | C15: ready_pickup | D15: 264 | E15: 0 | G15: external-delivery | H15: online | I15: 2024-08-23T22:57:44.525+02:00 | J15: 2024-08-23T23:03:05.326+02:00 | K15: 2024-08-23T23:03:05.326+02:00 | M15: -1 | O15: 5.3466833
A16: 45527 | B16: damejidlo | C16: ready_pickup | D16: 364 | E16: 0 | G16: external-delivery | H16: online | I16: 2024-08-23T22:54:44.690+02:00 | J16: 2024-08-23T23:01:38.275+02:00 | K16: 2024-08-23T23:01:38.275+02:00 | M16: 0 | O16: 6.8930833
A17: 45527 | B17: wolt | C17: delivered | D17: 343 | E17: 0 | F17: Wolt Kurýr | G17: external-delivery | H17: online | I17: 2024-08-23T22:30:29.545+02:00 | J17: 2024-08-23T22:36:48.180+02:00 | K17: 2024-08-23T22:36:48.180+02:00 | M17: -8 | O17: 6.3105833
A18: 45527 | B18: damejidlo | C18: ready_pickup | D18: 578 | E18: 0 | G18: external-delivery | H18: cash | I18: 2024-08-23T22:26:43.460+02:00 | J18: 2024-08-23T22:33:00.403+02:00 | K18: 2024-08-23T22:33:00.403+02:00 | M18: -2 | O18: 6.2823833
A19: 45527 | B19: generic | C19: ready_pickup | D19: 199 | E19: 50 | G19: pickup | H19: cash | I19: 2024-08-23T22:23:01.605+02:00 | J19: 2024-08-23T22:29:29.981+02:00 | K19: 2024-08-23T22:29:29.981+02:00 | M19: -12 | O19: 6.4729333
A20: 45527 | B20: wolt | C20: delivered | D20: 264 | E20: 0 | F20: Wolt Kurýr | G20: external-delivery | H20: online | I20: 2024-08-23T22:14:54.205+02:00 | J20: 2024-08-23T22:19:29.476+02:00 | K20: 2024-08-23T22:19:29.476+02:00 | M20: -10 | O20: 4.58785
A21: 45527 | B21: damejidlo | C21: ready_pickup | D21: 346 | E21: 0 | G21: external-delivery | H21: online | I21: 2024-08-23T21:57:43.519+02:00 | J21: 2024-08-23T22:03:36.346+02:00 | K21: 2024-08-23T22:03:36.346+02:00 | M21: -1 | O21: 5.88045
A22: 45527 | B22: wolt | C22: delivered | D22: 329 | E22: 0 | F22: Wolt Kurýr | G22: external-delivery | H22: online | I22: 2024-08-23T21:35:08.328+02:00 | J22: 2024-08-23T21:44:25.233+02:00 | K22: 2024-08-23T21:44:25.233+02:00 | M22: -5 | O22: 9.28175
A23: 45527 | B23: wolt | C23: delivered | D23: 313 | E23: 0 | F23: Wolt Kurýr | G23: external-delivery | H23: online | I23: 2024-08-23T21:30:40.018+02:00 | J23: 2024-08-23T21:37:22.255+02:00 | K23: 2024-08-23T21:37:22.255+02:00 | M23: -8 | O23: 6.70395
A24: 45527 | B24: damejidlo | C24: ready_pickup | D24: 394 | E24: 0 | G24: external-delivery | H24: online | I24: 2024-08-23T21:22:44.178+02:00 | J24: 2024-08-23T21:31:32.312+02:00 | K24: 2024-08-23T21:31:32.312+02:00 | M24: 0 | O24: 8.8022333
A25: 45527 | B25: damejidlo | C25: ready_pickup | D25: 816 | E25: 0 | G25: external-delivery | H25: online | I25: 2024-08-23T21:14:44.626+02:00 | J25: 2024-08-23T21:24:46.267+02:00 | K25: 2024-08-23T21:24:46.267+02:00 | M25: 0 | O25: 10.02735
A26: 45527 | B26: generic | C26: delivered | D26: 597 | E26: 35 | F26: Wolt Kurýr | G26: delivery | H26: online | I26: 2024-08-23T21:11:01.623+02:00 | J26: 2024-08-23T21:20:38.155+02:00 | K26: 2024-08-23T21:42:15.426+02:00 | L26: 2024-08-23T21:15:23.862+02:00 | M26: -6 | N26: 4.37065 | O26: 9.6088667
A27: 45527 | B27: wolt | C27: delivered | D27: 413 | E27: 0 | F27: Wolt Kurýr | G27: external-delivery | H27: online | I27: 2024-08-23T21:10:00.474+02:00 | J27: 2024-08-23T21:16:22.265+02:00 | K27: 2024-08-23T21:16:22.265+02:00 | M27: -10 | O27: 6.3631833
A28: 45527 | B28: damejidlo | C28: ready_pickup | D28: 264 | E28: 0 | G28: external-delivery | H28: cash | I28: 2024-08-23T21:08:44.645+02:00 | J28: 2024-08-23T21:14:02.511+02:00 | K28: 2024-08-23T21:14:02.511+02:00 | M28: 0 | O28: 5.2977667
A29: 45527 | B29: bolt | C29: ready_pickup | D29: 319 | E29: 0 | F29: Petr | G29: external-delivery | H29: online | I29: 2024-08-23T21:02:58.668+02:00 | J29: 2024-08-23T21:10:07.507+02:00 | K29: 2024-08-23T21:10:07.507+02:00 | M29: -7 | O29: 7.1473167
A30: 45527 | B30: generic | C30: delivered | D30: 475 | E30: 23 | F30: Čerešňák Michal | G30: delivery | H30: online | I30: 2024-08-23T21:02:01.356+02:00 | J30: 2024-08-23T21:08:07.021+02:00 | K30: 2024-08-23T21:32:43.488+02:00 | L30: 2024-08-23T21:02:01.984+02:00 | M30: 1 | N30: 0.010466667 | O30: 6.0944167
A31: 45527 | B31: wolt | C31: delivered | D31: 224 | E31: 0 | F31: Wolt Kurýr | G31: external-delivery | H31: online | I31: 2024-08-23T21:00:02.896+02:00 | J31: 2024-08-23T21:05:37.301+02:00 | K31: 2024-08-23T21:05:37.301+02:00 | M31: -10 | O31: 5.5734167
A32: 45527 | B32: wolt | C32: delivered | D32: 394 | E32: 0 | F32: Wolt Kurýr | G32: external-delivery | H32: online | I32: 2024-08-23T20:51:26.998+02:00 | J32: 2024-08-23T20:59:19.185+02:00 | K32: 2024-08-23T20:59:19.185+02:00 | M32: -7 | O32: 7.8697833
A33: 45527 | B33: bolt | C33: ready_pickup | D33: 264 | E33: 0 | F33: Roman | G33: external-delivery | H33: online | I33: 2024-08-23T20:45:51.474+02:00 | J33: 2024-08-23T20:52:46.169+02:00 | K33: 2024-08-23T20:52:46.169+02:00 | M33: -8 | O33: 6.9115833
A34: 45527 | B34: wolt | C34: delivered | D34: 882 | E34: 0 | F34: Wolt Kurýr | G34: external-delivery | H34: online | I34: 2024-08-23T20:44:53.746+02:00 | J34: 2024-08-23T20:52:57.180+02:00 | K34: 2024-08-23T20:52:57.180+02:00 | M34: -11 | O34: 8.0572333
A35: 45527 | B35: wolt | C35: delivered | D35: 715 | E35: 0 | F35: Wolt Kurýr | G35: external-delivery | H35: online | I35: 2024-08-23T20:36:51.238+02:00 | J35: 2024-08-23T20:49:19.224+02:00 | K35: 2024-08-23T20:49:19.224+02:00 | M35: -7 | O35: 12.466433
A36: 45527 | B36: damejidlo | C36: ready_pickup | D36: 1006 | E36: 0 | G36: external-delivery | H36: online | I36: 2024-08-23T20:33:43.896+02:00 | J36: 2024-08-23T20:43:20.314+02:00 | K36: 2024-08-23T20:43:20.314+02:00 | M36: -1 | O36: 9.6069667
A37: 45527 | B37: generic | C37: delivered | D37: 309 | E37: 0 | F37: Wolt Kurýr | G37: delivery | H37: online | I37: 2024-08-23T20:33:01.811+02:00 | J37: 2024-08-23T20:40:19.164+02:00 | K37: 2024-08-23T20:50:27.761+02:00 | L37: 2024-08-23T20:35:07.952+02:00 | M37: -10 | N37: 2.10235 | O37: 7.2892167
A38: 45527 | B38: generic | C38: ready_pickup | D38: 520 | E38: 124 | G38: pickup | H38: online | I38: 2024-08-23T20:28:01.471+02:00 | J38: 2024-08-23T20:45:12.971+02:00 | K38: 2024-08-23T20:45:12.971+02:00 | M38: -6 | O38: 17.191667
A39: 45527 | B39: generic | C39: delivered | D39: 358 | E39: 0 | F39: Čerešňák Michal | G39: delivery | H39: online | I39: 2024-08-23T20:26:01.979+02:00 | J39: 2024-08-23T20:30:25.004+02:00 | K39: 2024-08-23T20:57:34.627+02:00 | L39: 2024-08-23T20:26:02.500+02:00 | M39: -2 | N39: 0.0086833333 | O39: 4.38375
A40: 45527 | B40: generic | C40: delivered | D40: 338 | E40: 0 | F40: Čerešňák Michal | G40: delivery | H40: online | I40: 2024-08-23T20:21:01.522+02:00 | J40: 2024-08-23T20:28:46.998+02:00 | K40: 2024-08-23T20:38:35.431+02:00 | L40: 2024-08-23T20:21:02.078+02:00 | M40: -10 | N40: 0.0092666667 | O40: 7.7579333
...

Sheet August 2024
A1: Datum | B1: Název | C1: Jména Instor | D1: Začátek směny Instor | E1: Konec směny Instor | F1: Pauza Instor | G1: Počet hodin Instor | H1: Jména Kurýr | I1: Začátek směny Kurýr | J1: Konec směny Kurýr | K1: Pauza Kurýr | L1: Počet hodin Kurýr | M1: Počet rozvozů Kurýr | N1: Vlastní vůz | O1: Vyplatit PHM | P1: Wolt drive | Q1: Otevíral | R1: Zavíral | S1: Online Platby - Wolt | T1: Online Platby - Bolt | U1: Online Platby - Dáme Jídlo | V1: Vlastní API | W1: Online Platby - Wolt cash | X1: Online Platby - DJ Cash | Y1: Terminál | Z1: Stravenky | AA1: Hotovost | AB1: Tržba | AC1: Pokladna - VÝSLEDEK | AD1: COL | AE1: Benzín | AF1: Auta | AG1: Suroviny | AH1: Ostatní | AI1: PHM - soukromé | AJ1: Zrušené obj. ks | AK1: Zrušené obj. $ | AL1: Počet zpožděných objednávek z webu +5 min | AM1: Průměrný make Time | AN1: Počet vydajových dokladů | AO1: Počet nezrušených celkem | AP1: Počet našich rozvozů | AQ1: Počet pozdě přiřazeným WoltDrive 5+ | AR1: Woltrdrive zpožděný kvůli našemu pozdnímu přiřazení | AS1: % zpožděných našich rozvozů +5 min | AT1: Počet zpožděných Woltdrivem | AU1: % doručených včas | AV1: % zpožděných Woltdrivem
A2: 45505 | B2: Čtvrtek | C2: Černohorský Otakar | D2: 11:00 | E2: 17:00 | G2: 06:00
A3: 45505 | B3: Čtvrtek | C3: Michal Nedbal | D3: 17:00 | E3: 00:00 | G3: 07:00
A4: 45505 | B4: Čtvrtek | C4: Trachtová Martina | D4: 10:00 | E4: 17:00 | G4: 07:00
A5: 45505 | B5: Čtvrtek | H5: Novák Jakub | I5: 17:00 | J5: 00:00 | L5: 07:00 | M5: 9 | N5: TRUE | O5: 360
A6: 45505 | B6: Čtvrtek | H6: Čerešňák Michal | I6: 11:00 | J6: 17:00 | L6: 06:00 | M6: 6 | N6: TRUE | O6: 240
A7: 45505 | B7: Čtvrtek | P7: 3 | S7: 12155 | T7: 7267 | U7: 17983 | V7: 8801 | W7: 917 | X7: 1093 | Y7: 5130 | AA7: 1500 | AB7: 56736 | AC7: 7 | AD7: 0.22244544 | AE7: 500 | AG7: 1890 | AI7: 600 | AJ7: 1 | AK7: 264 | AL7: 4 | AM7: 12 min 15 s | AN7: 2 | AO7: 3
A8: 45506 | B8: Pátek | C8: Hanakova Ayuna | D8: 17:00 | E8: 01:00 | G8: 08:00
A9: 45506 | B9: Pátek | C9: Michal Nedbal | D9: 10:00 | E9: 22:00 | G9: 12:00
A10: 45506 | B10: Pátek | C10: Gomez Antonio | D10: 10:00 | E10: 17:00 | G10: 07:00
A11: 45506 | B11: Pátek | C11: Trachtová Martina | D11: 17:00 | E11: 01:00 | G11: 08:00
A12: 45506 | B12: Pátek | H12: Čerešňák Michal | I12: 10:00 | J12: 01:00 | L12: 15:00 | M12: 22 | N12: TRUE | O12: 880
A13: 45506 | B13: Pátek | P13: 6 | S13: 13714 | T13: 8559 | U13: 15123 | V13: 13992 | W13: 823 | X13: 4446 | Y13: 3340 | AA13: 7980 | AB13: 65404.5 | AC13: 6.5 | AD13: 0.26557244 | AH13: 1000 | AI13: 880 | AJ13: 0 | AK13: 0 | AL13: 4 | AM13: 11 min 50 s | AN13: 1 | AO13: 4
A14: 45507 | B14: Sobota | C14: Hanakova Ayuna | D14: 17:00 | E14: 01:00 | G14: 08:00
A15: 45507 | B15: Sobota | C15: Michal Nedbal | D15: 10:00 | E15: 22:00 | G15: 12:00
A16: 45507 | B16: Sobota | C16: Gomez Antonio | D16: 10:00 | E16: 17:00 | G16: 07:00
A17: 45507 | B17: Sobota | C17: Trachtová Martina | D17: 17:00 | E17: 01:00 | G17: 08:00
A18: 45507 | B18: Sobota | H18: Novák Jakub | I18: 11:00 | J18: 01:00 | L18: 14:00 | M18: 15 | N18: TRUE | O18: 600
A19: 45507 | B19: Sobota | P19: 2 | S19: 9875 | T19: 6927 | U19: 20583 | V19: 11023 | W19: 0 | X19: 795 | Y19: 8635 | AA19: 855 | AB19: 59046 | AC19: -328 | AD19: 0.26831101 | AG19: 220 | AI19: 600 | AJ19: 0 | AK19: 0 | AL19: 2 | AM19: 9 min 59 s | AN19: 1 | AO19: 1
A20: 45508 | B20: Neděle | C20: Michal Nedbal | D20: 10:00 | E20: 17:00 | G20: 07:00
A21: 45508 | B21: Neděle | C21: Hanakova Ayuna | D21: 17:00 | E21: 00:30 | G21: 07:30
A22: 45508 | B22: Neděle | C22: Pechová Barbora | D22: 10:00 | E22: 17:00 | G22: 07:00
A23: 45508 | B23: Neděle | C23: Trachtová Martina | D23: 17:00 | E23: 00:00 | G23: 07:00
A24: 45508 | B24: Neděle | H24: Čerešňák Michal | I24: 11:00 | J24: 00:00 | L24: 13:00 | M24: 18 | N24: TRUE | O24: 720
A25: 45508 | B25: Neděle | P25: 11 | S25: 12864 | T25: 7236 | U25: 23360 | V25: 12483 | W25: 358 | X25: 2604 | Y25: 4023 | AA25: 6230 | AB25: 67274 | AC25: 0 | AD25: 0.25279072 | AI25: 720 | AJ25: 1 | AK25: 321 | AL25: 19 | AM25: 11 min 28 s | AN25: 1 | AO25: 2
A26: 45509 | B26: Pondělí | C26: Gomez Antonio | D26: 17:00 | E26: 00:00 | G26: 07:00
A27: 45509 | B27: Pondělí | C27: Trachtová Martina | D27: 10:00 | E27: 00:30 | G27: 14:30
A28: 45509 | B28: Pondělí | H28: Kormash Liubov | I28: 11:00 | J28: 18:00 | L28: 07:00 | M28: 6 | N28: TRUE | O28: 240
A29: 45509 | B29: Pondělí | H29: Jakub Zimmer | I29: 18:00 | J29: 00:00 | L29: 06:00 | M29: 6 | N29: TRUE | O29: 240
A30: 45509 | B30: Pondělí | P30: 7 | S30: 9763 | T30: 4297 | U30: 9409 | V30: 9197 | W30: 0 | X30: 747 | Y30: 3343 | AA30: 3170 | AB30: 39700 | AC30: 39 | AD30: 0.39009164 | AH30: 80 | AI30: 480 | AJ30: 0 | AK30: 0 | AL30: 23 | AM30: 16 min 33 s | AN30: 2 | AO30: 4
A31: 45510 | B31: Úterý | C31: Michal Nedbal | D31: 17:00 | E31: 00:00 | G31: 07:00
A32: 45510 | B32: Úterý | C32: Trachtová Martina | D32: 17:00 | E32: 24:30 | G32: 07:30
A33: 45510 | B33: Úterý | C33: Gomez Antonio | D33: 10:00 | E33: 24:30 | G33: 14:30
A34: 45510 | B34: Úterý | H34: Novák Jakub | I34: 11:00 | J34: 17:00 | L34: 06:00 | M34: 7 | N34: TRUE | O34: 280
A35: 45510 | B35: Úterý | H35: Lažek Jaroslav | I35: 17:00 | J35: 00:30 | L35: 07:30 | M35: 12 | N35: TRUE | O35: 480
A36: 45510 | B36: Úterý | P36: 1 | S36: 8586 | T36: 6871 | U36: 13982 | V36: 9114 | W36: 0 | X36: 3462 | Y36: 4333 | AA36: 5210 | AB36: 49815.5 | AC36: 40.5 | AD36: 0.29691457 | AH36: 1000 | AI36: 760 | AJ36: 1 | AK36: 498 | AL36: 5 | AM36: 12 min 16 s | AN36: 2 | AO36: 0
A37: 45511 | B37: Středa | C37: Hanakova Ayuna | D37: 10:00 | E37: 17:00 | G37: 07:00
A38: 45511 | B38: Středa | C38: Veselý Ondřej | D38: 17:00 | E38: 00:00 | G38: 07:00
A39: 45511 | B39: Středa | C39: Čerešňák Michal | D39: 17:00 | E39: 00:00 | G39: 07:00
A40: 45511 | B40: Středa | H40: Kormash Liubov | I40: 11:00 | J40: 00:00 | L40: 13:00 | M40: 13 | N40: TRUE | O40: 520
...

Sheet Report
B1: Zličín | C1: Datum | D1: 46204 | F1: COL | I1: Tržba | L1: Online Platby
F2: =IFERROR(__xludf.DUMMYFUNCTION("IF(I2>0, 100 / (I2 / 112 * 100 / ((SUM(A12:A21, A25:A31) + (M17 + I32) + IFERROR(SUM(FILTER(HR!W5:W48, LEN(HR!A5:A48) > 0)), 0)) / 100)), ""Zadej tržbu"") "),"Zadej tržbu") -> Zadej tržbu | I2: =SUMIFS(RestiaCSV!C:C, RestiaCSV!B:B, "<>canceled", RestiaCSV!B:B, "<>expired") -> 0 | L2: Wolt | M2: =SUMIFS(RestiaCSV!C:C, RestiaCSV!A:A, Report!L2, RestiaCSV!B:B, "<>canceled", RestiaCSV!B:B, "<>expired") -> 0
B3: =CHOOSE(WEEKDAY(D1), "Neděle", "Pondělí", "Úterý", "Středa", "Čtvrtek", "Pátek", "Sobota") -> Středa | L3: Bolt | M3: =SUMIFS(RestiaCSV!C:C, RestiaCSV!A:A, Report!L3, RestiaCSV!B:B, "<>canceled") -> 0
L4: Dáme jídlo | M4: =SUMIFS(RestiaCSV!C:C, RestiaCSV!A:A, "damejidlo", RestiaCSV!G:G, "online", RestiaCSV!B:B, "<>canceled") -> 0
B5: Napiš vzkaz ⬇️ 📖 Deník 📖 ⬇️ Včerejší vzkaz | L5: Web | M5: =SUMIFS(RestiaCSV!C:C, RestiaCSV!A:A, "generic", RestiaCSV!G:G, "online", RestiaCSV!B:B, "<>canceled") -> 0
L6: Wolt drive cash | M6: =SUMIFS(RestiaCSV!C:C, RestiaCSV!E:E, "wolt kurýr", RestiaCSV!A:A, "<>wolt", RestiaCSV!G:G, "cash", RestiaCSV!B:B, "<>canceled") -> 0
L7: DJ Cash | M7: =SUMIFS(RestiaCSV!C:C, RestiaCSV!A:A, "damejidlo", RestiaCSV!G:G, "cash", RestiaCSV!B:B, "<>canceled") -> 0
L8: Hotovost
L9: Terminál
B10: Instor | G10: Otevíral | J10: Pokladna | L10: Stravenky
B11: Jméno | C11: Začátek směny | D11: Konec směny | E11: pauza | F11: Počet hodin | J11: =M2+M3+M4+M5+M6+M13+M14+M15+M16+M17+M9+M10+M11-I2 -> 0 | L11: Hotovost
A12: {=IF(ISBLANK(B12), 0, IF(ISNUMBER(MATCH(B12, HR!A:A, 0)), 0, IF(ISNUMBER(MATCH(B12, HR!B:B, 0)), INDEX(HR!V:V, MATCH(B12, HR!B:B, 0)) * (F12 * 24), 0)))} -> 0 | F12: =IF(OR(ISBLANK(B12), ISBLANK(D12), D12=0), "0:00", TEXT((IF(AND(TIMEVALUE(IF(ISBLANK(D12), "00:00", D12))>=TIMEVALUE("00:00"), TIMEVALUE(IF(ISBLANK(D12), "00:00", D12))<=TIMEVALUE("06:00")), TIMEVALUE(IF(ISBLANK(D12), "00:00", D12))+1, TIMEVALUE(IF(ISBLANK(D12), "00:00", D12))) - TIMEVALUE(IF(ISBLANK(C12), "00:00", C12)) - TIMEVALUE(IF(ISBLANK(E12), "00:00", E12))), "hh:mm")) -> 0:00 | L12: Výdaje
A13: {=IF(ISBLANK(#REF!), 0, IF(ISNUMBER(MATCH(#REF!, HR!A:A, 0)), 0, IF(ISNUMBER(MATCH(#REF!, HR!B:B, 0)), INDEX(HR!V:V, MATCH(#REF!, HR!B:B, 0)) * (F13 * 24), 0)))} -> 0 | F13: =IF(OR(ISBLANK(B13), ISBLANK(D14), D14=0), "0:00", TEXT((IF(AND(TIMEVALUE(IF(ISBLANK(D14), "00:00", D14))>=TIMEVALUE("00:00"), TIMEVALUE(IF(ISBLANK(D14), "00:00", D14))<=TIMEVALUE("06:00")), TIMEVALUE(IF(ISBLANK(D14), "00:00", D14))+1, TIMEVALUE(IF(ISBLANK(D14), "00:00", D14))) - TIMEVALUE(IF(ISBLANK(C13), "00:00", C13)) - TIMEVALUE(IF(ISBLANK(E13), "00:00", E13))), "hh:mm")) -> 0:00 | L13: Benzín
A14: {=IF(ISBLANK(B14), 0, IF(ISNUMBER(MATCH(B14, HR!A:A, 0)), 0, IF(ISNUMBER(MATCH(B14, HR!B:B, 0)), INDEX(HR!V:V, MATCH(B14, HR!B:B, 0)) * (F14 * 24), 0)))} -> 0 | F14: =IF(OR(ISBLANK(B14), ISBLANK(D15), D15=0), "0:00", TEXT((IF(AND(TIMEVALUE(IF(ISBLANK(D15), "00:00", D15))>=TIMEVALUE("00:00"), TIMEVALUE(IF(ISBLANK(D15), "00:00", D15))<=TIMEVALUE("06:00")), TIMEVALUE(IF(ISBLANK(D15), "00:00", D15))+1, TIMEVALUE(IF(ISBLANK(D15), "00:00", D15))) - TIMEVALUE(IF(ISBLANK(C14), "00:00", C14)) - TIMEVALUE(IF(ISBLANK(E14), "00:00", E14))), "hh:mm")) -> 0:00 | L14: Auta
A15: {=IF(ISBLANK(B15), 0, IF(ISNUMBER(MATCH(B15, HR!A:A, 0)), 0, IF(ISNUMBER(MATCH(B15, HR!B:B, 0)), INDEX(HR!V:V, MATCH(B15, HR!B:B, 0)) * (F15 * 24), 0)))} -> 0 | F15: =IF(OR(ISBLANK(B15), ISBLANK(D16), D16=0), "0:00", TEXT((IF(AND(TIMEVALUE(IF(ISBLANK(D16), "00:00", D16))>=TIMEVALUE("00:00"), TIMEVALUE(IF(ISBLANK(D16), "00:00", D16))<=TIMEVALUE("06:00")), TIMEVALUE(IF(ISBLANK(D16), "00:00", D16))+1, TIMEVALUE(IF(ISBLANK(D16), "00:00", D16))) - TIMEVALUE(IF(ISBLANK(C15), "00:00", C15)) - TIMEVALUE(IF(ISBLANK(E15), "00:00", E15))), "hh:mm")) -> 0:00 | L15: Suroviny
A16: {=IF(ISBLANK(B16), 0, IF(ISNUMBER(MATCH(B16, HR!A:A, 0)), 0, IF(ISNUMBER(MATCH(B16, HR!B:B, 0)), INDEX(HR!V:V, MATCH(B16, HR!B:B, 0)) * (F16 * 24), 0)))} -> 0 | F16: =IF(OR(ISBLANK(B16), ISBLANK(D17), D17=0), "0:00", TEXT((IF(AND(TIMEVALUE(IF(ISBLANK(D17), "00:00", D17))>=TIMEVALUE("00:00"), TIMEVALUE(IF(ISBLANK(D17), "00:00", D17))<=TIMEVALUE("06:00")), TIMEVALUE(IF(ISBLANK(D17), "00:00", D17))+1, TIMEVALUE(IF(ISBLANK(D17), "00:00", D17))) - TIMEVALUE(IF(ISBLANK(C16), "00:00", C16)) - TIMEVALUE(IF(ISBLANK(E16), "00:00", E16))), "hh:mm")) -> 0:00 | L16: Ostatní
A17: {=IF(ISBLANK(B17), 0, IF(ISNUMBER(MATCH(B17, HR!A:A, 0)), 0, IF(ISNUMBER(MATCH(B17, HR!B:B, 0)), INDEX(HR!V:V, MATCH(B17, HR!B:B, 0)) * (F17 * 24), 0)))} -> 0 | F17: =IF(OR(ISBLANK(B17), ISBLANK(D17), D17=0), "0:00", TEXT((IF(AND(TIMEVALUE(IF(ISBLANK(D17), "00:00", D17))>=TIMEVALUE("00:00"), TIMEVALUE(IF(ISBLANK(D17), "00:00", D17))<=TIMEVALUE("06:00")), TIMEVALUE(IF(ISBLANK(D17), "00:00", D17))+1, TIMEVALUE(IF(ISBLANK(D17), "00:00", D17))) - TIMEVALUE(IF(ISBLANK(C17), "00:00", C17)) - TIMEVALUE(IF(ISBLANK(E17), "00:00", E17))), "hh:mm")) -> 0:00 | L17: PHM - soukromé | M17: =sum(I25:I31) -> 0
A18: {=IF(ISBLANK(B18), 0, IF(ISNUMBER(MATCH(B18, HR!A:A, 0)), 0, IF(ISNUMBER(MATCH(B18, HR!B:B, 0)), INDEX(HR!V:V, MATCH(B18, HR!B:B, 0)) * (F18 * 24), 0)))} -> 0 | F18: =IF(OR(ISBLANK(B18), ISBLANK(D18), D18=0), "0:00", TEXT((IF(AND(TIMEVALUE(IF(ISBLANK(D18), "00:00", D18))>=TIMEVALUE("00:00"), TIMEVALUE(IF(ISBLANK(D18), "00:00", D18))<=TIMEVALUE("06:00")), TIMEVALUE(IF(ISBLANK(D18), "00:00", D18))+1, TIMEVALUE(IF(ISBLANK(D18), "00:00", D18))) - TIMEVALUE(IF(ISBLANK(C18), "00:00", C18)) - TIMEVALUE(IF(ISBLANK(E18), "00:00", E18))), "hh:mm")) -> 0:00 | G18: Zavíral
A19: {=IF(ISBLANK(B19), 0, IF(ISNUMBER(MATCH(B19, HR!A:A, 0)), 0, IF(ISNUMBER(MATCH(B19, HR!B:B, 0)), INDEX(HR!V:V, MATCH(B19, HR!B:B, 0)) * (F19 * 24), 0)))} -> 0 | F19: =IF(OR(ISBLANK(B19), ISBLANK(D19), D19=0), "0:00", TEXT((IF(AND(TIMEVALUE(IF(ISBLANK(D19), "00:00", D19))>=TIMEVALUE("00:00"), TIMEVALUE(IF(ISBLANK(D19), "00:00", D19))<=TIMEVALUE("06:00")), TIMEVALUE(IF(ISBLANK(D19), "00:00", D19))+1, TIMEVALUE(IF(ISBLANK(D19), "00:00", D19))) - TIMEVALUE(IF(ISBLANK(C19), "00:00", C19)) - TIMEVALUE(IF(ISBLANK(E19), "00:00", E19))), "hh:mm")) -> 0:00
A20: {=IF(ISBLANK(B20), 0, IF(ISNUMBER(MATCH(B20, HR!A:A, 0)), 0, IF(ISNUMBER(MATCH(B20, HR!B:B, 0)), INDEX(HR!V:V, MATCH(B20, HR!B:B, 0)) * (F20 * 24), 0)))} -> 0 | F20: =IF(OR(ISBLANK(B20), ISBLANK(D20), D20=0), "0:00", TEXT((IF(AND(TIMEVALUE(IF(ISBLANK(D20), "00:00", D20))>=TIMEVALUE("00:00"), TIMEVALUE(IF(ISBLANK(D20), "00:00", D20))<=TIMEVALUE("06:00")), TIMEVALUE(IF(ISBLANK(D20), "00:00", D20))+1, TIMEVALUE(IF(ISBLANK(D20), "00:00", D20))) - TIMEVALUE(IF(ISBLANK(C20), "00:00", C20)) - TIMEVALUE(IF(ISBLANK(E20), "00:00", E20))), "hh:mm")) -> 0:00
A21: {=IF(ISBLANK(B21), 0, IF(ISNUMBER(MATCH(B21, HR!A:A, 0)), 0, IF(ISNUMBER(MATCH(B21, HR!B:B, 0)), INDEX(HR!V:V, MATCH(B21, HR!B:B, 0)) * (F21 * 24), 0)))} -> 0 | F21: =IF(OR(ISBLANK(B21), ISBLANK(D21), D21=0), "0:00", TEXT((IF(AND(TIMEVALUE(IF(ISBLANK(D21), "00:00", D21))>=TIMEVALUE("00:00"), TIMEVALUE(IF(ISBLANK(D21), "00:00", D21))<=TIMEVALUE("06:00")), TIMEVALUE(IF(ISBLANK(D21), "00:00", D21))+1, TIMEVALUE(IF(ISBLANK(D21), "00:00", D21))) - TIMEVALUE(IF(ISBLANK(C21), "00:00", C21)) - TIMEVALUE(IF(ISBLANK(E21), "00:00", E21))), "hh:mm")) -> 0:00
J22: Zrušené obj. ks | K22: Zrušené obj. $ | L22: Počet zpožděných našich rozvozů +5 min | M22: Průměrný make Time
B23: Kurýr | J23: =COUNTIF(RestiaCSV!B:B, "canceled") -> 0 | K23: =SUMIF(RestiaCSV!B:B, "canceled", RestiaCSV!C:C) -> 0 | L23: =COUNTIFS(RestiaCSV!L:L, ">5", RestiaCSV!F:F, "delivery") -> 0 | M23: =INT(AVERAGEIFS(RestiaCSV!N:N, RestiaCSV!N:N, ">=5", RestiaCSV!N:N, "<=30")) & " min " & TEXT(MOD(AVERAGEIFS(RestiaCSV!N:N, RestiaCSV!N:N, ">=5", RestiaCSV!N:N, "<=30") * 60, 60), "00") & " s" -> #DIV/0!
B24: Jméno | C24: Začátek směny | D24: Konec směny | E24: pauza | F24: Počet hodin | G24: Počet rozvozů | H24: Vlastní vůz | I24: Vyplatit PHM | J24: počet výdajových dokadů | K24: Počet nezrušených celkem | L24: Počet našich rozvozů | M24: Počet pozdě přiřazeným WoltDrive 5+
A25: {=IF(ISBLANK(B25), 0, IF(ISNUMBER(MATCH(B25, HR!A:A, 0)), 0, IF(ISNUMBER(MATCH(B25, HR!B:B, 0)), INDEX(HR!V:V, MATCH(B25, HR!B:B, 0)) * (F25 * 24), 0)))} -> 0 | F25: =IF(OR(ISBLANK(B25), ISBLANK(D25), D25=0), "0:00", TEXT((IF(AND(TIMEVALUE(IF(ISBLANK(D25), "00:00", D25))>=TIMEVALUE("00:00"), TIMEVALUE(IF(ISBLANK(D25), "00:00", D25))<=TIMEVALUE("06:00")), TIMEVALUE(IF(ISBLANK(D25), "00:00", D25))+1, TIMEVALUE(IF(ISBLANK(D25), "00:00", D25))) - TIMEVALUE(IF(ISBLANK(C25), "00:00", C25)) - TIMEVALUE(IF(ISBLANK(E25), "00:00", E25))), "hh:mm")) -> 0:00 | G25: =COUNTIF(RestiaCSV!E:E, B25) -> 0 | H25: TRUE | I25: =IF(H25,G25*45, 0) -> 0
A26: {=IF(ISBLANK(B26), 0, IF(ISNUMBER(MATCH(B26, HR!A:A, 0)), 0, IF(ISNUMBER(MATCH(B26, HR!B:B, 0)), INDEX(HR!V:V, MATCH(B26, HR!B:B, 0)) * (F26 * 24), 0)))} -> 0 | F26: =IF(OR(ISBLANK(B26), ISBLANK(D26), D26=0), "0:00", TEXT((IF(AND(TIMEVALUE(IF(ISBLANK(D26), "00:00", D26))>=TIMEVALUE("00:00"), TIMEVALUE(IF(ISBLANK(D26), "00:00", D26))<=TIMEVALUE("06:00")), TIMEVALUE(IF(ISBLANK(D26), "00:00", D26))+1, TIMEVALUE(IF(ISBLANK(D26), "00:00", D26))) - TIMEVALUE(IF(ISBLANK(C26), "00:00", C26)) - TIMEVALUE(IF(ISBLANK(E26), "00:00", E26))), "hh:mm")) -> 0:00 | G26: =COUNTIF(RestiaCSV!E:E, B26) -> 0 | H26: TRUE | I26: =IF(H26,G26*45, 0) -> 0 | J26: =COUNTIF(I25:I31, ">0") -> 0 | K26: =IFERROR(__xludf.DUMMYFUNCTION("COUNTA(FILTER(RestiaCSV!B2:B32, RestiaCSV!B2:B32 <> ""canceled""))"),0.0) -> 0 | L26: =COUNTIF(RestiaCSV!F1:F32, "delivery") -> 0 | M26: =COUNTIFS(RestiaCSV!M:M, ">5",RestiaCSV!A:A, "<>wolt") -> 0
A27: {=IF(ISBLANK(B27), 0, IF(ISNUMBER(MATCH(B27, HR!A:A, 0)), 0, IF(ISNUMBER(MATCH(B27, HR!B:B, 0)), INDEX(HR!V:V, MATCH(B27, HR!B:B, 0)) * (F27 * 24), 0)))} -> 0 | F27: =IF(OR(ISBLANK(B27), ISBLANK(D27), D27=0), "0:00", TEXT((IF(AND(TIMEVALUE(IF(ISBLANK(D27), "00:00", D27))>=TIMEVALUE("00:00"), TIMEVALUE(IF(ISBLANK(D27), "00:00", D27))<=TIMEVALUE("06:00")), TIMEVALUE(IF(ISBLANK(D27), "00:00", D27))+1, TIMEVALUE(IF(ISBLANK(D27), "00:00", D27))) - TIMEVALUE(IF(ISBLANK(C27), "00:00", C27)) - TIMEVALUE(IF(ISBLANK(E27), "00:00", E27))), "hh:mm")) -> 0:00 | G27: =COUNTIF(RestiaCSV!E:E, B27) -> 0 | H27: TRUE | I27: =IF(H27,G27*45, 0) -> 0 | J27: Woltrdive zpožděný kvůli našemu pozdnímu přiřazení | L27: % zpožděných našich rozvozů +5 min | M27: Počet zpožděných Woltdrivem
A28: {=IF(ISBLANK(B28), 0, IF(ISNUMBER(MATCH(B28, HR!A:A, 0)), 0, IF(ISNUMBER(MATCH(B28, HR!B:B, 0)), INDEX(HR!V:V, MATCH(B28, HR!B:B, 0)) * (F28 * 24), 0)))} -> 0 | F28: =IF(OR(ISBLANK(B28), ISBLANK(D28), D28=0), "0:00", TEXT((IF(AND(TIMEVALUE(IF(ISBLANK(D28), "00:00", D28))>=TIMEVALUE("00:00"), TIMEVALUE(IF(ISBLANK(D28), "00:00", D28))<=TIMEVALUE("06:00")), TIMEVALUE(IF(ISBLANK(D28), "00:00", D28))+1, TIMEVALUE(IF(ISBLANK(D28), "00:00", D28))) - TIMEVALUE(IF(ISBLANK(C28), "00:00", C28)) - TIMEVALUE(IF(ISBLANK(E28), "00:00", E28))), "hh:mm")) -> 0:00 | G28: =COUNTIF(RestiaCSV!E:E, B28) -> 0 | H28: TRUE | I28: =IF(H28,G28*45, 0) -> 0
A29: {=IF(ISBLANK(B29), 0, IF(ISNUMBER(MATCH(B29, HR!A:A, 0)), 0, IF(ISNUMBER(MATCH(B29, HR!B:B, 0)), INDEX(HR!V:V, MATCH(B29, HR!B:B, 0)) * (F29 * 24), 0)))} -> 0 | F29: =IF(OR(ISBLANK(B29), ISBLANK(D29), D29=0), "0:00", TEXT((IF(AND(TIMEVALUE(IF(ISBLANK(D29), "00:00", D29))>=TIMEVALUE("00:00"), TIMEVALUE(IF(ISBLANK(D29), "00:00", D29))<=TIMEVALUE("06:00")), TIMEVALUE(IF(ISBLANK(D29), "00:00", D29))+1, TIMEVALUE(IF(ISBLANK(D29), "00:00", D29))) - TIMEVALUE(IF(ISBLANK(C29), "00:00", C29)) - TIMEVALUE(IF(ISBLANK(E29), "00:00", E29))), "hh:mm")) -> 0:00 | G29: =COUNTIF(RestiaCSV!E:E, B29) -> 0 | H29: TRUE | I29: =IF(H29,G29*45, 0) -> 0 | J29: =COUNTIFS(RestiaCSV!M:M, ">5", RestiaCSV!L:L, ">5") -> 0 | L29: =L23/L26 -> #DIV/0! | M29: =COUNTIFS(RestiaCSV!L:L, ">5", RestiaCSV!F:F, "delivery", RestiaCSV!E:E, "Wolt Kurýr") -> 0
A30: {=IF(ISBLANK(B30), 0, IF(ISNUMBER(MATCH(B30, HR!A:A, 0)), 0, IF(ISNUMBER(MATCH(B30, HR!B:B, 0)), INDEX(HR!V:V, MATCH(B30, HR!B:B, 0)) * (F30 * 24), 0)))} -> 0 | F30: =IF(OR(ISBLANK(B30), ISBLANK(D30), D30=0), "0:00", TEXT((IF(AND(TIMEVALUE(IF(ISBLANK(D30), "00:00", D30))>=TIMEVALUE("00:00"), TIMEVALUE(IF(ISBLANK(D30), "00:00", D30))<=TIMEVALUE("06:00")), TIMEVALUE(IF(ISBLANK(D30), "00:00", D30))+1, TIMEVALUE(IF(ISBLANK(D30), "00:00", D30))) - TIMEVALUE(IF(ISBLANK(C30), "00:00", C30)) - TIMEVALUE(IF(ISBLANK(E30), "00:00", E30))), "hh:mm")) -> 0:00 | G30: =COUNTIF(RestiaCSV!E:E, B30) -> 0 | H30: FALSE | I30: =IF(H30,G30*45, 0) -> 0 | L30: % doručených včas | M30: % zpožděných Woltdrivem
A31: {=IF(ISBLANK(B31), 0, IF(ISNUMBER(MATCH(B31, HR!A:A, 0)), 0, IF(ISNUMBER(MATCH(B31, HR!B:B, 0)), INDEX(HR!V:V, MATCH(B31, HR!B:B, 0)) * (F31 * 24), 0)))} -> 0 | F31: =IF(OR(ISBLANK(B31), ISBLANK(D31), D31=0), "0:00", TEXT((IF(AND(TIMEVALUE(IF(ISBLANK(D31), "00:00", D31))>=TIMEVALUE("00:00"), TIMEVALUE(IF(ISBLANK(D31), "00:00", D31))<=TIMEVALUE("06:00")), TIMEVALUE(IF(ISBLANK(D31), "00:00", D31))+1, TIMEVALUE(IF(ISBLANK(D31), "00:00", D31))) - TIMEVALUE(IF(ISBLANK(C31), "00:00", C31)) - TIMEVALUE(IF(ISBLANK(E31), "00:00", E31))), "hh:mm")) -> 0:00 | G31: =COUNTIF(RestiaCSV!E:E, B31) -> 0 | H31: FALSE | I31: =IF(H31,G31*45, 0) -> 0
B32: Wolt Kurýr | C32: Wolt drive | G32: =COUNTIFS(RestiaCSV!E:E, "wolt kurýr", RestiaCSV!A:A, "<>wolt") -> 0 | H32: TRUE | I32: =G32*127 -> 0 | L32: =100%-L29 -> #DIV/0! | M32: =M29/L26 -> #DIV/0!

Sheet Kontrola
B1: =Report!B1 -> Zličín | C1: 46203 | D1: Vyber datum <----------> | E1: 46203 | F1: COL | I1: Tržba | L1: Online Platby
F2: 0.25513576 | I2: 56034.9 | L2: Wolt | M2: 14732
B3: =CHOOSE(WEEKDAY(C1), "Neděle", "Pondělí", "Úterý", "Středa", "Čtvrtek", "Pátek", "Sobota") -> Úterý | L3: Bolt | M3: 2754
L4: Dáme jídlo | M4: 18024.8
B5: Celkem hodin Instor | F5: Celkem hodin Kurýr | L5: Web | M5: 12263.4
L6: Wolt drive cash | M6: 0
B7: =TEXT(SUMPRODUCT((IFERROR(LEFT(D10:D30, FIND(":", D10:D30) - 1) * 60, 0) + IFERROR(MID(D10:D30, FIND(":", D10:D30) + 1, LEN(D10:D30) - FIND(":", D10:D30)), 0))), "[h]:mm")/60 -> 28 | F7: =TEXT(SUMPRODUCT((IFERROR(LEFT(H10:H30, FIND(":", H10:H30) - 1) * 60, 0) + IFERROR(MID(H10:H30, FIND(":", H10:H30) + 1, LEN(H10:H30) - FIND(":", H10:H30)), 0))), "[h]:mm")/60 -> 16 | L7: DJ Cash | M7: 2167.2
B8: Instor | F8: Kurýr | J8: Pokladna | L8: Hotovost
B9: Jméno | C9: Počet dní | D9: Počet hodin | F9: Jméno | G9: Počet dní | H9: Počet hodin | I9: Počet rozvozů | J9: 0.3 | L9: Terminál | M9: 4364
B10: Veselý Ondřej | C10: 1 | D10: 15:00 | E10: 29:00 | F10: Lowe Jana | G10: 1 | H10: 3:00 | I10: 3 | L10: Stravenky | M10: 200
B11: Pechová Barbora | C11: 1 | D11: 8:00 | E11: 23:00 | F11: Novák Jakub | G11: 1 | H11: 6:00 | I11: 5 | L11: Hotovost | M11: 1376
B12: Čerešňák Michal | C12: 1 | D12: 5:00 | E12: 13:00 | F12: Dragoun Alfréd | G12: 1 | H12: 7:00 | I12: 12 | L12: Výdaje
E13: 13:00 | L13: Benzín | M13: 0
E14: 7:00 | L14: Auta | M14: 0
E15: 7:00 | L15: Suroviny | M15: 1421
L16: Ostatní | M16: 0
L17: PHM - soukromé | M17: 900
J19: Zrušené obj. ks | K19: Zrušené obj. $ | L19: Počet zpožděných našich rozvozů +5 min | M19: Průměrný make Time
J21: 0 | K21: 0 | L21: 1 | M21: 12 min 01 s
J22: počet výdajových dokadů | K22: Počet nezrušených celkem | L22: Počet našich rozvozů | M22: Počet pozdě přiřazeným WoltDrive 5+
J24: 3 | K24: 138 | L24: 21 | M24: 1
J25: Woltrdive zpožděný kvůli našemu pozdnímu přiřazení | L25: % zpožděných našich rozvozů +5 min | M25: Počet zpožděných Woltdrivem
J27: 1 | L27: 0.047619048 | M27: 1
L28: % doručených včas | M28: % zpožděných Woltdrivem
L30: 0.95238095 | M30: 0.047619048

Sheet RestiaCSV

Sheet HR
C1: =IFERROR(__xludf.DUMMYFUNCTION("IMPORTRANGE(""1TpIiNTfR1pnpn85VWQTTdvQ2Xcr0GStmWJ2UvfKxG_A"", ""Mzdy!A1:F200"")")," ") | V1: =IFERROR(__xludf.DUMMYFUNCTION("IMPORTRANGE(""1TpIiNTfR1pnpn85VWQTTdvQ2Xcr0GStmWJ2UvfKxG_A"", ""Mzdy!ac1:ad200"")"),31.0) -> 31 | W1: =IFERROR(__xludf.DUMMYFUNCTION("""COMPUTED_VALUE"""),"dní") -> dní
A4: Manažeři | B4: Zamestnanci pobocky | C4: =IFERROR(__xludf.DUMMYFUNCTION("""COMPUTED_VALUE"""),"Manažer") -> Manažer | D4: =IFERROR(__xludf.DUMMYFUNCTION("""COMPUTED_VALUE"""),"Instore") -> Instore | E4: =IFERROR(__xludf.DUMMYFUNCTION("""COMPUTED_VALUE"""),"První domácí, Pobočky max 4") -> První domácí, Pobočky max 4 | V4: =IFERROR(__xludf.DUMMYFUNCTION("""COMPUTED_VALUE"""),"Sp.hr. / h") -> Sp.hr. / h | W4: =IFERROR(__xludf.DUMMYFUNCTION("""COMPUTED_VALUE"""),"Sp.hr. / den") -> Sp.hr. / den
A5: =IF(AND(B5<>"", C5=TRUE, E5=Report!$B$1), B5, "") -> Nedbal Michal | B5: =IF(OR(E5=Report!$B$1, F5=Report!$B$1, G5=Report!$B$1, H5=Report!$B$1), D5, "") -> Nedbal Michal | C5: =IFERROR(__xludf.DUMMYFUNCTION("""COMPUTED_VALUE"""),TRUE) -> TRUE | D5: =IFERROR(__xludf.DUMMYFUNCTION("""COMPUTED_VALUE"""),"Nedbal Michal") -> Nedbal Michal | E5: =IFERROR(__xludf.DUMMYFUNCTION("""COMPUTED_VALUE"""),"Zličín") -> Zličín | F5: =IFERROR(__xludf.DUMMYFUNCTION("""COMPUTED_VALUE"""),"Malešice") -> Malešice | G5: =IFERROR(__xludf.DUMMYFUNCTION("""COMPUTED_VALUE"""),"Prosek") -> Prosek | V5: =IFERROR(__xludf.DUMMYFUNCTION("""COMPUTED_VALUE"""),432.3078) -> 432.3078 | W5: =IFERROR(__xludf.DUMMYFUNCTION("""COMPUTED_VALUE"""),2789.082580645161) -> 2789.0826
A6: =IF(AND(B6<>"", C6=TRUE, E6=Report!$B$1), B6, "") | B6: =IF(OR(E6=Report!$B$1, F6=Report!$B$1, G6=Report!$B$1, H6=Report!$B$1), D6, "") | C6: =IFERROR(__xludf.DUMMYFUNCTION("""COMPUTED_VALUE"""),TRUE) -> TRUE | D6: =IFERROR(__xludf.DUMMYFUNCTION("""COMPUTED_VALUE"""),"Sova Martin") -> Sova Martin | E6: =IFERROR(__xludf.DUMMYFUNCTION("""COMPUTED_VALUE"""),"Chodov") -> Chodov | F6: =IFERROR(__xludf.DUMMYFUNCTION("""COMPUTED_VALUE"""),"Libuš") -> Libuš | G6: =IFERROR(__xludf.DUMMYFUNCTION("""COMPUTED_VALUE"""),"Výroba") -> Výroba | V6: =IFERROR(__xludf.DUMMYFUNCTION("""COMPUTED_VALUE"""),432.3078) -> 432.3078 | W6: =IFERROR(__xludf.DUMMYFUNCTION("""COMPUTED_VALUE"""),2789.082580645161) -> 2789.0826
A7: =IF(AND(B7<>"", C7=TRUE, E7=Report!$B$1), B7, "") | B7: =IF(OR(E7=Report!$B$1, F7=Report!$B$1, G7=Report!$B$1, H7=Report!$B$1), D7, "") | C7: =IFERROR(__xludf.DUMMYFUNCTION("""COMPUTED_VALUE"""),TRUE) -> TRUE | D7: =IFERROR(__xludf.DUMMYFUNCTION("""COMPUTED_VALUE"""),"Paziak Viktoriia") -> Paziak Viktoriia | E7: =IFERROR(__xludf.DUMMYFUNCTION("""COMPUTED_VALUE"""),"Výroba") -> Výroba | V7: =IFERROR(__xludf.DUMMYFUNCTION("""COMPUTED_VALUE"""),341.19) -> 341.19 | W7: =IFERROR(__xludf.DUMMYFUNCTION("""COMPUTED_VALUE"""),2201.2258064516127) -> 2201.2258
A8: =IF(AND(B8<>"", C8=TRUE, E8=Report!$B$1), B8, "") | B8: =IF(OR(E8=Report!$B$1, F8=Report!$B$1, G8=Report!$B$1, H8=Report!$B$1), D8, "") | C8: =IFERROR(__xludf.DUMMYFUNCTION("""COMPUTED_VALUE"""),FALSE) -> FALSE | D8: =IFERROR(__xludf.DUMMYFUNCTION("""COMPUTED_VALUE"""),"Ahurieva Viktoriia") -> Ahurieva Viktoriia | E8: =IFERROR(__xludf.DUMMYFUNCTION("""COMPUTED_VALUE"""),"Libuš") -> Libuš | F8: =IFERROR(__xludf.DUMMYFUNCTION("""COMPUTED_VALUE"""),"Malešice") -> Malešice | G8: =IFERROR(__xludf.DUMMYFUNCTION("""COMPUTED_VALUE"""),"Výroba") -> Výroba | H8: =IFERROR(__xludf.DUMMYFUNCTION("""COMPUTED_VALUE"""),"Prosek") -> Prosek | V8: =IFERROR(__xludf.DUMMYFUNCTION("""COMPUTED_VALUE"""),432.3078) -> 432.3078 | W8: =IFERROR(__xludf.DUMMYFUNCTION("""COMPUTED_VALUE"""),2789.082580645161) -> 2789.0826
A9: =IF(AND(B9<>"", C9=TRUE, E9=Report!$B$1), B9, "") | B9: =IF(OR(E9=Report!$B$1, F9=Report!$B$1, G9=Report!$B$1, H9=Report!$B$1), D9, "") | C9: =IFERROR(__xludf.DUMMYFUNCTION("""COMPUTED_VALUE"""),TRUE) -> TRUE | D9: =IFERROR(__xludf.DUMMYFUNCTION("""COMPUTED_VALUE"""),"Pešová Hana") -> Pešová Hana | E9: =IFERROR(__xludf.DUMMYFUNCTION("""COMPUTED_VALUE"""),"Chodov") -> Chodov | F9: =IFERROR(__xludf.DUMMYFUNCTION("""COMPUTED_VALUE"""),"Prosek") -> Prosek | V9: =IFERROR(__xludf.DUMMYFUNCTION("""COMPUTED_VALUE"""),341.19) -> 341.19 | W9: =IFERROR(__xludf.DUMMYFUNCTION("""COMPUTED_VALUE"""),2201.2258064516127) -> 2201.2258
A10: =IF(AND(B10<>"", C10=TRUE, E10=Report!$B$1), B10, "") | B10: =IF(OR(E10=Report!$B$1, F10=Report!$B$1, G10=Report!$B$1, H10=Report!$B$1), D10, "") | C10: =IFERROR(__xludf.DUMMYFUNCTION("""COMPUTED_VALUE"""),TRUE) -> TRUE | D10: =IFERROR(__xludf.DUMMYFUNCTION("""COMPUTED_VALUE"""),"Šebesta Tomáš") -> Šebesta Tomáš | E10: =IFERROR(__xludf.DUMMYFUNCTION("""COMPUTED_VALUE"""),"Prosek") -> Prosek | F10: =IFERROR(__xludf.DUMMYFUNCTION("""COMPUTED_VALUE"""),"Libuš") -> Libuš | G10: =IFERROR(__xludf.DUMMYFUNCTION("""COMPUTED_VALUE"""),"Malešice") -> Malešice | H10: =IFERROR(__xludf.DUMMYFUNCTION("""COMPUTED_VALUE"""),"Chodov") -> Chodov | V10: =IFERROR(__xludf.DUMMYFUNCTION("""COMPUTED_VALUE"""),432.3078) -> 432.3078 | W10: =IFERROR(__xludf.DUMMYFUNCTION("""COMPUTED_VALUE"""),2789.082580645161) -> 2789.0826
A11: =IF(AND(B11<>"", C11=TRUE, E11=Report!$B$1), B11, "") | B11: =IF(OR(E11=Report!$B$1, F11=Report!$B$1, G11=Report!$B$1, H11=Report!$B$1), D11, "") -> Hanakova Ayuna | C11: =IFERROR(__xludf.DUMMYFUNCTION("""COMPUTED_VALUE"""),FALSE) -> FALSE | D11: =IFERROR(__xludf.DUMMYFUNCTION("""COMPUTED_VALUE"""),"Hanakova Ayuna") -> Hanakova Ayuna | E11: =IFERROR(__xludf.DUMMYFUNCTION("""COMPUTED_VALUE"""),"Zličín") -> Zličín | V11: =IFERROR(__xludf.DUMMYFUNCTION("""COMPUTED_VALUE"""),295.698) -> 295.698 | W11: =IFERROR(__xludf.DUMMYFUNCTION("""COMPUTED_VALUE"""),0.0) -> 0
A12: =IF(AND(B12<>"", C12=TRUE, E12=Report!$B$1), B12, "") | B12: =IF(OR(E12=Report!$B$1, F12=Report!$B$1, G12=Report!$B$1, H12=Report!$B$1), D12, "") | C12: =IFERROR(__xludf.DUMMYFUNCTION("""COMPUTED_VALUE"""),FALSE) -> FALSE | D12: =IFERROR(__xludf.DUMMYFUNCTION("""COMPUTED_VALUE"""),"Vondráček Lukáš") -> Vondráček Lukáš | V12: =IFERROR(__xludf.DUMMYFUNCTION("""COMPUTED_VALUE"""),0.0) -> 0 | W12: =IFERROR(__xludf.DUMMYFUNCTION("""COMPUTED_VALUE"""),0.0) -> 0
A13: =IF(AND(B13<>"", C13=TRUE, E13=Report!$B$1), B13, "") -> Veselý Ondřej | B13: =IF(OR(E13=Report!$B$1, F13=Report!$B$1, G13=Report!$B$1, H13=Report!$B$1), D13, "") -> Veselý Ondřej | C13: =IFERROR(__xludf.DUMMYFUNCTION("""COMPUTED_VALUE"""),TRUE) -> TRUE | D13: =IFERROR(__xludf.DUMMYFUNCTION("""COMPUTED_VALUE"""),"Veselý Ondřej") -> Veselý Ondřej | E13: =IFERROR(__xludf.DUMMYFUNCTION("""COMPUTED_VALUE"""),"Zličín") -> Zličín | F13: =IFERROR(__xludf.DUMMYFUNCTION("""COMPUTED_VALUE"""),"Malešice") -> Malešice | V13: =IFERROR(__xludf.DUMMYFUNCTION("""COMPUTED_VALUE"""),341.19) -> 341.19 | W13: =IFERROR(__xludf.DUMMYFUNCTION("""COMPUTED_VALUE"""),2201.2258064516127) -> 2201.2258
A14: =IF(AND(B14<>"", C14=TRUE, E14=Report!$B$1), B14, "") | B14: =IF(OR(E14=Report!$B$1, F14=Report!$B$1, G14=Report!$B$1, H14=Report!$B$1), D14, "") | C14: =IFERROR(__xludf.DUMMYFUNCTION("""COMPUTED_VALUE"""),FALSE) -> FALSE | D14: =IFERROR(__xludf.DUMMYFUNCTION("""COMPUTED_VALUE"""),"Coufal Jakub") -> Coufal Jakub | E14: =IFERROR(__xludf.DUMMYFUNCTION("""COMPUTED_VALUE"""),"Libuš") -> Libuš | F14: =IFERROR(__xludf.DUMMYFUNCTION("""COMPUTED_VALUE"""),"Malešice") -> Malešice | G14: =IFERROR(__xludf.DUMMYFUNCTION("""COMPUTED_VALUE"""),"Prosek") -> Prosek | V14: =IFERROR(__xludf.DUMMYFUNCTION("""COMPUTED_VALUE"""),250.20600000000002) -> 250.206 | W14: =IFERROR(__xludf.DUMMYFUNCTION("""COMPUTED_VALUE"""),0.0) -> 0
A15: =IF(AND(B15<>"", C15=TRUE, E15=Report!$B$1), B15, "") | B15: =IF(OR(E15=Report!$B$1, F15=Report!$B$1, G15=Report!$B$1, H15=Report!$B$1), D15, "") | C15: =IFERROR(__xludf.DUMMYFUNCTION("""COMPUTED_VALUE"""),TRUE) -> TRUE | D15: =IFERROR(__xludf.DUMMYFUNCTION("""COMPUTED_VALUE"""),"Kinkorová Petra") -> Kinkorová Petra | E15: =IFERROR(__xludf.DUMMYFUNCTION("""COMPUTED_VALUE"""),"Malešice") -> Malešice | F15: =IFERROR(__xludf.DUMMYFUNCTION("""COMPUTED_VALUE"""),"Bolevec") -> Bolevec | V15: =IFERROR(__xludf.DUMMYFUNCTION("""COMPUTED_VALUE"""),341.19) -> 341.19 | W15: =IFERROR(__xludf.DUMMYFUNCTION("""COMPUTED_VALUE"""),2201.2258064516127) -> 2201.2258
A16: =IF(AND(B16<>"", C16=TRUE, E16=Report!$B$1), B16, "") | B16: =IF(OR(E16=Report!$B$1, F16=Report!$B$1, G16=Report!$B$1, H16=Report!$B$1), D16, "") | C16: =IFERROR(__xludf.DUMMYFUNCTION("""COMPUTED_VALUE"""),TRUE) -> TRUE | D16: =IFERROR(__xludf.DUMMYFUNCTION("""COMPUTED_VALUE"""),"Nováková Adéla") -> Nováková Adéla | E16: =IFERROR(__xludf.DUMMYFUNCTION("""COMPUTED_VALUE"""),"Prosek") -> Prosek | F16: =IFERROR(__xludf.DUMMYFUNCTION("""COMPUTED_VALUE"""),"Malešice") -> Malešice | V16: =IFERROR(__xludf.DUMMYFUNCTION("""COMPUTED_VALUE"""),341.19) -> 341.19 | W16: =IFERROR(__xludf.DUMMYFUNCTION("""COMPUTED_VALUE"""),2201.2258064516127) -> 2201.2258
A17: =IF(AND(B17<>"", C17=TRUE, E17=Report!$B$1), B17, "") | B17: =IF(OR(E17=Report!$B$1, F17=Report!$B$1, G17=Report!$B$1, H17=Report!$B$1), D17, "") -> Pechová Barbora | C17: =IFERROR(__xludf.DUMMYFUNCTION("""COMPUTED_VALUE"""),FALSE) -> FALSE | D17: =IFERROR(__xludf.DUMMYFUNCTION("""COMPUTED_VALUE"""),"Pechová Barbora") -> Pechová Barbora | E17: =IFERROR(__xludf.DUMMYFUNCTION("""COMPUTED_VALUE"""),"Zličín") -> Zličín | V17: =IFERROR(__xludf.DUMMYFUNCTION("""COMPUTED_VALUE"""),267.6) -> 267.6 | W17: =IFERROR(__xludf.DUMMYFUNCTION("""COMPUTED_VALUE"""),0.0) -> 0
A18: =IF(AND(B18<>"", C18=TRUE, E18=Report!$B$1), B18, "") | B18: =IF(OR(E18=Report!$B$1, F18=Report!$B$1, G18=Report!$B$1, H18=Report!$B$1), D18, "") -> Pánková Vendula | C18: =IFERROR(__xludf.DUMMYFUNCTION("""COMPUTED_VALUE"""),FALSE) -> FALSE | D18: =IFERROR(__xludf.DUMMYFUNCTION("""COMPUTED_VALUE"""),"Pánková Vendula") -> Pánková Vendula | E18: =IFERROR(__xludf.DUMMYFUNCTION("""COMPUTED_VALUE"""),"Zličín") -> Zličín | V18: =IFERROR(__xludf.DUMMYFUNCTION("""COMPUTED_VALUE"""),267.6) -> 267.6 | W18: =IFERROR(__xludf.DUMMYFUNCTION("""COMPUTED_VALUE"""),0.0) -> 0
A19: =IF(AND(B19<>"", C19=TRUE, E19=Report!$B$1), B19, "") | B19: =IF(OR(E19=Report!$B$1, F19=Report!$B$1, G19=Report!$B$1, H19=Report!$B$1), D19, "") -> Hegedüs Erik | C19: =IFERROR(__xludf.DUMMYFUNCTION("""COMPUTED_VALUE"""),TRUE) -> TRUE | D19: =IFERROR(__xludf.DUMMYFUNCTION("""COMPUTED_VALUE"""),"Hegedüs Erik") -> Hegedüs Erik | E19: =IFERROR(__xludf.DUMMYFUNCTION("""COMPUTED_VALUE"""),"Libuš") -> Libuš | F19: =IFERROR(__xludf.DUMMYFUNCTION("""COMPUTED_VALUE"""),"Chodov") -> Chodov | G19: =IFERROR(__xludf.DUMMYFUNCTION("""COMPUTED_VALUE"""),"Malešice") -> Malešice | H19: =IFERROR(__xludf.DUMMYFUNCTION("""COMPUTED_VALUE"""),"Zličín") -> Zličín | V19: =IFERROR(__xludf.DUMMYFUNCTION("""COMPUTED_VALUE"""),432.3078) -> 432.3078 | W19: =IFERROR(__xludf.DUMMYFUNCTION("""COMPUTED_VALUE"""),2789.082580645161) -> 2789.0826
A20: =IF(AND(B20<>"", C20=TRUE, E20=Report!$B$1), B20, "") | B20: =IF(OR(E20=Report!$B$1, F20=Report!$B$1, G20=Report!$B$1, H20=Report!$B$1), D20, "") | C20: =IFERROR(__xludf.DUMMYFUNCTION("""COMPUTED_VALUE"""),TRUE) -> TRUE | D20: =IFERROR(__xludf.DUMMYFUNCTION("""COMPUTED_VALUE"""),"Roth Stanislav ml.") -> Roth Stanislav ml. | E20: =IFERROR(__xludf.DUMMYFUNCTION("""COMPUTED_VALUE"""),"Bolevec") -> Bolevec | V20: =IFERROR(__xludf.DUMMYFUNCTION("""COMPUTED_VALUE"""),432.3078) -> 432.3078 | W20: =IFERROR(__xludf.DUMMYFUNCTION("""COMPUTED_VALUE"""),2789.082580645161) -> 2789.0826
A21: =IF(AND(B21<>"", C21=TRUE, E21=Report!$B$1), B21, "") | B21: =IF(OR(E21=Report!$B$1, F21=Report!$B$1, G21=Report!$B$1, H21=Report!$B$1), D21, "") | C21: =IFERROR(__xludf.DUMMYFUNCTION("""COMPUTED_VALUE"""),FALSE) -> FALSE | D21: =IFERROR(__xludf.DUMMYFUNCTION("""COMPUTED_VALUE"""),"Bubník Martin") -> Bubník Martin | E21: =IFERROR(__xludf.DUMMYFUNCTION("""COMPUTED_VALUE"""),"Libuš") -> Libuš | F21: =IFERROR(__xludf.DUMMYFUNCTION("""COMPUTED_VALUE"""),"Malešice") -> Malešice | V21: =IFERROR(__xludf.DUMMYFUNCTION("""COMPUTED_VALUE"""),267.6) -> 267.6 | W21: =IFERROR(__xludf.DUMMYFUNCTION("""COMPUTED_VALUE"""),0.0) -> 0
A22: =IF(AND(B22<>"", C22=TRUE, E22=Report!$B$1), B22, "") | B22: =IF(OR(E22=Report!$B$1, F22=Report!$B$1, G22=Report!$B$1, H22=Report!$B$1), D22, "") | C22: =IFERROR(__xludf.DUMMYFUNCTION("""COMPUTED_VALUE"""),FALSE) -> FALSE | D22: =IFERROR(__xludf.DUMMYFUNCTION("""COMPUTED_VALUE"""),"Berdar Vasyl") -> Berdar Vasyl | E22: =IFERROR(__xludf.DUMMYFUNCTION("""COMPUTED_VALUE"""),"Libuš") -> Libuš | V22: =IFERROR(__xludf.DUMMYFUNCTION("""COMPUTED_VALUE"""),286.332) -> 286.332 | W22: =IFERROR(__xludf.DUMMYFUNCTION("""COMPUTED_VALUE"""),0.0) -> 0
A23: =IF(AND(B23<>"", C23=TRUE, E23=Report!$B$1), B23, "") | B23: =IF(OR(E23=Report!$B$1, F23=Report!$B$1, G23=Report!$B$1, H23=Report!$B$1), D23, "") -> Yarushynskyi Vladyslav | C23: =IFERROR(__xludf.DUMMYFUNCTION("""COMPUTED_VALUE"""),FALSE) -> FALSE | D23: =IFERROR(__xludf.DUMMYFUNCTION("""COMPUTED_VALUE"""),"Yarushynskyi Vladyslav") -> Yarushynskyi Vladyslav | E23: =IFERROR(__xludf.DUMMYFUNCTION("""COMPUTED_VALUE"""),"Malešice") -> Malešice | F23: =IFERROR(__xludf.DUMMYFUNCTION("""COMPUTED_VALUE"""),"Chodov") -> Chodov | G23: =IFERROR(__xludf.DUMMYFUNCTION("""COMPUTED_VALUE"""),"Zličín") -> Zličín | H23: =IFERROR(__xludf.DUMMYFUNCTION("""COMPUTED_VALUE"""),"Prosek") -> Prosek | V23: =IFERROR(__xludf.DUMMYFUNCTION("""COMPUTED_VALUE"""),267.6) -> 267.6 | W23: =IFERROR(__xludf.DUMMYFUNCTION("""COMPUTED_VALUE"""),0.0) -> 0
A24: =IF(AND(B24<>"", C24=TRUE, E24=Report!$B$1), B24, "") | B24: =IF(OR(E24=Report!$B$1, F24=Report!$B$1, G24=Report!$B$1, H24=Report!$B$1), D24, "") | C24: =IFERROR(__xludf.DUMMYFUNCTION("""COMPUTED_VALUE"""),FALSE) -> FALSE | D24: =IFERROR(__xludf.DUMMYFUNCTION("""COMPUTED_VALUE"""),"Židek Petr") -> Židek Petr | E24: =IFERROR(__xludf.DUMMYFUNCTION("""COMPUTED_VALUE"""),"Chodov") -> Chodov | F24: =IFERROR(__xludf.DUMMYFUNCTION("""COMPUTED_VALUE"""),"Malešice") -> Malešice | V24: =IFERROR(__xludf.DUMMYFUNCTION("""COMPUTED_VALUE"""),250.20600000000002) -> 250.206 | W24: =IFERROR(__xludf.DUMMYFUNCTION("""COMPUTED_VALUE"""),0.0) -> 0
A25: =IF(AND(B25<>"", C25=TRUE, E25=Report!$B$1), B25, "") | B25: =IF(OR(E25=Report!$B$1, F25=Report!$B$1, G25=Report!$B$1, H25=Report!$B$1), D25, "") | C25: =IFERROR(__xludf.DUMMYFUNCTION("""COMPUTED_VALUE"""),FALSE) -> FALSE | D25: =IFERROR(__xludf.DUMMYFUNCTION("""COMPUTED_VALUE"""),"Gorol Patrik") -> Gorol Patrik | E25: =IFERROR(__xludf.DUMMYFUNCTION("""COMPUTED_VALUE"""),"Malešice") -> Malešice | F25: =IFERROR(__xludf.DUMMYFUNCTION("""COMPUTED_VALUE"""),"Libuš") -> Libuš | G25: =IFERROR(__xludf.DUMMYFUNCTION("""COMPUTED_VALUE"""),"Prosek") -> Prosek | V25: =IFERROR(__xludf.DUMMYFUNCTION("""COMPUTED_VALUE"""),231.474) -> 231.474 | W25: =IFERROR(__xludf.DUMMYFUNCTION("""COMPUTED_VALUE"""),0.0) -> 0
A26: =IF(AND(B26<>"", C26=TRUE, E26=Report!$B$1), B26, "") | B26: =IF(OR(E26=Report!$B$1, F26=Report!$B$1, G26=Report!$B$1, H26=Report!$B$1), D26, "") | C26: =IFERROR(__xludf.DUMMYFUNCTION("""COMPUTED_VALUE"""),FALSE) -> FALSE | D26: =IFERROR(__xludf.DUMMYFUNCTION("""COMPUTED_VALUE"""),"Hegedüs Gergö") -> Hegedüs Gergö | E26: =IFERROR(__xludf.DUMMYFUNCTION("""COMPUTED_VALUE"""),"Libuš") -> Libuš | V26: =IFERROR(__xludf.DUMMYFUNCTION("""COMPUTED_VALUE"""),214.08) -> 214.08 | W26: =IFERROR(__xludf.DUMMYFUNCTION("""COMPUTED_VALUE"""),0.0) -> 0
A27: =IF(AND(B27<>"", C27=TRUE, E27=Report!$B$1), B27, "") | B27: =IF(OR(E27=Report!$B$1, F27=Report!$B$1, G27=Report!$B$1, H27=Report!$B$1), D27, "") | C27: =IFERROR(__xludf.DUMMYFUNCTION("""COMPUTED_VALUE"""),FALSE) -> FALSE | D27: =IFERROR(__xludf.DUMMYFUNCTION("""COMPUTED_VALUE"""),"Barvínková Eliška") -> Barvínková Eliška | E27: =IFERROR(__xludf.DUMMYFUNCTION("""COMPUTED_VALUE"""),"Libuš") -> Libuš | V27: =IFERROR(__xludf.DUMMYFUNCTION("""COMPUTED_VALUE"""),231.474) -> 231.474 | W27: =IFERROR(__xludf.DUMMYFUNCTION("""COMPUTED_VALUE"""),0.0) -> 0
A28: =IF(AND(B28<>"", C28=TRUE, E28=Report!$B$1), B28, "") | B28: =IF(OR(E28=Report!$B$1, F28=Report!$B$1, G28=Report!$B$1, H28=Report!$B$1), D28, "") | C28: =IFERROR(__xludf.DUMMYFUNCTION("""COMPUTED_VALUE"""),FALSE) -> FALSE | D28: =IFERROR(__xludf.DUMMYFUNCTION("""COMPUTED_VALUE"""),"Kursheva Diana") -> Kursheva Diana | E28: =IFERROR(__xludf.DUMMYFUNCTION("""COMPUTED_VALUE"""),"Výroba") -> Výroba | F28: =IFERROR(__xludf.DUMMYFUNCTION("""COMPUTED_VALUE"""),"Chodov") -> Chodov | V28: =IFERROR(__xludf.DUMMYFUNCTION("""COMPUTED_VALUE"""),250.20600000000002) -> 250.206 | W28: =IFERROR(__xludf.DUMMYFUNCTION("""COMPUTED_VALUE"""),0.0) -> 0
A29: =IF(AND(B29<>"", C29=TRUE, E29=Report!$B$1), B29, "") | B29: =IF(OR(E29=Report!$B$1, F29=Report!$B$1, G29=Report!$B$1, H29=Report!$B$1), D29, "") | C29: =IFERROR(__xludf.DUMMYFUNCTION("""COMPUTED_VALUE"""),FALSE) -> FALSE | D29: =IFERROR(__xludf.DUMMYFUNCTION("""COMPUTED_VALUE"""),"Kubík Martin") -> Kubík Martin | E29: =IFERROR(__xludf.DUMMYFUNCTION("""COMPUTED_VALUE"""),"Libuš") -> Libuš | V29: =IFERROR(__xludf.DUMMYFUNCTION("""COMPUTED_VALUE"""),250.20600000000002) -> 250.206 | W29: =IFERROR(__xludf.DUMMYFUNCTION("""COMPUTED_VALUE"""),0.0) -> 0
A30: =IF(AND(B30<>"", C30=TRUE, E30=Report!$B$1), B30, "") | B30: =IF(OR(E30=Report!$B$1, F30=Report!$B$1, G30=Report!$B$1, H30=Report!$B$1), D30, "") -> Putna Jaroslav | C30: =IFERROR(__xludf.DUMMYFUNCTION("""COMPUTED_VALUE"""),FALSE) -> FALSE | D30: =IFERROR(__xludf.DUMMYFUNCTION("""COMPUTED_VALUE"""),"Putna Jaroslav") -> Putna Jaroslav | E30: =IFERROR(__xludf.DUMMYFUNCTION("""COMPUTED_VALUE"""),"Zličín") -> Zličín | F30: =IFERROR(__xludf.DUMMYFUNCTION("""COMPUTED_VALUE"""),"Prosek") -> Prosek | V30: =IFERROR(__xludf.DUMMYFUNCTION("""COMPUTED_VALUE"""),250.20600000000002) -> 250.206 | W30: =IFERROR(__xludf.DUMMYFUNCTION("""COMPUTED_VALUE"""),0.0) -> 0
A31: =IF(AND(B31<>"", C31=TRUE, E31=Report!$B$1), B31, "") | B31: =IF(OR(E31=Report!$B$1, F31=Report!$B$1, G31=Report!$B$1, H31=Report!$B$1), D31, "") | C31: =IFERROR(__xludf.DUMMYFUNCTION("""COMPUTED_VALUE"""),FALSE) -> FALSE | D31: =IFERROR(__xludf.DUMMYFUNCTION("""COMPUTED_VALUE"""),"Kopic Jakub") -> Kopic Jakub | E31: =IFERROR(__xludf.DUMMYFUNCTION("""COMPUTED_VALUE"""),"Malešice") -> Malešice | F31: =IFERROR(__xludf.DUMMYFUNCTION("""COMPUTED_VALUE"""),"Prosek") -> Prosek | G31: =IFERROR(__xludf.DUMMYFUNCTION("""COMPUTED_VALUE"""),"Libuš") -> Libuš | H31: =IFERROR(__xludf.DUMMYFUNCTION("""COMPUTED_VALUE"""),"Prosek") -> Prosek | V31: =IFERROR(__xludf.DUMMYFUNCTION("""COMPUTED_VALUE"""),250.20600000000002) -> 250.206 | W31: =IFERROR(__xludf.DUMMYFUNCTION("""COMPUTED_VALUE"""),0.0) -> 0
A32: =IF(AND(B32<>"", C32=TRUE, E32=Report!$B$1), B32, "") | B32: =IF(OR(E32=Report!$B$1, F32=Report!$B$1, G32=Report!$B$1, H32=Report!$B$1), D32, "") | C32: =IFERROR(__xludf.DUMMYFUNCTION("""COMPUTED_VALUE"""),FALSE) -> FALSE | D32: =IFERROR(__xludf.DUMMYFUNCTION("""COMPUTED_VALUE"""),"Fáberová Kateřina") -> Fáberová Kateřina | E32: =IFERROR(__xludf.DUMMYFUNCTION("""COMPUTED_VALUE"""),"Prosek") -> Prosek | V32: =IFERROR(__xludf.DUMMYFUNCTION("""COMPUTED_VALUE"""),250.20600000000002) -> 250.206 | W32: =IFERROR(__xludf.DUMMYFUNCTION("""COMPUTED_VALUE"""),0.0) -> 0
A33: =IF(AND(B33<>"", C33=TRUE, E33=Report!$B$1), B33, "") | B33: =IF(OR(E33=Report!$B$1, F33=Report!$B$1, G33=Report!$B$1, H33=Report!$B$1), D33, "") | C33: =IFERROR(__xludf.DUMMYFUNCTION("""COMPUTED_VALUE"""),FALSE) -> FALSE | D33: =IFERROR(__xludf.DUMMYFUNCTION("""COMPUTED_VALUE"""),"Chlubnová Adéla") -> Chlubnová Adéla | E33: =IFERROR(__xludf.DUMMYFUNCTION("""COMPUTED_VALUE"""),"Chodov") -> Chodov | V33: =IFERROR(__xludf.DUMMYFUNCTION("""COMPUTED_VALUE"""),250.20600000000002) -> 250.206 | W33: =IFERROR(__xludf.DUMMYFUNCTION("""COMPUTED_VALUE"""),0.0) -> 0
A34: =IF(AND(B34<>"", C34=TRUE, E34=Report!$B$1), B34, "") | B34: =IF(OR(E34=Report!$B$1, F34=Report!$B$1, G34=Report!$B$1, H34=Report!$B$1), D34, "") | C34: =IFERROR(__xludf.DUMMYFUNCTION("""COMPUTED_VALUE"""),FALSE) -> FALSE | D34: =IFERROR(__xludf.DUMMYFUNCTION("""COMPUTED_VALUE"""),"Prošek Václav") -> Prošek Václav | E34: =IFERROR(__xludf.DUMMYFUNCTION("""COMPUTED_VALUE"""),"Libuš") -> Libuš | V34: =IFERROR(__xludf.DUMMYFUNCTION("""COMPUTED_VALUE"""),250.20600000000002) -> 250.206 | W34: =IFERROR(__xludf.DUMMYFUNCTION("""COMPUTED_VALUE"""),0.0) -> 0
A35: =IF(AND(B35<>"", C35=TRUE, E35=Report!$B$1), B35, "") | B35: =IF(OR(E35=Report!$B$1, F35=Report!$B$1, G35=Report!$B$1, H35=Report!$B$1), D35, "") | C35: =IFERROR(__xludf.DUMMYFUNCTION("""COMPUTED_VALUE"""),FALSE) -> FALSE | D35: =IFERROR(__xludf.DUMMYFUNCTION("""COMPUTED_VALUE"""),"Millington Emmanuel") -> Millington Emmanuel | E35: =IFERROR(__xludf.DUMMYFUNCTION("""COMPUTED_VALUE"""),"Libuš") -> Libuš | V35: =IFERROR(__xludf.DUMMYFUNCTION("""COMPUTED_VALUE"""),250.20600000000002) -> 250.206 | W35: =IFERROR(__xludf.DUMMYFUNCTION("""COMPUTED_VALUE"""),0.0) -> 0
A36: =IF(AND(B36<>"", C36=TRUE, E36=Report!$B$1), B36, "") | B36: =IF(OR(E36=Report!$B$1, F36=Report!$B$1, G36=Report!$B$1, H36=Report!$B$1), D36, "") | C36: =IFERROR(__xludf.DUMMYFUNCTION("""COMPUTED_VALUE"""),FALSE) -> FALSE | D36: =IFERROR(__xludf.DUMMYFUNCTION("""COMPUTED_VALUE"""),"Kašpárek Jan") -> Kašpárek Jan | E36: =IFERROR(__xludf.DUMMYFUNCTION("""COMPUTED_VALUE"""),"Libuš") -> Libuš | V36: =IFERROR(__xludf.DUMMYFUNCTION("""COMPUTED_VALUE"""),250.20600000000002) -> 250.206 | W36: =IFERROR(__xludf.DUMMYFUNCTION("""COMPUTED_VALUE"""),0.0) -> 0
A37: =IF(AND(B37<>"", C37=TRUE, E37=Report!$B$1), B37, "") | B37: =IF(OR(E37=Report!$B$1, F37=Report!$B$1, G37=Report!$B$1, H37=Report!$B$1), D37, "") | C37: =IFERROR(__xludf.DUMMYFUNCTION("""COMPUTED_VALUE"""),FALSE) -> FALSE | D37: =IFERROR(__xludf.DUMMYFUNCTION("""COMPUTED_VALUE"""),"Koteliuk Maryna") -> Koteliuk Maryna | E37: =IFERROR(__xludf.DUMMYFUNCTION("""COMPUTED_VALUE"""),"Výroba") -> Výroba | V37: =IFERROR(__xludf.DUMMYFUNCTION("""COMPUTED_VALUE"""),250.20600000000002) -> 250.206 | W37: =IFERROR(__xludf.DUMMYFUNCTION("""COMPUTED_VALUE"""),0.0) -> 0
A38: =IF(AND(B38<>"", C38=TRUE, E38=Report!$B$1), B38, "") | B38: =IF(OR(E38=Report!$B$1, F38=Report!$B$1, G38=Report!$B$1, H38=Report!$B$1), D38, "") | C38: =IFERROR(__xludf.DUMMYFUNCTION("""COMPUTED_VALUE"""),FALSE) -> FALSE | D38: =IFERROR(__xludf.DUMMYFUNCTION("""COMPUTED_VALUE"""),"Remač Jiří") -> Remač Jiří | E38: =IFERROR(__xludf.DUMMYFUNCTION("""COMPUTED_VALUE"""),"Libuš") -> Libuš | V38: =IFERROR(__xludf.DUMMYFUNCTION("""COMPUTED_VALUE"""),250.20600000000002) -> 250.206 | W38: =IFERROR(__xludf.DUMMYFUNCTION("""COMPUTED_VALUE"""),0.0) -> 0
A39: =IF(AND(B39<>"", C39=TRUE, E39=Report!$B$1), B39, "") | B39: =IF(OR(E39=Report!$B$1, F39=Report!$B$1, G39=Report!$B$1, H39=Report!$B$1), D39, "") | C39: =IFERROR(__xludf.DUMMYFUNCTION("""COMPUTED_VALUE"""),FALSE) -> FALSE | V39: =IFERROR(__xludf.DUMMYFUNCTION("""COMPUTED_VALUE"""),0.0) -> 0 | W39: =IFERROR(__xludf.DUMMYFUNCTION("""COMPUTED_VALUE"""),0.0) -> 0
A40: =IF(AND(B40<>"", C40=TRUE, E40=Report!$B$1), B40, "") | B40: =IF(OR(E40=Report!$B$1, F40=Report!$B$1, G40=Report!$B$1, H40=Report!$B$1), D40, "") | C40: =IFERROR(__xludf.DUMMYFUNCTION("""COMPUTED_VALUE"""),FALSE) -> FALSE | V40: =IFERROR(__xludf.DUMMYFUNCTION("""COMPUTED_VALUE"""),0.0) -> 0 | W40: =IFERROR(__xludf.DUMMYFUNCTION("""COMPUTED_VALUE"""),0.0) -> 0
A41: =IF(AND(B41<>"", C41=TRUE, E41=Report!$B$1), B41, "") | B41: =IF(OR(E41=Report!$B$1, F41=Report!$B$1, G41=Report!$B$1, H41=Report!$B$1), D41, "") | C41: =IFERROR(__xludf.DUMMYFUNCTION("""COMPUTED_VALUE"""),FALSE) -> FALSE | V41: =IFERROR(__xludf.DUMMYFUNCTION("""COMPUTED_VALUE"""),0.0) -> 0 | W41: =IFERROR(__xludf.DUMMYFUNCTION("""COMPUTED_VALUE"""),0.0) -> 0
A42: =IF(AND(B42<>"", C42=TRUE, E42=Report!$B$1), B42, "") | B42: =IF(OR(E42=Report!$B$1, F42=Report!$B$1, G42=Report!$B$1, H42=Report!$B$1), D42, "") | C42: =IFERROR(__xludf.DUMMYFUNCTION("""COMPUTED_VALUE"""),FALSE) -> FALSE | V42: =IFERROR(__xludf.DUMMYFUNCTION("""COMPUTED_VALUE"""),0.0) -> 0 | W42: =IFERROR(__xludf.DUMMYFUNCTION("""COMPUTED_VALUE"""),0.0) -> 0
...

Sheet Denik

Sheet Směny
