Workbook

Sheet Report
B1: Malesice | C1: Datum | D1: 45962 | F1: COL | I1: Tržba | L1: Online Platby
F2: =IFERROR(__xludf.DUMMYFUNCTION("IF(I2>0, 100 / (I2 / 112 * 100 / ((SUM(A12:A21, A25:A31) + (M17 + I32) + IFERROR(SUM(FILTER(HR!W5:W48, LEN(HR!A5:A48) > 0)), 0)) / 100)), ""Zadej tržbu"")"),"#DIV/0!") -> #DIV/0! | I2: =SUM(RestiaCSV!C:C) - SUMIFS(RestiaCSV!C:C, RestiaCSV!B:B, "canceled") -> 29656 | L2: Wolt | M2: =SUMIFS(RestiaCSV!C:C, RestiaCSV!A:A, Report!L2, RestiaCSV!B:B, "<>canceled") -> 12916
B3: =CHOOSE(WEEKDAY(D1), "Neděle", "Pondělí", "Úterý", "Středa", "Čtvrtek", "Pátek", "Sobota") -> Sobota | L3: Bolt | M3: =SUMIFS(RestiaCSV!C:C, RestiaCSV!A:A, Report!L3, RestiaCSV!B:B, "<>canceled") -> 3655
L4: Dáme jídlo | M4: =SUMIFS(RestiaCSV!C:C, RestiaCSV!A:A, "damejidlo", RestiaCSV!G:G, "online", RestiaCSV!B:B, "<>canceled") -> 6192
B5: Napiš vzkaz ⬇️ 📖 Deník 📖 ⬇️ Včerejší vzkaz | L5: Web | M5: =SUMIFS(RestiaCSV!C:C, RestiaCSV!A:A, "generic", RestiaCSV!G:G, "online", RestiaCSV!B:B, "<>canceled") -> 5528
L6: Wolt drive cash | M6: =SUMIFS(RestiaCSV!C:C, RestiaCSV!E:E, "wolt kurýr", RestiaCSV!A:A, "<>wolt", RestiaCSV!G:G, "cash", RestiaCSV!B:B, "<>canceled") -> 0
F7: test, uloží se to správně? | L7: DJ Cash | M7: =SUMIFS(RestiaCSV!C:C, RestiaCSV!A:A, "damejidlo", RestiaCSV!G:G, "cash", RestiaCSV!B:B, "<>canceled") -> 0
L8: Hotovost
L9: Terminál | M9: 884
B10: Instor | G10: Otevíral | J10: Pokladna | L10: Stravenky
B11: Jméno | C11: Začátek směny | D11: Konec směny | E11: pauza | F11: Počet hodin | G11: Novák Dalibor | J11: =M2+M3+M4+M5+M6+M13+M14+M15+M16+M17+M9+M10+M11-I2 -> 2698 | L11: Hotovost | M11: 2679
A12: {=IF(ISBLANK(B12), 0, IF(ISNUMBER(MATCH(B12, HR!A:A, 0)), 0, IF(ISNUMBER(MATCH(B12, HR!B:B, 0)), INDEX(HR!V:V, MATCH(B12, HR!B:B, 0)) * (F12 * 24), 0)))} -> 0 | B12: Novák Dalibor | C12: 10:00 | D12: 17:00 | F12: =IF(OR(ISBLANK(B12), ISBLANK(D12), D12=0), "0:00", TEXT((IF(AND(TIMEVALUE(IF(ISBLANK(D12), "00:00", D12))>=TIMEVALUE("00:00"), TIMEVALUE(IF(ISBLANK(D12), "00:00", D12))<=TIMEVALUE("06:00")), TIMEVALUE(IF(ISBLANK(D12), "00:00", D12))+1, TIMEVALUE(IF(ISBLANK(D12), "00:00", D12))) - TIMEVALUE(IF(ISBLANK(C12), "00:00", C12)) - TIMEVALUE(IF(ISBLANK(E12), "00:00", E12))), "hh:mm")) -> 07:00 | L12: Výdaje
A13: {=IF(ISBLANK(B13), 0, IF(ISNUMBER(MATCH(B13, HR!A:A, 0)), 0, IF(ISNUMBER(MATCH(B13, HR!B:B, 0)), INDEX(HR!V:V, MATCH(B13, HR!B:B, 0)) * (F13 * 24), 0)))} -> 0 | B13: Hegedüs Erik | C13: 17:00 | D13: 01:00 | F13: =IF(OR(ISBLANK(B13), ISBLANK(D13), D13=0), "0:00", TEXT((IF(AND(TIMEVALUE(IF(ISBLANK(D13), "00:00", D13))>=TIMEVALUE("00:00"), TIMEVALUE(IF(ISBLANK(D13), "00:00", D13))<=TIMEVALUE("06:00")), TIMEVALUE(IF(ISBLANK(D13), "00:00", D13))+1, TIMEVALUE(IF(ISBLANK(D13), "00:00", D13))) - TIMEVALUE(IF(ISBLANK(C13), "00:00", C13)) - TIMEVALUE(IF(ISBLANK(E13), "00:00", E13))), "hh:mm")) -> 08:00 | L13: Benzín | M13: 500
A14: {=IF(ISBLANK(B14), 0, IF(ISNUMBER(MATCH(B14, HR!A:A, 0)), 0, IF(ISNUMBER(MATCH(B14, HR!B:B, 0)), INDEX(HR!V:V, MATCH(B14, HR!B:B, 0)) * (F14 * 24), 0)))} -> 0 | F14: =IF(OR(ISBLANK(B14), ISBLANK(D14), D14=0), "0:00", TEXT((IF(AND(TIMEVALUE(IF(ISBLANK(D14), "00:00", D14))>=TIMEVALUE("00:00"), TIMEVALUE(IF(ISBLANK(D14), "00:00", D14))<=TIMEVALUE("06:00")), TIMEVALUE(IF(ISBLANK(D14), "00:00", D14))+1, TIMEVALUE(IF(ISBLANK(D14), "00:00", D14))) - TIMEVALUE(IF(ISBLANK(C14), "00:00", C14)) - TIMEVALUE(IF(ISBLANK(E14), "00:00", E14))), "hh:mm")) -> 0:00 | L14: Auta
A15: {=IF(ISBLANK(B15), 0, IF(ISNUMBER(MATCH(B15, HR!A:A, 0)), 0, IF(ISNUMBER(MATCH(B15, HR!B:B, 0)), INDEX(HR!V:V, MATCH(B15, HR!B:B, 0)) * (F15 * 24), 0)))} -> 0 | F15: =IF(OR(ISBLANK(B15), ISBLANK(D15), D15=0), "0:00", TEXT((IF(AND(TIMEVALUE(IF(ISBLANK(D15), "00:00", D15))>=TIMEVALUE("00:00"), TIMEVALUE(IF(ISBLANK(D15), "00:00", D15))<=TIMEVALUE("06:00")), TIMEVALUE(IF(ISBLANK(D15), "00:00", D15))+1, TIMEVALUE(IF(ISBLANK(D15), "00:00", D15))) - TIMEVALUE(IF(ISBLANK(C15), "00:00", C15)) - TIMEVALUE(IF(ISBLANK(E15), "00:00", E15))), "hh:mm")) -> 0:00 | L15: Suroviny
A16: {=IF(ISBLANK(B16), 0, IF(ISNUMBER(MATCH(B16, HR!A:A, 0)), 0, IF(ISNUMBER(MATCH(B16, HR!B:B, 0)), INDEX(HR!V:V, MATCH(B16, HR!B:B, 0)) * (F16 * 24), 0)))} -> 0 | F16: =IF(OR(ISBLANK(B16), ISBLANK(D16), D16=0), "0:00", TEXT((IF(AND(TIMEVALUE(IF(ISBLANK(D16), "00:00", D16))>=TIMEVALUE("00:00"), TIMEVALUE(IF(ISBLANK(D16), "00:00", D16))<=TIMEVALUE("06:00")), TIMEVALUE(IF(ISBLANK(D16), "00:00", D16))+1, TIMEVALUE(IF(ISBLANK(D16), "00:00", D16))) - TIMEVALUE(IF(ISBLANK(C16), "00:00", C16)) - TIMEVALUE(IF(ISBLANK(E16), "00:00", E16))), "hh:mm")) -> 0:00 | L16: Ostatní
A17: {=IF(ISBLANK(B17), 0, IF(ISNUMBER(MATCH(B17, HR!A:A, 0)), 0, IF(ISNUMBER(MATCH(B17, HR!B:B, 0)), INDEX(HR!V:V, MATCH(B17, HR!B:B, 0)) * (F17 * 24), 0)))} -> 0 | F17: =IF(OR(ISBLANK(B17), ISBLANK(D17), D17=0), "0:00", TEXT((IF(AND(TIMEVALUE(IF(ISBLANK(D17), "00:00", D17))>=TIMEVALUE("00:00"), TIMEVALUE(IF(ISBLANK(D17), "00:00", D17))<=TIMEVALUE("06:00")), TIMEVALUE(IF(ISBLANK(D17), "00:00", D17))+1, TIMEVALUE(IF(ISBLANK(D17), "00:00", D17))) - TIMEVALUE(IF(ISBLANK(C17), "00:00", C17)) - TIMEVALUE(IF(ISBLANK(E17), "00:00", E17))), "hh:mm")) -> 0:00 | L17: PHM - soukromé | M17: =SUM(I25:I31) -> 0
A18: {=IF(ISBLANK(B18), 0, IF(ISNUMBER(MATCH(B18, HR!A:A, 0)), 0, IF(ISNUMBER(MATCH(B18, HR!B:B, 0)), INDEX(HR!V:V, MATCH(B18, HR!B:B, 0)) * (F18 * 24), 0)))} -> 0 | F18: =IF(OR(ISBLANK(B18), ISBLANK(D18), D18=0), "0:00", TEXT((IF(AND(TIMEVALUE(IF(ISBLANK(D18), "00:00", D18))>=TIMEVALUE("00:00"), TIMEVALUE(IF(ISBLANK(D18), "00:00", D18))<=TIMEVALUE("06:00")), TIMEVALUE(IF(ISBLANK(D18), "00:00", D18))+1, TIMEVALUE(IF(ISBLANK(D18), "00:00", D18))) - TIMEVALUE(IF(ISBLANK(C18), "00:00", C18)) - TIMEVALUE(IF(ISBLANK(E18), "00:00", E18))), "hh:mm")) -> 0:00 | G18: Zavíral
A19: {=IF(ISBLANK(B19), 0, IF(ISNUMBER(MATCH(B19, HR!A:A, 0)), 0, IF(ISNUMBER(MATCH(B19, HR!B:B, 0)), INDEX(HR!V:V, MATCH(B19, HR!B:B, 0)) * (F19 * 24), 0)))} -> 0 | F19: =IF(OR(ISBLANK(B19), ISBLANK(D19), D19=0), "0:00", TEXT((IF(AND(TIMEVALUE(IF(ISBLANK(D19), "00:00", D19))>=TIMEVALUE("00:00"), TIMEVALUE(IF(ISBLANK(D19), "00:00", D19))<=TIMEVALUE("06:00")), TIMEVALUE(IF(ISBLANK(D19), "00:00", D19))+1, TIMEVALUE(IF(ISBLANK(D19), "00:00", D19))) - TIMEVALUE(IF(ISBLANK(C19), "00:00", C19)) - TIMEVALUE(IF(ISBLANK(E19), "00:00", E19))), "hh:mm")) -> 0:00 | G19: Hegedüs Erik
A20: {=IF(ISBLANK(B20), 0, IF(ISNUMBER(MATCH(B20, HR!A:A, 0)), 0, IF(ISNUMBER(MATCH(B20, HR!B:B, 0)), INDEX(HR!V:V, MATCH(B20, HR!B:B, 0)) * (F20 * 24), 0)))} -> 0 | F20: =IF(OR(ISBLANK(B20), ISBLANK(D20), D20=0), "0:00", TEXT((IF(AND(TIMEVALUE(IF(ISBLANK(D20), "00:00", D20))>=TIMEVALUE("00:00"), TIMEVALUE(IF(ISBLANK(D20), "00:00", D20))<=TIMEVALUE("06:00")), TIMEVALUE(IF(ISBLANK(D20), "00:00", D20))+1, TIMEVALUE(IF(ISBLANK(D20), "00:00", D20))) - TIMEVALUE(IF(ISBLANK(C20), "00:00", C20)) - TIMEVALUE(IF(ISBLANK(E20), "00:00", E20))), "hh:mm")) -> 0:00
A21: {=IF(ISBLANK(B21), 0, IF(ISNUMBER(MATCH(B21, HR!A:A, 0)), 0, IF(ISNUMBER(MATCH(B21, HR!B:B, 0)), INDEX(HR!V:V, MATCH(B21, HR!B:B, 0)) * (F21 * 24), 0)))} -> 0 | F21: =IF(OR(ISBLANK(B21), ISBLANK(D21), D21=0), "0:00", TEXT((IF(AND(TIMEVALUE(IF(ISBLANK(D21), "00:00", D21))>=TIMEVALUE("00:00"), TIMEVALUE(IF(ISBLANK(D21), "00:00", D21))<=TIMEVALUE("06:00")), TIMEVALUE(IF(ISBLANK(D21), "00:00", D21))+1, TIMEVALUE(IF(ISBLANK(D21), "00:00", D21))) - TIMEVALUE(IF(ISBLANK(C21), "00:00", C21)) - TIMEVALUE(IF(ISBLANK(E21), "00:00", E21))), "hh:mm")) -> 0:00
J22: Zrušené obj. ks | K22: Zrušené obj. $ | L22: Počet zpožděných našich rozvozů +5 min | M22: Průměrný make Time
B23: Kurýr | J23: =COUNTIF(RestiaCSV!B:B, "canceled") -> 0 | K23: =SUMIF(RestiaCSV!B:B, "canceled", RestiaCSV!C:C) -> 0 | L23: =COUNTIFS(RestiaCSV!L:L, ">5", RestiaCSV!F:F, "delivery") -> 0 | M23: =INT(AVERAGE(RestiaCSV!N2:N32)) & " min " & TEXT(MOD(AVERAGE(RestiaCSV!N2:N32) * 60, 60), "00") & " s" -> 9 min 06 s
B24: Jméno | C24: Začátek směny | D24: Konec směny | E24: pauza | F24: Počet hodin | G24: Počet rozvozů | H24: Vlastní vůz | I24: Vyplatit PHM | J24: počet výdajových dokadů | K24: Počet nezrušených celkem | L24: Počet našich rozvozů | M24: Počet pozdě přiřazeným WoltDrive 5+
A25: {=IF(ISBLANK(B25), 0, IF(ISNUMBER(MATCH(B25, HR!A:A, 0)), 0, IF(ISNUMBER(MATCH(B25, HR!B:B, 0)), INDEX(HR!V:V, MATCH(B25, HR!B:B, 0)) * (F25 * 24), 0)))} -> 0 | B25: Lažek Jaroslav | C25: 17:00 | D25: 21:00 | F25: =IF(OR(ISBLANK(B25), ISBLANK(D25), D25=0), "0:00", TEXT((IF(AND(TIMEVALUE(IF(ISBLANK(D25), "00:00", D25))>=TIMEVALUE("00:00"), TIMEVALUE(IF(ISBLANK(D25), "00:00", D25))<=TIMEVALUE("06:00")), TIMEVALUE(IF(ISBLANK(D25), "00:00", D25))+1, TIMEVALUE(IF(ISBLANK(D25), "00:00", D25))) - TIMEVALUE(IF(ISBLANK(C25), "00:00", C25)) - TIMEVALUE(IF(ISBLANK(E25), "00:00", E25))), "hh:mm")) -> 04:00 | G25: =COUNTIF(RestiaCSV!E:E, B25) -> 0 | I25: =IF(H25,G25*40, 0) -> 0
A26: {=IF(ISBLANK(B26), 0, IF(ISNUMBER(MATCH(B26, HR!A:A, 0)), 0, IF(ISNUMBER(MATCH(B26, HR!B:B, 0)), INDEX(HR!V:V, MATCH(B26, HR!B:B, 0)) * (F26 * 24), 0)))} -> 0 | B26: Reischl Jan | C26: 11:00 | D26: 23:00 | F26: =IF(OR(ISBLANK(B26), ISBLANK(D26), D26=0), "0:00", TEXT((IF(AND(TIMEVALUE(IF(ISBLANK(D26), "00:00", D26))>=TIMEVALUE("00:00"), TIMEVALUE(IF(ISBLANK(D26), "00:00", D26))<=TIMEVALUE("06:00")), TIMEVALUE(IF(ISBLANK(D26), "00:00", D26))+1, TIMEVALUE(IF(ISBLANK(D26), "00:00", D26))) - TIMEVALUE(IF(ISBLANK(C26), "00:00", C26)) - TIMEVALUE(IF(ISBLANK(E26), "00:00", E26))), "hh:mm")) -> 12:00 | G26: =COUNTIF(RestiaCSV!E:E, B26) -> 0 | I26: =IF(H26,G26*40, 0) -> 0 | J26: =COUNTIF(I25:I31, ">0") -> 0 | K26: =IFERROR(__xludf.DUMMYFUNCTION("COUNTA(FILTER(RestiaCSV!B2:B32, RestiaCSV!B2:B32 <> ""canceled""))"),58.0) -> 58 | L26: =COUNTIF(RestiaCSV!F1:F32, "delivery") -> 8 | M26: =COUNTIF(RestiaCSV!M:M, ">5") -> 1
A27: {=IF(ISBLANK(B27), 0, IF(ISNUMBER(MATCH(B27, HR!A:A, 0)), 0, IF(ISNUMBER(MATCH(B27, HR!B:B, 0)), INDEX(HR!V:V, MATCH(B27, HR!B:B, 0)) * (F27 * 24), 0)))} -> 0 | F27: =IF(OR(ISBLANK(B27), ISBLANK(D27), D27=0), "0:00", TEXT((IF(AND(TIMEVALUE(IF(ISBLANK(D27), "00:00", D27))>=TIMEVALUE("00:00"), TIMEVALUE(IF(ISBLANK(D27), "00:00", D27))<=TIMEVALUE("06:00")), TIMEVALUE(IF(ISBLANK(D27), "00:00", D27))+1, TIMEVALUE(IF(ISBLANK(D27), "00:00", D27))) - TIMEVALUE(IF(ISBLANK(C27), "00:00", C27)) - TIMEVALUE(IF(ISBLANK(E27), "00:00", E27))), "hh:mm")) -> 0:00 | G27: =COUNTIF(RestiaCSV!E:E, B27) -> 0 | I27: =IF(H27,G27*40, 0) -> 0 | J27: Woltrdive zpožděný kvůli našemu pozdnímu přiřazení | L27: % zpožděných našich rozvozů +5 min | M27: Počet zpožděných Woltdrivem
A28: {=IF(ISBLANK(B28), 0, IF(ISNUMBER(MATCH(B28, HR!A:A, 0)), 0, IF(ISNUMBER(MATCH(B28, HR!B:B, 0)), INDEX(HR!V:V, MATCH(B28, HR!B:B, 0)) * (F28 * 24), 0)))} -> 0 | F28: =IF(OR(ISBLANK(B28), ISBLANK(D28), D28=0), "0:00", TEXT((IF(AND(TIMEVALUE(IF(ISBLANK(D28), "00:00", D28))>=TIMEVALUE("00:00"), TIMEVALUE(IF(ISBLANK(D28), "00:00", D28))<=TIMEVALUE("06:00")), TIMEVALUE(IF(ISBLANK(D28), "00:00", D28))+1, TIMEVALUE(IF(ISBLANK(D28), "00:00", D28))) - TIMEVALUE(IF(ISBLANK(C28), "00:00", C28)) - TIMEVALUE(IF(ISBLANK(E28), "00:00", E28))), "hh:mm")) -> 0:00 | G28: =COUNTIF(RestiaCSV!E:E, B28) -> 0 | I28: =IF(H28,G28*40, 0) -> 0
A29: {=IF(ISBLANK(B29), 0, IF(ISNUMBER(MATCH(B29, HR!A:A, 0)), 0, IF(ISNUMBER(MATCH(B29, HR!B:B, 0)), INDEX(HR!V:V, MATCH(B29, HR!B:B, 0)) * (F29 * 24), 0)))} -> 0 | F29: =IF(OR(ISBLANK(B29), ISBLANK(D29), D29=0), "0:00", TEXT((IF(AND(TIMEVALUE(IF(ISBLANK(D29), "00:00", D29))>=TIMEVALUE("00:00"), TIMEVALUE(IF(ISBLANK(D29), "00:00", D29))<=TIMEVALUE("06:00")), TIMEVALUE(IF(ISBLANK(D29), "00:00", D29))+1, TIMEVALUE(IF(ISBLANK(D29), "00:00", D29))) - TIMEVALUE(IF(ISBLANK(C29), "00:00", C29)) - TIMEVALUE(IF(ISBLANK(E29), "00:00", E29))), "hh:mm")) -> 0:00 | G29: =COUNTIF(RestiaCSV!E:E, B29) -> 0 | I29: =IF(H29,G29*40, 0) -> 0 | J29: =COUNTIFS(RestiaCSV!M:M, ">5", RestiaCSV!L:L, ">5") -> 0 | L29: =L23/L26 -> 0 | M29: =COUNTIFS(RestiaCSV!L:L, ">5", RestiaCSV!F:F, "delivery", RestiaCSV!E:E, "Wolt Kurýr") -> 0
A30: {=IF(ISBLANK(B30), 0, IF(ISNUMBER(MATCH(B30, HR!A:A, 0)), 0, IF(ISNUMBER(MATCH(B30, HR!B:B, 0)), INDEX(HR!V:V, MATCH(B30, HR!B:B, 0)) * (F30 * 24), 0)))} -> 0 | F30: =IF(OR(ISBLANK(B30), ISBLANK(D30), D30=0), "0:00", TEXT((IF(AND(TIMEVALUE(IF(ISBLANK(D30), "00:00", D30))>=TIMEVALUE("00:00"), TIMEVALUE(IF(ISBLANK(D30), "00:00", D30))<=TIMEVALUE("06:00")), TIMEVALUE(IF(ISBLANK(D30), "00:00", D30))+1, TIMEVALUE(IF(ISBLANK(D30), "00:00", D30))) - TIMEVALUE(IF(ISBLANK(C30), "00:00", C30)) - TIMEVALUE(IF(ISBLANK(E30), "00:00", E30))), "hh:mm")) -> 0:00 | G30: =COUNTIF(RestiaCSV!E:E, B30) -> 0 | I30: =IF(H30,G30*40, 0) -> 0 | L30: % doručených včas | M30: % zpožděných Woltdrivem
A31: {=IF(ISBLANK(B31), 0, IF(ISNUMBER(MATCH(B31, HR!A:A, 0)), 0, IF(ISNUMBER(MATCH(B31, HR!B:B, 0)), INDEX(HR!V:V, MATCH(B31, HR!B:B, 0)) * (F31 * 24), 0)))} -> 0 | F31: =IF(OR(ISBLANK(B31), ISBLANK(D31), D31=0), "0:00", TEXT((IF(AND(TIMEVALUE(IF(ISBLANK(D31), "00:00", D31))>=TIMEVALUE("00:00"), TIMEVALUE(IF(ISBLANK(D31), "00:00", D31))<=TIMEVALUE("06:00")), TIMEVALUE(IF(ISBLANK(D31), "00:00", D31))+1, TIMEVALUE(IF(ISBLANK(D31), "00:00", D31))) - TIMEVALUE(IF(ISBLANK(C31), "00:00", C31)) - TIMEVALUE(IF(ISBLANK(E31), "00:00", E31))), "hh:mm")) -> 0:00 | G31: =COUNTIF(RestiaCSV!E:E, B31) -> 0 | I31: =IF(H31,G31*40, 0) -> 0
B32: Wolt Kurýr | C32: Wolt drive | G32: =COUNTIFS(RestiaCSV!E:E, "wolt kurýr", RestiaCSV!A:A, "<>wolt") -> 0 | H32: TRUE | I32: =G32*127 -> 0 | L32: =100%-L29 -> 1 | M32: =M29/L26 -> 0

Sheet Kontrola
B1: =Report!B1 -> Malesice | C1: 45973 | D1: Vyber datum <----------> | E1: 45973 | F1: COL | I1: Tržba | L1: Online Platby
L2: Wolt
B3: =CHOOSE(WEEKDAY(C1), "Neděle", "Pondělí", "Úterý", "Středa", "Čtvrtek", "Pátek", "Sobota") -> Středa | D3: =CHOOSE(WEEKDAY(E1), "Neděle", "Pondělí", "Úterý", "Středa", "Čtvrtek", "Pátek", "Sobota") -> Středa | L3: Bolt
L4: Dáme jídlo
B5: Celkem hodin Instor | F5: Celkem hodin Kurýr | L5: Web
L6: Wolt drive cash
B7: =TEXT(SUMPRODUCT((IFERROR(LEFT(D10:D30, FIND(":", D10:D30) - 1) * 60, 0) + IFERROR(MID(D10:D30, FIND(":", D10:D30) + 1, LEN(D10:D30) - FIND(":", D10:D30)), 0))), "[h]:mm")/60 -> 0 | F7: =TEXT(SUMPRODUCT((IFERROR(LEFT(H10:H30, FIND(":", H10:H30) - 1) * 60, 0) + IFERROR(MID(H10:H30, FIND(":", H10:H30) + 1, LEN(H10:H30) - FIND(":", H10:H30)), 0))), "[h]:mm")/60 -> 0 | L7: DJ Cash
B8: Instor | F8: Kurýr | J8: Pokladna | L8: Hotovost
B9: Jméno | C9: Počet dní | D9: Počet hodin | F9: Jméno | G9: Počet dní | H9: Počet hodin | I9: Počet rozvozů | L9: Terminál
E10: 29:00 | L10: Stravenky
E11: 23:00 | L11: Hotovost
E12: 13:00 | L12: Výdaje
E13: 13:00 | L13: Benzín
E14: 7:00 | L14: Auta
E15: 7:00 | L15: Suroviny
L16: Ostatní
L17: PHM - soukromé
J19: Zrušené obj. ks | K19: Zrušené obj. $ | L19: Počet zpožděných našich rozvozů +5 min | M19: Průměrný make Time
J22: počet výdajových dokadů | K22: Počet nezrušených celkem | L22: Počet našich rozvozů | M22: Počet pozdě přiřazeným WoltDrive 5+
J25: Woltrdive zpožděný kvůli našemu pozdnímu přiřazení | L25: % zpožděných našich rozvozů +5 min | M25: Počet zpožděných Woltdrivem
L28: % doručených včas | M28: % zpožděných Woltdrivem

Sheet RestiaCSV
A1: Platforma | B1: Stav | C1: Cena | D1: Sleva | E1: Kurýr | F1: Doručení | G1: Platba | H1: Vytvořeno | I1: Připraveno v | J1: Dokončeno v | K1: Přenos do dispecinku | L1: Zpoždění | M1: Přiřazení WoltDrivu | N1: Make Time | O1: Název profilu
A2: damejidlo | B2: delivered | C2: 264 | D2: 0 | F2: external-delivery | G2: online | H2: 2025-12-11T00:32:12.340+01:00 | I2: 2025-12-11T00:38:48.115+01:00 | J2: 2025-12-11T00:38:48.115+01:00 | L2: -8 | N2: 6.59625 | O2: Pizza Comeback Prosek
A3: generic | B3: delivered | C3: 199 | D3: 50 | F3: pickup | G3: cash | H3: 2025-12-11T00:26:03.460+01:00 | I3: 2025-12-11T00:32:59.834+01:00 | J3: 2025-12-11T00:32:59.834+01:00 | L3: -12 | N3: 6.9395667 | O3: Adaptee bridge
A4: bolt | B4: delivered | C4: 264 | D4: 0 | E4: Kirill | F4: external-delivery | G4: online | H4: 2025-12-11T00:08:02.667+01:00 | I4: 2025-12-11T00:17:25.884+01:00 | J4: 2025-12-11T00:17:25.884+01:00 | L4: -5 | N4: 9.38695 | O4: Pizza Comeback Prosek
A5: generic | B5: delivered | C5: 199 | D5: 50 | F5: pickup | G5: cash | H5: 2025-12-10T23:58:06.246+01:00 | I5: 2025-12-11T00:04:32.685+01:00 | J5: 2025-12-11T00:04:32.685+01:00 | L5: -12 | N5: 6.44065 | O5: Adaptee bridge
A6: wolt | B6: delivered | C6: 1316 | D6: 0 | E6: Wolt Kurýr | F6: external-delivery | G6: online | H6: 2025-12-10T23:55:16.379+01:00 | I6: 2025-12-11T00:12:17.930+01:00 | J6: 2025-12-11T00:12:17.930+01:00 | L6: -2 | N6: 17.02585 | O6: Pizza Comeback Prosek
A7: wolt | B7: delivered | C7: 658 | D7: 0 | E7: Wolt Kurýr | F7: external-delivery | G7: online | H7: 2025-12-10T23:53:16.080+01:00 | I7: 2025-12-11T00:07:17.931+01:00 | J7: 2025-12-11T00:07:17.931+01:00 | L7: -5 | N7: 14.03085 | O7: Pizza Comeback Prosek
A8: wolt | B8: delivered | C8: 224 | D8: 0 | E8: Wolt Kurýr | F8: external-delivery | G8: online | H8: 2025-12-10T23:50:15.930+01:00 | I8: 2025-12-10T23:56:49.890+01:00 | J8: 2025-12-10T23:56:49.890+01:00 | L8: -8 | N8: 6.566 | O8: Pizza Comeback Prosek
A9: wolt | B9: delivered | C9: 1081 | D9: 0 | E9: Wolt Kurýr | F9: external-delivery | G9: online | H9: 2025-12-10T23:47:15.346+01:00 | I9: 2025-12-11T00:02:02.913+01:00 | J9: 2025-12-11T00:02:02.913+01:00 | L9: -5 | N9: 14.792783 | O9: Pizza Comeback Prosek
A10: wolt | B10: delivered | C10: 553 | D10: 0 | E10: Wolt Kurýr | F10: external-delivery | G10: online | H10: 2025-12-10T23:45:11.671+01:00 | I10: 2025-12-10T23:58:20.775+01:00 | J10: 2025-12-10T23:58:20.775+01:00 | L10: -6 | N10: 13.151733 | O10: Pizza Comeback Prosek
A11: wolt | B11: delivered | C11: 832 | D11: 0 | E11: Wolt Kurýr | F11: external-delivery | G11: online | H11: 2025-12-10T23:40:39.504+01:00 | I11: 2025-12-10T23:49:48.773+01:00 | J11: 2025-12-10T23:49:48.773+01:00 | L11: -10 | N11: 9.1544833 | O11: Pizza Comeback Prosek
A12: generic | B12: delivered | C12: 409 | D12: 0 | E12: Novák Dalibor | F12: delivery | G12: online | H12: 2025-12-10T23:39:03.718+01:00 | I12: 2025-12-10T23:45:56.662+01:00 | J12: 2025-12-11T00:01:40.024+01:00 | K12: 2025-12-10T23:39:04.266+01:00 | L12: -26 | M12: 0.0091333333 | N12: 6.8824 | O12: Adaptee bridge
A13: wolt | B13: delivered | C13: 464 | D13: 0 | E13: Wolt Kurýr | F13: external-delivery | G13: online | H13: 2025-12-10T23:30:03.152+01:00 | I13: 2025-12-10T23:39:10.847+01:00 | J13: 2025-12-10T23:39:10.847+01:00 | L13: -5 | N13: 9.12825 | O13: Pizza Comeback Prosek
A14: wolt | B14: delivered | C14: 458 | D14: 0 | E14: Wolt Kurýr | F14: external-delivery | G14: online | H14: 2025-12-10T23:16:58.844+01:00 | I14: 2025-12-10T23:21:20.864+01:00 | J14: 2025-12-10T23:21:20.864+01:00 | L14: -10 | N14: 4.367 | O14: Pizza Comeback Prosek
A15: wolt | B15: delivered | C15: 279 | D15: 0 | E15: Wolt Kurýr | F15: external-delivery | G15: online | H15: 2025-12-10T23:03:52.305+01:00 | I15: 2025-12-10T23:12:06.596+01:00 | J15: 2025-12-10T23:12:06.596+01:00 | L15: -6 | N15: 8.2381833 | O15: Pizza Comeback Prosek
A16: wolt | B16: delivered | C16: 1529 | D16: 0 | E16: Wolt Kurýr | F16: external-delivery | G16: online | H16: 2025-12-10T23:01:22.529+01:00 | I16: 2025-12-10T23:12:09.608+01:00 | J16: 2025-12-10T23:12:09.608+01:00 | L16: -9 | N16: 10.78465 | O16: Pizza Comeback Prosek
A17: damejidlo | B17: delivered | C17: 433 | D17: 0 | F17: external-delivery | G17: online | H17: 2025-12-10T22:58:22.753+01:00 | I17: 2025-12-10T23:09:14.683+01:00 | J17: 2025-12-10T23:09:14.683+01:00 | L17: -4 | N17: 10.8655 | O17: Pizza Comeback Prosek
A18: bolt | B18: delivered | C18: 529 | D18: 0 | E18: Abdurakhmon | F18: external-delivery | G18: online | H18: 2025-12-10T22:56:04.730+01:00 | I18: 2025-12-10T23:03:32.580+01:00 | J18: 2025-12-10T23:03:32.580+01:00 | L18: -12 | N18: 7.4641667 | O18: Pizza Comeback Prosek
A19: manual | B19: delivered | C19: 409 | D19: 0 | F19: pickup | G19: cash | H19: 2025-12-10T22:52:09.024+01:00 | I19: 2025-12-10T22:54:49.426+01:00 | J19: 2025-12-10T22:54:49.426+01:00 | L19: -2 | N19: 2.6733667 | O19: Ručně zadané obj.
A20: damejidlo | B20: delivered | C20: 419 | D20: 0 | F20: external-delivery | G20: online | H20: 2025-12-10T22:31:02.111+01:00 | I20: 2025-12-10T22:36:43.661+01:00 | J20: 2025-12-10T22:36:43.661+01:00 | L20: -9 | N20: 5.6925 | O20: Pizza Comeback Prosek
A21: bolt | B21: delivered | C21: 329 | D21: 0 | E21: Artemii | F21: external-delivery | G21: online | H21: 2025-12-10T21:37:52.436+01:00 | I21: 2025-12-10T21:45:47.385+01:00 | J21: 2025-12-10T21:45:47.385+01:00 | L21: -7 | N21: 7.9158167 | O21: Pizza Comeback Prosek
A22: bolt | B22: delivered | C22: 558 | D22: 0 | E22: Artemii | F22: external-delivery | G22: online | H22: 2025-12-10T21:37:36.348+01:00 | I22: 2025-12-10T21:42:43.328+01:00 | J22: 2025-12-10T21:42:43.328+01:00 | L22: -14 | N22: 5.1163333 | O22: Pizza Comeback Prosek
A23: generic | B23: delivered | C23: 1001 | D23: 0 | E23: Novák Dalibor | F23: delivery | G23: online | H23: 2025-12-10T21:24:04.845+01:00 | I23: 2025-12-10T21:30:15.089+01:00 | J23: 2025-12-10T21:55:00.617+01:00 | K23: 2025-12-10T21:24:05.412+01:00 | L23: -23 | M23: 0.00945 | N23: 6.1707333 | O23: Adaptee bridge
A24: wolt | B24: delivered | C24: 384 | D24: 0 | E24: Wolt Kurýr | F24: external-delivery | G24: online | H24: 2025-12-10T21:06:13.337+01:00 | I24: 2025-12-10T21:11:43.262+01:00 | J24: 2025-12-10T21:11:43.262+01:00 | L24: -9 | N24: 5.49875 | O24: Pizza Comeback Prosek
A25: generic | B25: delivered | C25: 443 | D25: 0 | E25: Novák Dalibor | F25: delivery | G25: online | H25: 2025-12-10T20:52:03.671+01:00 | I25: 2025-12-10T21:00:27.990+01:00 | J25: 2025-12-10T21:21:04.986+01:00 | K25: 2025-12-10T20:52:03.931+01:00 | L25: -18 | M25: 0.0043333333 | N25: 8.4053167 | O25: Adaptee bridge
A26: damejidlo | B26: delivered | C26: 553 | D26: 0 | F26: external-delivery | G26: online | H26: 2025-12-10T20:48:56.718+01:00 | I26: 2025-12-10T21:00:27.304+01:00 | J26: 2025-12-10T21:00:27.304+01:00 | L26: -8 | N26: 11.509767 | O26: Pizza Comeback Prosek
A27: bolt | B27: delivered | C27: 264 | D27: 0 | E27: Muhammadamin | F27: external-delivery | G27: online | H27: 2025-12-10T20:30:44.586+01:00 | I27: 2025-12-10T20:37:17.712+01:00 | J27: 2025-12-10T20:37:17.712+01:00 | L27: -8 | N27: 6.5521 | O27: Pizza Comeback Prosek
A28: wolt | B28: delivered | C28: 264 | D28: 0 | E28: Wolt Kurýr | F28: external-delivery | G28: online | H28: 2025-12-10T20:18:10.377+01:00 | I28: 2025-12-10T20:34:09.042+01:00 | J28: 2025-12-10T20:34:09.042+01:00 | L28: 0 | N28: 15.97775 | O28: Pizza Comeback Prosek
A29: generic | B29: delivered | C29: 804 | D29: 0 | E29: Novák Dalibor | F29: delivery | G29: online | H29: 2025-12-10T20:17:03.109+01:00 | I29: 2025-12-10T20:30:04.874+01:00 | J29: 2025-12-10T20:42:26.546+01:00 | K29: 2025-12-10T20:17:03.349+01:00 | L29: -7 | M29: 0.004 | N29: 13.029417 | O29: Adaptee bridge
A30: damejidlo | B30: delivered | C30: 758 | D30: 0 | F30: external-delivery | G30: online | H30: 2025-12-10T20:01:26.910+01:00 | I30: 2025-12-10T20:13:53.064+01:00 | J30: 2025-12-10T20:13:53.064+01:00 | L30: -7 | N30: 12.4359 | O30: Pizza Comeback Prosek
A31: wolt | B31: delivered | C31: 378 | D31: 0 | E31: Wolt Kurýr | F31: external-delivery | G31: online | H31: 2025-12-10T19:48:59.003+01:00 | I31: 2025-12-10T19:57:53.962+01:00 | J31: 2025-12-10T19:57:53.962+01:00 | L31: -6 | N31: 8.9159833 | O31: Pizza Comeback Prosek
A32: damejidlo | B32: delivered | C32: 331 | D32: 0 | F32: external-delivery | G32: online | H32: 2025-12-10T19:47:28.849+01:00 | I32: 2025-12-10T19:55:00.054+01:00 | J32: 2025-12-10T19:55:00.054+01:00 | L32: -7 | N32: 7.5200833 | O32: Pizza Comeback Prosek
A33: damejidlo | B33: delivered | C33: 264 | D33: 0 | F33: external-delivery | G33: online | H33: 2025-12-10T19:37:31.444+01:00 | I33: 2025-12-10T19:41:11.974+01:00 | J33: 2025-12-10T19:41:11.974+01:00 | L33: -11 | N33: 3.6755 | O33: Pizza Comeback Prosek
A34: damejidlo | B34: delivered | C34: 867 | D34: 0 | F34: external-delivery | G34: online | H34: 2025-12-10T19:04:42.289+01:00 | I34: 2025-12-10T19:12:54.540+01:00 | J34: 2025-12-10T19:12:54.540+01:00 | L34: -11 | N34: 8.2041833 | O34: Pizza Comeback Prosek
A35: wolt | B35: delivered | C35: 264 | D35: 0 | E35: Wolt Kurýr | F35: external-delivery | G35: online | H35: 2025-12-10T19:00:46.415+01:00 | I35: 2025-12-10T19:05:11.140+01:00 | J35: 2025-12-10T19:05:11.140+01:00 | L35: -10 | N35: 4.4120833 | O35: Pizza Comeback Prosek
A36: wolt | B36: delivered | C36: 415 | D36: 0 | E36: Wolt Kurýr | F36: external-delivery | G36: online | H36: 2025-12-10T18:50:37.925+01:00 | I36: 2025-12-10T18:58:43.264+01:00 | J36: 2025-12-10T18:58:43.264+01:00 | L36: -6 | N36: 8.0889833 | O36: Pizza Comeback Prosek
A37: wolt | B37: delivered | C37: 723 | D37: 0 | E37: Wolt Kurýr | F37: external-delivery | G37: online | H37: 2025-12-10T18:03:52.405+01:00 | I37: 2025-12-10T18:15:17.332+01:00 | J37: 2025-12-10T18:15:17.332+01:00 | L37: -8 | N37: 11.41545 | O37: Pizza Comeback Prosek
A38: damejidlo | B38: delivered | C38: 471 | D38: 0 | F38: external-delivery | G38: online | H38: 2025-12-10T18:03:41.294+01:00 | I38: 2025-12-10T18:12:04.981+01:00 | J38: 2025-12-10T18:12:04.981+01:00 | L38: -6 | N38: 8.3947833 | O38: Pizza Comeback Prosek
A39: generic | B39: delivered | C39: 664 | D39: 0 | E39: Novák Dalibor | F39: delivery | G39: online | H39: 2025-12-10T17:57:05.879+01:00 | I39: 2025-12-10T18:05:14.711+01:00 | J39: 2025-12-10T18:21:33.822+01:00 | K39: 2025-12-10T17:57:06.287+01:00 | L39: -29 | M39: 0.0068 | N39: 8.1472 | O39: Adaptee bridge
A40: damejidlo | B40: delivered | C40: 811 | D40: 0 | F40: external-delivery | G40: online | H40: 2025-12-10T17:55:23.777+01:00 | I40: 2025-12-10T18:06:52.835+01:00 | J40: 2025-12-10T18:06:52.835+01:00 | L40: -8 | N40: 11.4843 | O40: Pizza Comeback Prosek
...

Sheet August 2024
A1: Datum | B1: Název | C1: Jména Instor | D1: Začátek směny Instor | E1: Konec směny Instor | F1: Pauza Instor | G1: Počet hodin Instor | H1: Jména Kurýr | I1: Začátek směny Kurýr | J1: Konec směny Kurýr | K1: Pauza Kurýr | L1: Počet hodin Kurýr | M1: Počet rozvozů Kurýr | N1: Vlastní vůz | O1: Vyplatit PHM | P1: Wolt drive | Q1: Otevíral | R1: Zavíral | S1: Online Platby - Wolt | T1: Online Platby - Bolt | U1: Online Platby - Dáme Jídlo | V1: Vlastní API | W1: Online Platby - Wolt cash | X1: Online Platby - DJ Cash | Y1: Terminál | Z1: Stravenky | AA1: Hotovost | AB1: Tržba | AC1: Pokladna - VÝSLEDEK | AD1: COL | AE1: Benzín | AF1: Auta | AG1: Suroviny | AH1: Ostatní | AI1: PHM - soukromé | AJ1: Zrušené obj. ks | AK1: Zrušené obj. $ | AL1: Počet zpožděných objednávek z webu +5 min | AM1: Průměrný make Time | AN1: Počet vydajových dokladů | AO1: Počet nezrušených celkem | AP1: Počet našich rozvozů | AQ1: Počet pozdě přiřazeným WoltDrive 5+ | AR1: Woltrdrive zpožděný kvůli našemu pozdnímu přiřazení | AS1: % zpožděných našich rozvozů +5 min | AT1: Počet zpožděných Woltdrivem | AU1: % doručených včas | AV1: % zpožděných Woltdrivem
A2: 45524 | B2: Úterý | C2: Martin Sova | D2: 10:00 | E2: 13:00 | G2: 03:00
A3: 45524 | B3: Úterý | C3: Ahurieva Viktoriia | D3: 13:00 | E3: 01:00 | G3: 12:00
A4: 45524 | B4: Úterý | H4: Ondřej Navrátil | I4: 11:00 | J4: 18:00 | L4: 07:00 | M4: 9
A5: 45524 | B5: Úterý | H5: Zbyněk Hyský | I5: 18:00 | J5: 00:00 | L5: 06:00 | M5: 13 | N5: TRUE | O5: 520
A6: 45524 | B6: Úterý | H6: Pešová Hana | I6: 17:00 | J6: 01:00 | L6: 08:00
A7: 45524 | B7: Úterý | P7: 7 | Q7: Martin Sova | R7: Ahurieva Viktoriia | S7: 8461 | T7: 3807 | U7: 8309 | V7: 10131 | W7: 1300 | X7: 2815 | Y7: 3723 | AA7: 1160 | AB7: 42831 | AC7: 0 | AD7: 0.38519359 | AE7: 2000 | AH7: 3420 | AI7: 520 | AJ7: 0 | AK7: 0 | AL7: 7 | AM7: 15 min 46 s | AN7: 1 | AO7: 107 | AP7: 29 | AQ7: 5 | AR7: 5 | AS7: 0.24137931 | AT7: 5 | AU7: 0.75862069 | AV7: 0.17241379

Sheet HR
C1: =IFERROR(__xludf.DUMMYFUNCTION("IMPORTRANGE(""1TpIiNTfR1pnpn85VWQTTdvQ2Xcr0GStmWJ2UvfKxG_A"", ""Mzdy!A1:F200"")"),"#REF!") -> #REF! | V1: =IFERROR(__xludf.DUMMYFUNCTION("IMPORTRANGE(""1TpIiNTfR1pnpn85VWQTTdvQ2Xcr0GStmWJ2UvfKxG_A"", ""Mzdy!ac1:ad200"")"),"#REF!") -> #REF!
A4: Manažeři | B4: Zamestnanci pobocky
A5: =IF(AND(B5<>"", C5=TRUE, E5=Report!$B$1), B5, "") | B5: =IF(OR(E5=Report!$B$1, F5=Report!$B$1, G5=Report!$B$1, H5=Report!$B$1), D5, "")
A6: =IF(AND(B6<>"", C6=TRUE, E6=Report!$B$1), B6, "") | B6: =IF(OR(E6=Report!$B$1, F6=Report!$B$1, G6=Report!$B$1, H6=Report!$B$1), D6, "")
A7: =IF(AND(B7<>"", C7=TRUE, E7=Report!$B$1), B7, "") | B7: =IF(OR(E7=Report!$B$1, F7=Report!$B$1, G7=Report!$B$1, H7=Report!$B$1), D7, "")
A8: =IF(AND(B8<>"", C8=TRUE, E8=Report!$B$1), B8, "") | B8: =IF(OR(E8=Report!$B$1, F8=Report!$B$1, G8=Report!$B$1, H8=Report!$B$1), D8, "")
A9: =IF(AND(B9<>"", C9=TRUE, E9=Report!$B$1), B9, "") | B9: =IF(OR(E9=Report!$B$1, F9=Report!$B$1, G9=Report!$B$1, H9=Report!$B$1), D9, "")
A10: =IF(AND(B10<>"", C10=TRUE, E10=Report!$B$1), B10, "") | B10: =IF(OR(E10=Report!$B$1, F10=Report!$B$1, G10=Report!$B$1, H10=Report!$B$1), D10, "")
A11: =IF(AND(B11<>"", C11=TRUE, E11=Report!$B$1), B11, "") | B11: =IF(OR(E11=Report!$B$1, F11=Report!$B$1, G11=Report!$B$1, H11=Report!$B$1), D11, "")
A12: =IF(AND(B12<>"", C12=TRUE, E12=Report!$B$1), B12, "") | B12: =IF(OR(E12=Report!$B$1, F12=Report!$B$1, G12=Report!$B$1, H12=Report!$B$1), D12, "")
A13: =IF(AND(B13<>"", C13=TRUE, E13=Report!$B$1), B13, "") | B13: =IF(OR(E13=Report!$B$1, F13=Report!$B$1, G13=Report!$B$1, H13=Report!$B$1), D13, "")
A14: =IF(AND(B14<>"", C14=TRUE, E14=Report!$B$1), B14, "") | B14: =IF(OR(E14=Report!$B$1, F14=Report!$B$1, G14=Report!$B$1, H14=Report!$B$1), D14, "")
A15: =IF(AND(B15<>"", C15=TRUE, E15=Report!$B$1), B15, "") | B15: =IF(OR(E15=Report!$B$1, F15=Report!$B$1, G15=Report!$B$1, H15=Report!$B$1), D15, "")
A16: =IF(AND(B16<>"", C16=TRUE, E16=Report!$B$1), B16, "") | B16: =IF(OR(E16=Report!$B$1, F16=Report!$B$1, G16=Report!$B$1, H16=Report!$B$1), D16, "")
... A43: =IF(AND(B43<>"", C43=TRUE, E43=Report!$B$1), B43, "") | B43: =IF(OR(E43=Report!$B$1, F43=Report!$B$1, G43=Report!$B$1, H43=Report!$B$1), D43, "")
B44: =IF(OR(E44=Report!$B$1, F44=Report!$B$1, G44=Report!$B$1, H44=Report!$B$1), D44, "")
B45: =IF(OR(E45=Report!$B$1, F45=Report!$B$1, G45=Report!$B$1, H45=Report!$B$1), D45, "")
B46: =IF(OR(E46=Report!$B$1, F46=Report!$B$1, G46=Report!$B$1, H46=Report!$B$1), D46, "")
B47: =IF(OR(E47=Report!$B$1, F47=Report!$B$1, G47=Report!$B$1, H47=Report!$B$1), D47, "")
B48: =IF(OR(E48=Report!$B$1, F48=Report!$B$1, G48=Report!$B$1, H48=Report!$B$1), D48, "")
B49: =IF(OR(E49=Report!$B$1, F49=Report!$B$1, G49=Report!$B$1, H49=Report!$B$1), D49, "")
B50: =IF(OR(E50=Report!$B$1, F50=Report!$B$1, G50=Report!$B$1, H50=Report!$B$1), D50, "")
B51: =IF(OR(E51=Report!$B$1, F51=Report!$B$1, G51=Report!$B$1, H51=Report!$B$1), D51, "")
B52: =IF(OR(E52=Report!$B$1, F52=Report!$B$1, G52=Report!$B$1, H52=Report!$B$1), D52, "")
B53: =IF(OR(E53=Report!$B$1, F53=Report!$B$1, G53=Report!$B$1, H53=Report!$B$1), D53, "")
B54: =IF(OR(E54=Report!$B$1, F54=Report!$B$1, G54=Report!$B$1, H54=Report!$B$1), D54, "")
B55: =IF(OR(E55=Report!$B$1, F55=Report!$B$1, G55=Report!$B$1, H55=Report!$B$1), D55, "")
... B179: =IF(OR(E179=Report!$B$1, F179=Report!$B$1, G179=Report!$B$1, H179=Report!$B$1), D179, "")
