Workbook

Sheet Kontrola
B1: Zličín | C1: 45536 | D1: Vyber datum <----------> | E1: 45550 | F1: COL | I1: Tržba | L1: Online Platby
L2: Wolt
B3: =CHOOSE(WEEKDAY(C1), "Neděle", "Pondělí", "Úterý", "Středa", "Čtvrtek", "Pátek", "Sobota") -> Neděle | D3: =CHOOSE(WEEKDAY(E1), "Neděle", "Pondělí", "Úterý", "Středa", "Čtvrtek", "Pátek", "Sobota") -> Neděle | L3: Bolt
L4: Dáme jídlo
B5: Celkem hodin Instor | F5: Celkem hodin Kurýr | L5: Web
L6: Wolt drive cash
B7: =TEXT(SUMPRODUCT((IFERROR(LEFT(D10:D30, FIND(":", D10:D30) - 1) * 60, 0) + IFERROR(MID(D10:D30, FIND(":", D10:D30) + 1, LEN(D10:D30) - FIND(":", D10:D30)), 0))), "[h]:mm")/60 -> 0 | F7: =TEXT(SUMPRODUCT((IFERROR(LEFT(H10:H30, FIND(":", H10:H30) - 1) * 60, 0) + IFERROR(MID(H10:H30, FIND(":", H10:H30) + 1, LEN(H10:H30) - FIND(":", H10:H30)), 0))), "[h]:mm")/60 -> 0 | L7: DJ Cash
B8: Instor | F8: Kurýr | J8: Pokladna | L8: Hotovost
F9: Jméno | G9: Počet dní | H9: Počet hodin | I9: Počet rozvozů | L9: Terminál
E10: 29:00 | L10: Stravenky
E11: 23:00 | L11: Hotovost
E12: 13:00 | L12: Výdaje
E13: 13:00 | L13: Benzín
E14: 7:00 | L14: Auta
E15: 7:00 | L15: Suroviny
L16: Ostatní
L17: PHM - soukromé
J19: Zrušené obj. ks | K19: Zrušené obj. $ | L19: Počet zpožděných našich rozvozů +5 min | M19: Průměrný make Time
J22: počet výdajových dokadů | K22: Počet nezrušených celkem | L22: Počet našich rozvozů | M22: Počet pozdě přiřazeným WoltDrive 5+
J25: Woltrdive zpožděný kvůli našemu pozdnímu přiřazení | L25: % zpožděných našich rozvozů +5 min | M25: Počet zpožděných Woltdrivem
L28: % doručených včas | M28: % zpožděných Woltdrivem

Sheet Dashboard
A1: 46099 | B1: Vyber datum <----------> | C1: 46099 | E1: 1. | F1: 2. | G1: 3. | H1: 4. | L1: 46096 | W1: cos+chem | AA1: odvod cent.
E2: FALSE | F2: FALSE | G2: FALSE | H2: FALSE | W2: 0.27 | AA2: 0.2
B4: Tržba | C4: COL | D4: Pokladna | E4: Počet objednávek | F4: % včas | G4: Hodiny instore | H4: Hodiny kurýr | I4: Make time | J4: Wolt drive | K4: naše rozvozy | L4: WOLT | M4: BOLT | N4: FOODORA online | O4: WEB online | P4: Karty | Q4: stravenky | S4: Hrubý obrat | T4: Tržba čistá | U4: Náklad mzdy | V4: Agregatory 25% | W4: COS + chemie | X4: Nájem + služby | Y4: Energie | Z4: Ostatní | AA4: odvod cent. | AB4: Zisk
A5: Malešice | B5: {=INDIRECT("'"&A5&"'!I2")} -> 36317 | C5: {=INDIRECT("'"&A5&"'!f2")} -> 0.31857577 | D5: {=INDIRECT("'"&A5&"'!J9")} -> 12 | E5: {=INDIRECT("'"&A5&"'!K24")} -> 86 | F5: {=INDIRECT("'"&A5&"'!L30")} -> 0.94736842 | G5: {=INDIRECT("'"&A5&"'!B7")} -> 15 | H5: {=INDIRECT("'"&A5&"'!f7")} -> 16 | I5: {=INDIRECT("'"&A5&"'!M21")} -> 11 min 23 s | J5: {=INDIRECT("'"&A5&"'!K30")} -> 1 | K5: {=INDIRECT("'"&A5&"'!L24")} -> 19 | L5: {=INDIRECT("'"&A5&"'!M2")} -> 12014 | M5: {=INDIRECT("'"&A5&"'!M3")} -> 6921 | N5: {=INDIRECT("'"&A5&"'!M4")} -> 6168 | O5: {=INDIRECT("'"&A5&"'!M5")} -> 8020 | P5: {=INDIRECT("'"&A5&"'!M9")} -> 1006 | Q5: {=INDIRECT("'"&A5&"'!M10")} -> 0 | R5: Malešice | S5: =Dashboard!B5 -> 36317 | T5: =S5/112*100 -> 32425.893 | U5: =Dashboard!C5*T5 -> 10330.104 | V5: =S5/100*25 -> 9079.25 | W5: =$W$2*T5 -> 8754.9911 | X5: 35000 | Y5: 35000 | AA5: =$AA$2*T5 -> 6485.1786 | AB5: =T5-U5-V5-W5-X5-Y5-Z5-AA5 -> -72223.631
B7: Tržba | C7: COL | D7: Pokladna | E7: Počet objednávek | F7: % včas | G7: Hodiny instore | H7: Hodiny kurýr | I7: Make time | J7: Wolt drive | K7: naše rozvozy | L7: =L4 -> WOLT | M7: =M4 -> BOLT | N7: =N4 -> FOODORA online | O7: =O4 -> WEB online | P7: =P4 -> Karty | Q7: stravenky | S7: =S4 -> Hrubý obrat | T7: =T4 -> Tržba čistá | U7: =U4 -> Náklad mzdy | V7: =V4 -> Agregatory 25% | W7: =W4 -> COS + chemie | X7: =X4 -> Nájem + služby | Y7: =Y4 -> Energie | Z7: =Z4 -> Ostatní | ... AB7: =AB4 -> Zisk
A8: Zličín | B8: {=INDIRECT("'"&A8&"'!I2")} -> 54069.5 | C8: {=INDIRECT("'"&A8&"'!f2")} -> 0.26639125 | D8: {=INDIRECT("'"&A8&"'!J9")} -> 0.5 | E8: {=INDIRECT("'"&A8&"'!K24")} -> 123 | F8: {=INDIRECT("'"&A8&"'!L30")} -> 0.95 | G8: {=INDIRECT("'"&A8&"'!B7")} -> 22 | H8: {=INDIRECT("'"&A8&"'!f7")} -> 14 | I8: {=INDIRECT("'"&A8&"'!M21")} -> 13 min 06 s | J8: {=INDIRECT("'"&A8&"'!K30")} -> 0 | K8: {=INDIRECT("'"&A8&"'!L24")} -> 20 | L8: {=INDIRECT("'"&A8&"'!M2")} -> 13210 | M8: {=INDIRECT("'"&A8&"'!M3")} -> 6247 | N8: {=INDIRECT("'"&A8&"'!M4")} -> 13756 | O8: {=INDIRECT("'"&A8&"'!M5")} -> 11505 | P8: {=INDIRECT("'"&A8&"'!M9")} -> 5690 | Q8: {=INDIRECT("'"&A8&"'!M10")} -> 0 | R8: Zličín | S8: =B8 -> 54069.5 | T8: =S8/112*100 -> 48276.339 | U8: =C8*T8 -> 12860.394 | V8: =S8/100*25 -> 13517.375 | W8: =$W$2*T8 -> 13034.612 | X8: 35000 | Y8: 35000 | AA8: =$AA$2*T8 -> 9655.2679 | AB8: =T8-U8-V8-W8-X8-Y8-Z8-AA8 -> -70791.31
B10: Tržba | C10: COL | D10: Pokladna | E10: Počet objednávek | F10: % včas | G10: Hodiny instore | H10: Hodiny kurýr | I10: Make time | J10: Wolt drive | K10: naše rozvozy | L10: =L7 -> WOLT | M10: =M7 -> BOLT | N10: =N7 -> FOODORA online | O10: =O7 -> WEB online | P10: =P7 -> Karty | Q10: stravenky | S10: =S7 -> Hrubý obrat | T10: =T7 -> Tržba čistá | U10: =U7 -> Náklad mzdy | V10: =V7 -> Agregatory 25% | W10: =W7 -> COS + chemie | X10: =X7 -> Nájem + služby | Y10: =Y7 -> Energie | Z10: =Z7 -> Ostatní | ... AB10: =AB7 -> Zisk
A11: Chodov | B11: {=INDIRECT("'"&A11&"'!I2")} -> 45313 | C11: {=INDIRECT("'"&A11&"'!f2")} -> 0.38378806 | D11: {=INDIRECT("'"&A11&"'!J9")} -> 0 | E11: {=INDIRECT("'"&A11&"'!K24")} -> 115 | F11: {=INDIRECT("'"&A11&"'!L30")} -> 0.88235294 | G11: {=INDIRECT("'"&A11&"'!B7")} -> 28 | H11: {=INDIRECT("'"&A11&"'!f7")} -> 19 | I11: {=INDIRECT("'"&A11&"'!M21")} -> 12 min 16 s | J11: {=INDIRECT("'"&A11&"'!K30")} -> 0 | K11: {=INDIRECT("'"&A11&"'!L24")} -> 34 | L11: {=INDIRECT("'"&A11&"'!M2")} -> 11601 | M11: {=INDIRECT("'"&A11&"'!M3")} -> 4018 | N11: {=INDIRECT("'"&A11&"'!M4")} -> 5896 | O11: {=INDIRECT("'"&A11&"'!M5")} -> 16846 | P11: {=INDIRECT("'"&A11&"'!M9")} -> 3432 | Q11: {=INDIRECT("'"&A11&"'!M10")} -> 0 | R11: Chodov | S11: =B11 -> 45313 | T11: =S11/112*100 -> 40458.036 | U11: =C11*T11 -> 15527.311 | V11: =S11/100*25 -> 11328.25 | W11: =$W$2*T11 -> 10923.67 | X11: 35000 | Y11: 35000 | AA11: =$AA$2*T11 -> 8091.6071 | AB11: =T11-U11-V11-W11-X11-Y11-Z11-AA11 -> -75412.802
B13: Tržba | C13: COL | D13: Pokladna | E13: Počet objednávek | F13: % včas | G13: Hodiny instore | H13: Hodiny kurýr | I13: Make time | J13: Wolt drive | K13: naše rozvozy | L13: =L10 -> WOLT | M13: =M10 -> BOLT | N13: =N10 -> FOODORA online | O13: =O10 -> WEB online | P13: =P10 -> Karty | Q13: stravenky | S13: =S10 -> Hrubý obrat | T13: =T10 -> Tržba čistá | U13: =U10 -> Náklad mzdy | V13: =V10 -> Agregatory 25% | W13: =W10 -> COS + chemie | X13: =X10 -> Nájem + služby | Y13: =Y10 -> Energie | Z13: =Z10 -> Ostatní | ... AB13: =AB10 -> Zisk
A14: Libuš | B14: {=INDIRECT("'"&A14&"'!I2")} -> 33988.5 | C14: {=INDIRECT("'"&A14&"'!f2")} -> 0.37827515 | D14: {=INDIRECT("'"&A14&"'!J9")} -> 0.5 | E14: {=INDIRECT("'"&A14&"'!K24")} -> 84 | F14: {=INDIRECT("'"&A14&"'!L30")} -> 0.89473684 | G14: {=INDIRECT("'"&A14&"'!B7")} -> 18.5 | H14: {=INDIRECT("'"&A14&"'!f7")} -> 12.5 | I14: {=INDIRECT("'"&A14&"'!M21")} -> 14 min 44 s | J14: {=INDIRECT("'"&A14&"'!K30")} -> 2 | K14: {=INDIRECT("'"&A14&"'!L24")} -> 19 | L14: {=INDIRECT("'"&A14&"'!M2")} -> 8098 | M14: {=INDIRECT("'"&A14&"'!M3")} -> 1450 | N14: {=INDIRECT("'"&A14&"'!M4")} -> 7563 | O14: {=INDIRECT("'"&A14&"'!M5")} -> 10188 | P14: {=INDIRECT("'"&A14&"'!M9")} -> 1225 | Q14: {=INDIRECT("'"&A14&"'!M10")} -> 0 | R14: Libuš | S14: =B14 -> 33988.5 | T14: =S14/112*100 -> 30346.875 | U14: =C14*T14 -> 11479.469 | V14: =S14/100*25 -> 8497.125 | W14: =$W$2*T14 -> 8193.6562 | X14: 35000 | Y14: 35000 | AA14: =$AA$2*T14 -> 6069.375 | AB14: =T14-U14-V14-W14-X14-Y14-Z14-AA14 -> -73892.75
B16: Tržba | C16: COL | D16: Pokladna | E16: Počet objednávek | F16: % včas | G16: Hodiny instore | H16: Hodiny kurýr | I16: Make time | J16: Wolt drive | K16: naše rozvozy | L16: =L13 -> WOLT | M16: =M13 -> BOLT | N16: =N13 -> FOODORA online | O16: =O13 -> WEB online | P16: =P13 -> Karty | Q16: stravenky | S16: =S13 -> Hrubý obrat | T16: =T13 -> Tržba čistá | U16: =U13 -> Náklad mzdy | V16: =V13 -> Agregatory 25% | W16: =W13 -> COS + chemie | X16: =X13 -> Nájem + služby | Y16: =Y13 -> Energie | Z16: =Z13 -> Ostatní | ... AB16: =AB13 -> Zisk
A17: Prosek | B17: {=INDIRECT("'"&A17&"'!I2")} -> 27516 | C17: {=INDIRECT("'"&A17&"'!f2")} -> 0.28007752 | D17: {=INDIRECT("'"&A17&"'!J9")} -> 0 | E17: {=INDIRECT("'"&A17&"'!K24")} -> 63 | F17: {=INDIRECT("'"&A17&"'!L30")} -> 1 | G17: {=INDIRECT("'"&A17&"'!B7")} -> 1 | H17: {=INDIRECT("'"&A17&"'!f7")} -> 14 | I17: {=INDIRECT("'"&A17&"'!M21")} -> 10 min 13 s | J17: {=INDIRECT("'"&A17&"'!K30")} -> 0 | K17: {=INDIRECT("'"&A17&"'!L24")} -> 8 | L17: {=INDIRECT("'"&A17&"'!M2")} -> 10177 | M17: {=INDIRECT("'"&A17&"'!M3")} -> 5854 | N17: {=INDIRECT("'"&A17&"'!M4")} -> 5685 | O17: {=INDIRECT("'"&A17&"'!M5")} -> 2977 | P17: {=INDIRECT("'"&A17&"'!M9")} -> 673 | Q17: {=INDIRECT("'"&A17&"'!M10")} -> 0 | R17: Prosek | S17: =B17 -> 27516 | T17: =S17/112*100 -> 24567.857 | U17: =C17*T17 -> 6880.9046 | V17: =S17/100*25 -> 6879 | W17: =$W$2*T17 -> 6633.3214 | X17: 40000 | Y17: 35000 | AA17: =$AA$2*T17 -> 4913.5714 | AB17: =T17-U17-V17-W17-X17-Y17-Z17-AA17 -> -75738.94
B19: Tržba | C19: COL | D19: Pokladna | E19: Počet objednávek | F19: % včas | G19: Hodiny instore | H19: Hodiny kurýr | I19: Make time | J19: Wolt drive | K19: naše rozvozy | L19: =L16 -> WOLT | M19: =M16 -> BOLT | N19: =N16 -> FOODORA online | O19: =O16 -> WEB online | P19: =P16 -> Karty | Q19: stravenky | S19: =S16 -> Hrubý obrat | T19: =T16 -> Tržba čistá | U19: =U16 -> Náklad mzdy | V19: =V16 -> Agregatory 25% | W19: =W16 -> COS + chemie | X19: =X16 -> Nájem + služby | Y19: =Y16 -> Energie | Z19: =Z16 -> Ostatní | ... AB19: =AB16 -> Zisk
A20: Bolevec | B20: {=INDIRECT("'"&A20&"'!I2")} -> 12859 | C20: {=INDIRECT("'"&A20&"'!f2")} -> 0.80835167 | D20: {=INDIRECT("'"&A20&"'!J9")} -> 0 | E20: {=INDIRECT("'"&A20&"'!K24")} -> 39 | F20: {=INDIRECT("'"&A20&"'!L30")} -> 0.83333333 | G20: {=INDIRECT("'"&A20&"'!B7")} -> 23.5 | H20: {=INDIRECT("'"&A20&"'!f7")} -> 13 | I20: {=INDIRECT("'"&A20&"'!M21")} -> 14 min 03 s | J20: {=INDIRECT("'"&A20&"'!K30")} -> 0 | K20: {=INDIRECT("'"&A20&"'!L24")} -> 6 | L20: {=INDIRECT("'"&A20&"'!M2")} -> 0 | M20: {=INDIRECT("'"&A20&"'!M3")} -> 1055 | N20: {=INDIRECT("'"&A20&"'!M4")} -> 4305 | O20: {=INDIRECT("'"&A20&"'!M5")} -> 2288 | P20: {=INDIRECT("'"&A20&"'!M9")} -> 2252 | Q20: {=INDIRECT("'"&A20&"'!M10")} -> 0 | R20: =A20 -> Bolevec | S20: =B20 -> 12859 | T20: =S20/112*100 -> 11481.25 | U20: =C20*T20 -> 9280.8876 | V20: =S20/100*25 -> 3214.75 | W20: =$W$2*T20 -> 3099.9375 | X20: 40000 | Y20: 35000 | AA20: =$AA$2*T20 -> 2296.25 | AB20: =T20-U20-V20-W20-X20-Y20-Z20-AA20 -> -81410.575
B22: Tržba | C22: COL | D22: Pokladna | E22: Počet objednávek | F22: % včas | G22: Hodiny instore | H22: Hodiny kurýr | I22: Make time | J22: Wolt drive | K22: naše rozvozy | L22: =L19 -> WOLT | M22: =M19 -> BOLT | N22: =N19 -> FOODORA online | O22: =O19 -> WEB online | P22: =P19 -> Karty | Q22: stravenky | S22: =S19 -> Hrubý obrat | T22: =T19 -> Tržba čistá | U22: =U19 -> Náklad mzdy | V22: =V19 -> Agregatory 25% | W22: =W19 -> COS + chemie | X22: =X19 -> Nájem + služby | Y22: =Y19 -> Energie | Z22: =Z19 -> Ostatní | ... AB22: =AB19 -> Zisk
A23: Součet | B23: =sum(B5+B8+B11+B14+B17+B20) -> 210063 | C23: =(B5/112*100*C5+B8/112*100*C8+B11/112*100*C11+B14/112*100*C14+B17/112*100*C17+B5/112*100*C5)/((B5+B8+B11+B14+B17+B20)/112*100)*100 -> 35.940304 | D23: =sum(D5+D8+D11+D14+D17+D20) -> 13 | E23: =sum(E5+E8+E11+E14+E17+E20) -> 510 | F23: =AVERAGE(F5:F21) -> 0.91796526 | G23: =sum(G5+G8+G11+G14+G17+G20) -> 108 | H23: =sum(H5+H8+H11+H14+H17+H20) -> 88.5 | I23: {=AVERAGE(LEFT({I5; I8; I11; I14; I17; I20}, FIND(" min", {I5; I8; I11; I14; I17; I20})-1)*60 + MID({I5; I8; I11; I14; I17; I20}, FIND(" min", {I5; I8; I11; I14; I17; I20})+5, FIND(" s", {I5; I8; I11; I14; I17; I20})-FIND(" min", {I5; I8; I11; I14; I17; I20})-5))/60} -> 12.625 | J23: =sum(J5+J8+J11+J14+J17+J20) -> 3 | K23: =sum(K5+K8+K11+K14+K17+K20) -> 106 | L23: =sum(L5+L8+L11+L14+L17+L20) -> 55100 | M23: =sum(M5+M8+M11+M14+M17+M20) -> 25545 | N23: =sum(N5+N8+N11+N14+N17+N20) -> 43373 | O23: =sum(O5+O8+O11+O14+O17+O20) -> 51824 | P23: =sum(P5+P8+P11+P14+P17+P20) -> 14278 | Q23: =sum(Q5+Q8+Q11+Q14+Q17+Q20) -> 0 | R23: Součet | S23: =sum(S5+S8+S11+S14+S17+S20) -> 210063 | T23: =sum(T5+T8+T11+T14+T17+T20) -> 187556.25 | U23: =sum(U5+U8+U11+U14+U17+U20) -> 66359.07 | V23: =sum(V5+V8+V11+V14+V17+V20) -> 52515.75 | W23: =sum(W5+W8+W11+W14+W17+W20) -> 50640.188 | X23: =sum(X5+X8+X11+X14+X17+X20) -> 220000 | Y23: =sum(Y5+Y8+Y11+Y14+Y17+Y20) -> 210000 | Z23: =sum(Z5+Z8+Z11+Z14+Z17+Z20) -> 0 | ... AB23: =sum(AB5+AB8+AB11+AB14+AB17+AB20) -> -449470.01
L26: =SUM(L23:N24) -> 124018
L27: =(L26/B23)*100 -> 59.038479 | O27: =(P23/B23)*100 -> 6.7970085

Sheet Porovnat
B1: Malešice | F1: Součet
B2: 1. | C2: 2. | D2: 3. | E2: 4.
A3: Datum | B3: 28.02.2026 - 15.03.2026 | C3: 01.03.2025 - 16.03.2025 | D3: 01.03.2025 - 31.03.2025 | E3: 01.02.2025 - 28.02.2025
A4: Tržba | B4: 788787 | C4: 724978.7 | D4: 1441649.4 | E4: 1335686.3 | F4: Tržba | G4: =SUM(B4:E4) -> 4291101.4
A5: COL | B5: 0.28819333 | C5: 0.28596295 | D5: 0.28681752 | E5: 0.31083122 | F5: COL | G5: =AVERAGEIF(B5:E5, "<>") -> 0.29295125
A6: Pokladna | B6: 2 | C6: 2.8 | D6: -639.7 | E6: 10.5 | F6: Pokladna | G6: =SUM(B6:E6) -> -624.4
A7: Počet objednávek | B7: 1890 | C7: 1715 | D7: 3483 | E7: 3203 | F7: Počet objednávek | G7: =SUM(B7:E7) -> 10291
A8: % včas | B8: 0.92713394 | C8: 0.85013202 | D8: 0.87314512 | E8: 0.88433882 | F8: % včas | G8: =AVERAGEIF(B8:E8, "<>") -> 0.88368747
A9: Hodiny instore | B9: 382 | C9: 406.5 | D9: 744.5 | E9: 691.5 | F9: Hodiny instore | G9: =SUM(B9:E9) -> 2224.5
A10: Hodiny kurýr | B10: 292 | C10: 148.5 | D10: 365 | E10: 349 | F10: Hodiny kurýr | G10: =SUM(B10:E10) -> 1154.5
A11: Make time | B11: 11 min 50 s | C11: 12 min 15 s | D11: 12 min 16 s | E11: 11 min 20 s | F11: Make time | G11: =IFERROR(__xludf.DUMMYFUNCTION("LET( data, FILTER(B11:E11, B11:E11 <> """"), totalSeconds, ARRAYFORMULA(IFERROR(VALUE(LEFT(data, FIND("" min"", data) - 1)) * 60 + VALUE(MID(data, FIND("" min"", data) + 4, FIND("" s"", data) - FIND("" min"", data) - 4)), 0)), avgSeconds, AVE"&"RAGE(totalSeconds), avgMinutes, INT(avgSeconds / 60), avgRemainingSeconds, MOD(avgSeconds, 60), TEXT(avgMinutes, ""0"") & "" min "" & TEXT(ROUND(avgRemainingSeconds), ""00"") & "" s"" ) "),"11 min 55 s") -> 11 min 55 s
A12: Wolt drive | B12: 34 | C12: 72 | D12: 108 | E12: 238 | F12: Wolt drive | G12: =SUM(B12:E12) -> 452
A13: naše rozvozy | B13: 356 | C13: 357 | D13: 699 | E13: 657 | F13: naše rozvozy | G13: =SUM(B13:E13) -> 2069
A14: WOLT | B14: 233484 | C14: 209261 | D14: 481512.22 | E14: 427461 | F14: WOLT | G14: =SUM(B14:E14) -> 1351718.2
A15: BOLT | B15: 106980 | C15: 93824 | D15: 160062 | E15: 171871.8 | F15: BOLT | G15: =SUM(B15:E15) -> 532737.8
A16: FOODODA online | B16: 154301 | C16: 146830 | D16: 268027 | E16: 238282 | F16: FOODODA online | G16: =SUM(B16:E16) -> 807440
A17: WEB online | B17: 154002 | C17: 149140.5 | D17: 279756.5 | E17: 270961 | F17: WEB online | G17: =SUM(B17:E17) -> 853860
A18: Karty | B18: 53982 | C18: 44406 | D18: 92609 | E18: 65643 | F18: Karty | G18: =SUM(B18:E18) -> 256640
B20: Zličín | F20: Součet
B21: 1. | C21: 2. | D21: 3. | E21: 4.
A22: Datum | B22: 28.02.2026 - 15.03.2026 | C22: 01.03.2025 - 16.03.2025 | D22: 01.03.2025 - 31.03.2025 | E22: 01.02.2025 - 28.02.2025
A23: Tržba | B23: 1013489.7 | C23: 1061873 | D23: 2052546 | E23: 1764912.7 | F23: Tržba | G23: =SUM(B23:E23) -> 5892821.4
A24: COL | B24: 0.2574184 | C24: 0.24011265 | D24: 0.24289485 | E24: 0.24669195 | F24: COL | G24: =AVERAGEIF(B24:E24, "<>") -> 0.24677946
A25: Pokladna | B25: 15.8 | C25: 265.5 | D25: 288.5 | E25: 14.5 | F25: Pokladna | G25: =SUM(B25:E25) -> 584.3
A26: Počet objednávek | B26: 2286 | C26: 2328 | D26: 4501 | E26: 3915 | F26: Počet objednávek | G26: =SUM(B26:E26) -> 13030
A27: % včas | B27: 0.90808262 | C27: 0.88313411 | D27: 0.90371024 | E27: 0.86426382 | F27: % včas | G27: =AVERAGEIF(B27:E27, "<>") -> 0.8897977
A28: Hodiny instore | B28: 504 | C28: 408 | D28: 793 | E28: 642 | F28: Hodiny instore | G28: =SUM(B28:E28) -> 2347
A29: Hodiny kurýr | B29: 245.5 | C29: 272.5 | D29: 551 | E29: 567 | F29: Hodiny kurýr | G29: =SUM(B29:E29) -> 1636
A30: Make time | B30: 10 min 33 s | C30: 9 min 35 s | D30: 9 min 41 s | E30: 9 min 39 s | F30: Make time | G30: =IFERROR(__xludf.DUMMYFUNCTION("LET( data, FILTER(B30:E30, B30:E30 <> """"), totalSeconds, ARRAYFORMULA(IFERROR(VALUE(LEFT(data, FIND("" min"", data) - 1)) * 60 + VALUE(MID(data, FIND("" min"", data) + 4, FIND("" s"", data) - FIND("" min"", data) - 4)), 0)), avgSeconds, AVE"&"RAGE(totalSeconds), avgMinutes, INT(avgSeconds / 60), avgRemainingSeconds, MOD(avgSeconds, 60), TEXT(avgMinutes, ""0"") & "" min "" & TEXT(ROUND(avgRemainingSeconds), ""00"") & "" s"" ) "),"9 min 52 s") -> 9 min 52 s
A31: Wolt drive | B31: 92 | C31: 104 | D31: 179 | E31: 124 | F31: Wolt drive | G31: =SUM(B31:E31) -> 499
A32: naše rozvozy | B32: 458 | C32: 428 | D32: 832 | E32: 755 | F32: naše rozvozy | G32: =SUM(B32:E32) -> 2473
A33: =A14 -> WOLT | B33: 249537 | C33: 259146 | D33: 524796 | E33: 424249 | F33: WOLT | G33: =SUM(B33:E33) -> 1457728
A34: =A15 -> BOLT | B34: 81232 | C34: 106763 | D34: 211948 | E34: 191156.2 | F34: BOLT | G34: =SUM(B34:E34) -> 591099.2
A35: =A16 -> FOODODA online | B35: 253226 | C35: 302068 | D35: 559988 | E35: 502050 | F35: FOODODA online | G35: =SUM(B35:E35) -> 1617332
A36: =A17 -> WEB online | B36: 243248.5 | C36: 224735 | D36: 434007 | E36: 374670.5 | F36: WEB online | G36: =SUM(B36:E36) -> 1276661
A37: =A18 -> Karty | B37: 85713 | C37: 67780.5 | D37: 128998.5 | E37: 106030.5 | F37: Karty | G37: =SUM(B37:E37) -> 388522.5
B39: Chodov | F39: Součet
B40: 1. | C40: 2. | D40: 3. | E40: 4.
A41: Datum | B41: 28.02.2026 - 15.03.2026 | C41: 01.03.2025 - 16.03.2025 | D41: 01.03.2025 - 31.03.2025 | E41: 01.02.2025 - 28.02.2025
A42: Tržba | B42: 905252.5 | C42: 777474 | D42: 1474078.5 | E42: 1281101.1 | F42: Tržba | G42: =SUM(B42:E42) -> 4437906.1
...

Sheet Kopie listu Ziskovost 1
F1: cos+chem | J1: odvod cent. | M1: Centrála | N1: Odvod
F2: 0.27 | J2: 0.20782888 | M2: Office | N2: 232000
B4: Hrubý obrat | C4: Tržba čistá | D4: Náklad mzdy | E4: Agregatory 25% | F4: COS + chemie | G4: Nájem + služby | H4: Energie | I4: Ostatní | J4: odvod cent. | K4: Zisk
A5: Malešice | B5: 1233974.5 | C5: 1101762.9 | D5: 332779.98 | E5: 189110 | F5: 297476 | G5: 35000 | H5: 35000 | J5: 228978.16 | K5: -16581.184 | M5: Vyroba | N5: 300000
M6: Adaptee | N6: 20000
B7: Hrubý obrat | C7: Tržba čistá | D7: Náklad mzdy | E7: Agregatory 25% | F7: COS + chemie | G7: Nájem + služby | H7: Energie | I7: Ostatní | J7: odvod cent. | K7: Zisk | M7: Vodfone | N7: 15000
A8: Zličín | B8: 1623854.5 | C8: 1449870.1 | D8: 378851.81 | E8: 255929.25 | F8: 391464.92 | G8: 35000 | H8: 35000 | J8: 301324.88 | K8: 52299.227 | M8: Opravy | N8: 50000
M9: Sklad | N9: 20000
B10: Hrubý obrat | C10: Tržba čistá | D10: Náklad mzdy | E10: Agregatory 25% | F10: COS + chemie | G10: Nájem + služby | H10: Energie | I10: Ostatní | J10: odvod cent. | K10: Zisk | M10: Vozový park | N10: 20000
A11: Chodov | B11: 1341015.5 | C11: 1197335.3 | D11: 388153.54 | E11: 181905.75 | F11: 323280.52 | G11: 35000 | H11: 35000 | J11: 248840.85 | K11: -14845.391 | M11: Kancelář | N11: 35000
M12: Marketing | N12: 150000
B13: Hrubý obrat | C13: Tržba čistá | D13: Náklad mzdy | E13: Agregatory 25% | F13: COS + chemie | G13: Nájem + služby | H13: Energie | I13: Ostatní | J13: odvod cent. | K13: Zisk | M13: Poplatky str. karty, banka | N13: 14657.38
A14: Libuš | B14: 757930.9 | C14: 676724.02 | D14: 213786.55 | E14: 124231.25 | F14: 182715.48 | G14: 35000 | H14: 35000 | J14: 140642.79 | K14: -54652.058 | M14: Restia | N14: 15000
M15: Bonusy | N15: 50000
B16: Hrubý obrat | C16: Tržba čistá | D16: Náklad mzdy | E16: Agregatory 25% | F16: COS + chemie | G16: Nájem + služby | H16: Energie | I16: Ostatní | J16: odvod cent. | K16: Zisk | M16: Dovolené | N16: 135183.28
A17: Prosek | B17: 784397.5 | C17: 700354.91 | D17: 308627.44 | E17: 150533 | F17: 189095.83 | G17: 35000 | H17: 35000 | J17: 145553.98 | K17: -163455.33 | M17: BOZP, DDD, HACCP | N17: 8500
B19: Hrubý obrat | C19: Tržba čistá | D19: Náklad mzdy | E19: Agregatory 25% | F19: COS + chemie | G19: Nájem + služby | H19: Energie | I19: Ostatní | J19: odvod cent. | K19: Zisk
A20: =Dashboard!A20 -> Bolevec | B20: 784397.5 | C20: 700354.91 | D20: 308627.44 | E20: 150533 | F20: 189095.83 | G20: 35000 | H20: 35000 | J20: 145553.98 | K20: -163455.33
N21: 1065340.7
B22: Hrubý obrat | C22: Tržba čistá | D22: Náklad mzdy | E22: Agregatory 25% | F22: COS + chemie | G22: Nájem + služby | H22: Energie | I22: Ostatní | J22: odvod cent. | K22: Zisk
A23: Součet | B23: 5741172.9 | C23: 5126047.2 | D23: 1622199.3 | E23: 901709.25 | F23: 1384032.8 | G23: 175000 | H23: 175000 | I23: 0 | J23: 1065340.7 | K23: -197234.74 | N23: 0.20782888
M24: Centrála | N24: Odvod
K25: -0.038476965 | M25: Office | N25: 232000
F27: cos+chem | J27: odvod cent.
F28: 0.27 | J28: 0.21775686 | M28: Vyroba | N28: 300000
M29: Adaptee | N29: 20000
B30: Hrubý obrat | C30: Tržba čistá | D30: Náklad mzdy | E30: Agregatory 25% | F30: COS + chemie | G30: Nájem + služby | H30: Energie | I30: Ostatní | J30: odvod cent. | K30: Zisk | M30: Vodfone | N30: 15000
A31: Malešice | B31: 1233647.7 | C31: 1101471.2 | D31: 355439.61 | E31: 192595.5 | F31: 297397.21 | G31: 35000 | H31: 35000 | J31: 239852.9 | K31: -53814.067 | M31: Opravy | N31: 50000
M32: Sklad | N32: 20000
B33: Hrubý obrat | C33: Tržba čistá | D33: Náklad mzdy | E33: Agregatory 25% | F33: COS + chemie | G33: Nájem + služby | H33: Energie | I33: Ostatní | J33: odvod cent. | K33: Zisk | M33: Vozový park | N33: 20000
A34: Zličín | B34: 1606828.4 | C34: 1434668.2 | D34: 401099.34 | E34: 256159.75 | F34: 387360.42 | G34: 35000 | H34: 35000 | J34: 312408.85 | K34: 7639.8614 | M34: Kancelář | N34: 35000
M35: Marketing | N35: 150000
B36: Hrubý obrat | C36: Tržba čistá | D36: Náklad mzdy | E36: Agregatory 25% | F36: COS + chemie | G36: Nájem + služby | H36: Energie | I36: Ostatní | J36: odvod cent. | K36: Zisk | M36: Poplatky str. karty, banka | N36: 13787.839
A37: Chodov | B37: 1279770.6 | C37: 1142652.3 | D37: 360107.8 | E37: 169564.75 | F37: 308516.13 | G37: 35000 | H37: 35000 | J37: 248820.38 | K37: -14356.738 | M37: Restia | N37: 15000
M38: Bonusy | N38: 50000
B39: Hrubý obrat | C39: Tržba čistá | D39: Náklad mzdy | E39: Agregatory 25% | F39: COS + chemie | G39: Nájem + služby | H39: Energie | I39: Ostatní | J39: odvod cent. | K39: Zisk | M39: Dovolené | N39: 132241.96
A40: Libuš | B40: 714502.1 | C40: 637948.3 | D40: 218497.43 | E40: 122310.5 | F40: 172246.04 | G40: 35000 | H40: 35000 | J40: 138917.62 | K40: -84023.292 | M40: BOZP, DDD, HACCP | N40: 8500
B42: Hrubý obrat | C42: Tržba čistá | D42: Náklad mzdy | E42: Agregatory 25% | F42: COS + chemie | G42: Nájem + služby | H42: Energie | I42: Ostatní | J42: odvod cent. | K42: Zisk
A43: Prosek | B43: 625071.7 | C43: 558099.73 | D43: 251759.29 | E43: 119782 | F43: 150686.93 | G43: 35000 | H43: 35000 | J43: 121530.05 | K43: -155658.53
N44: 1061529.8
...

Sheet Kopie listu Ziskovost
E1: Agregatory | F1: cos+chem | J1: odvod cent. | M1: Centrála | N1: Odvod
C2: Wolt | D2: Bolt | E2: Foodora | F2: 0.25 | J2: =N23 -> 5.5795402 | M2: Office | N2: 232000
C3: 26 | D3: 25 | E3: 30
B4: Hrubý obrat | C4: Tržba čistá | D4: Náklad mzdy | E4: Agregatory 25% | F4: COS + chemie | G4: Nájem + služby | H4: Energie | I4: Ostatní | J4: odvod cent. | K4: Zisk
A5: Malešice | B5: =Dashboard!B5 -> 36317 | C5: =B5/112*100 -> 32425.893 | D5: =Dashboard!C5*C5 -> 10330.104 | E5: =(Dashboard!L5/100*$C$3+Dashboard!M5/100*$D$3+Dashboard!N5/100*$E$3) -> 6704.29 | F5: =$F$2*C5 -> 8106.4732 | G5: 35000 | H5: 35000 | J5: =$J$2*C5 -> 180921.57 | K5: =C5-D5-E5-F5-G5-H5-I5-J5 -> -243636.55 | M5: Vyroba | N5: 300000
M6: Adaptee | N6: 20000
B7: =B4 -> Hrubý obrat | C7: =C4 -> Tržba čistá | D7: =D4 -> Náklad mzdy | E7: =E4 -> Agregatory 25% | F7: =F4 -> COS + chemie | G7: =G4 -> Nájem + služby | H7: =H4 -> Energie | I7: =I4 -> Ostatní | ... K7: =K4 -> Zisk | M7: Vodfone | N7: 15000
A8: Zličín | B8: =Dashboard!B8 -> 54069.5 | C8: =B8/112*100 -> 48276.339 | D8: =Dashboard!C8*C8 -> 12860.394 | E8: =(Dashboard!L8/100*$C$3+Dashboard!M8/100*$D$3+Dashboard!N8/100*$E$3) -> 9123.15 | F8: =$F$2*C8 -> 12069.085 | G8: 35000 | H8: 35000 | J8: =$J$2*C8 -> 269359.77 | K8: =C8-D8-E8-F8-G8-H8-I8-J8 -> -325136.06 | M8: Opravy | N8: 50000
M9: Sklad | N9: 20000
B10: =B7 -> Hrubý obrat | C10: =C7 -> Tržba čistá | D10: =D7 -> Náklad mzdy | E10: =E7 -> Agregatory 25% | F10: =F7 -> COS + chemie | G10: =G7 -> Nájem + služby | H10: =H7 -> Energie | I10: =I7 -> Ostatní | ... K10: =K7 -> Zisk | M10: Vozový park | N10: 20000
A11: Chodov | B11: =Dashboard!B11 -> 45313 | C11: =B11/112*100 -> 40458.036 | D11: =Dashboard!C11*C11 -> 15527.311 | E11: =(Dashboard!L11/100*$C$3+Dashboard!M11/100*$D$3+Dashboard!N11/100*$E$3) -> 5789.56 | F11: =$F$2*C11 -> 10114.509 | G11: 35000 | H11: 35000 | J11: =$J$2*C11 -> 225737.24 | K11: =C11-D11-E11-F11-G11-H11-I11-J11 -> -286710.58 | M11: Kancelář | N11: 35000
M12: Marketing | N12: 200000
B13: =B10 -> Hrubý obrat | C13: =C10 -> Tržba čistá | D13: =D10 -> Náklad mzdy | E13: =E10 -> Agregatory 25% | F13: =F10 -> COS + chemie | G13: =G10 -> Nájem + služby | H13: =H10 -> Energie | I13: =I10 -> Ostatní | ... K13: =K10 -> Zisk | M13: Poplatky str. karty, banka | N13: =1%*Dashboard!P23+6%*Dashboard!Q23+1%*Dashboard!O23 -> 661.02
A14: Libuš | B14: =Dashboard!B14 -> 33988.5 | C14: =B14/112*100 -> 30346.875 | D14: =Dashboard!C14*C14 -> 11479.469 | E14: =(Dashboard!L14/100*$C$3+Dashboard!M14/100*$D$3+Dashboard!N14/100*$E$3) -> 4736.88 | F14: =$F$2*C14 -> 7586.7188 | G14: 35000 | H14: 35000 | J14: =$J$2*C14 -> 169321.61 | K14: =C14-D14-E14-F14-G14-H14-I14-J14 -> -232777.8 | M14: Restia | N14: 15000
M15: Bonusy | N15: 50000
B16: =B13 -> Hrubý obrat | C16: =C13 -> Tržba čistá | D16: =D13 -> Náklad mzdy | E16: =E13 -> Agregatory 25% | F16: =F13 -> COS + chemie | G16: =G13 -> Nájem + služby | H16: =H13 -> Energie | I16: =I13 -> Ostatní | ... K16: =K13 -> Zisk | M16: Dovolené | N16: =D20/12 -> 4756.5152
A17: Prosek | B17: =Dashboard!B17 -> 27516 | C17: =B17/112*100 -> 24567.857 | D17: =Dashboard!C17*C17 -> 6880.9046 | E17: =(Dashboard!L17/100*$C$3+Dashboard!M17/100*$D$3+Dashboard!N17/100*$E$3) -> 5815.02 | F17: =$F$2*C17 -> 6141.9643 | G17: 35000 | H17: 35000 | J17: =$J$2*C17 -> 137077.35 | K17: =C17-D17-E17-F17-G17-H17-I17-J17 -> -201347.38 | M17: BOZP+ | N17: 20000
B19: =B16 -> Hrubý obrat | C19: =C16 -> Tržba čistá | D19: =D16 -> Náklad mzdy | E19: =E16 -> Agregatory 25% | F19: =F16 -> COS + chemie | G19: =G16 -> Nájem + služby | H19: =H16 -> Energie | I19: =I16 -> Ostatní | ... K19: =K16 -> Zisk
A20: Součet | B20: =sum(B5+B8+B11+B14+B17) -> 197204 | C20: =sum(C5+C8+C11+C14+C17) -> 176075 | D20: =sum(D5+D8+D11+D14+D17) -> 57078.182 | E20: =sum(E5+E8+E11+E14+E17) -> 32168.9 | F20: =sum(F5+F8+F11+F14+F17) -> 44018.75 | G20: =sum(G5+G8+G11+G14+G17) -> 175000 | H20: =sum(H5+H8+H11+H14+H17) -> 175000 | I20: =sum(I5+I8+I11+I14+I17) -> 0 | ... K20: =sum(K5+K8+K11+K14+K17) -> -1289608.4
N21: =SUM(N2:N20) -> 982417.54
D22: =D20/C20 -> 0.32416971 | E22: =E20/C20 -> 0.18269999 | F22: =F20/C20 -> 0.25 | K22: =K20/C20 -> -7.3241992
N23: =N21/C27 -> 5.5795402
D26: 0.294
A27: Součet | B27: =B20+B29 -> 197204 | C27: =B27/112*100 -> 176075 | D27: =C27*D26 -> 51766.05 | E27: =C27*E22 -> 32168.9 | F27: =C27*F22 -> 44018.75 | G27: =G20 -> 175000 | H27: =H20 -> 175000 | I27: =I20 -> 0 | J27: 1092099.5 | K27: =C27-(D27+E27+F27+G27+H27+I27+J27) -> -1393978.2
B29: 0 | D29: =D27/C27 -> 0.294 | E29: =E27/C27 -> 0.18269999 | F29: =F27/C27 -> 0.25 | J29: =J27/C27 -> 6.2024677 | K29: =K27/C27 -> -7.916957
D33: 100000 | E33: 5
E34: 30
E35: =D33/E33/E34 -> 666.66667
E36: 7
E37: =E35*E36 -> 4666.6667 | F37: 200 | G37: =E37/F37 -> 23.333333 | H37: =G37/E36 -> 3.3333333
J45: =1341+150+2356 -> 3847

Sheet Ziskovost
F1: cos+chem | J1: odvod cent. | K1: 6 | M1: Centrála | N1: Odvod
F2: 0.232 | J2: =N23 -> 7.883827 | K2: =N22 -> 1478661 | M2: Office | N2: 414000
B4: Hrubý obrat | C4: Tržba čistá | D4: Náklad mzdy | E4: Agregatory 25% | F4: COS + chemie | G4: Nájem + služby | H4: Energie | I4: Ostatní | J4: odvod cent. | K4: Zisk
A5: Malešice | B5: =Dashboard!B5 -> 36317 | C5: =B5/112*100 -> 32425.893 | D5: =Dashboard!C5*C5 -> 10330.104 | E5: =(Dashboard!L5+Dashboard!M5+Dashboard!N5)/100*25 -> 6275.75 | F5: =$F$2*C5 -> 7522.8071 | G5: 26000 | H5: 35000 | I5: 3000 | J5: =C5*J$2 -> 255640.13 | K5: =C5-D5-E5-F5-G5-H5-I5-J5 -> -311342.9 | M5: Vyroba | N5: 255000
M6: Adaptee | N6: 21000
B7: =B4 -> Hrubý obrat | C7: =C4 -> Tržba čistá | D7: =D4 -> Náklad mzdy | E7: =E4 -> Agregatory 25% | F7: =F4 -> COS + chemie | G7: =G4 -> Nájem + služby | H7: =H4 -> Energie | I7: =I4 -> Ostatní | ... K7: =K4 -> Zisk | M7: Vodafone | N7: 18000
A8: Zličín | B8: =Dashboard!B8 -> 54069.5 | C8: =B8/112*100 -> 48276.339 | D8: =Dashboard!C8*C8 -> 12860.394 | E8: =(Dashboard!L8+Dashboard!M8+Dashboard!N8)/100*25 -> 8303.25 | F8: =$F$2*C8 -> 11200.111 | G8: 28000 | H8: 35000 | I8: 2200 | J8: =C8*J$2 -> 380602.31 | K8: =C8-D8-E8-F8-G8-H8-I8-J8 -> -429889.72 | M8: Opravy | N8: 50000
M9: Sklad | N9: 20000
B10: =B7 -> Hrubý obrat | C10: =C7 -> Tržba čistá | D10: =D7 -> Náklad mzdy | E10: =E7 -> Agregatory 25% | F10: =F7 -> COS + chemie | G10: =G7 -> Nájem + služby | H10: =H7 -> Energie | I10: =I7 -> Ostatní | ... K10: =K7 -> Zisk | M10: Vozový park | N10: 20000
A11: Chodov | B11: =Dashboard!B11 -> 45313 | C11: =B11/112*100 -> 40458.036 | D11: =Dashboard!C11*C11 -> 15527.311 | E11: =(Dashboard!L11+Dashboard!M11+Dashboard!N11)/100*25 -> 5378.75 | F11: =$F$2*C11 -> 9386.2643 | G11: 31000 | H11: 35000 | I11: 2300 | J11: =C11*J$2 -> 318964.15 | K11: =C11-D11-E11-F11-G11-H11-I11-J11 -> -377098.44 | M11: Kancelář | N11: 30000
M12: Marketing | N12: 250000
B13: =B10 -> Hrubý obrat | C13: =C10 -> Tržba čistá | D13: =D10 -> Náklad mzdy | E13: =E10 -> Agregatory 25% | F13: =F10 -> COS + chemie | G13: =G10 -> Nájem + služby | H13: =H10 -> Energie | I13: =I10 -> Ostatní | ... K13: =K10 -> Zisk | M13: Poplatky str. karty, banka | N13: =1%*Dashboard!P23+6%*Dashboard!Q23+1%*Dashboard!O23 -> 661.02
A14: Libuš | B14: =Dashboard!B14 -> 33988.5 | C14: =B14/112*100 -> 30346.875 | D14: =Dashboard!C14*C14 -> 11479.469 | E14: =(Dashboard!L14+Dashboard!M14+Dashboard!N14)/100*25 -> 4277.75 | F14: =$F$2*C14 -> 7040.475 | G14: 30000 | H14: 35000 | I14: 3000 | J14: =C14*J$2 -> 239249.51 | K14: =C14-D14-E14-F14-G14-H14-I14-J14 -> -299700.33 | M14: Restia | N14: 18000
M15: Bonusy | N15: 134000
B16: =B13 -> Hrubý obrat | C16: =C13 -> Tržba čistá | D16: =D13 -> Náklad mzdy | E16: =E13 -> Agregatory 25% | F16: =F13 -> COS + chemie | G16: =G13 -> Nájem + služby | H16: =H13 -> Energie | I16: =I13 -> Ostatní | ... K16: =K13 -> Zisk | M16: Dovolené | N16: 170000
A17: Prosek | B17: =Dashboard!B17 -> 27516 | C17: =B17/112*100 -> 24567.857 | D17: =Dashboard!C17*C17 -> 6880.9046 | E17: =(Dashboard!L17+Dashboard!M17+Dashboard!N17)/100*25 -> 5429 | F17: =$F$2*C17 -> 5699.7429 | G17: 54000 | H17: 35000 | I17: 2300 | J17: =C17*J$2 -> 193688.73 | K17: =C17-D17-E17-F17-G17-H17-I17-J17 -> -278430.52 | M17: BOZP, DDD, HACCP | N17: 10000
M18: Multisportky + bolt | N18: 18000
B19: =B16 -> Hrubý obrat | C19: =C16 -> Tržba čistá | D19: =D16 -> Náklad mzdy | E19: =E16 -> Agregatory 25% | F19: =F16 -> COS + chemie | G19: =G16 -> Nájem + služby | H19: =H16 -> Energie | I19: =I16 -> Ostatní | ... K19: =K16 -> Zisk | M19: Drobné nákupy | N19: 30000
A20: =Dashboard!A20 -> Bolevec | B20: =Dashboard!B20 -> 12859 | C20: =B20/112*100 -> 11481.25 | D20: =Dashboard!C20*C20 -> 9280.8876 | E20: =(Dashboard!L20+Dashboard!M20+Dashboard!N20)/100*17 -> 911.2 | F20: =$F$2*C20 -> 2663.65 | G20: 35000 | H20: 35000 | I20: 3500 | J20: =C20*J$2 -> 90516.188 | K20: =C20-D20-E20-F20-G20-H20-I20-J20 -> -165390.68
M21: účetní | N21: 20000
B22: =B16 -> Hrubý obrat | C22: =C16 -> Tržba čistá | D22: =D16 -> Náklad mzdy | E22: =E16 -> Agregatory 25% | F22: =F16 -> COS + chemie | G22: =G16 -> Nájem + služby | H22: =H16 -> Energie | I22: =I16 -> Ostatní | ... K22: =K16 -> Zisk | N22: =SUM(N2:N21) -> 1478661
A23: Součet | B23: =sum(B5+B8+B11+B14+B17+B20) -> 210063 | C23: =sum(C5+C8+C11+C14+C17+C20) -> 187556.25 | D23: =sum(D5+D8+D11+D14+D17+D20) -> 66359.07 | E23: =sum(E5+E8+E11+E14+E17+E20) -> 30575.7 | F23: =sum(F5+F8+F11+F14+F17+F20) -> 43513.05 | G23: =sum(G5+G8+G11+G14+G17+G20) -> 204000 | H23: =sum(H5+H8+H11+H14+H17+H20) -> 210000 | I23: =sum(I5+I8+I11+I14+I17+I20) -> 16300 | ... K23: =sum(K5+K8+K11+K14+K17+K20) -> -1861852.6 | N23: =N22/C23 -> 7.883827
K25: =K23/C23 -> -9.9269024
G59: 59605

Sheet Malešice
B1: Malešice | C1: 46099 | D1: Vyber datum <----------> | E1: 46099 | F1: COL | I1: Tržba | L1: Online Platby
F2: 0.31857577 | I2: 36317 | L2: Wolt | M2: 12014
B3: =CHOOSE(WEEKDAY(C1), "Neděle", "Pondělí", "Úterý", "Středa", "Čtvrtek", "Pátek", "Sobota") -> Středa | D3: =CHOOSE(WEEKDAY(E1), "Neděle", "Pondělí", "Úterý", "Středa", "Čtvrtek", "Pátek", "Sobota") -> Středa | L3: Bolt | M3: 6921
L4: Dáme jídlo | M4: 6168
B5: Celkem hodin Instor | F5: Celkem hodin Kurýr | L5: Web | M5: 8020
L6: Wolt drive cash | M6: 0
B7: =TEXT(SUMPRODUCT((IFERROR(LEFT(D10:D30, FIND(":", D10:D30) - 1) * 60, 0) + IFERROR(MID(D10:D30, FIND(":", D10:D30) + 1, LEN(D10:D30) - FIND(":", D10:D30)), 0))), "[h]:mm")/60 -> 15 | F7: =TEXT(SUMPRODUCT((IFERROR(LEFT(H10:H30, FIND(":", H10:H30) - 1) * 60, 0) + IFERROR(MID(H10:H30, FIND(":", H10:H30) + 1, LEN(H10:H30) - FIND(":", H10:H30)), 0))), "[h]:mm")/60 -> 16 | L7: DJ Cash | M7: 0
B8: Instor | F8: Kurýr | J8: Pokladna | L8: Hotovost
B9: Jméno | C9: Počet dní | D9: Počet hodin | F9: Jméno | G9: Počet dní | H9: Počet hodin | I9: Počet rozvozů | J9: 12 | L9: Terminál | M9: 1006
B10: Yarushynskyi Vladyslav | C10: 1 | D10: 8:00 | E10: 29:00 | F10: Kalina Filip | G10: 1 | H10: 5:00 | I10: 5 | L10: Stravenky | M10: 0
B11: Kopic Jakub | C11: 1 | D11: 7:00 | E11: 23:00 | F11: Hendrych Rostislav | G11: 1 | H11: 11:00 | I11: 13 | L11: Hotovost | M11: 0
E12: 13:00 | L12: Výdaje
E13: 13:00 | L13: Benzín | M13: 1000
E14: 7:00 | L14: Auta | M14: 0
E15: 7:00 | L15: Suroviny | M15: 0
L16: Ostatní | M16: 1000
L17: PHM - soukromé | M17: 200
J19: Zrušené obj. ks | K19: Zrušené obj. $ | L19: Počet zpožděných našich rozvozů +5 min | M19: Průměrný make Time
J21: 0 | K21: 0 | L21: 1 | M21: 11 min 23 s
J22: počet výdajových dokadů | K22: Počet nezrušených celkem | L22: Počet našich rozvozů | M22: Počet pozdě přiřazeným WoltDrive 5+
J24: 1 | K24: 86 | L24: 19 | M24: 0
J25: Woltrdive zpožděný kvůli našemu pozdnímu přiřazení | L25: % zpožděných našich rozvozů +5 min | M25: Počet zpožděných Woltdrivem
J27: 0 | L27: 0.052631579 | M27: 0
K28: Počet Wolt drive | L28: % doručených včas | M28: % zpožděných Woltdrivem
K30: 1 | L30: 0.94736842 | M30: 0
B31: Veselý Ondřej | C31: 2 | D31: 16:30 | F31: Hubr Samuel | G31: 3 | H31: 20:00 | I31: 31
B32: Kopic Jakub | C32: 2 | D32: 19:00 | F32: Coufal Jakub | G32: 1 | H32: 7:00 | I32: 0
F33: Serin David | G33: 1 | H33: 5:30 | I33: 9

Sheet Zličín
B1: Zličín | C1: 46099 | D1: Vyber datum <----------> | E1: 46099 | F1: COL | I1: Tržba | L1: Online Platby
F2: 0.26639125 | I2: 54069.5 | L2: Wolt | M2: 13210
B3: =CHOOSE(WEEKDAY(C1), "Neděle", "Pondělí", "Úterý", "Středa", "Čtvrtek", "Pátek", "Sobota") -> Středa | D3: =CHOOSE(WEEKDAY(E1), "Neděle", "Pondělí", "Úterý", "Středa", "Čtvrtek", "Pátek", "Sobota") -> Středa | L3: Bolt | M3: 6247
L4: Dáme jídlo | M4: 13756
B5: Celkem hodin Instor | F5: Celkem hodin Kurýr | L5: Web | M5: 11505
L6: Wolt drive cash | M6: 0
B7: =TEXT(SUMPRODUCT((IFERROR(LEFT(D10:D30, FIND(":", D10:D30) - 1) * 60, 0) + IFERROR(MID(D10:D30, FIND(":", D10:D30) + 1, LEN(D10:D30) - FIND(":", D10:D30)), 0))), "[h]:mm")/60 -> 22 | F7: =TEXT(SUMPRODUCT((IFERROR(LEFT(H10:H30, FIND(":", H10:H30) - 1) * 60, 0) + IFERROR(MID(H10:H30, FIND(":", H10:H30) + 1, LEN(H10:H30) - FIND(":", H10:H30)), 0))), "[h]:mm")/60 -> 14 | L7: DJ Cash | M7: 823
B8: Instor | F8: Kurýr | J8: Pokladna | L8: Hotovost
B9: Jméno | C9: Počet dní | D9: Počet hodin | F9: Jméno | G9: Počet dní | H9: Počet hodin | I9: Počet rozvozů | J9: 0.5 | L9: Terminál | M9: 5690
B10: Hanakova Ayuna | C10: 1 | D10: 7:00 | E10: 29:00 | F10: Zimmer Jakub | G10: 1 | H10: 7:00 | I10: 12 | L10: Stravenky | M10: 0
B11: Veselý Ondřej | C11: 1 | D11: 7:30 | E11: 23:00 | F11: Kormash Liubov | G11: 1 | H11: 7:00 | I11: 8 | L11: Hotovost | M11: 459
B12: Pánková Vendula | C12: 1 | D12: 7:30 | E12: 13:00 | L12: Výdaje
E13: 13:00 | L13: Benzín | M13: 0
E14: 7:00 | L14: Auta | M14: 0
E15: 7:00 | L15: Suroviny | M15: 0
L16: Ostatní | M16: 2403
L17: PHM - soukromé | M17: 800
J19: Zrušené obj. ks | K19: Zrušené obj. $ | L19: Počet zpožděných našich rozvozů +5 min | M19: Průměrný make Time
J21: 1 | K21: 0 | L21: 1 | M21: 13 min 06 s
J22: počet výdajových dokadů | K22: Počet nezrušených celkem | L22: Počet našich rozvozů | M22: Počet pozdě přiřazeným WoltDrive 5+
J24: 2 | K24: 123 | L24: 20 | M24: 0
J25: Woltrdive zpožděný kvůli našemu pozdnímu přiřazení | L25: % zpožděných našich rozvozů +5 min | M25: Počet zpožděných Woltdrivem
J27: 0 | L27: 0.05 | M27: 0
K28: Počet Wolt drive | L28: % doručených včas | M28: % zpožděných Woltdrivem
K30: 0 | L30: 0.95 | M30: 0

Sheet Chodov
B1: Chodov | C1: 46099 | D1: Vyber datum <----------> | E1: 46099 | F1: COL | I1: Tržba | L1: Online Platby
F2: 0.38378806 | I2: 45313 | L2: Wolt | M2: 11601
B3: =CHOOSE(WEEKDAY(C1), "Neděle", "Pondělí", "Úterý", "Středa", "Čtvrtek", "Pátek", "Sobota") -> Středa | D3: =CHOOSE(WEEKDAY(E1), "Neděle", "Pondělí", "Úterý", "Středa", "Čtvrtek", "Pátek", "Sobota") -> Středa | L3: Bolt | M3: 4018
L4: Dáme jídlo | M4: 5896
B5: Celkem hodin Instor | F5: Celkem hodin Kurýr | L5: Web | M5: 16846
L6: Wolt drive cash | M6: 0
B7: =TEXT(SUMPRODUCT((IFERROR(LEFT(D10:D30, FIND(":", D10:D30) - 1) * 60, 0) + IFERROR(MID(D10:D30, FIND(":", D10:D30) + 1, LEN(D10:D30) - FIND(":", D10:D30)), 0))), "[h]:mm")/60 -> 28 | F7: =TEXT(SUMPRODUCT((IFERROR(LEFT(H10:H30, FIND(":", H10:H30) - 1) * 60, 0) + IFERROR(MID(H10:H30, FIND(":", H10:H30) + 1, LEN(H10:H30) - FIND(":", H10:H30)), 0))), "[h]:mm")/60 -> 19 | L7: DJ Cash | M7: 1587
B8: Instor | F8: Kurýr | J8: Pokladna | L8: Hotovost
B9: Jméno | C9: Počet dní | D9: Počet hodin | F9: Jméno | G9: Počet dní | H9: Počet hodin | I9: Počet rozvozů | J9: 0 | L9: Terminál | M9: 3432
B10: Židek Petr | C10: 1 | D10: 7:00 | E10: 29:00 | F10: Navrátil Ondřej | G10: 1 | H10: 8:00 | I10: 10 | L10: Stravenky | M10: 0
B11: Sova Martin | C11: 1 | D11: 14:00 | E11: 23:00 | F11: Nekolný Vladimír | G11: 1 | H11: 5:00 | I11: 8 | L11: Hotovost | M11: 2560
B12: Šebesta Tomáš | C12: 1 | D12: 7:00 | E12: 13:00 | F12: Lanský Zoltan | G12: 1 | H12: 6:00 | I12: 16 | L12: Výdaje
E13: 13:00 | L13: Benzín | M13: 0
E14: 7:00 | L14: Auta | M14: 0
E15: 7:00 | L15: Suroviny | M15: 0
L16: Ostatní | M16: 0
L17: PHM - soukromé | M17: 960
J19: Zrušené obj. ks | K19: Zrušené obj. $ | L19: Počet zpožděných našich rozvozů +5 min | M19: Průměrný make Time
J21: 0 | K21: 0 | L21: 4 | M21: 12 min 16 s
J22: počet výdajových dokadů | K22: Počet nezrušených celkem | L22: Počet našich rozvozů | M22: Počet pozdě přiřazeným WoltDrive 5+
J24: 2 | K24: 115 | L24: 34 | M24: 1
J25: Woltrdive zpožděný kvůli našemu pozdnímu přiřazení | L25: % zpožděných našich rozvozů +5 min | M25: Počet zpožděných Woltdrivem
J27: 0 | L27: 0.11764706 | M27: 0
K28: Počet Wolt drive | L28: % doručených včas | M28: % zpožděných Woltdrivem
K30: 0 | L30: 0.88235294 | M30: 0
F31: Přibyl Jan | G31: 6 | H31: 32:00 | I31: 52
F32: Jan Přibyl | G32: 3 | H32: 16:30 | I32: 27
F33: Hrach Michal | G33: 6 | H33: 57:30 | I33: 82
F34: Pelikán Jan | G34: 2 | H34: 9:00 | I34: 0
F35: Pražák Aleš | G35: 2 | H35: 12:00 | I35: 22
F36: Reischl Jan | G36: 1 | H36: 6:00 | I36: 6
F37: Pelikán Jan | G37: 2 | H37: 9:00 | I37: 0
F38: Reischl Jan | G38: 3 | H38: 18:00 | I38: 12

Sheet Libuš
B1: Libuš | C1: 46099 | D1: Vyber datum <----------> | E1: 46099 | F1: COL | I1: Tržba | L1: Online Platby
F2: 0.37827515 | I2: 33988.5 | L2: Wolt | M2: 8098
B3: =CHOOSE(WEEKDAY(C1), "Neděle", "Pondělí", "Úterý", "Středa", "Čtvrtek", "Pátek", "Sobota") -> Středa | D3: =CHOOSE(WEEKDAY(E1), "Neděle", "Pondělí", "Úterý", "Středa", "Čtvrtek", "Pátek", "Sobota") -> Středa | L3: Bolt | M3: 1450
L4: Dáme jídlo | M4: 7563
B5: Celkem hodin Instor | F5: Celkem hodin Kurýr | L5: Web | M5: 10188
L6: Wolt drive cash | M6: 1882
B7: =TEXT(SUMPRODUCT((IFERROR(LEFT(D10:D30, FIND(":", D10:D30) - 1) * 60, 0) + IFERROR(MID(D10:D30, FIND(":", D10:D30) + 1, LEN(D10:D30) - FIND(":", D10:D30)), 0))), "[h]:mm")/60 -> 18.5 | F7: =TEXT(SUMPRODUCT((IFERROR(LEFT(H10:H30, FIND(":", H10:H30) - 1) * 60, 0) + IFERROR(MID(H10:H30, FIND(":", H10:H30) + 1, LEN(H10:H30) - FIND(":", H10:H30)), 0))), "[h]:mm")/60 -> 12.5 | L7: DJ Cash | M7: 1853
B8: Instor | F8: Kurýr | J8: Pokladna | L8: Hotovost
B9: Jméno | C9: Počet dní | D9: Počet hodin | F9: Jméno | G9: Počet dní | H9: Počet hodin | I9: Počet rozvozů | J9: 0.5 | L9: Terminál | M9: 1225
B10: Eszenyiová Patrícia | C10: 1 | D10: 7:00 | E10: 29:00 | F10: Dušek Sam | G10: 1 | H10: 12:30 | I10: 17 | L10: Stravenky | M10: 0
B11: Novák Dalibor | C11: 1 | D11: 8:30 | E11: 23:00 | L11: Hotovost | M11: 2804
B12: Coufal Jakub | C12: 1 | D12: 3:00 | E12: 13:00 | L12: Výdaje
E13: 13:00 | L13: Benzín | M13: 0
E14: 7:00 | L14: Auta | M14: 0
E15: 7:00 | L15: Suroviny | M15: 0
L16: Ostatní | M16: 99
L17: PHM - soukromé | M17: 680
J19: Zrušené obj. ks | K19: Zrušené obj. $ | L19: Počet zpožděných našich rozvozů +5 min | M19: Průměrný make Time
J21: 0 | K21: 0 | L21: 2 | M21: 14 min 44 s
J22: počet výdajových dokadů | K22: Počet nezrušených celkem | L22: Počet našich rozvozů | M22: Počet pozdě přiřazeným WoltDrive 5+
J24: 1 | K24: 84 | L24: 19 | M24: 3
J25: Woltrdive zpožděný kvůli našemu pozdnímu přiřazení | L25: % zpožděných našich rozvozů +5 min | M25: Počet zpožděných Woltdrivem
J27: 1 | L27: 0.10526316 | M27: 1
K28: Počet Wolt drive | L28: % doručených včas | M28: % zpožděných Woltdrivem
K30: 2 | L30: 0.89473684 | M30: 0.052631579
F31: Dušek Sam | G31: 24 | H31: 230:00 | I31: 268
F32: Hanibal Filip | G32: 7 | H32: 41:00 | I32: 34
F33: Dominik Nedvěd | G33: 2 | H33: 30:00 | I33: 30
F34: Kalina Filip | G34: 1 | H34: 15:00 | I34: 7
F35: Nedvěd Dominik | G35: 4 | H35: 39:00 | I35: 44

Sheet Prosek
B1: Prosek | C1: 46099 | D1: Vyber datum <----------> | E1: 46099 | F1: COL | I1: Tržba | L1: Online Platby
F2: 0.28007752 | I2: 27516 | L2: Wolt | M2: 10177
B3: =CHOOSE(WEEKDAY(C1), "Neděle", "Pondělí", "Úterý", "Středa", "Čtvrtek", "Pátek", "Sobota") -> Středa | D3: =CHOOSE(WEEKDAY(E1), "Neděle", "Pondělí", "Úterý", "Středa", "Čtvrtek", "Pátek", "Sobota") -> Středa | L3: Bolt | M3: 5854
L4: Dáme jídlo | M4: 5685
B5: Celkem hodin Instor | F5: Celkem hodin Kurýr | L5: Web | M5: 2977
L6: Wolt drive cash | M6: 0
B7: =TEXT(SUMPRODUCT((IFERROR(LEFT(D10:D30, FIND(":", D10:D30) - 1) * 60, 0) + IFERROR(MID(D10:D30, FIND(":", D10:D30) + 1, LEN(D10:D30) - FIND(":", D10:D30)), 0))), "[h]:mm")/60 -> 1 | F7: =TEXT(SUMPRODUCT((IFERROR(LEFT(H10:H30, FIND(":", H10:H30) - 1) * 60, 0) + IFERROR(MID(H10:H30, FIND(":", H10:H30) + 1, LEN(H10:H30) - FIND(":", H10:H30)), 0))), "[h]:mm")/60 -> 14 | L7: DJ Cash | M7: 0
B8: Instor | F8: Kurýr | J8: Pokladna | L8: Hotovost
B9: Jméno | C9: Počet dní | D9: Počet hodin | F9: Jméno | G9: Počet dní | H9: Počet hodin | I9: Počet rozvozů | J9: 0 | L9: Terminál | M9: 673
B10: Nováková Adéla | C10: 1 | D10: 1:00 | E10: 29:00 | F10: Vychivskyi Volodymyr | G10: 1 | H10: 14:00 | I10: 8 | L10: Stravenky | M10: 0
E11: 23:00 | L11: Hotovost | M11: 0
E12: 13:00 | L12: Výdaje
E13: 13:00 | L13: Benzín | M13: 0
E14: 7:00 | L14: Auta | M14: 0
E15: 7:00 | L15: Suroviny | M15: 0
L16: Ostatní | M16: 1830
L17: PHM - soukromé | M17: 320
J19: Zrušené obj. ks | K19: Zrušené obj. $ | L19: Počet zpožděných našich rozvozů +5 min | M19: Průměrný make Time
J21: 0 | K21: 0 | L21: 0 | M21: 10 min 13 s
J22: počet výdajových dokadů | K22: Počet nezrušených celkem | L22: Počet našich rozvozů | M22: Počet pozdě přiřazeným WoltDrive 5+
J24: 1 | K24: 63 | L24: 8 | M24: 0
J25: Woltrdive zpožděný kvůli našemu pozdnímu přiřazení | L25: % zpožděných našich rozvozů +5 min | M25: Počet zpožděných Woltdrivem
J27: 0 | L27: 0 | M27: 0
K28: Počet Wolt drive | L28: % doručených včas | M28: % zpožděných Woltdrivem
K30: 0 | L30: 1 | M30: 0

Sheet August 2024
A1: Datum | B1: Název | C1: Jména Instor | D1: Začátek směny Instor | E1: Konec směny Instor | F1: Pauza Instor | G1: Počet hodin Instor | H1: Jména Kurýr | I1: Začátek směny Kurýr | J1: Konec směny Kurýr | K1: Pauza Kurýr | L1: Počet hodin Kurýr | M1: Počet rozvozů Kurýr | N1: Vlastní vůz | O1: Vyplatit PHM | P1: Wolt drive | Q1: Otevíral | R1: Zavíral | S1: Online Platby - Wolt | T1: Online Platby - Bolt | U1: Online Platby - Dáme Jídlo | V1: Vlastní API | W1: Online Platby - Wolt cash | X1: Online Platby - DJ Cash | Y1: Terminál | Z1: Stravenky | AA1: Hotovost | AB1: Tržba | AC1: Pokladna - VÝSLEDEK | AD1: COL | AE1: Benzín | AF1: Auta | AG1: Suroviny | AH1: Ostatní | AI1: PHM - soukromé | AJ1: Zrušené obj. ks | AK1: Zrušené obj. $ | AL1: Počet zpožděných objednávek z webu +5 min | AM1: Průměrný make Time | AN1: Počet vydajových dokladů | AO1: Počet nezrušených celkem | AP1: Počet našich rozvozů | AQ1: Počet pozdě přiřazeným WoltDrive 5+ | AR1: Woltrdrive zpožděný kvůli našemu pozdnímu přiřazení | AS1: % zpožděných našich rozvozů +5 min | AT1: Počet zpožděných Woltdrivem | AU1: % doručených včas | AV1: % zpožděných Woltdrivem
A2: 45524 | B2: Úterý | C2: Martin Sova | D2: 10:00 | E2: 13:00 | G2: 03:00
A3: 45524 | B3: Úterý | C3: Ahurieva Viktoriia | D3: 13:00 | E3: 01:00 | G3: 12:00
A4: 45524 | B4: Úterý | H4: Ondřej Navrátil | I4: 11:00 | J4: 18:00 | L4: 07:00
A5: 45524 | B5: Úterý | H5: Zbyněk Hyský | I5: 18:00 | J5: 00:00 | L5: 06:00 | N5: TRUE | O5: 520
A6: 45524 | B6: Úterý | H6: Pešová Hana | I6: 17:00 | J6: 01:00 | L6: 08:00
A7: 45524 | B7: Úterý | P7: 7 | Q7: Martin Sova | R7: Ahurieva Viktoriia | S7: 8461 | T7: 3807 | U7: 8309 | V7: 10131 | W7: 1300 | X7: 2815 | Y7: 3723 | AA7: 1160 | AB7: 42831 | AC7: 0 | AD7: 0.38519359 | AE7: 2000 | AH7: 3420 | AI7: 520 | AJ7: 0 | AK7: 0 | AL7: 7 | AM7: 15 min 46 s | AN7: 1 | AO7: 107 | AP7: 29 | AQ7: 5 | AR7: 5 | AS7: 0.24137931 | AT7: 5 | AU7: 0.75862069 | AV7: 0.17241379

Sheet RestiaCSV
A1: Platforma | B1: Stav | C1: Cena | D1: Sleva | E1: Kurýr | F1: Doručení | G1: Platba | H1: Vytvořeno | I1: Připraveno v | J1: Dokončeno v | K1: Přenos do dispecinku | L1: Zpoždění | M1: Přiřazení WoltDrivu | N1: Make Time
A2: damejidlo | B2: delivered | C2: 607 | D2: 0 | G2: online | H2: 2024-09-15T02:38:04.762+02:00 | J2: 2024-09-15T02:49:23.552+02:00 | L2: -1 | N2: 11.313167
A3: damejidlo | B3: delivered | C3: 472 | D3: 0 | F3: external-delivery | G3: cash | H3: 2024-09-15T02:19:03.897+02:00 | I3: 2024-09-15T02:29:22.618+02:00 | J3: 2024-09-15T02:29:22.618+02:00 | L3: -1 | N3: 10.312017
A4: damejidlo | B4: ready_pickup | C4: 254 | D4: 100 | F4: external-delivery | G4: online | H4: 2024-09-15T02:00:03.376+02:00 | I4: 2024-09-15T02:13:09.849+02:00 | J4: 2024-09-15T02:13:09.849+02:00 | L4: 2 | N4: 13.107883
A5: damejidlo | B5: delivered | C5: 264 | D5: 0 | F5: external-delivery | G5: online | H5: 2024-09-15T01:46:42.899+02:00 | I5: 2024-09-15T02:04:37.516+02:00 | J5: 2024-09-15T02:04:37.516+02:00 | L5: 8 | N5: 17.910283
A6: damejidlo | B6: delivered | C6: 585 | D6: 0 | F6: external-delivery | G6: online | H6: 2024-09-15T01:43:35.193+02:00 | I6: 2024-09-15T02:03:32.641+02:00 | J6: 2024-09-15T02:03:32.641+02:00 | L6: 7 | N6: 19.957467
A7: wolt | B7: delivered | C7: 431 | D7: 0 | E7: Wolt Kurýr | F7: external-delivery | G7: online | H7: 2024-09-15T00:54:35.548+02:00 | I7: 2024-09-15T01:06:03.818+02:00 | J7: 2024-09-15T01:06:03.818+02:00 | L7: -3 | N7: 11.471167
A8: damejidlo | B8: delivered | C8: 593 | D8: 0 | F8: external-delivery | G8: cash | H8: 2024-09-15T00:10:02.306+02:00 | I8: 2024-09-15T00:32:03.547+02:00 | J8: 2024-09-15T00:32:03.547+02:00 | L8: 10 | N8: 22.020683
A9: damejidlo | B9: delivered | C9: 440 | D9: 0 | F9: external-delivery | G9: online | H9: 2024-09-15T00:10:02.297+02:00 | I9: 2024-09-15T00:23:57.598+02:00 | L9: 2 | N9: 13.921683
A10: damejidlo | J10: 2024-09-15T00:19:54.587+02:00 | L10: -1 | N10: 9.8726167
A11: damejidlo | J11: 2024-09-15T00:10:26.487+02:00 | L11: 2 | N11: 15.407483
A12: wolt | E12: Wolt Kurýr | J12: 2024-09-14T23:53:06.751+02:00 | L12: -6 | N12: 8.6211
A13: wolt | E13: Wolt Kurýr | J13: 2024-09-14T23:24:28.424+02:00 | L13: -7 | N13: 7.6314833
A14: wolt | E14: Wolt Kurýr | J14: 2024-09-14T23:19:58.488+02:00 | L14: -10 | N14: 4.63145
A15: damejidlo | J15: 2024-09-14T23:10:44.500+02:00 | L15: 0 | N15: 10.719017
A16: damejidlo | J16: 2024-09-14T23:07:03.490+02:00 | L16: 1 | N16: 10.049033
A17: damejidlo | J17: 2024-09-14T23:05:27.522+02:00 | L17: 0 | N17: 10.436717
A18: bolt | E18: Olga | J18: 2024-09-14T22:55:38.379+02:00 | L18: -13 | N18: 1.2670667
A19: damejidlo | J19: 2024-09-14T22:58:05.489+02:00 | L19: 1 | N19: 12.05605
A20: damejidlo | J20: 2024-09-14T22:53:13.008+02:00 | L20: 5 | N20: 15.21935
A21: damejidlo | N21: 12.421783
A22: manual | J22: 2024-09-14T22:40:09.177+02:00 | L22: 2 | N22: 7.90375
A23: generic | J23: 2024-09-14T22:30:48.168+02:00 | L23: -10 | N23: 7.7170333
A24: damejidlo | N24: 7.7303167
A25: generic | J25: 2024-09-14T22:09:53.153+02:00 | L25: -8 | N25: 10.818733
A26: damejidlo | J26: 2024-09-14T22:03:54.508+02:00 | L26: 0 | N26: 8.8622
A27: wolt | E27: Wolt Kurýr | N27: 9.5138333
A28: wolt | E28: Wolt Kurýr | J28: 2024-09-14T21:44:43.640+02:00 | L28: -5 | N28: 9.4268833
A29: damejidlo | J29: 2024-09-14T21:36:48.500+02:00 | L29: -1 | N29: 10.660567
A30: damejidlo | J30: 2024-09-14T21:30:07.482+02:00 | N30: 7.06655
A31: damejidlo | B31: delivered | C31: 324.5 | D31: 100.5 | F31: external-delivery | G31: online | H31: 2024-09-14T21:15:13.114+02:00 | I31: 2024-09-14T21:28:49.413+02:00 | J31: 2024-09-14T21:28:49.413+02:00 | L31: 3 | N31: 13.604983
A32: generic | B32: delivered | C32: 277 | D32: 52 | E32: Martin Jurkovič | F32: delivery | G32: online | H32: 2024-09-14T21:10:03.528+02:00 | I32: 2024-09-14T21:21:53.179+02:00 | J32: 2024-09-14T21:47:16.204+02:00 | K32: 2024-09-14T21:10:04.248+02:00 | L32: -1 | M32: 0.012 | N32: 11.827517
A33: generic | B33: delivered | C33: 394 | D33: 0 | E33: Martin Jurkovič | F33: delivery | G33: online | H33: 2024-09-14T21:06:05.505+02:00 | I33: 2024-09-14T21:18:40.133+02:00 | J33: 2024-09-14T21:32:06.448+02:00 | K33: 2024-09-14T21:06:06.051+02:00 | L33: -10 | M33: 0.0091 | N33: 12.577133
A34: damejidlo | B34: delivered | C34: 329 | D34: 0 | F34: external-delivery | G34: online | H34: 2024-09-14T20:36:21.082+02:00 | I34: 2024-09-14T20:49:20.393+02:00 | J34: 2024-09-14T20:49:20.393+02:00 | L34: 3 | N34: 12.988517
A35: wolt | B35: delivered | C35: 364 | D35: 0 | E35: Wolt Kurýr | F35: external-delivery | G35: online | H35: 2024-09-14T20:35:31.821+02:00 | I35: 2024-09-14T20:43:30.340+02:00 | J35: 2024-09-14T20:43:30.340+02:00 | L35: -7 | N35: 7.9753167
A36: wolt | B36: delivered | C36: 311 | D36: 0 | E36: Wolt Kurýr | F36: external-delivery | G36: online | H36: 2024-09-14T20:28:57.222+02:00 | I36: 2024-09-14T20:39:51.641+02:00 | J36: 2024-09-14T20:39:51.641+02:00 | L36: -4 | N36: 10.906983
A37: manual | B37: delivered | C37: 368 | D37: 0 | F37: pickup | G37: cash | H37: 2024-09-14T20:27:34.064+02:00 | I37: 2024-09-14T20:37:37.135+02:00 | J37: 2024-09-14T20:37:37.135+02:00 | L37: 5 | N37: 10.051183
A38: wolt | B38: delivered | C38: 129 | D38: 0 | E38: Wolt Kurýr | F38: external-delivery | G38: online | H38: 2024-09-14T20:06:24.089+02:00 | I38: 2024-09-14T20:15:14.342+02:00 | J38: 2024-09-14T20:15:14.342+02:00 | L38: -13 | N38: 8.83755
A39: damejidlo | B39: delivered | C39: 303 | D39: 0 | F39: external-delivery | G39: online | H39: 2024-09-14T20:06:23.112+02:00 | I39: 2024-09-14T20:14:52.336+02:00 | J39: 2024-09-14T20:14:52.336+02:00 | L39: 0 | N39: 8.4870667
A40: wolt | B40: delivered | C40: 329 | D40: 0 | E40: Wolt Kurýr | F40: external-delivery | G40: online | H40: 2024-09-14T19:30:41.299+02:00 | I40: 2024-09-14T20:02:41.348+02:00 | J40: 2024-09-14T20:02:41.348+02:00 | L40: 17 | N40: 32.000817
...

Sheet HR
B1: Vlož Souhrn mzdy | C1: =IFERROR(__xludf.DUMMYFUNCTION("IMPORTRANGE(""1TpIiNTfR1pnpn85VWQTTdvQ2Xcr0GStmWJ2UvfKxG_A"", ""Mzdy!A1:Z200"")"),"#REF!") -> #REF!
A4: Manažeři | B4: Zamestnanci pobocky
A5: =IF(AND(B5<>"", C5=TRUE, E5=Report!$B$1), B5, "") -> #REF! | B5: =IF(OR(E5=Report!$B$1, F5=Report!$B$1, G5=Report!$B$1, H5=Report!$B$1), D5, "") -> #REF!
A6: =IF(AND(B6<>"", C6=TRUE, E6=Report!$B$1), B6, "") -> #REF! | B6: =IF(OR(E6=Report!$B$1, F6=Report!$B$1, G6=Report!$B$1, H6=Report!$B$1), D6, "") -> #REF!
A7: =IF(AND(B7<>"", C7=TRUE, E7=Report!$B$1), B7, "") -> #REF! | B7: =IF(OR(E7=Report!$B$1, F7=Report!$B$1, G7=Report!$B$1, H7=Report!$B$1), D7, "") -> #REF!
A8: =IF(AND(B8<>"", C8=TRUE, E8=Report!$B$1), B8, "") -> #REF! | B8: =IF(OR(E8=Report!$B$1, F8=Report!$B$1, G8=Report!$B$1, H8=Report!$B$1), D8, "") -> #REF!
A9: =IF(AND(B9<>"", C9=TRUE, E9=Report!$B$1), B9, "") -> #REF! | B9: =IF(OR(E9=Report!$B$1, F9=Report!$B$1, G9=Report!$B$1, H9=Report!$B$1), D9, "") -> #REF!
A10: =IF(AND(B10<>"", C10=TRUE, E10=Report!$B$1), B10, "") -> #REF!
A11: =IF(AND(B11<>"", C11=TRUE, E11=Report!$B$1), B11, "") -> #REF!
A12: =IF(AND(B12<>"", C12=TRUE, E12=Report!$B$1), B12, "") -> #REF!
A13: =IF(AND(B13<>"", C13=TRUE, E13=Report!$B$1), B13, "") -> #REF!
A14: =IF(AND(B14<>"", C14=TRUE, E14=Report!$B$1), B14, "") -> #REF!
A15: =IF(AND(B15<>"", C15=TRUE, E15=Report!$B$1), B15, "") -> #REF!
A16: =IF(AND(B16<>"", C16=TRUE, E16=Report!$B$1), B16, "") -> #REF!
A17: =IF(AND(B17<>"", C17=TRUE, E17=Report!$B$1), B17, "") -> #REF!
A18: =IF(AND(B18<>"", C18=TRUE, E18=Report!$B$1), B18, "") -> #REF!
A19: =IF(AND(B19<>"", C19=TRUE, E19=Report!$B$1), B19, "") -> #REF!
A20: =IF(AND(B20<>"", C20=TRUE, E20=Report!$B$1), B20, "") -> #REF!
A21: =IF(AND(B21<>"", C21=TRUE, E21=Report!$B$1), B21, "") -> #REF!
... A30: =IF(AND(B30<>"", C30=TRUE, E30=Report!$B$1), B30, "") -> #REF!
A31: =IF(AND(B31<>"", C31=TRUE, E31=Report!$B$1), B31, "") -> #REF! | B31: =IF(OR(E31=Report!$B$1, F31=Report!$B$1, G31=Report!$B$1, H31=Report!$B$1), D31, "") -> #REF!
A32: =IF(AND(B32<>"", C32=TRUE, E32=Report!$B$1), B32, "") -> #REF! | B32: =IF(OR(E32=Report!$B$1, F32=Report!$B$1, G32=Report!$B$1, H32=Report!$B$1), D32, "") -> #REF!
A33: =IF(AND(B33<>"", C33=TRUE, E33=Report!$B$1), B33, "") -> #REF! | B33: =IF(OR(E33=Report!$B$1, F33=Report!$B$1, G33=Report!$B$1, H33=Report!$B$1), D33, "") -> #REF!
A34: =IF(AND(B34<>"", C34=TRUE, E34=Report!$B$1), B34, "") -> #REF! | B34: =IF(OR(E34=Report!$B$1, F34=Report!$B$1, G34=Report!$B$1, H34=Report!$B$1), D34, "") -> #REF!
A35: =IF(AND(B35<>"", C35=TRUE, E35=Report!$B$1), B35, "") -> #REF! | B35: =IF(OR(E35=Report!$B$1, F35=Report!$B$1, G35=Report!$B$1, H35=Report!$B$1), D35, "") -> #REF!
A36: =IF(AND(B36<>"", C36=TRUE, E36=Report!$B$1), B36, "") -> #REF! | B36: =IF(OR(E36=Report!$B$1, F36=Report!$B$1, G36=Report!$B$1, H36=Report!$B$1), D36, "") -> #REF!
A37: =IF(AND(B37<>"", C37=TRUE, E37=Report!$B$1), B37, "") -> #REF! | B37: =IF(OR(E37=Report!$B$1, F37=Report!$B$1, G37=Report!$B$1, H37=Report!$B$1), D37, "") -> #REF!
A38: =IF(AND(B38<>"", C38=TRUE, E38=Report!$B$1), B38, "") -> #REF! | B38: =IF(OR(E38=Report!$B$1, F38=Report!$B$1, G38=Report!$B$1, H38=Report!$B$1), D38, "") -> #REF!
A39: =IF(AND(B39<>"", C39=TRUE, E39=Report!$B$1), B39, "") -> #REF! | B39: =IF(OR(E39=Report!$B$1, F39=Report!$B$1, G39=Report!$B$1, H39=Report!$B$1), D39, "") -> #REF!
A40: =IF(AND(B40<>"", C40=TRUE, E40=Report!$B$1), B40, "") -> #REF! | B40: =IF(OR(E40=Report!$B$1, F40=Report!$B$1, G40=Report!$B$1, H40=Report!$B$1), D40, "") -> #REF!
A41: =IF(AND(B41<>"", C41=TRUE, E41=Report!$B$1), B41, "") -> #REF! | B41: =IF(OR(E41=Report!$B$1, F41=Report!$B$1, G41=Report!$B$1, H41=Report!$B$1), D41, "") -> #REF!
A42: =IF(AND(B42<>"", C42=TRUE, E42=Report!$B$1), B42, "") -> #REF! | B42: =IF(OR(E42=Report!$B$1, F42=Report!$B$1, G42=Report!$B$1, H42=Report!$B$1), D42, "") -> #REF!
A43: =IF(AND(B43<>"", C43=TRUE, E43=Report!$B$1), B43, "") -> #REF! | B43: =IF(OR(E43=Report!$B$1, F43=Report!$B$1, G43=Report!$B$1, H43=Report!$B$1), D43, "") -> #REF!
B44: =IF(OR(E44=Report!$B$1, F44=Report!$B$1, G44=Report!$B$1, H44=Report!$B$1), D44, "") -> #REF!
B45: =IF(OR(E45=Report!$B$1, F45=Report!$B$1, G45=Report!$B$1, H45=Report!$B$1), D45, "") -> #REF!
B46: =IF(OR(E46=Report!$B$1, F46=Report!$B$1, G46=Report!$B$1, H46=Report!$B$1), D46, "") -> #REF!
B47: =IF(OR(E47=Report!$B$1, F47=Report!$B$1, G47=Report!$B$1, H47=Report!$B$1), D47, "") -> #REF!
B48: =IF(OR(E48=Report!$B$1, F48=Report!$B$1, G48=Report!$B$1, H48=Report!$B$1), D48, "") -> #REF!
B49: =IF(OR(E49=Report!$B$1, F49=Report!$B$1, G49=Report!$B$1, H49=Report!$B$1), D49, "") -> #REF!
B50: =IF(OR(E50=Report!$B$1, F50=Report!$B$1, G50=Report!$B$1, H50=Report!$B$1), D50, "") -> #REF!
...

Sheet Bolevec
B1: Bolevec | C1: 46099 | D1: Vyber datum <----------> | E1: 46099 | F1: COL | I1: Tržba | L1: Online Platby
F2: 0.80835167 | I2: 12859 | L2: Wolt | M2: 0
B3: =CHOOSE(WEEKDAY(C1), "Neděle", "Pondělí", "Úterý", "Středa", "Čtvrtek", "Pátek", "Sobota") -> Středa | D3: =CHOOSE(WEEKDAY(E1), "Neděle", "Pondělí", "Úterý", "Středa", "Čtvrtek", "Pátek", "Sobota") -> Středa | L3: Bolt | M3: 1055
L4: Dáme jídlo | M4: 4305
B5: Celkem hodin Instor | F5: Celkem hodin Kurýr | L5: Web | M5: 2288
L6: Wolt drive cash | M6: 0
B7: =TEXT(SUMPRODUCT((IFERROR(LEFT(D10:D30, FIND(":", D10:D30) - 1) * 60, 0) + IFERROR(MID(D10:D30, FIND(":", D10:D30) + 1, LEN(D10:D30) - FIND(":", D10:D30)), 0))), "[h]:mm")/60 -> 23.5 | F7: =TEXT(SUMPRODUCT((IFERROR(LEFT(H10:H30, FIND(":", H10:H30) - 1) * 60, 0) + IFERROR(MID(H10:H30, FIND(":", H10:H30) + 1, LEN(H10:H30) - FIND(":", H10:H30)), 0))), "[h]:mm")/60 -> 13 | L7: DJ Cash | M7: 692
B8: Instor | F8: Kurýr | J8: Pokladna | L8: Hotovost
F9: Jméno | G9: Počet dní | H9: Počet hodin | I9: Počet rozvozů | J9: 0 | L9: Terminál | M9: 2252
B10: Roth Stanislav ml. | C10: 1 | D10: 10:00 | E10: 29:00 | F10: Kneblová Anna | G10: 1 | H10: 6:00 | I10: 2 | L10: Stravenky | M10: 0
B11: Rothová Anastasia | C11: 1 | D11: 1:00 | E11: 23:00 | F11: Světlík František | G11: 1 | H11: 7:00 | I11: 4 | L11: Hotovost | M11: 2719
B12: Vostrý Daniel | C12: 1 | D12: 4:00 | E12: 13:00 | L12: Výdaje
B13: Tůma Vladimír | C13: 1 | D13: 8:30 | E13: 13:00 | L13: Benzín | M13: 0
E14: 7:00 | L14: Auta | M14: 0
E15: 7:00 | L15: Suroviny | M15: 0
L16: Ostatní | M16: 0
L17: PHM - soukromé | M17: 240
J19: Zrušené obj. ks | K19: Zrušené obj. $ | L19: Počet zpožděných našich rozvozů +5 min | M19: Průměrný make Time
J21: 0 | K21: 0 | L21: 1 | M21: 14 min 03 s
J22: počet výdajových dokadů | K22: Počet nezrušených celkem | L22: Počet našich rozvozů | M22: Počet pozdě přiřazeným WoltDrive 5+
J24: 2 | K24: 39 | L24: 6 | M24: 3
J25: Woltrdive zpožděný kvůli našemu pozdnímu přiřazení | L25: % zpožděných našich rozvozů +5 min | M25: Počet zpožděných Woltdrivem
J27: 1 | L27: 0.16666667 | M27: 0
K28: Počet Wolt drive | L28: % doručených včas | M28: % zpožděných Woltdrivem
K30: 0 | L30: 0.83333333 | M30: 0
